Workbook
Name اسم: 'مجموع الفترتين'!$A$11:$C$542
Name الاسماء: 'الفترة الاولى'!$A$11:$C$510
Name امتحانات: 'مجموع الفترتين'!$A$11:$A$430
Name بيان: 'مجموع الفترتين'!$C$11:$AR$1706
Name تسلسل: 'الفترة الاولى'!$A$11:$A$723
Name درجات: 'الفترة الاولى'!$C$11:$EO$510

Sheet مجموع الفترتين
A1: دولة ليبيا
A2: وزارة التربية والتعليم
A3: إدارة الإمتحانات
A4: ='الفترة الاولى'!A5 -> كشف رصد النتائج النهائية للصف التاسع من مرحلة التعليم الاساسي 1446 - 1447 هجرية الموافق 2025 - 2026 ميلادية
A5: ='الفترة الاولى'!A6:F6 -> المدرسة / | C5: ='الفترة الاولى'!$C$6 -> سهول العلم للتعليم الخاص
A6: رقم مسلسل | B6: رقم القيد | C6: اسم التلميذ بالكامل | D6: المــــــــــــــــــــــــــــواد الدراسيــــــــــــــــــــــــــــــــــــــــــــــــــــــــة
D7: ='الفترة الاولى'!E8 -> التربية الإسلامية | F7: ='الفترة الاولى'!G8 -> 2 | G7: ='الفترة الاولى'!H8 -> النحو والقراءة والنصوص | I7: ='الفترة الاولى'!J8 -> 4 | J7: ='الفترة الاولى'!K8 -> الكتابة (الخط والاملاء والخط ) | L7: ='الفترة الاولى'!M8 -> 2 | M7: ='الفترة الاولى'!N8 -> الإنجليزي | O7: ='الفترة الاولى'!P8 -> 4 | P7: ='الفترة الاولى'!Q8 -> الحاسوب | R7: ='الفترة الاولى'!S8 -> 2 | S7: ='الفترة الاولى'!T8 -> الرياضيات | U7: ='الفترة الاولى'!V8 -> 5 | V7: ='الفترة الاولى'!W8 -> العلوم | X7: ='الفترة الاولى'!Y8 -> 5 | Y7: ='الفترة الاولى'!Z8 -> التاريخ | AA7: ='الفترة الاولى'!AB8 -> 2 | AB7: ='الفترة الاولى'!AC8 -> الجغرافيا | AD7: ='الفترة الاولى'!AE8 -> 2 | AE7: ='الفترة الاولى'!AF8 -> 0 | AG7: ='الفترة الاولى'!AH8 -> 0
D8: الفترة الاولى | E8: الفترة الثانية | F8: المجموع | G8: الفترة الاولى | H8: الفترة الثانية | I8: المجموع | J8: الفترة الاولى | K8: الفترة الثانية | L8: المجموع | M8: الفترة الاولى | N8: الفترة الثانية | O8: المجموع | P8: الفترة الاولى | Q8: الفترة الثانية | R8: المجموع | S8: الفترة الاولى | T8: الفترة الثانية | U8: المجموع | V8: الفترة الاولى | W8: الفترة الثانية | X8: المجموع | Y8: الفترة الاولى | Z8: الفترة الثانية | AA8: المجموع | AB8: الفترة الاولى | AC8: الفترة الثانية | AD8: المجموع | AE8: الفترة الاولى | AF8: الفترة الثانية | AG8: المجموع
D9: =F7*0.15*40 -> 12 | E9: =F7*0.15*40 -> 12 | F9: =SUM(D9:E9) -> 24 | G9: =I7*0.15*40 -> 24 | H9: =I7*0.15*40 -> 24 | I9: =SUM(G9:H9) -> 48 | J9: =L7*0.15*40 -> 12 | K9: =L7*0.15*40 -> 12 | L9: =SUM(J9:K9) -> 24 | M9: =O7*0.15*40 -> 24 | N9: =O7*0.15*40 -> 24 | O9: =SUM(M9:N9) -> 48 | P9: =R7*0.15*40 -> 12 | Q9: =R7*0.15*40 -> 12 | R9: =SUM(P9:Q9) -> 24 | S9: =U7*0.15*40 -> 30 | T9: =U7*0.15*40 -> 30 | U9: =SUM(S9:T9) -> 60 | V9: =X7*0.15*40 -> 30 | W9: =X7*0.15*40 -> 30 | X9: =SUM(V9:W9) -> 60 | Y9: =AA7*0.15*40 -> 12 | Z9: =AA7*0.15*40 -> 12 | AA9: =SUM(Y9:Z9) -> 24 | AB9: =AD7*0.15*40 -> 12 | AC9: =AD7*0.15*40 -> 12 | AD9: =SUM(AB9:AC9) -> 24 | AE9: =AG7*0.15*40 -> 0 | AF9: =AG7*0.15*40 -> 0 | AG9: =SUM(AE9:AF9) -> 0
A11: 1 | B11: =IFERROR(VLOOKUP(A11,الاسماء,2,0),"") -> 0 | C11: =IFERROR(VLOOKUP(A11,الاسماء,3,0),"") -> احمد توفيق احمد وحيده | D11: =IFERROR(VLOOKUP($C11,درجات,5,0),0) -> 10 | E11: =IFERROR(VLOOKUP($C11,درجات,43,0),0) -> 10 | F11: =SUM(D11:E11) -> 20 | G11: =IFERROR(VLOOKUP($C11,درجات,8,0),0) -> 17 | H11: =IFERROR(VLOOKUP($C11,درجات,46,0),0) -> 18 | I11: =SUM(G11:H11) -> 35 | J11: =IFERROR(VLOOKUP($C11,درجات,11,0),0) -> 8 | K11: =IFERROR(VLOOKUP($C11,درجات,49,0),0) -> 9 | L11: =SUM(J11:K11) -> 17 | M11: =IFERROR(VLOOKUP($C11,درجات,14,0),0) -> 19 | N11: =IFERROR(VLOOKUP($C11,درجات,52,0),0) -> 20 | O11: =SUM(M11:N11) -> 39 | P11: =IFERROR(VLOOKUP($C11,درجات,17,0),0) -> 11 | Q11: =IFERROR(VLOOKUP($C11,درجات,55,0),0) -> 11 | R11: =SUM(P11:Q11) -> 22 | S11: =IFERROR(VLOOKUP($C11,درجات,20,0),0) -> 12 | T11: =IFERROR(VLOOKUP($C11,درجات,58,0),0) -> 12 | U11: =SUM(S11:T11) -> 24 | V11: =IFERROR(VLOOKUP($C11,درجات,23,0),0) -> 17 | W11: =IFERROR(VLOOKUP($C11,درجات,61,0),0) -> 18 | X11: =SUM(V11:W11) -> 35 | Y11: =IFERROR(VLOOKUP($C11,درجات,26,0),0) -> 9 | Z11: =IFERROR(VLOOKUP($C11,درجات,64,0),0) -> 9 | AA11: =SUM(Y11:Z11) -> 18 | AB11: =IFERROR(VLOOKUP($C11,درجات,29,0),0) -> 9 | AC11: =IFERROR(VLOOKUP($C11,درجات,67,0),0) -> 7 | AD11: =SUM(AB11:AC11) -> 16 | AE11: =IFERROR(VLOOKUP($C11,درجات,32,0),0) -> 0 | AF11: =IFERROR(VLOOKUP($C11,درجات,70,0),0) -> 0 | AG11: =SUM(AE11:AF11) -> 0
A12: 2 | B12: =IFERROR(VLOOKUP(A12,الاسماء,2,0),0) -> 0 | C12: =IFERROR(VLOOKUP(A12,الاسماء,3,0),"") -> اسلام محمد عوض الحداد | D12: =IFERROR(VLOOKUP($C12,درجات,5,0),0) -> 12 | E12: =IFERROR(VLOOKUP($C12,درجات,43,0),0) -> 12 | F12: =SUM(D12:E12) -> 24 | G12: =IFERROR(VLOOKUP($C12,درجات,8,0),0) -> 20 | H12: =IFERROR(VLOOKUP($C12,درجات,46,0),0) -> 22 | I12: =SUM(G12:H12) -> 42 | J12: =IFERROR(VLOOKUP($C12,درجات,11,0),0) -> 11 | K12: =IFERROR(VLOOKUP($C12,درجات,49,0),0) -> 11 | L12: =SUM(J12:K12) -> 22 | M12: =IFERROR(VLOOKUP($C12,درجات,14,0),0) -> 22 | N12: =IFERROR(VLOOKUP($C12,درجات,52,0),0) -> 23 | O12: =SUM(M12:N12) -> 45 | P12: =IFERROR(VLOOKUP($C12,درجات,17,0),0) -> 12 | Q12: =IFERROR(VLOOKUP($C12,درجات,55,0),0) -> 12 | R12: =SUM(P12:Q12) -> 24 | S12: =IFERROR(VLOOKUP($C12,درجات,20,0),0) -> 21 | T12: =IFERROR(VLOOKUP($C12,درجات,58,0),0) -> 25 | U12: =SUM(S12:T12) -> 46 | V12: =IFERROR(VLOOKUP($C12,درجات,23,0),0) -> 25 | W12: =IFERROR(VLOOKUP($C12,درجات,61,0),0) -> 28 | X12: =SUM(V12:W12) -> 53 | Y12: =IFERROR(VLOOKUP($C12,درجات,26,0),0) -> 12 | Z12: =IFERROR(VLOOKUP($C12,درجات,64,0),0) -> 12 | AA12: =SUM(Y12:Z12) -> 24 | AB12: =IFERROR(VLOOKUP($C12,درجات,29,0),0) -> 11 | AC12: =IFERROR(VLOOKUP($C12,درجات,67,0),0) -> 11 | AD12: =SUM(AB12:AC12) -> 22 | AE12: =IFERROR(VLOOKUP($C12,درجات,32,0),0) -> 0 | AF12: =IFERROR(VLOOKUP($C12,درجات,70,0),0) -> 0 | AG12: =SUM(AE12:AF12) -> 0
A13: 3 | B13: =IFERROR(VLOOKUP(A13,الاسماء,2,0),"") -> 0 | C13: =IFERROR(VLOOKUP(A13,الاسماء,3,0),"") -> اسيل فاروق فيصل ابو الطويرات | D13: =IFERROR(VLOOKUP($C13,درجات,5,0),0) -> 9 | E13: =IFERROR(VLOOKUP($C13,درجات,43,0),0) -> 10 | F13: =SUM(D13:E13) -> 19 | G13: =IFERROR(VLOOKUP($C13,درجات,8,0),0) -> 15 | H13: =IFERROR(VLOOKUP($C13,درجات,46,0),0) -> 20 | I13: =SUM(G13:H13) -> 35 | J13: =IFERROR(VLOOKUP($C13,درجات,11,0),0) -> 9 | K13: =IFERROR(VLOOKUP($C13,درجات,49,0),0) -> 8 | L13: =SUM(J13:K13) -> 17 | M13: =IFERROR(VLOOKUP($C13,درجات,14,0),0) -> 20 | N13: =IFERROR(VLOOKUP($C13,درجات,52,0),0) -> 21 | O13: =SUM(M13:N13) -> 41 | P13: =IFERROR(VLOOKUP($C13,درجات,17,0),0) -> 11 | Q13: =IFERROR(VLOOKUP($C13,درجات,55,0),0) -> 11 | R13: =SUM(P13:Q13) -> 22 | S13: =IFERROR(VLOOKUP($C13,درجات,20,0),0) -> 12 | T13: =IFERROR(VLOOKUP($C13,درجات,58,0),0) -> 13 | U13: =SUM(S13:T13) -> 25 | V13: =IFERROR(VLOOKUP($C13,درجات,23,0),0) -> 18 | W13: =IFERROR(VLOOKUP($C13,درجات,61,0),0) -> 21 | X13: =SUM(V13:W13) -> 39 | Y13: =IFERROR(VLOOKUP($C13,درجات,26,0),0) -> 8 | Z13: =IFERROR(VLOOKUP($C13,درجات,64,0),0) -> 8 | AA13: =SUM(Y13:Z13) -> 16 | AB13: =IFERROR(VLOOKUP($C13,درجات,29,0),0) -> 10 | AC13: =IFERROR(VLOOKUP($C13,درجات,67,0),0) -> 9 | AD13: =SUM(AB13:AC13) -> 19 | AE13: =IFERROR(VLOOKUP($C13,درجات,32,0),0) -> 0 | AF13: =IFERROR(VLOOKUP($C13,درجات,70,0),0) -> 0 | AG13: =SUM(AE13:AF13) -> 0
A14: 4 | B14: =IFERROR(VLOOKUP(A14,الاسماء,2,0),"") -> 0 | C14: =IFERROR(VLOOKUP(A14,الاسماء,3,0),"") -> انس محمد عبدالكريم ابوحميده | D14: =IFERROR(VLOOKUP($C14,درجات,5,0),0) -> 12 | E14: =IFERROR(VLOOKUP($C14,درجات,43,0),0) -> 12 | F14: =SUM(D14:E14) -> 24 | G14: =IFERROR(VLOOKUP($C14,درجات,8,0),0) -> 21 | H14: =IFERROR(VLOOKUP($C14,درجات,46,0),0) -> 23 | I14: =SUM(G14:H14) -> 44 | J14: =IFERROR(VLOOKUP($C14,درجات,11,0),0) -> 10 | K14: =IFERROR(VLOOKUP($C14,درجات,49,0),0) -> 11 | L14: =SUM(J14:K14) -> 21 | M14: =IFERROR(VLOOKUP($C14,درجات,14,0),0) -> 24 | N14: =IFERROR(VLOOKUP($C14,درجات,52,0),0) -> 22 | O14: =SUM(M14:N14) -> 46 | P14: =IFERROR(VLOOKUP($C14,درجات,17,0),0) -> 12 | Q14: =IFERROR(VLOOKUP($C14,درجات,55,0),0) -> 12 | R14: =SUM(P14:Q14) -> 24 | S14: =IFERROR(VLOOKUP($C14,درجات,20,0),0) -> 22 | T14: =IFERROR(VLOOKUP($C14,درجات,58,0),0) -> 25 | U14: =SUM(S14:T14) -> 47 | V14: =IFERROR(VLOOKUP($C14,درجات,23,0),0) -> 26 | W14: =IFERROR(VLOOKUP($C14,درجات,61,0),0) -> 29 | X14: =SUM(V14:W14) -> 55 | Y14: =IFERROR(VLOOKUP($C14,درجات,26,0),0) -> 12 | Z14: =IFERROR(VLOOKUP($C14,درجات,64,0),0) -> 12 | AA14: =SUM(Y14:Z14) -> 24 | AB14: =IFERROR(VLOOKUP($C14,درجات,29,0),0) -> 11 | AC14: =IFERROR(VLOOKUP($C14,درجات,67,0),0) -> 12 | AD14: =SUM(AB14:AC14) -> 23 | AE14: =IFERROR(VLOOKUP($C14,درجات,32,0),0) -> 0 | AF14: =IFERROR(VLOOKUP($C14,درجات,70,0),0) -> 0 | AG14: =SUM(AE14:AF14) -> 0
A15: 5 | B15: =IFERROR(VLOOKUP(A15,الاسماء,2,0),"") -> 0 | C15: =IFERROR(VLOOKUP(A15,الاسماء,3,0),"") -> إيناس فاروق فيصل ابو الطويرات | D15: =IFERROR(VLOOKUP($C15,درجات,5,0),0) -> 10 | E15: =IFERROR(VLOOKUP($C15,درجات,43,0),0) -> 10 | F15: =SUM(D15:E15) -> 20 | G15: =IFERROR(VLOOKUP($C15,درجات,8,0),0) -> 15 | H15: =IFERROR(VLOOKUP($C15,درجات,46,0),0) -> 17 | I15: =SUM(G15:H15) -> 32 | J15: =IFERROR(VLOOKUP($C15,درجات,11,0),0) -> 9 | K15: =IFERROR(VLOOKUP($C15,درجات,49,0),0) -> 8 | L15: =SUM(J15:K15) -> 17 | M15: =IFERROR(VLOOKUP($C15,درجات,14,0),0) -> 24 | N15: =IFERROR(VLOOKUP($C15,درجات,52,0),0) -> 20 | O15: =SUM(M15:N15) -> 44 | P15: =IFERROR(VLOOKUP($C15,درجات,17,0),0) -> 11 | Q15: =IFERROR(VLOOKUP($C15,درجات,55,0),0) -> 12 | R15: =SUM(P15:Q15) -> 23 | S15: =IFERROR(VLOOKUP($C15,درجات,20,0),0) -> 12 | T15: =IFERROR(VLOOKUP($C15,درجات,58,0),0) -> 12 | U15: =SUM(S15:T15) -> 24 | V15: =IFERROR(VLOOKUP($C15,درجات,23,0),0) -> 19 | W15: =IFERROR(VLOOKUP($C15,درجات,61,0),0) -> 23 | X15: =SUM(V15:W15) -> 42 | Y15: =IFERROR(VLOOKUP($C15,درجات,26,0),0) -> 8 | Z15: =IFERROR(VLOOKUP($C15,درجات,64,0),0) -> 8 | AA15: =SUM(Y15:Z15) -> 16 | AB15: =IFERROR(VLOOKUP($C15,درجات,29,0),0) -> 9 | AC15: =IFERROR(VLOOKUP($C15,درجات,67,0),0) -> 9 | AD15: =SUM(AB15:AC15) -> 18 | AE15: =IFERROR(VLOOKUP($C15,درجات,32,0),0) -> 0 | AF15: =IFERROR(VLOOKUP($C15,درجات,70,0),0) -> 0 | AG15: =SUM(AE15:AF15) -> 0
A16: 6 | B16: =IFERROR(VLOOKUP(A16,الاسماء,2,0),"") -> 0 | C16: =IFERROR(VLOOKUP(A16,الاسماء,3,0),"") -> جمعة خيرى عبدالله الدرهوبي | D16: =IFERROR(VLOOKUP($C16,درجات,5,0),0) -> 10 | E16: =IFERROR(VLOOKUP($C16,درجات,43,0),0) -> 11 | F16: =SUM(D16:E16) -> 21 | G16: =IFERROR(VLOOKUP($C16,درجات,8,0),0) -> 18 | H16: =IFERROR(VLOOKUP($C16,درجات,46,0),0) -> 17 | I16: =SUM(G16:H16) -> 35 | J16: =IFERROR(VLOOKUP($C16,درجات,11,0),0) -> 8 | K16: =IFERROR(VLOOKUP($C16,درجات,49,0),0) -> 8 | L16: =SUM(J16:K16) -> 16 | M16: =IFERROR(VLOOKUP($C16,درجات,14,0),0) -> 20 | N16: =IFERROR(VLOOKUP($C16,درجات,52,0),0) -> 22 | O16: =SUM(M16:N16) -> 42 | P16: =IFERROR(VLOOKUP($C16,درجات,17,0),0) -> 12 | Q16: =IFERROR(VLOOKUP($C16,درجات,55,0),0) -> 11 | R16: =SUM(P16:Q16) -> 23 | S16: =IFERROR(VLOOKUP($C16,درجات,20,0),0) -> 13 | T16: =IFERROR(VLOOKUP($C16,درجات,58,0),0) -> 17 | U16: =SUM(S16:T16) -> 30 | V16: =IFERROR(VLOOKUP($C16,درجات,23,0),0) -> 19 | W16: =IFERROR(VLOOKUP($C16,درجات,61,0),0) -> 18 | X16: =SUM(V16:W16) -> 37 | Y16: =IFERROR(VLOOKUP($C16,درجات,26,0),0) -> 9 | Z16: =IFERROR(VLOOKUP($C16,درجات,64,0),0) -> 11 | AA16: =SUM(Y16:Z16) -> 20 | AB16: =IFERROR(VLOOKUP($C16,درجات,29,0),0) -> 10 | AC16: =IFERROR(VLOOKUP($C16,درجات,67,0),0) -> 11 | AD16: =SUM(AB16:AC16) -> 21 | AE16: =IFERROR(VLOOKUP($C16,درجات,32,0),0) -> 0 | AF16: =IFERROR(VLOOKUP($C16,درجات,70,0),0) -> 0 | AG16: =SUM(AE16:AF16) -> 0
A17: 7 | B17: =IFERROR(VLOOKUP(A17,الاسماء,2,0),"") -> 0 | C17: =IFERROR(VLOOKUP(A17,الاسماء,3,0),"") -> دنيه علي حمد القبائلى | D17: =IFERROR(VLOOKUP($C17,درجات,5,0),0) -> 12 | E17: =IFERROR(VLOOKUP($C17,درجات,43,0),0) -> 12 | F17: =SUM(D17:E17) -> 24 | G17: =IFERROR(VLOOKUP($C17,درجات,8,0),0) -> 23 | H17: =IFERROR(VLOOKUP($C17,درجات,46,0),0) -> 23 | I17: =SUM(G17:H17) -> 46 | J17: =IFERROR(VLOOKUP($C17,درجات,11,0),0) -> 11 | K17: =IFERROR(VLOOKUP($C17,درجات,49,0),0) -> 11 | L17: =SUM(J17:K17) -> 22 | M17: =IFERROR(VLOOKUP($C17,درجات,14,0),0) -> 23 | N17: =IFERROR(VLOOKUP($C17,درجات,52,0),0) -> 24 | O17: =SUM(M17:N17) -> 47 | P17: =IFERROR(VLOOKUP($C17,درجات,17,0),0) -> 12 | Q17: =IFERROR(VLOOKUP($C17,درجات,55,0),0) -> 12 | R17: =SUM(P17:Q17) -> 24 | S17: =IFERROR(VLOOKUP($C17,درجات,20,0),0) -> 23 | T17: =IFERROR(VLOOKUP($C17,درجات,58,0),0) -> 24 | U17: =SUM(S17:T17) -> 47 | V17: =IFERROR(VLOOKUP($C17,درجات,23,0),0) -> 24 | W17: =IFERROR(VLOOKUP($C17,درجات,61,0),0) -> 29 | X17: =SUM(V17:W17) -> 53 | Y17: =IFERROR(VLOOKUP($C17,درجات,26,0),0) -> 12 | Z17: =IFERROR(VLOOKUP($C17,درجات,64,0),0) -> 11 | AA17: =SUM(Y17:Z17) -> 23 | AB17: =IFERROR(VLOOKUP($C17,درجات,29,0),0) -> 11 | AC17: =IFERROR(VLOOKUP($C17,درجات,67,0),0) -> 12 | AD17: =SUM(AB17:AC17) -> 23 | AE17: =IFERROR(VLOOKUP($C17,درجات,32,0),0) -> 0 | AF17: =IFERROR(VLOOKUP($C17,درجات,70,0),0) -> 0 | AG17: =SUM(AE17:AF17) -> 0
A18: 8 | B18: =IFERROR(VLOOKUP(A18,الاسماء,2,0),"") -> 0 | C18: =IFERROR(VLOOKUP(A18,الاسماء,3,0),"") -> رزان خليل محمد المغربي | D18: =IFERROR(VLOOKUP($C18,درجات,5,0),0) -> 12 | E18: =IFERROR(VLOOKUP($C18,درجات,43,0),0) -> 11 | F18: =SUM(D18:E18) -> 23 | G18: =IFERROR(VLOOKUP($C18,درجات,8,0),0) -> 22 | H18: =IFERROR(VLOOKUP($C18,درجات,46,0),0) -> 23 | I18: =SUM(G18:H18) -> 45 | J18: =IFERROR(VLOOKUP($C18,درجات,11,0),0) -> 10 | K18: =IFERROR(VLOOKUP($C18,درجات,49,0),0) -> 11 | L18: =SUM(J18:K18) -> 21 | M18: =IFERROR(VLOOKUP($C18,درجات,14,0),0) -> 24 | N18: =IFERROR(VLOOKUP($C18,درجات,52,0),0) -> 24 | O18: =SUM(M18:N18) -> 48 | P18: =IFERROR(VLOOKUP($C18,درجات,17,0),0) -> 12 | Q18: =IFERROR(VLOOKUP($C18,درجات,55,0),0) -> 12 | R18: =SUM(P18:Q18) -> 24 | S18: =IFERROR(VLOOKUP($C18,درجات,20,0),0) -> 22 | T18: =IFERROR(VLOOKUP($C18,درجات,58,0),0) -> 22 | U18: =SUM(S18:T18) -> 44 | V18: =IFERROR(VLOOKUP($C18,درجات,23,0),0) -> 26 | W18: =IFERROR(VLOOKUP($C18,درجات,61,0),0) -> 28 | X18: =SUM(V18:W18) -> 54 | Y18: =IFERROR(VLOOKUP($C18,درجات,26,0),0) -> 12 | Z18: =IFERROR(VLOOKUP($C18,درجات,64,0),0) -> 11 | AA18: =SUM(Y18:Z18) -> 23 | AB18: =IFERROR(VLOOKUP($C18,درجات,29,0),0) -> 11 | AC18: =IFERROR(VLOOKUP($C18,درجات,67,0),0) -> 12 | AD18: =SUM(AB18:AC18) -> 23 | AE18: =IFERROR(VLOOKUP($C18,درجات,32,0),0) -> 0 | AF18: =IFERROR(VLOOKUP($C18,درجات,70,0),0) -> 0 | AG18: =SUM(AE18:AF18) -> 0
A19: 9 | B19: =IFERROR(VLOOKUP(A19,الاسماء,2,0),"") -> 0 | C19: =IFERROR(VLOOKUP(A19,الاسماء,3,0),"") -> رفال عبدالحميد سالم القاضي | D19: =IFERROR(VLOOKUP($C19,درجات,5,0),0) -> 11 | E19: =IFERROR(VLOOKUP($C19,درجات,43,0),0) -> 12 | F19: =SUM(D19:E19) -> 23 | G19: =IFERROR(VLOOKUP($C19,درجات,8,0),0) -> 21 | H19: =IFERROR(VLOOKUP($C19,درجات,46,0),0) -> 24 | I19: =SUM(G19:H19) -> 45 | J19: =IFERROR(VLOOKUP($C19,درجات,11,0),0) -> 12 | K19: =IFERROR(VLOOKUP($C19,درجات,49,0),0) -> 12 | L19: =SUM(J19:K19) -> 24 | M19: =IFERROR(VLOOKUP($C19,درجات,14,0),0) -> 24 | N19: =IFERROR(VLOOKUP($C19,درجات,52,0),0) -> 24 | O19: =SUM(M19:N19) -> 48 | P19: =IFERROR(VLOOKUP($C19,درجات,17,0),0) -> 12 | Q19: =IFERROR(VLOOKUP($C19,درجات,55,0),0) -> 12 | R19: =SUM(P19:Q19) -> 24 | S19: =IFERROR(VLOOKUP($C19,درجات,20,0),0) -> 24 | T19: =IFERROR(VLOOKUP($C19,درجات,58,0),0) -> 28 | U19: =SUM(S19:T19) -> 52 | V19: =IFERROR(VLOOKUP($C19,درجات,23,0),0) -> 29 | W19: =IFERROR(VLOOKUP($C19,درجات,61,0),0) -> 28 | X19: =SUM(V19:W19) -> 57 | Y19: =IFERROR(VLOOKUP($C19,درجات,26,0),0) -> 12 | Z19: =IFERROR(VLOOKUP($C19,درجات,64,0),0) -> 12 | AA19: =SUM(Y19:Z19) -> 24 | AB19: =IFERROR(VLOOKUP($C19,درجات,29,0),0) -> 12 | AC19: =IFERROR(VLOOKUP($C19,درجات,67,0),0) -> 12 | AD19: =SUM(AB19:AC19) -> 24 | AE19: =IFERROR(VLOOKUP($C19,درجات,32,0),0) -> 0 | AF19: =IFERROR(VLOOKUP($C19,درجات,70,0),0) -> 0 | AG19: =SUM(AE19:AF19) -> 0
A20: 10 | B20: =IFERROR(VLOOKUP(A20,الاسماء,2,0),"") -> 0 | C20: =IFERROR(VLOOKUP(A20,الاسماء,3,0),"") -> رنا عبدالحميد سيد ابوبكر | D20: =IFERROR(VLOOKUP($C20,درجات,5,0),0) -> 12 | E20: =IFERROR(VLOOKUP($C20,درجات,43,0),0) -> 11 | F20: =SUM(D20:E20) -> 23 | G20: =IFERROR(VLOOKUP($C20,درجات,8,0),0) -> 21 | H20: =IFERROR(VLOOKUP($C20,درجات,46,0),0) -> 22 | I20: =SUM(G20:H20) -> 43 | J20: =IFERROR(VLOOKUP($C20,درجات,11,0),0) -> 9 | K20: =IFERROR(VLOOKUP($C20,درجات,49,0),0) -> 10 | L20: =SUM(J20:K20) -> 19 | M20: =IFERROR(VLOOKUP($C20,درجات,14,0),0) -> 24 | N20: =IFERROR(VLOOKUP($C20,درجات,52,0),0) -> 24 | O20: =SUM(M20:N20) -> 48 | P20: =IFERROR(VLOOKUP($C20,درجات,17,0),0) -> 12 | Q20: =IFERROR(VLOOKUP($C20,درجات,55,0),0) -> 12 | R20: =SUM(P20:Q20) -> 24 | S20: =IFERROR(VLOOKUP($C20,درجات,20,0),0) -> 23 | T20: =IFERROR(VLOOKUP($C20,درجات,58,0),0) -> 24 | U20: =SUM(S20:T20) -> 47 | V20: =IFERROR(VLOOKUP($C20,درجات,23,0),0) -> 29 | W20: =IFERROR(VLOOKUP($C20,درجات,61,0),0) -> 29 | X20: =SUM(V20:W20) -> 58 | Y20: =IFERROR(VLOOKUP($C20,درجات,26,0),0) -> 12 | Z20: =IFERROR(VLOOKUP($C20,درجات,64,0),0) -> 11 | AA20: =SUM(Y20:Z20) -> 23 | AB20: =IFERROR(VLOOKUP($C20,درجات,29,0),0) -> 10 | AC20: =IFERROR(VLOOKUP($C20,درجات,67,0),0) -> 12 | AD20: =SUM(AB20:AC20) -> 22 | AE20: =IFERROR(VLOOKUP($C20,درجات,32,0),0) -> 0 | AF20: =IFERROR(VLOOKUP($C20,درجات,70,0),0) -> 0 | AG20: =SUM(AE20:AF20) -> 0
A21: 11 | B21: =IFERROR(VLOOKUP(A21,الاسماء,2,0),"") -> 0 | C21: =IFERROR(VLOOKUP(A21,الاسماء,3,0),"") -> ريناد محمد ابراهيم السلامي | D21: =IFERROR(VLOOKUP($C21,درجات,5,0),0) -> 10 | E21: =IFERROR(VLOOKUP($C21,درجات,43,0),0) -> 11 | F21: =SUM(D21:E21) -> 21 | G21: =IFERROR(VLOOKUP($C21,درجات,8,0),0) -> 18 | H21: =IFERROR(VLOOKUP($C21,درجات,46,0),0) -> 22 | I21: =SUM(G21:H21) -> 40 | J21: =IFERROR(VLOOKUP($C21,درجات,11,0),0) -> 7 | K21: =IFERROR(VLOOKUP($C21,درجات,49,0),0) -> 11 | L21: =SUM(J21:K21) -> 18 | M21: =IFERROR(VLOOKUP($C21,درجات,14,0),0) -> 22 | N21: =IFERROR(VLOOKUP($C21,درجات,52,0),0) -> 24 | O21: =SUM(M21:N21) -> 46 | P21: =IFERROR(VLOOKUP($C21,درجات,17,0),0) -> 11 | Q21: =IFERROR(VLOOKUP($C21,درجات,55,0),0) -> 12 | R21: =SUM(P21:Q21) -> 23 | S21: =IFERROR(VLOOKUP($C21,درجات,20,0),0) -> 18 | T21: =IFERROR(VLOOKUP($C21,درجات,58,0),0) -> 18 | U21: =SUM(S21:T21) -> 36 | V21: =IFERROR(VLOOKUP($C21,درجات,23,0),0) -> 26 | W21: =IFERROR(VLOOKUP($C21,درجات,61,0),0) -> 25 | X21: =SUM(V21:W21) -> 51 | Y21: =IFERROR(VLOOKUP($C21,درجات,26,0),0) -> 11 | Z21: =IFERROR(VLOOKUP($C21,درجات,64,0),0) -> 10 | AA21: =SUM(Y21:Z21) -> 21 | AB21: =IFERROR(VLOOKUP($C21,درجات,29,0),0) -> 11 | AC21: =IFERROR(VLOOKUP($C21,درجات,67,0),0) -> 11 | AD21: =SUM(AB21:AC21) -> 22 | AE21: =IFERROR(VLOOKUP($C21,درجات,32,0),0) -> 0 | AF21: =IFERROR(VLOOKUP($C21,درجات,70,0),0) -> 0 | AG21: =SUM(AE21:AF21) -> 0
A22: 12 | B22: =IFERROR(VLOOKUP(A22,الاسماء,2,0),"") -> 0 | C22: =IFERROR(VLOOKUP(A22,الاسماء,3,0),"") -> عبدالرحيم عبدالمولي الجمل | D22: =IFERROR(VLOOKUP($C22,درجات,5,0),0) -> 7 | E22: =IFERROR(VLOOKUP($C22,درجات,43,0),0) -> 8 | F22: =SUM(D22:E22) -> 15 | G22: =IFERROR(VLOOKUP($C22,درجات,8,0),0) -> 12 | H22: =IFERROR(VLOOKUP($C22,درجات,46,0),0) -> 14 | I22: =SUM(G22:H22) -> 26 | J22: =IFERROR(VLOOKUP($C22,درجات,11,0),0) -> 5 | K22: =IFERROR(VLOOKUP($C22,درجات,49,0),0) -> 7 | L22: =SUM(J22:K22) -> 12 | M22: =IFERROR(VLOOKUP($C22,درجات,14,0),0) -> 19 | N22: =IFERROR(VLOOKUP($C22,درجات,52,0),0) -> 20 | O22: =SUM(M22:N22) -> 39 | P22: =IFERROR(VLOOKUP($C22,درجات,17,0),0) -> 11 | Q22: =IFERROR(VLOOKUP($C22,درجات,55,0),0) -> 11 | R22: =SUM(P22:Q22) -> 22 | S22: =IFERROR(VLOOKUP($C22,درجات,20,0),0) -> 14 | T22: =IFERROR(VLOOKUP($C22,درجات,58,0),0) -> 13 | U22: =SUM(S22:T22) -> 27 | V22: =IFERROR(VLOOKUP($C22,درجات,23,0),0) -> 16 | W22: =IFERROR(VLOOKUP($C22,درجات,61,0),0) -> 16 | X22: =SUM(V22:W22) -> 32 | Y22: =IFERROR(VLOOKUP($C22,درجات,26,0),0) -> 9 | Z22: =IFERROR(VLOOKUP($C22,درجات,64,0),0) -> 7 | AA22: =SUM(Y22:Z22) -> 16 | AB22: =IFERROR(VLOOKUP($C22,درجات,29,0),0) -> 10 | AC22: =IFERROR(VLOOKUP($C22,درجات,67,0),0) -> 9 | AD22: =SUM(AB22:AC22) -> 19 | AE22: =IFERROR(VLOOKUP($C22,درجات,32,0),0) -> 0 | AF22: =IFERROR(VLOOKUP($C22,درجات,70,0),0) -> 0 | AG22: =SUM(AE22:AF22) -> 0
A23: 13 | B23: =IFERROR(VLOOKUP(A23,الاسماء,2,0),"") -> 0 | C23: =IFERROR(VLOOKUP(A23,الاسماء,3,0),"") -> عبدالله احمد سالم العزيبي | D23: =IFERROR(VLOOKUP($C23,درجات,5,0),0) -> 12 | E23: =IFERROR(VLOOKUP($C23,درجات,43,0),0) -> 10 | F23: =SUM(D23:E23) -> 22 | G23: =IFERROR(VLOOKUP($C23,درجات,8,0),0) -> 16 | H23: =IFERROR(VLOOKUP($C23,درجات,46,0),0) -> 12 | I23: =SUM(G23:H23) -> 28 | J23: =IFERROR(VLOOKUP($C23,درجات,11,0),0) -> 7 | K23: =IFERROR(VLOOKUP($C23,درجات,49,0),0) -> 8 | L23: =SUM(J23:K23) -> 15 | M23: =IFERROR(VLOOKUP($C23,درجات,14,0),0) -> 22 | N23: =IFERROR(VLOOKUP($C23,درجات,52,0),0) -> 22 | O23: =SUM(M23:N23) -> 44 | P23: =IFERROR(VLOOKUP($C23,درجات,17,0),0) -> 12 | Q23: =IFERROR(VLOOKUP($C23,درجات,55,0),0) -> 11 | R23: =SUM(P23:Q23) -> 23 | S23: =IFERROR(VLOOKUP($C23,درجات,20,0),0) -> 12 | T23: =IFERROR(VLOOKUP($C23,درجات,58,0),0) -> 20 | U23: =SUM(S23:T23) -> 32 | V23: =IFERROR(VLOOKUP($C23,درجات,23,0),0) -> 20 | W23: =IFERROR(VLOOKUP($C23,درجات,61,0),0) -> 20 | X23: =SUM(V23:W23) -> 40 | Y23: =IFERROR(VLOOKUP($C23,درجات,26,0),0) -> 12 | Z23: =IFERROR(VLOOKUP($C23,درجات,64,0),0) -> 10 | AA23: =SUM(Y23:Z23) -> 22 | AB23: =IFERROR(VLOOKUP($C23,درجات,29,0),0) -> 10 | AC23: =IFERROR(VLOOKUP($C23,درجات,67,0),0) -> 11 | AD23: =SUM(AB23:AC23) -> 21 | AE23: =IFERROR(VLOOKUP($C23,درجات,32,0),0) -> 0 | AF23: =IFERROR(VLOOKUP($C23,درجات,70,0),0) -> 0 | AG23: =SUM(AE23:AF23) -> 0
A24: 14 | B24: =IFERROR(VLOOKUP(A24,الاسماء,2,0),"") -> 0 | C24: =IFERROR(VLOOKUP(A24,الاسماء,3,0),"") -> علاء الدين لطفي الهادى امعمر | D24: =IFERROR(VLOOKUP($C24,درجات,5,0),0) -> 8 | E24: =IFERROR(VLOOKUP($C24,درجات,43,0),0) -> 9 | F24: =SUM(D24:E24) -> 17 | G24: =IFERROR(VLOOKUP($C24,درجات,8,0),0) -> 16 | H24: =IFERROR(VLOOKUP($C24,درجات,46,0),0) -> 13 | I24: =SUM(G24:H24) -> 29 | J24: =IFERROR(VLOOKUP($C24,درجات,11,0),0) -> 7 | K24: =IFERROR(VLOOKUP($C24,درجات,49,0),0) -> 6 | L24: =SUM(J24:K24) -> 13 | M24: =IFERROR(VLOOKUP($C24,درجات,14,0),0) -> 18 | N24: =IFERROR(VLOOKUP($C24,درجات,52,0),0) -> 19 | O24: =SUM(M24:N24) -> 37 | P24: =IFERROR(VLOOKUP($C24,درجات,17,0),0) -> 11 | Q24: =IFERROR(VLOOKUP($C24,درجات,55,0),0) -> 11 | R24: =SUM(P24:Q24) -> 22 | S24: =IFERROR(VLOOKUP($C24,درجات,20,0),0) -> 12 | T24: =IFERROR(VLOOKUP($C24,درجات,58,0),0) -> 10 | U24: =SUM(S24:T24) -> 22 | V24: =IFERROR(VLOOKUP($C24,درجات,23,0),0) -> 18 | W24: =IFERROR(VLOOKUP($C24,درجات,61,0),0) -> 18 | X24: =SUM(V24:W24) -> 36 | Y24: =IFERROR(VLOOKUP($C24,درجات,26,0),0) -> 7 | Z24: =IFERROR(VLOOKUP($C24,درجات,64,0),0) -> 9 | AA24: =SUM(Y24:Z24) -> 16 | AB24: =IFERROR(VLOOKUP($C24,درجات,29,0),0) -> 8 | AC24: =IFERROR(VLOOKUP($C24,درجات,67,0),0) -> 8 | AD24: =SUM(AB24:AC24) -> 16 | AE24: =IFERROR(VLOOKUP($C24,درجات,32,0),0) -> 0 | AF24: =IFERROR(VLOOKUP($C24,درجات,70,0),0) -> 0 | AG24: =SUM(AE24:AF24) -> 0
... A30: 20 | B30: =IFERROR(VLOOKUP(A30,الاسماء,2,0),"") -> 0 | C30: =IFERROR(VLOOKUP(A30,الاسماء,3,0),"") -> نورالدين الشعاب سليمان رجب | D30: =IFERROR(VLOOKUP($C30,درجات,5,0),0) -> 9 | E30: =IFERROR(VLOOKUP($C30,درجات,43,0),0) -> 11 | F30: =SUM(D30:E30) -> 20 | G30: =IFERROR(VLOOKUP($C30,درجات,8,0),0) -> 12 | H30: =IFERROR(VLOOKUP($C30,درجات,46,0),0) -> 12 | I30: =SUM(G30:H30) -> 24 | J30: =IFERROR(VLOOKUP($C30,درجات,11,0),0) -> 8 | K30: =IFERROR(VLOOKUP($C30,درجات,49,0),0) -> 6 | L30: =SUM(J30:K30) -> 14 | M30: =IFERROR(VLOOKUP($C30,درجات,14,0),0) -> 19 | N30: =IFERROR(VLOOKUP($C30,درجات,52,0),0) -> 21 | O30: =SUM(M30:N30) -> 40 | P30: =IFERROR(VLOOKUP($C30,درجات,17,0),0) -> 12 | Q30: =IFERROR(VLOOKUP($C30,درجات,55,0),0) -> 10 | R30: =SUM(P30:Q30) -> 22 | S30: =IFERROR(VLOOKUP($C30,درجات,20,0),0) -> 13 | T30: =IFERROR(VLOOKUP($C30,درجات,58,0),0) -> 6 | U30: =SUM(S30:T30) -> 19 | V30: =IFERROR(VLOOKUP($C30,درجات,23,0),0) -> 18 | W30: =IFERROR(VLOOKUP($C30,درجات,61,0),0) -> 20 | X30: =SUM(V30:W30) -> 38 | Y30: =IFERROR(VLOOKUP($C30,درجات,26,0),0) -> 9 | Z30: =IFERROR(VLOOKUP($C30,درجات,64,0),0) -> 9 | AA30: =SUM(Y30:Z30) -> 18 | AB30: =IFERROR(VLOOKUP($C30,درجات,29,0),0) -> 8 | AC30: =IFERROR(VLOOKUP($C30,درجات,67,0),0) -> 8 | AD30: =SUM(AB30:AC30) -> 16 | AE30: =IFERROR(VLOOKUP($C30,درجات,32,0),0) -> 0 | AF30: =IFERROR(VLOOKUP($C30,درجات,70,0),0) -> 0 | AG30: =SUM(AE30:AF30) -> 0
C32: الاسم | F32: التوقيع | K32: إقرار مدير المدرسة | AE32: ختم مدير المدرسة
A33: كتبه | C33: ='الفترة الاولى'!$CA$10 -> 0 | K33: أقر أنا | N33: ='الفترة الاولى'!$CA$16 -> أ. فهيم عبدالمجيد بوازويتة | U33: مدير مدرسة | X33: ='الفترة الاولى'!$C$6 -> سهول العلم للتعليم الخاص
A34: أملاه | C34: ='الفترة الاولى'!$CA$11 -> 0 | K34: بأن جميع ماوردة في هدا الكشف مطابقا للبينات المثبتة بالسجلات
A35: رجع الكتابة | C35: ='الفترة الاولى'!$CA$12 -> 0 | K35: التاريخ | M35: =TODAY() -> 46181 | T35: التوقيع
A36: رجع الملاء | C36: ='الفترة الاولى'!$CA$13 -> 0
A38: 21 | B38: =IFERROR(VLOOKUP(A38,الاسماء,2,0),"") -> 0 | C38: =IFERROR(VLOOKUP(A38,الاسماء,3,0),"") -> 0 | D38: =IFERROR(VLOOKUP($C38,درجات,5,0),0) -> 0 | E38: =IFERROR(VLOOKUP($C38,درجات,43,0),0) -> 0 | F38: =SUM(D38:E38) -> 0 | G38: =IFERROR(VLOOKUP($C38,درجات,8,0),0) -> 0 | H38: =IFERROR(VLOOKUP($C38,درجات,46,0),0) -> 0 | I38: =SUM(G38:H38) -> 0 | J38: =IFERROR(VLOOKUP($C38,درجات,11,0),0) -> 0 | K38: =IFERROR(VLOOKUP($C38,درجات,49,0),0) -> 0 | L38: =SUM(J38:K38) -> 0 | M38: =IFERROR(VLOOKUP($C38,درجات,14,0),0) -> 0 | N38: =IFERROR(VLOOKUP($C38,درجات,52,0),0) -> 0 | O38: =SUM(M38:N38) -> 0 | P38: =IFERROR(VLOOKUP($C38,درجات,17,0),0) -> 0 | Q38: =IFERROR(VLOOKUP($C38,درجات,55,0),0) -> 0 | R38: =SUM(P38:Q38) -> 0 | S38: =IFERROR(VLOOKUP($C38,درجات,20,0),0) -> 0 | T38: =IFERROR(VLOOKUP($C38,درجات,58,0),0) -> 0 | U38: =SUM(S38:T38) -> 0 | V38: =IFERROR(VLOOKUP($C38,درجات,23,0),0) -> 0 | W38: =IFERROR(VLOOKUP($C38,درجات,61,0),0) -> 0 | X38: =SUM(V38:W38) -> 0 | Y38: =IFERROR(VLOOKUP($C38,درجات,26,0),0) -> 0 | Z38: =IFERROR(VLOOKUP($C38,درجات,64,0),0) -> 0 | AA38: =SUM(Y38:Z38) -> 0 | AB38: =IFERROR(VLOOKUP($C38,درجات,29,0),0) -> 0 | AC38: =IFERROR(VLOOKUP($C38,درجات,67,0),0) -> 0 | AD38: =SUM(AB38:AC38) -> 0 | AE38: =IFERROR(VLOOKUP($C38,درجات,32,0),0) -> 0 | AF38: =IFERROR(VLOOKUP($C38,درجات,70,0),0) -> 0 | AG38: =SUM(AE38:AF38) -> 0
A39: 22 | B39: =IFERROR(VLOOKUP(A39,الاسماء,2,0),0) -> 0 | C39: =IFERROR(VLOOKUP(A39,الاسماء,3,0),"") -> 0 | D39: =IFERROR(VLOOKUP($C39,درجات,5,0),0) -> 0 | E39: =IFERROR(VLOOKUP($C39,درجات,43,0),0) -> 0 | F39: =SUM(D39:E39) -> 0 | G39: =IFERROR(VLOOKUP($C39,درجات,8,0),0) -> 0 | H39: =IFERROR(VLOOKUP($C39,درجات,46,0),0) -> 0 | I39: =SUM(G39:H39) -> 0 | J39: =IFERROR(VLOOKUP($C39,درجات,11,0),0) -> 0 | K39: =IFERROR(VLOOKUP($C39,درجات,49,0),0) -> 0 | L39: =SUM(J39:K39) -> 0 | M39: =IFERROR(VLOOKUP($C39,درجات,14,0),0) -> 0 | N39: =IFERROR(VLOOKUP($C39,درجات,52,0),0) -> 0 | O39: =SUM(M39:N39) -> 0 | P39: =IFERROR(VLOOKUP($C39,درجات,17,0),0) -> 0 | Q39: =IFERROR(VLOOKUP($C39,درجات,55,0),0) -> 0 | R39: =SUM(P39:Q39) -> 0 | S39: =IFERROR(VLOOKUP($C39,درجات,20,0),0) -> 0 | T39: =IFERROR(VLOOKUP($C39,درجات,58,0),0) -> 0 | U39: =SUM(S39:T39) -> 0 | V39: =IFERROR(VLOOKUP($C39,درجات,23,0),0) -> 0 | W39: =IFERROR(VLOOKUP($C39,درجات,61,0),0) -> 0 | X39: =SUM(V39:W39) -> 0 | Y39: =IFERROR(VLOOKUP($C39,درجات,26,0),0) -> 0 | Z39: =IFERROR(VLOOKUP($C39,درجات,64,0),0) -> 0 | AA39: =SUM(Y39:Z39) -> 0 | AB39: =IFERROR(VLOOKUP($C39,درجات,29,0),0) -> 0 | AC39: =IFERROR(VLOOKUP($C39,درجات,67,0),0) -> 0 | AD39: =SUM(AB39:AC39) -> 0 | AE39: =IFERROR(VLOOKUP($C39,درجات,32,0),0) -> 0 | AF39: =IFERROR(VLOOKUP($C39,درجات,70,0),0) -> 0 | AG39: =SUM(AE39:AF39) -> 0
A40: 23 | B40: =IFERROR(VLOOKUP(A40,الاسماء,2,0),"") -> 0 | C40: =IFERROR(VLOOKUP(A40,الاسماء,3,0),"") -> 0 | D40: =IFERROR(VLOOKUP($C40,درجات,5,0),0) -> 0 | E40: =IFERROR(VLOOKUP($C40,درجات,43,0),0) -> 0 | F40: =SUM(D40:E40) -> 0 | G40: =IFERROR(VLOOKUP($C40,درجات,8,0),0) -> 0 | H40: =IFERROR(VLOOKUP($C40,درجات,46,0),0) -> 0 | I40: =SUM(G40:H40) -> 0 | J40: =IFERROR(VLOOKUP($C40,درجات,11,0),0) -> 0 | K40: =IFERROR(VLOOKUP($C40,درجات,49,0),0) -> 0 | L40: =SUM(J40:K40) -> 0 | M40: =IFERROR(VLOOKUP($C40,درجات,14,0),0) -> 0 | N40: =IFERROR(VLOOKUP($C40,درجات,52,0),0) -> 0 | O40: =SUM(M40:N40) -> 0 | P40: =IFERROR(VLOOKUP($C40,درجات,17,0),0) -> 0 | Q40: =IFERROR(VLOOKUP($C40,درجات,55,0),0) -> 0 | R40: =SUM(P40:Q40) -> 0 | S40: =IFERROR(VLOOKUP($C40,درجات,20,0),0) -> 0 | T40: =IFERROR(VLOOKUP($C40,درجات,58,0),0) -> 0 | U40: =SUM(S40:T40) -> 0 | V40: =IFERROR(VLOOKUP($C40,درجات,23,0),0) -> 0 | W40: =IFERROR(VLOOKUP($C40,درجات,61,0),0) -> 0 | X40: =SUM(V40:W40) -> 0 | Y40: =IFERROR(VLOOKUP($C40,درجات,26,0),0) -> 0 | Z40: =IFERROR(VLOOKUP($C40,درجات,64,0),0) -> 0 | AA40: =SUM(Y40:Z40) -> 0 | AB40: =IFERROR(VLOOKUP($C40,درجات,29,0),0) -> 0 | AC40: =IFERROR(VLOOKUP($C40,درجات,67,0),0) -> 0 | AD40: =SUM(AB40:AC40) -> 0 | AE40: =IFERROR(VLOOKUP($C40,درجات,32,0),0) -> 0 | AF40: =IFERROR(VLOOKUP($C40,درجات,70,0),0) -> 0 | AG40: =SUM(AE40:AF40) -> 0
A41: 24 | B41: =IFERROR(VLOOKUP(A41,الاسماء,2,0),"") -> 0 | C41: =IFERROR(VLOOKUP(A41,الاسماء,3,0),"") -> 0 | D41: =IFERROR(VLOOKUP($C41,درجات,5,0),0) -> 0 | E41: =IFERROR(VLOOKUP($C41,درجات,43,0),0) -> 0 | F41: =SUM(D41:E41) -> 0 | G41: =IFERROR(VLOOKUP($C41,درجات,8,0),0) -> 0 | H41: =IFERROR(VLOOKUP($C41,درجات,46,0),0) -> 0 | I41: =SUM(G41:H41) -> 0 | J41: =IFERROR(VLOOKUP($C41,درجات,11,0),0) -> 0 | K41: =IFERROR(VLOOKUP($C41,درجات,49,0),0) -> 0 | L41: =SUM(J41:K41) -> 0 | M41: =IFERROR(VLOOKUP($C41,درجات,14,0),0) -> 0 | N41: =IFERROR(VLOOKUP($C41,درجات,52,0),0) -> 0 | O41: =SUM(M41:N41) -> 0 | P41: =IFERROR(VLOOKUP($C41,درجات,17,0),0) -> 0 | Q41: =IFERROR(VLOOKUP($C41,درجات,55,0),0) -> 0 | R41: =SUM(P41:Q41) -> 0 | S41: =IFERROR(VLOOKUP($C41,درجات,20,0),0) -> 0 | T41: =IFERROR(VLOOKUP($C41,درجات,58,0),0) -> 0 | U41: =SUM(S41:T41) -> 0 | V41: =IFERROR(VLOOKUP($C41,درجات,23,0),0) -> 0 | W41: =IFERROR(VLOOKUP($C41,درجات,61,0),0) -> 0 | X41: =SUM(V41:W41) -> 0 | Y41: =IFERROR(VLOOKUP($C41,درجات,26,0),0) -> 0 | Z41: =IFERROR(VLOOKUP($C41,درجات,64,0),0) -> 0 | AA41: =SUM(Y41:Z41) -> 0 | AB41: =IFERROR(VLOOKUP($C41,درجات,29,0),0) -> 0 | AC41: =IFERROR(VLOOKUP($C41,درجات,67,0),0) -> 0 | AD41: =SUM(AB41:AC41) -> 0 | AE41: =IFERROR(VLOOKUP($C41,درجات,32,0),0) -> 0 | AF41: =IFERROR(VLOOKUP($C41,درجات,70,0),0) -> 0 | AG41: =SUM(AE41:AF41) -> 0
A42: 25 | B42: =IFERROR(VLOOKUP(A42,الاسماء,2,0),"") -> 0 | C42: =IFERROR(VLOOKUP(A42,الاسماء,3,0),"") -> 0 | D42: =IFERROR(VLOOKUP($C42,درجات,5,0),0) -> 0 | E42: =IFERROR(VLOOKUP($C42,درجات,43,0),0) -> 0 | F42: =SUM(D42:E42) -> 0 | G42: =IFERROR(VLOOKUP($C42,درجات,8,0),0) -> 0 | H42: =IFERROR(VLOOKUP($C42,درجات,46,0),0) -> 0 | I42: =SUM(G42:H42) -> 0 | J42: =IFERROR(VLOOKUP($C42,درجات,11,0),0) -> 0 | K42: =IFERROR(VLOOKUP($C42,درجات,49,0),0) -> 0 | L42: =SUM(J42:K42) -> 0 | M42: =IFERROR(VLOOKUP($C42,درجات,14,0),0) -> 0 | N42: =IFERROR(VLOOKUP($C42,درجات,52,0),0) -> 0 | O42: =SUM(M42:N42) -> 0 | P42: =IFERROR(VLOOKUP($C42,درجات,17,0),0) -> 0 | Q42: =IFERROR(VLOOKUP($C42,درجات,55,0),0) -> 0 | R42: =SUM(P42:Q42) -> 0 | S42: =IFERROR(VLOOKUP($C42,درجات,20,0),0) -> 0 | T42: =IFERROR(VLOOKUP($C42,درجات,58,0),0) -> 0 | U42: =SUM(S42:T42) -> 0 | V42: =IFERROR(VLOOKUP($C42,درجات,23,0),0) -> 0 | W42: =IFERROR(VLOOKUP($C42,درجات,61,0),0) -> 0 | X42: =SUM(V42:W42) -> 0 | Y42: =IFERROR(VLOOKUP($C42,درجات,26,0),0) -> 0 | Z42: =IFERROR(VLOOKUP($C42,درجات,64,0),0) -> 0 | AA42: =SUM(Y42:Z42) -> 0 | AB42: =IFERROR(VLOOKUP($C42,درجات,29,0),0) -> 0 | AC42: =IFERROR(VLOOKUP($C42,درجات,67,0),0) -> 0 | AD42: =SUM(AB42:AC42) -> 0 | AE42: =IFERROR(VLOOKUP($C42,درجات,32,0),0) -> 0 | AF42: =IFERROR(VLOOKUP($C42,درجات,70,0),0) -> 0 | AG42: =SUM(AE42:AF42) -> 0
A43: 26 | B43: =IFERROR(VLOOKUP(A43,الاسماء,2,0),"") -> 0 | C43: =IFERROR(VLOOKUP(A43,الاسماء,3,0),"") -> 0 | D43: =IFERROR(VLOOKUP($C43,درجات,5,0),0) -> 0 | E43: =IFERROR(VLOOKUP($C43,درجات,43,0),0) -> 0 | F43: =SUM(D43:E43) -> 0 | G43: =IFERROR(VLOOKUP($C43,درجات,8,0),0) -> 0 | H43: =IFERROR(VLOOKUP($C43,درجات,46,0),0) -> 0 | I43: =SUM(G43:H43) -> 0 | J43: =IFERROR(VLOOKUP($C43,درجات,11,0),0) -> 0 | K43: =IFERROR(VLOOKUP($C43,درجات,49,0),0) -> 0 | L43: =SUM(J43:K43) -> 0 | M43: =IFERROR(VLOOKUP($C43,درجات,14,0),0) -> 0 | N43: =IFERROR(VLOOKUP($C43,درجات,52,0),0) -> 0 | O43: =SUM(M43:N43) -> 0 | P43: =IFERROR(VLOOKUP($C43,درجات,17,0),0) -> 0 | Q43: =IFERROR(VLOOKUP($C43,درجات,55,0),0) -> 0 | R43: =SUM(P43:Q43) -> 0 | S43: =IFERROR(VLOOKUP($C43,درجات,20,0),0) -> 0 | T43: =IFERROR(VLOOKUP($C43,درجات,58,0),0) -> 0 | U43: =SUM(S43:T43) -> 0 | V43: =IFERROR(VLOOKUP($C43,درجات,23,0),0) -> 0 | W43: =IFERROR(VLOOKUP($C43,درجات,61,0),0) -> 0 | X43: =SUM(V43:W43) -> 0 | Y43: =IFERROR(VLOOKUP($C43,درجات,26,0),0) -> 0 | Z43: =IFERROR(VLOOKUP($C43,درجات,64,0),0) -> 0 | AA43: =SUM(Y43:Z43) -> 0 | AB43: =IFERROR(VLOOKUP($C43,درجات,29,0),0) -> 0 | AC43: =IFERROR(VLOOKUP($C43,درجات,67,0),0) -> 0 | AD43: =SUM(AB43:AC43) -> 0 | AE43: =IFERROR(VLOOKUP($C43,درجات,32,0),0) -> 0 | AF43: =IFERROR(VLOOKUP($C43,درجات,70,0),0) -> 0 | AG43: =SUM(AE43:AF43) -> 0
A44: 27 | B44: =IFERROR(VLOOKUP(A44,الاسماء,2,0),"") -> 0 | C44: =IFERROR(VLOOKUP(A44,الاسماء,3,0),"") -> 0 | D44: =IFERROR(VLOOKUP($C44,درجات,5,0),0) -> 0 | E44: =IFERROR(VLOOKUP($C44,درجات,43,0),0) -> 0 | F44: =SUM(D44:E44) -> 0 | G44: =IFERROR(VLOOKUP($C44,درجات,8,0),0) -> 0 | H44: =IFERROR(VLOOKUP($C44,درجات,46,0),0) -> 0 | I44: =SUM(G44:H44) -> 0 | J44: =IFERROR(VLOOKUP($C44,درجات,11,0),0) -> 0 | K44: =IFERROR(VLOOKUP($C44,درجات,49,0),0) -> 0 | L44: =SUM(J44:K44) -> 0 | M44: =IFERROR(VLOOKUP($C44,درجات,14,0),0) -> 0 | N44: =IFERROR(VLOOKUP($C44,درجات,52,0),0) -> 0 | O44: =SUM(M44:N44) -> 0 | P44: =IFERROR(VLOOKUP($C44,درجات,17,0),0) -> 0 | Q44: =IFERROR(VLOOKUP($C44,درجات,55,0),0) -> 0 | R44: =SUM(P44:Q44) -> 0 | S44: =IFERROR(VLOOKUP($C44,درجات,20,0),0) -> 0 | T44: =IFERROR(VLOOKUP($C44,درجات,58,0),0) -> 0 | U44: =SUM(S44:T44) -> 0 | V44: =IFERROR(VLOOKUP($C44,درجات,23,0),0) -> 0 | W44: =IFERROR(VLOOKUP($C44,درجات,61,0),0) -> 0 | X44: =SUM(V44:W44) -> 0 | Y44: =IFERROR(VLOOKUP($C44,درجات,26,0),0) -> 0 | Z44: =IFERROR(VLOOKUP($C44,درجات,64,0),0) -> 0 | AA44: =SUM(Y44:Z44) -> 0 | AB44: =IFERROR(VLOOKUP($C44,درجات,29,0),0) -> 0 | AC44: =IFERROR(VLOOKUP($C44,درجات,67,0),0) -> 0 | AD44: =SUM(AB44:AC44) -> 0 | AE44: =IFERROR(VLOOKUP($C44,درجات,32,0),0) -> 0 | AF44: =IFERROR(VLOOKUP($C44,درجات,70,0),0) -> 0 | AG44: =SUM(AE44:AF44) -> 0
A45: 28 | B45: =IFERROR(VLOOKUP(A45,الاسماء,2,0),"") -> 0 | C45: =IFERROR(VLOOKUP(A45,الاسماء,3,0),"") -> 0 | D45: =IFERROR(VLOOKUP($C45,درجات,5,0),0) -> 0 | E45: =IFERROR(VLOOKUP($C45,درجات,43,0),0) -> 0 | F45: =SUM(D45:E45) -> 0 | G45: =IFERROR(VLOOKUP($C45,درجات,8,0),0) -> 0 | H45: =IFERROR(VLOOKUP($C45,درجات,46,0),0) -> 0 | I45: =SUM(G45:H45) -> 0 | J45: =IFERROR(VLOOKUP($C45,درجات,11,0),0) -> 0 | K45: =IFERROR(VLOOKUP($C45,درجات,49,0),0) -> 0 | L45: =SUM(J45:K45) -> 0 | M45: =IFERROR(VLOOKUP($C45,درجات,14,0),0) -> 0 | N45: =IFERROR(VLOOKUP($C45,درجات,52,0),0) -> 0 | O45: =SUM(M45:N45) -> 0 | P45: =IFERROR(VLOOKUP($C45,درجات,17,0),0) -> 0 | Q45: =IFERROR(VLOOKUP($C45,درجات,55,0),0) -> 0 | R45: =SUM(P45:Q45) -> 0 | S45: =IFERROR(VLOOKUP($C45,درجات,20,0),0) -> 0 | T45: =IFERROR(VLOOKUP($C45,درجات,58,0),0) -> 0 | U45: =SUM(S45:T45) -> 0 | V45: =IFERROR(VLOOKUP($C45,درجات,23,0),0) -> 0 | W45: =IFERROR(VLOOKUP($C45,درجات,61,0),0) -> 0 | X45: =SUM(V45:W45) -> 0 | Y45: =IFERROR(VLOOKUP($C45,درجات,26,0),0) -> 0 | Z45: =IFERROR(VLOOKUP($C45,درجات,64,0),0) -> 0 | AA45: =SUM(Y45:Z45) -> 0 | AB45: =IFERROR(VLOOKUP($C45,درجات,29,0),0) -> 0 | AC45: =IFERROR(VLOOKUP($C45,درجات,67,0),0) -> 0 | AD45: =SUM(AB45:AC45) -> 0 | AE45: =IFERROR(VLOOKUP($C45,درجات,32,0),0) -> 0 | AF45: =IFERROR(VLOOKUP($C45,درجات,70,0),0) -> 0 | AG45: =SUM(AE45:AF45) -> 0
A46: 29 | B46: =IFERROR(VLOOKUP(A46,الاسماء,2,0),"") -> 0 | C46: =IFERROR(VLOOKUP(A46,الاسماء,3,0),"") -> 0 | D46: =IFERROR(VLOOKUP($C46,درجات,5,0),0) -> 0 | E46: =IFERROR(VLOOKUP($C46,درجات,43,0),0) -> 0 | F46: =SUM(D46:E46) -> 0 | G46: =IFERROR(VLOOKUP($C46,درجات,8,0),0) -> 0 | H46: =IFERROR(VLOOKUP($C46,درجات,46,0),0) -> 0 | I46: =SUM(G46:H46) -> 0 | J46: =IFERROR(VLOOKUP($C46,درجات,11,0),0) -> 0 | K46: =IFERROR(VLOOKUP($C46,درجات,49,0),0) -> 0 | L46: =SUM(J46:K46) -> 0 | M46: =IFERROR(VLOOKUP($C46,درجات,14,0),0) -> 0 | N46: =IFERROR(VLOOKUP($C46,درجات,52,0),0) -> 0 | O46: =SUM(M46:N46) -> 0 | P46: =IFERROR(VLOOKUP($C46,درجات,17,0),0) -> 0 | Q46: =IFERROR(VLOOKUP($C46,درجات,55,0),0) -> 0 | R46: =SUM(P46:Q46) -> 0 | S46: =IFERROR(VLOOKUP($C46,درجات,20,0),0) -> 0 | T46: =IFERROR(VLOOKUP($C46,درجات,58,0),0) -> 0 | U46: =SUM(S46:T46) -> 0 | V46: =IFERROR(VLOOKUP($C46,درجات,23,0),0) -> 0 | W46: =IFERROR(VLOOKUP($C46,درجات,61,0),0) -> 0 | X46: =SUM(V46:W46) -> 0 | Y46: =IFERROR(VLOOKUP($C46,درجات,26,0),0) -> 0 | Z46: =IFERROR(VLOOKUP($C46,درجات,64,0),0) -> 0 | AA46: =SUM(Y46:Z46) -> 0 | AB46: =IFERROR(VLOOKUP($C46,درجات,29,0),0) -> 0 | AC46: =IFERROR(VLOOKUP($C46,درجات,67,0),0) -> 0 | AD46: =SUM(AB46:AC46) -> 0 | AE46: =IFERROR(VLOOKUP($C46,درجات,32,0),0) -> 0 | AF46: =IFERROR(VLOOKUP($C46,درجات,70,0),0) -> 0 | AG46: =SUM(AE46:AF46) -> 0
A47: 30 | B47: =IFERROR(VLOOKUP(A47,الاسماء,2,0),"") -> 0 | C47: =IFERROR(VLOOKUP(A47,الاسماء,3,0),"") -> 0 | D47: =IFERROR(VLOOKUP($C47,درجات,5,0),0) -> 0 | E47: =IFERROR(VLOOKUP($C47,درجات,43,0),0) -> 0 | F47: =SUM(D47:E47) -> 0 | G47: =IFERROR(VLOOKUP($C47,درجات,8,0),0) -> 0 | H47: =IFERROR(VLOOKUP($C47,درجات,46,0),0) -> 0 | I47: =SUM(G47:H47) -> 0 | J47: =IFERROR(VLOOKUP($C47,درجات,11,0),0) -> 0 | K47: =IFERROR(VLOOKUP($C47,درجات,49,0),0) -> 0 | L47: =SUM(J47:K47) -> 0 | M47: =IFERROR(VLOOKUP($C47,درجات,14,0),0) -> 0 | N47: =IFERROR(VLOOKUP($C47,درجات,52,0),0) -> 0 | O47: =SUM(M47:N47) -> 0 | P47: =IFERROR(VLOOKUP($C47,درجات,17,0),0) -> 0 | Q47: =IFERROR(VLOOKUP($C47,درجات,55,0),0) -> 0 | R47: =SUM(P47:Q47) -> 0 | S47: =IFERROR(VLOOKUP($C47,درجات,20,0),0) -> 0 | T47: =IFERROR(VLOOKUP($C47,درجات,58,0),0) -> 0 | U47: =SUM(S47:T47) -> 0 | V47: =IFERROR(VLOOKUP($C47,درجات,23,0),0) -> 0 | W47: =IFERROR(VLOOKUP($C47,درجات,61,0),0) -> 0 | X47: =SUM(V47:W47) -> 0 | Y47: =IFERROR(VLOOKUP($C47,درجات,26,0),0) -> 0 | Z47: =IFERROR(VLOOKUP($C47,درجات,64,0),0) -> 0 | AA47: =SUM(Y47:Z47) -> 0 | AB47: =IFERROR(VLOOKUP($C47,درجات,29,0),0) -> 0 | AC47: =IFERROR(VLOOKUP($C47,درجات,67,0),0) -> 0 | AD47: =SUM(AB47:AC47) -> 0 | AE47: =IFERROR(VLOOKUP($C47,درجات,32,0),0) -> 0 | AF47: =IFERROR(VLOOKUP($C47,درجات,70,0),0) -> 0 | AG47: =SUM(AE47:AF47) -> 0
A48: 31 | B48: =IFERROR(VLOOKUP(A48,الاسماء,2,0),"") -> 0 | C48: =IFERROR(VLOOKUP(A48,الاسماء,3,0),"") -> 0 | D48: =IFERROR(VLOOKUP($C48,درجات,5,0),0) -> 0 | E48: =IFERROR(VLOOKUP($C48,درجات,43,0),0) -> 0 | F48: =SUM(D48:E48) -> 0 | G48: =IFERROR(VLOOKUP($C48,درجات,8,0),0) -> 0 | H48: =IFERROR(VLOOKUP($C48,درجات,46,0),0) -> 0 | I48: =SUM(G48:H48) -> 0 | J48: =IFERROR(VLOOKUP($C48,درجات,11,0),0) -> 0 | K48: =IFERROR(VLOOKUP($C48,درجات,49,0),0) -> 0 | L48: =SUM(J48:K48) -> 0 | M48: =IFERROR(VLOOKUP($C48,درجات,14,0),0) -> 0 | N48: =IFERROR(VLOOKUP($C48,درجات,52,0),0) -> 0 | O48: =SUM(M48:N48) -> 0 | P48: =IFERROR(VLOOKUP($C48,درجات,17,0),0) -> 0 | Q48: =IFERROR(VLOOKUP($C48,درجات,55,0),0) -> 0 | R48: =SUM(P48:Q48) -> 0 | S48: =IFERROR(VLOOKUP($C48,درجات,20,0),0) -> 0 | T48: =IFERROR(VLOOKUP($C48,درجات,58,0),0) -> 0 | U48: =SUM(S48:T48) -> 0 | V48: =IFERROR(VLOOKUP($C48,درجات,23,0),0) -> 0 | W48: =IFERROR(VLOOKUP($C48,درجات,61,0),0) -> 0 | X48: =SUM(V48:W48) -> 0 | Y48: =IFERROR(VLOOKUP($C48,درجات,26,0),0) -> 0 | Z48: =IFERROR(VLOOKUP($C48,درجات,64,0),0) -> 0 | AA48: =SUM(Y48:Z48) -> 0 | AB48: =IFERROR(VLOOKUP($C48,درجات,29,0),0) -> 0 | AC48: =IFERROR(VLOOKUP($C48,درجات,67,0),0) -> 0 | AD48: =SUM(AB48:AC48) -> 0 | AE48: =IFERROR(VLOOKUP($C48,درجات,32,0),0) -> 0 | AF48: =IFERROR(VLOOKUP($C48,درجات,70,0),0) -> 0 | AG48: =SUM(AE48:AF48) -> 0
...

Sheet ص الفترة الاولى
B1: بطاقة تقدير بيان للصف ( التاسع ) من التعليم الاساسي | J1: مكتب امتحانات تاجوراء | O1: 6 | S1: بطاقة تقدير بيان للصف ( التاسع ) من التعليم الاساسي | AA1: مكتب امتحانات تاجوراء | AF1: 6 | AJ1: بطاقة تقدير بيان للصف ( التاسع ) من التعليم الاساسي | AR1: مكتب امتحانات تاجوراء | AW1: =AF1+5 -> 11 | BA1: بطاقة تقدير بيان للصف ( التاسع ) من التعليم الاساسي | BI1: مكتب امتحانات تاجوراء | BN1: =AW1+5 -> 16 | BV1: =SUM(F7:F16) -> 336
B2: ='الفترة الاولى'!$A$6 -> المدرسة / | C2: ='الفترة الاولى'!$C$6 -> سهول العلم للتعليم الخاص | H2: الاسم | J2: =VLOOKUP(O1,اسم,3,0) -> جمعة خيرى عبدالله الدرهوبي | S2: ='الفترة الاولى'!$A$6 -> المدرسة / | T2: ='الفترة الاولى'!$C$6 -> سهول العلم للتعليم الخاص | Y2: الاسم | AA2: =VLOOKUP(AF1,اسم,3,0) -> جمعة خيرى عبدالله الدرهوبي | AJ2: ='الفترة الاولى'!$A$6 -> المدرسة / | AK2: ='الفترة الاولى'!$C$6 -> سهول العلم للتعليم الخاص | AP2: الاسم | AR2: =VLOOKUP(AW1,اسم,3,0) -> ريناد محمد ابراهيم السلامي | BA2: ='الفترة الاولى'!$A$6 -> المدرسة / | BB2: ='الفترة الاولى'!$C$6 -> سهول العلم للتعليم الخاص | BG2: الاسم | BI2: =VLOOKUP(BN1,اسم,3,0) -> مالك علي حمد القبائلى | BV2: =BV1/2 -> 168
B3: العام الدراسي 1446 - 1447 هجرية / الموافق 2025 - 2026 ميلادية | S3: العام الدراسي 1446 - 1447 هجرية / الموافق 2025 - 2026 ميلادية | AJ3: العام الدراسي 1445 - 1446 هجرية / الموافق 2024 - 2025 ميلادية | BA3: العام الدراسي 1445 - 1446 هجرية / الموافق 2024 - 2025 ميلادية
B4: المواد الدراسية المقررة | C4: عدد الحصص | D4: النهايــــات | F4: درجــات الفترتين | K4: ملاحظات عن نتيجة الطالب خلال الفتـــرة | S4: المواد الدراسية المقررة | T4: عدد الحصص | U4: النهايــــات | W4: درجــات الفترتين | AB4: ملاحظات عن نتيجة الطالب خلال الفتـــرة | AJ4: المواد الدراسية المقررة | AK4: عدد الحصص | AL4: النهايــــات | AN4: درجــات الفترتين | AS4: ملاحظات عن نتيجة الطالب خلال الفتـــرة | BA4: المواد الدراسية المقررة | BB4: عدد الحصص | BC4: النهايــــات | BE4: درجــات الفترتين | BJ4: ملاحظات عن نتيجة الطالب خلال الفتـــرة | BS4: 0 | BT4: ضعيف
D5: الكبرى | E5: الصغرى | F5: الدرجة المقررة للفترتيــن 60% | G5: الدرجة المقررة للفترة | H5: الفترة الاول | I5: الفترة الثانية | K5: الأولى: | L5: =LOOKUP(H17,$BS$4:$BT$8) -> جيد | U5: الكبرى | V5: الصغرى | W5: الدرجة المقررة للفترتيــن 30% | X5: الدرجة المقررة للفترة | Y5: الفترة الاول | Z5: الفترة الثانية | AB5: الأولى: | AC5: =LOOKUP(Y17,$BS$4:$BT$8) -> جيد | AL5: الكبرى | AM5: الصغرى | AN5: الدرجة المقررة للفترتيــن 30% | AO5: الدرجة المقررة للفترة | AP5: الفترة الاول | AQ5: الفترة الثانية | AS5: الأولى: | AT5: =LOOKUP(AP17,$BS$4:$BT$8) -> جيدجداً | BC5: الكبرى | BD5: الصغرى | BE5: الدرجة المقررة للفترتيــن 30% | BF5: الدرجة المقررة للفترة | BG5: الفترة الاول | BH5: الفترة الثانية | BJ5: الأولى: | BK5: =LOOKUP(BG17,$BS$4:$BT$8) -> جيد | BS5: =BV2*0.5 -> 84 | BT5: مقبول
K6: =IF(L5<>"ضعيف","","يحتاج الى اهتمام في المواد ") | AB6: =IF(AC5<>"ضعيف","","يحتاج الى اهتمام في المواد ") | AS6: =IF(AT5<>"ضعيف","","يحتاج الى اهتمام في المواد ") | BJ6: =IF(BK5<>"ضعيف","","يحتاج الى اهتمام في المواد ") | BS6: =BV2*0.65 -> 109.2 | BT6: جيد
B7: ='الفترة الاولى'!$E$8 -> التربية الإسلامية | C7: ='الفترة الاولى'!$G$8 -> 2 | D7: =C7*40 -> 80 | E7: =D7*0.5 -> 40 | F7: =D7*0.3 -> 24 | G7: =D7*0.15 -> 12 | H7: =IFERROR(VLOOKUP(J2,بيان,2,0),0) -> 10 | I7: =IFERROR(VLOOKUP(J1,بيان,6,0),0) -> 0 | K7: =IF(H7=0,"",IF(H7<G7/2,B7,"")) | L7: =IF(H8=0,"",IF(H8<G8/2,B8,"")) | M7: =IF(H9=0,"",IF(H9<G9/2,B9,"")) | N7: =IF(H10=0,"",IF(H10<G10/2,B10,"")) | O7: =IF(H11=0,"",IF(H11<G11/2,B11,"")) | S7: ='الفترة الاولى'!$E$8 -> التربية الإسلامية | T7: ='الفترة الاولى'!$G$8 -> 2 | U7: =T7*40 -> 80 | V7: =U7*0.5 -> 40 | W7: =U7*0.3 -> 24 | X7: =U7*0.15 -> 12 | Y7: =IFERROR(VLOOKUP(AA2,بيان,2,0),0) -> 10 | Z7: =IFERROR(VLOOKUP(AA2,بيان,3,0),0) -> 11 | AB7: =IF(Y7=0,"",IF(Y7<X7/2,S7,"")) | AC7: =IF(Y8=0,"",IF(Y8<X8/2,S8,"")) | AD7: =IF(Y9=0,"",IF(Y9<X9/2,S9,"")) | AE7: =IF(Y10=0,"",IF(Y10<X10/2,S10,"")) | AF7: =IF(Y11=0,"",IF(Y11<X11/2,S11,"")) | AJ7: ='الفترة الاولى'!$E$8 -> التربية الإسلامية | AK7: ='الفترة الاولى'!$G$8 -> 2 | AL7: =AK7*40 -> 80 | AM7: =AL7*0.5 -> 40 | AN7: =AL7*0.3 -> 24 | AO7: =AL7*0.15 -> 12 | AP7: =IFERROR(VLOOKUP(AR2,بيان,2,0),0) -> 10 | AQ7: =IFERROR(VLOOKUP(AR2,بيان,3,0),0) -> 11 | AS7: =IF(AP7=0,"",IF(AP7<AO7/2,AJ7,"")) | AT7: =IF(AP8=0,"",IF(AP8<AO8/2,AJ8,"")) | AU7: =IF(AP9=0,"",IF(AP9<AO9/2,AJ9,"")) | AV7: =IF(AP10=0,"",IF(AP10<AO10/2,AJ10,"")) | AW7: =IF(AP11=0,"",IF(AP11<AO11/2,AJ11,"")) | BA7: ='الفترة الاولى'!$E$8 -> التربية الإسلامية | BB7: ='الفترة الاولى'!$G$8 -> 2 | BC7: =BB7*40 -> 80 | BD7: =BC7*0.5 -> 40 | BE7: =BC7*0.3 -> 24 | BF7: =BC7*0.15 -> 12 | BG7: =IFERROR(VLOOKUP(BI2,بيان,2,0),0) -> 11 | BH7: =IFERROR(VLOOKUP(BI2,بيان,3,0),0) -> 11 | BJ7: =IF(BG7=0,"",IF(BG7<BF7/2,BA7,"")) | BK7: =IF(BG8=0,"",IF(BG8<BF8/2,BA8,"")) | BL7: =IF(BG9=0,"",IF(BG9<BF9/2,BA9,"")) | BM7: =IF(BG10=0,"",IF(BG10<BF10/2,BA10,"")) | BN7: =IF(BG11=0,"",IF(BG11<BF11/2,BA11,"")) | BS7: =BV2*0.75 -> 126 | BT7: جيدجداً
B8: ='الفترة الاولى'!$H$8 -> النحو والقراءة والنصوص | C8: ='الفترة الاولى'!$J$8 -> 4 | D8: =C8*40 -> 160 | E8: =D8*0.5 -> 80 | F8: =D8*0.3 -> 48 | G8: =D8*0.15 -> 24 | H8: =IFERROR(VLOOKUP(J2,بيان,5,0),0) -> 18 | I8: =IFERROR(VLOOKUP(J2,بيان,6,0),0) -> 17 | K8: =IF(H12=0,"",IF(H12<G12/2,B12,"")) -> الرياضيات | L8: =IF(H13=0,"",IF(H13<G13/2,B13,"")) | M8: =IF(H14=0,"",IF(H14<G14/2,B14,"")) | N8: =IF(H15=0,"",IF(H15<G15/2,B15,"")) | O8: =IF(H16=0,"",IF(H16<G16/2,B16,"")) | S8: ='الفترة الاولى'!$H$8 -> النحو والقراءة والنصوص | T8: ='الفترة الاولى'!$J$8 -> 4 | U8: =T8*40 -> 160 | V8: =U8*0.5 -> 80 | W8: =U8*0.3 -> 48 | X8: =U8*0.15 -> 24 | Y8: =IFERROR(VLOOKUP(AA2,بيان,5,0),0) -> 18 | Z8: =IFERROR(VLOOKUP(AA2,بيان,6,0),0) -> 17 | AB8: =IF(Y12=0,"",IF(Y12<X12/2,S12,"")) -> الرياضيات | AC8: =IF(Y13=0,"",IF(Y13<X13/2,S13,"")) | AD8: =IF(Y14=0,"",IF(Y14<X14/2,S14,"")) | AE8: =IF(Y15=0,"",IF(Y15<X15/2,S15,"")) | AF8: =IF(Y16=0,"",IF(Y16<X16/2,S16,"")) | AJ8: ='الفترة الاولى'!$H$8 -> النحو والقراءة والنصوص | AK8: ='الفترة الاولى'!$J$8 -> 4 | AL8: =AK8*40 -> 160 | AM8: =AL8*0.5 -> 80 | AN8: =AL8*0.3 -> 48 | AO8: =AL8*0.15 -> 24 | AP8: =IFERROR(VLOOKUP(AR2,بيان,5,0),0) -> 18 | AQ8: =IFERROR(VLOOKUP(AR2,بيان,6,0),0) -> 22 | AS8: =IF(AP12=0,"",IF(AP12<AO12/2,AJ12,"")) | AT8: =IF(AP13=0,"",IF(AP13<AO13/2,AJ13,"")) | AU8: =IF(AP14=0,"",IF(AP14<AO14/2,AJ14,"")) | AV8: =IF(AP15=0,"",IF(AP15<AO15/2,AJ15,"")) -> الجغرافيا | AW8: =IF(AP16=0,"",IF(AP16<AO16/2,AJ16,"")) | BA8: ='الفترة الاولى'!$H$8 -> النحو والقراءة والنصوص | BB8: ='الفترة الاولى'!$J$8 -> 4 | BC8: =BB8*40 -> 160 | BD8: =BC8*0.5 -> 80 | BE8: =BC8*0.3 -> 48 | BF8: =BC8*0.15 -> 24 | BG8: =IFERROR(VLOOKUP(BI2,بيان,5,0),0) -> 19 | BH8: =IFERROR(VLOOKUP(BI2,بيان,6,0),0) -> 18 | BJ8: =IF(BG12=0,"",IF(BG12<BF12/2,BA12,"")) -> الرياضيات | BK8: =IF(BG13=0,"",IF(BG13<BF13/2,BA13,"")) | BL8: =IF(BG14=0,"",IF(BG14<BF14/2,BA14,"")) | BM8: =IF(BG15=0,"",IF(BG15<BF15/2,BA15,"")) -> الجغرافيا | BN8: =IF(BG16=0,"",IF(BG16<BF16/2,BA16,"")) | BS8: =BV2*0.85 -> 142.8 | BT8: ممتاز
B9: ='الفترة الاولى'!$K$8 -> الكتابة (الخط والاملاء والخط ) | C9: ='الفترة الاولى'!$M$8 -> 2 | D9: =C9*40 -> 80 | E9: =D9*0.5 -> 40 | F9: =D9*0.3 -> 24 | G9: =D9*0.15 -> 12 | H9: =IFERROR(VLOOKUP(J2,بيان,8,0),0) -> 8 | I9: =IFERROR(VLOOKUP(J2,بيان,9,0),0) -> 8 | S9: ='الفترة الاولى'!$K$8 -> الكتابة (الخط والاملاء والخط ) | T9: ='الفترة الاولى'!$M$8 -> 2 | U9: =T9*40 -> 80 | V9: =U9*0.5 -> 40 | W9: =U9*0.3 -> 24 | X9: =U9*0.15 -> 12 | Y9: =IFERROR(VLOOKUP(AA2,بيان,8,0),0) -> 8 | Z9: =IFERROR(VLOOKUP(AA2,بيان,9,0),0) -> 8 | AJ9: ='الفترة الاولى'!$K$8 -> الكتابة (الخط والاملاء والخط ) | AK9: ='الفترة الاولى'!$M$8 -> 2 | AL9: =AK9*40 -> 80 | AM9: =AL9*0.5 -> 40 | AN9: =AL9*0.3 -> 24 | AO9: =AL9*0.15 -> 12 | AP9: =IFERROR(VLOOKUP(AR2,بيان,8,0),0) -> 7 | AQ9: =IFERROR(VLOOKUP(AR2,بيان,9,0),0) -> 11 | BA9: ='الفترة الاولى'!$K$8 -> الكتابة (الخط والاملاء والخط ) | BB9: ='الفترة الاولى'!$M$8 -> 2 | BC9: =BB9*40 -> 80 | BD9: =BC9*0.5 -> 40 | BE9: =BC9*0.3 -> 24 | BF9: =BC9*0.15 -> 12 | BG9: =IFERROR(VLOOKUP(BI2,بيان,8,0),0) -> 8 | BH9: =IFERROR(VLOOKUP(BI2,بيان,9,0),0) -> 11
B10: ='الفترة الاولى'!$N$8 -> الإنجليزي | C10: ='الفترة الاولى'!$P$8 -> 4 | D10: =C10*40 -> 160 | E10: =D10*0.5 -> 80 | F10: =D10*0.3 -> 48 | G10: =D10*0.15 -> 24 | H10: =IFERROR(VLOOKUP(J2,بيان,11,0),0) -> 20 | I10: =IFERROR(VLOOKUP(J2,بيان,12,0),0) -> 22 | K10: يعتمد مدير المدرسة | S10: ='الفترة الاولى'!$N$8 -> الإنجليزي | T10: ='الفترة الاولى'!$P$8 -> 4 | U10: =T10*40 -> 160 | V10: =U10*0.5 -> 80 | W10: =U10*0.3 -> 48 | X10: =U10*0.15 -> 24 | Y10: =IFERROR(VLOOKUP(AA2,بيان,11,0),0) -> 20 | Z10: =IFERROR(VLOOKUP(AA2,بيان,12,0),0) -> 22 | AB10: يعتمد مدير المدرسة | AJ10: ='الفترة الاولى'!$N$8 -> الإنجليزي | AK10: ='الفترة الاولى'!$P$8 -> 4 | AL10: =AK10*40 -> 160 | AM10: =AL10*0.5 -> 80 | AN10: =AL10*0.3 -> 48 | AO10: =AL10*0.15 -> 24 | AP10: =IFERROR(VLOOKUP(AR2,بيان,11,0),0) -> 22 | AQ10: =IFERROR(VLOOKUP(AR2,بيان,12,0),0) -> 24 | AS10: يعتمد مدير المدرسة | BA10: ='الفترة الاولى'!$N$8 -> الإنجليزي | BB10: ='الفترة الاولى'!$P$8 -> 4 | BC10: =BB10*40 -> 160 | BD10: =BC10*0.5 -> 80 | BE10: =BC10*0.3 -> 48 | BF10: =BC10*0.15 -> 24 | BG10: =IFERROR(VLOOKUP(BI2,بيان,11,0),0) -> 22 | BH10: =IFERROR(VLOOKUP(BI2,بيان,12,0),0) -> 24 | BJ10: يعتمد مدير المدرسة
B11: ='الفترة الاولى'!$Q$8 -> الحاسوب | C11: ='الفترة الاولى'!$S$8 -> 2 | D11: =C11*40 -> 80 | E11: =D11*0.5 -> 40 | F11: =D11*0.3 -> 24 | G11: =D11*0.15 -> 12 | H11: =IFERROR(VLOOKUP(J2,بيان,14,0),0) -> 12 | I11: =IFERROR(VLOOKUP(J2,بيان,15,0),0) -> 11 | K11: ='الفترة الاولى'!$CA$16 -> أ. فهيم عبدالمجيد بوازويتة | S11: ='الفترة الاولى'!$Q$8 -> الحاسوب | T11: ='الفترة الاولى'!$S$8 -> 2 | U11: =T11*40 -> 80 | V11: =U11*0.5 -> 40 | W11: =U11*0.3 -> 24 | X11: =U11*0.15 -> 12 | Y11: =IFERROR(VLOOKUP(AA2,بيان,14,0),0) -> 12 | Z11: =IFERROR(VLOOKUP(AA2,بيان,15,0),0) -> 11 | AB11: ='الفترة الاولى'!$CA$16 -> أ. فهيم عبدالمجيد بوازويتة | AJ11: ='الفترة الاولى'!$Q$8 -> الحاسوب | AK11: ='الفترة الاولى'!$S$8 -> 2 | AL11: =AK11*40 -> 80 | AM11: =AL11*0.5 -> 40 | AN11: =AL11*0.3 -> 24 | AO11: =AL11*0.15 -> 12 | AP11: =IFERROR(VLOOKUP(AR2,بيان,14,0),0) -> 11 | AQ11: =IFERROR(VLOOKUP(AR2,بيان,15,0),0) -> 12 | AS11: ='الفترة الاولى'!$CA$16 -> أ. فهيم عبدالمجيد بوازويتة | BA11: ='الفترة الاولى'!$Q$8 -> الحاسوب | BB11: ='الفترة الاولى'!$S$8 -> 2 | BC11: =BB11*40 -> 80 | BD11: =BC11*0.5 -> 40 | BE11: =BC11*0.3 -> 24 | BF11: =BC11*0.15 -> 12 | BG11: =IFERROR(VLOOKUP(BI2,بيان,14,0),0) -> 12 | BH11: =IFERROR(VLOOKUP(BI2,بيان,15,0),0) -> 11 | BJ11: ='الفترة الاولى'!$CA$16 -> أ. فهيم عبدالمجيد بوازويتة
B12: ='الفترة الاولى'!$T$8 -> الرياضيات | C12: ='الفترة الاولى'!$V$8 -> 5 | D12: =C12*40 -> 200 | E12: =D12*0.5 -> 100 | F12: =D12*0.3 -> 60 | G12: =D12*0.15 -> 30 | H12: =IFERROR(VLOOKUP(J2,بيان,17,0),0) -> 13 | I12: 10 | K12: التاريخ | S12: ='الفترة الاولى'!$T$8 -> الرياضيات | T12: ='الفترة الاولى'!$V$8 -> 5 | U12: =T12*40 -> 200 | V12: =U12*0.5 -> 100 | W12: =U12*0.3 -> 60 | X12: =U12*0.15 -> 30 | Y12: =IFERROR(VLOOKUP(AA2,بيان,17,0),0) -> 13 | Z12: =IFERROR(VLOOKUP(AA2,بيان,18,0),0) -> 17 | AB12: التاريخ | AC12: =TODAY() -> 46181 | AJ12: ='الفترة الاولى'!$T$8 -> الرياضيات | AK12: ='الفترة الاولى'!$V$8 -> 5 | AL12: =AK12*40 -> 200 | AM12: =AL12*0.5 -> 100 | AN12: =AL12*0.3 -> 60 | AO12: =AL12*0.15 -> 30 | AP12: =IFERROR(VLOOKUP(AR2,بيان,17,0),0) -> 18 | AQ12: =IFERROR(VLOOKUP(AR2,بيان,18,0),0) -> 18 | AS12: التاريخ | AT12: =TODAY() -> 46181 | BA12: ='الفترة الاولى'!$T$8 -> الرياضيات | BB12: ='الفترة الاولى'!$V$8 -> 5 | BC12: =BB12*40 -> 200 | BD12: =BC12*0.5 -> 100 | BE12: =BC12*0.3 -> 60 | BF12: =BC12*0.15 -> 30 | BG12: =IFERROR(VLOOKUP(BI2,بيان,17,0),0) -> 12 | BH12: =IFERROR(VLOOKUP(BI2,بيان,18,0),0) -> 18 | BJ12: التاريخ | BK12: =TODAY() -> 46181
B13: ='الفترة الاولى'!$W$8 -> العلوم | C13: ='الفترة الاولى'!$Y$8 -> 5 | D13: =C13*40 -> 200 | E13: =D13*0.5 -> 100 | F13: =D13*0.3 -> 60 | G13: =D13*0.15 -> 30 | H13: =IFERROR(VLOOKUP(J2,بيان,20,0),0) -> 19 | I13: =IFERROR(VLOOKUP(J2,بيان,21,0),0) -> 18 | K13: الختم | S13: ='الفترة الاولى'!$W$8 -> العلوم | T13: ='الفترة الاولى'!$Y$8 -> 5 | U13: =T13*40 -> 200 | V13: =U13*0.5 -> 100 | W13: =U13*0.3 -> 60 | X13: =U13*0.15 -> 30 | Y13: =IFERROR(VLOOKUP(AA2,بيان,20,0),0) -> 19 | Z13: =IFERROR(VLOOKUP(AA2,بيان,21,0),0) -> 18 | AB13: الختم | AJ13: ='الفترة الاولى'!$W$8 -> العلوم | AK13: ='الفترة الاولى'!$Y$8 -> 5 | AL13: =AK13*40 -> 200 | AM13: =AL13*0.5 -> 100 | AN13: =AL13*0.3 -> 60 | AO13: =AL13*0.15 -> 30 | AP13: =IFERROR(VLOOKUP(AR2,بيان,20,0),0) -> 26 | AQ13: =IFERROR(VLOOKUP(AR2,بيان,21,0),0) -> 25 | AS13: الختم | BA13: ='الفترة الاولى'!$W$8 -> العلوم | BB13: ='الفترة الاولى'!$Y$8 -> 5 | BC13: =BB13*40 -> 200 | BD13: =BC13*0.5 -> 100 | BE13: =BC13*0.3 -> 60 | BF13: =BC13*0.15 -> 30 | BG13: =IFERROR(VLOOKUP(BI2,بيان,20,0),0) -> 17 | BH13: =IFERROR(VLOOKUP(BI2,بيان,21,0),0) -> 21 | BJ13: الختم
B14: ='الفترة الاولى'!$Z$8 -> التاريخ | C14: ='الفترة الاولى'!$AB$8 -> 2 | D14: =C14*40 -> 80 | E14: =D14*0.5 -> 40 | F14: =D14*0.3 -> 24 | G14: =D14*0.15 -> 12 | H14: =IFERROR(VLOOKUP(J2,بيان,23,0),0) -> 9 | I14: =IFERROR(VLOOKUP(J2,بيان,24,0),0) -> 11 | K14: الثانية | S14: ='الفترة الاولى'!$Z$8 -> التاريخ | T14: ='الفترة الاولى'!$AB$8 -> 2 | U14: =T14*40 -> 80 | V14: =U14*0.5 -> 40 | W14: =U14*0.3 -> 24 | X14: =U14*0.15 -> 12 | Y14: =IFERROR(VLOOKUP(AA2,بيان,23,0),0) -> 9 | Z14: =IFERROR(VLOOKUP(AA2,بيان,24,0),0) -> 11 | AB14: الثانية | AC14: يحتاج إلى عناية في مادة | AJ14: ='الفترة الاولى'!$Z$8 -> التاريخ | AK14: ='الفترة الاولى'!$AB$8 -> 2 | AL14: =AK14*40 -> 80 | AM14: =AL14*0.5 -> 40 | AN14: =AL14*0.3 -> 24 | AO14: =AL14*0.15 -> 12 | AP14: =IFERROR(VLOOKUP(AR2,بيان,23,0),0) -> 11 | AQ14: =IFERROR(VLOOKUP(AR2,بيان,24,0),0) -> 10 | AS14: الثانية | AT14: =IF(AQ17=0,"",LOOKUP(AQ17,$BS$4:$BT$8)) -> ممتاز | BA14: ='الفترة الاولى'!$Z$8 -> التاريخ | BB14: ='الفترة الاولى'!$AB$8 -> 2 | BC14: =BB14*40 -> 80 | BD14: =BC14*0.5 -> 40 | BE14: =BC14*0.3 -> 24 | BF14: =BC14*0.15 -> 12 | BG14: =IFERROR(VLOOKUP(BI2,بيان,23,0),0) -> 10 | BH14: =IFERROR(VLOOKUP(BI2,بيان,24,0),0) -> 8 | BJ14: الثانية | BK14: =IF(BH17=0,"",LOOKUP(BH17,$BS$4:$BT$8)) -> جيدجداً
B15: ='الفترة الاولى'!$AC$8 -> الجغرافيا | C15: ='الفترة الاولى'!$AE$8 -> 2 | D15: =C15*40 -> 80 | E15: =D15*0.5 -> 40 | F15: =D14*0.3 -> 24 | G15: =D14*0.15 -> 12 | H15: =IFERROR(VLOOKUP(J2,بيان,26,0),0) -> 10 | I15: =IFERROR(VLOOKUP(J2,بيان,27,0),0) -> 11 | K15: =IF(L14<>"ضعيف","","يحتاج الى اهتمام في المواد ") | S15: ='الفترة الاولى'!$AC$8 -> الجغرافيا | T15: ='الفترة الاولى'!$AE$8 -> 2 | U15: =T15*40 -> 80 | V15: =U15*0.5 -> 40 | W15: =D14*0.3 -> 24 | X15: =U14*0.15 -> 12 | Y15: =IFERROR(VLOOKUP(AA2,بيان,26,0),0) -> 10 | Z15: =IFERROR(VLOOKUP(AA2,بيان,27,0),0) -> 11 | AB15: =IF(AC14<>"ضعيف","","يحتاج الى اهتمام في المواد ") | AJ15: ='الفترة الاولى'!$AC$8 -> الجغرافيا | AK15: ='الفترة الاولى'!$AE$8 -> 2 | AL15: =AK15*40 -> 80 | AM15: =AL15*0.5 -> 40 | AN15: =AL15*0.6 -> 48 | AO15: =AL15*0.3 -> 24 | AP15: =IFERROR(VLOOKUP(AR2,بيان,26,0),0) -> 11 | AQ15: =IFERROR(VLOOKUP(AR2,بيان,27,0),0) -> 11 | AS15: =IF(AT14<>"ضعيف","","يحتاج الى اهتمام في المواد ") | BA15: ='الفترة الاولى'!$AC$8 -> الجغرافيا | BB15: ='الفترة الاولى'!$AE$8 -> 2 | BC15: =BB15*40 -> 80 | BD15: =BC15*0.5 -> 40 | BE15: =BC15*0.6 -> 48 | BF15: =BC15*0.3 -> 24 | BG15: =IFERROR(VLOOKUP(BI2,بيان,26,0),0) -> 9 | BH15: =IFERROR(VLOOKUP(BI2,بيان,27,0),0) -> 10 | BJ15: =IF(BK14<>"ضعيف","","يحتاج الى اهتمام في المواد ")
B16: ='الفترة الاولى'!$AF$8 -> 0 | C16: ='الفترة الاولى'!$AH$8 -> 0 | D16: =C16*40 -> 0 | E16: =D16*0.5 -> 0 | F16: =D16*0.6 -> 0 | G16: =D16*0.3 -> 0 | H16: =IFERROR(VLOOKUP(J2,بيان,29,0),0) -> 0 | I16: =IFERROR(VLOOKUP(J2,بيان,30,0),0) -> 0 | K16: =IF(I7=0,"",IF(I7<G7/2,B7,"")) | L16: =IF(I8=0,"",IF(I8<G8/2,B8,"")) | M16: =IF(I9=0,"",IF(I9<G9/2,B9,"")) | N16: =IF(I10=0,"",IF(I10<G10/2,B10,"")) | O16: =IF(I11=0,"",IF(I11<G11/2,B11,"")) | S16: ='الفترة الاولى'!$AF$8 -> 0 | T16: ='الفترة الاولى'!$AH$8 -> 0 | U16: =T16*40 -> 0 | V16: =U16*0.5 -> 0 | W16: =U16*0.6 -> 0 | X16: =U16*0.3 -> 0 | Y16: =IFERROR(VLOOKUP(AA2,بيان,29,0),0) -> 0 | Z16: =IFERROR(VLOOKUP(AA2,بيان,30,0),0) -> 0 | AB16: =IF(Z7=0,"",IF(Z7<X7/2,S7,"")) | AC16: =IF(Z8=0,"",IF(Z8<X8/2,S8,"")) | AD16: =IF(Z9=0,"",IF(Z9<X9/2,S9,"")) | AE16: =IF(Z10=0,"",IF(Z10<X10/2,S10,"")) | AF16: =IF(Z11=0,"",IF(Z11<X11/2,S11,"")) | AJ16: ='الفترة الاولى'!$AF$8 -> 0 | AK16: ='الفترة الاولى'!$AH$8 -> 0 | AL16: =AK16*40 -> 0 | AM16: =AL16*0.5 -> 0 | AN16: =AL16*0.6 -> 0 | AO16: =AL16*0.3 -> 0 | AP16: =IFERROR(VLOOKUP(AR2,بيان,29,0),0) -> 0 | AQ16: =IFERROR(VLOOKUP(AR2,بيان,30,0),0) -> 0 | AS16: =IF(AQ7=0,"",IF(AQ7<AO7/2,AJ7,"")) | AT16: =IF(AQ8=0,"",IF(AQ8<AO8/2,AJ8,"")) | AU16: =IF(AQ9=0,"",IF(AQ9<AO9/2,AJ9,"")) | AV16: =IF(AQ10=0,"",IF(AQ10<AO10/2,AJ10,"")) | AW16: =IF(AQ11=0,"",IF(AQ11<AO11/2,AJ11,"")) | BA16: ='الفترة الاولى'!$AF$8 -> 0 | BB16: ='الفترة الاولى'!$AH$8 -> 0 | BC16: =BB16*40 -> 0 | BD16: =BC16*0.5 -> 0 | BE16: =BC16*0.6 -> 0 | BF16: =BC16*0.3 -> 0 | BG16: =IFERROR(VLOOKUP(BI2,بيان,29,0),0) -> 0 | BH16: =IFERROR(VLOOKUP(BI2,بيان,30,0),0) -> 0 | BJ16: =IF(BH7=0,"",IF(BH7<BF7/2,BA7,"")) | BK16: =IF(BH8=0,"",IF(BH8<BF8/2,BA8,"")) | BL16: =IF(BH9=0,"",IF(BH9<BF9/2,BA9,"")) | BM16: =IF(BH10=0,"",IF(BH10<BF10/2,BA10,"")) | BN16: =IF(BH11=0,"",IF(BH11<BF11/2,BA11,""))
B17: المجموع | D17: =SUM(D7:D16) -> 1120 | E17: =D17*0.5 -> 560 | G17: =SUM(G7:G16) -> 168 | H17: =SUM(H7:H16) -> 119 | I17: =SUM(I7:I16) -> 108 | K17: =IF(I12=0,"",IF(I12<G12/2,B12,"")) -> الرياضيات | L17: =IF(I13=0,"",IF(I13<G13/2,B13,"")) | M17: =IF(I14=0,"",IF(I14<G14/2,B14,"")) | N17: =IF(I15=0,"",IF(I15<G15/2,B15,"")) | O17: =IF(I16=0,"",IF(I16<G16/2,B16,"")) | S17: المجموع | U17: =SUM(U7:U16) -> 1120 | V17: =U17*0.5 -> 560 | X17: =SUM(X7:X16) -> 168 | Y17: =SUM(Y7:Y16) -> 119 | Z17: =SUM(Z7:Z16) -> 126 | AB17: =IF(Z12=0,"",IF(Z12<X12/2,S12,"")) | AC17: =IF(Z13=0,"",IF(Z13<X13/2,S13,"")) | AD17: =IF(Z14=0,"",IF(Z14<X14/2,S14,"")) | AE17: =IF(Z15=0,"",IF(Z15<X15/2,S15,"")) | AF17: =IF(Z16=0,"",IF(Z16<X16/2,S16,"")) | AJ17: المجموع | AL17: =SUM(AL7:AL16) -> 1120 | AM17: =AL17*0.5 -> 560 | AO17: =SUM(AO7:AO16) -> 180 | AP17: =SUM(AP7:AP16) -> 134 | AQ17: =SUM(AQ7:AQ16) -> 144 | AS17: =IF(AQ12=0,"",IF(AQ12<AO12/2,AJ12,"")) | AT17: =IF(AQ13=0,"",IF(AQ13<AO13/2,AJ13,"")) | AU17: =IF(AQ14=0,"",IF(AQ14<AO14/2,AJ14,"")) | AV17: =IF(AQ15=0,"",IF(AQ15<AO15/2,AJ15,"")) -> الجغرافيا | AW17: =IF(AQ16=0,"",IF(AQ16<AO16/2,AJ16,"")) | BA17: المجموع | BC17: =SUM(BC7:BC16) -> 1120 | BD17: =BC17*0.5 -> 560 | BF17: =SUM(BF7:BF16) -> 180 | BG17: =SUM(BG7:BG16) -> 120 | BH17: =SUM(BH7:BH16) -> 132 | BJ17: =IF(BH12=0,"",IF(BH12<BF12/2,BA12,"")) | BK17: =IF(BH13=0,"",IF(BH13<BF13/2,BA13,"")) | BL17: =IF(BH14=0,"",IF(BH14<BF14/2,BA14,"")) | BM17: =IF(BH15=0,"",IF(BH15<BF15/2,BA15,"")) -> الجغرافيا | BN17: =IF(BH16=0,"",IF(BH16<BF16/2,BA16,""))
B19: الغياب | C19: مشروع | S19: الغياب | T19: مشروع | AJ19: الغياب | AK19: مشروع | BA19: الغياب | BB19: مشروع
C20: غير مشروع | K20: تنبيـــــــــــه | T20: غير مشروع | AB20: تنبيـــــــــــه | AK20: غير مشروع | AS20: تنبيـــــــــــه | BB20: غير مشروع | BJ20: تنبيـــــــــــه
K21: يجب إعطاء هذه البطاقة للتلميذ فىنهاية كل فتـــــرة | AB21: يجب إعطاء هذه البطاقة للتلميذ في نهاية كل فتـــــرة | AS21: يجب إعطاء هذه البطاقة للتلميذ فىنهاية كل فتـــــرة | BJ21: يجب إعطاء هذه البطاقة للتلميذ فىنهاية كل فتـــــرة
B22: التوقيعــــات | D22: الفترة الاول | G22: الفترة الثانيــــــة | S22: التوقيعــــات | U22: الفترة الاول | X22: الفترة الثانيــــــة | AJ22: التوقيعــــات | AL22: الفترة الاول | AO22: الفترة الثانيــــــة | BA22: التوقيعــــات | BC22: الفترة الاول | BF22: الفترة الثانيــــــة
B23: رائــــد الصف | K23: كل كشط أو تغيير في هذه االبطاقة يلغيها | S23: رائــــد الصف | AB23: كل كشط أو تغيير في هذه االبطاقة يلغيها | AJ23: رائــــد الصف | AS23: كل كشط أو تغيير في هذه االبطاقة يلغيها | BA23: رائــــد الصف | BJ23: كل كشط أو تغيير في هذه االبطاقة يلغيها
B24: مدير المدرسة | S24: مدير المدرسة | AJ24: مدير المدرسة | BA24: مدير المدرسة
B25: ولي الأمــــر | S25: ولي الأمــــر | AJ25: ولي الأمــــر | BA25: ولي الأمــــر
B28: بطاقة تقدير بيان للصف ( التاسع ) من التعليم الاساسي | J28: مكتب امتحانات تاجوراء | O28: 8 | S28: بطاقة تقدير بيان للصف ( التاسع ) من التعليم الاساسي | AA28: مكتب امتحانات تاجوراء | AF28: 13 | AJ28: بطاقة تقدير بيان للصف ( التاسع ) من التعليم الاساسي | AR28: مكتب امتحانات تاجوراء | AW28: =AF28+5 -> 18 | BA28: بطاقة تقدير بيان للصف ( التاسع ) من التعليم الاساسي | BI28: مكتب امتحانات تاجوراء | BN28: =AW28+5 -> 23 | BV28: =SUM(F34:F44) -> 336
