Workbook
Name اسماء: ادخال1!$B$11:$ES$433
Name الترتيب1: ادخال1!$AU$11:$AV$319
Name الترتيب2: ادخال1!$BA$11:$BB$319
Name الترتيب3: ادخال1!$BF$11:$BG$320
Name عمود1: ادخال1!$A$11:$A$319
Name عمود2: ادخال1!$B$11:$B$319
Name مستجد: ادخال1!$CK$3:$CK$4
Name مسلسل: ادخال1!$A$11:$B$319

Sheet بيانات الصحيفة 
A1: 8 | B1: دولة ليبيا | P1: =A1-5 -> 3 | Q1: دولة ليبيا | AE1: =P1-5 -> -2 | AF1: دولة ليبيا | AT1: =AE1-5 -> -7 | AU1: دولة ليبيا
A2: وزارة التعليم | P2: وزارة التعليم | AE2: وزارة التعليم | AT2: وزارة التعليم
A3: المركز الوطني للامتحانات | P3: المركز الوطني للامتحانات | AE3: المركز الوطني للامتحانات | AT3: المركز الوطني للامتحانات
A4: بطاقة تقدير الدرجات لمرحلة التعليم | K4: =ادخال1!$CG$7 -> الاساسي | P4: بطاقة تقدير الدرجات لمرحلة التعليم | Z4: =ادخال1!$CG$7 -> الاساسي | AE4: بطاقة تقدير الدرجات لمرحلة التعليم | AO4: =ادخال1!$CG$7 -> الاساسي | AT4: بطاقة تقدير الدرجات لمرحلة التعليم | BD4: =ادخال1!$CG$7 -> الاساسي
A5: للصف | G5: =ادخال1!$CE$5 -> الثالث الابتدائي | P5: للصف | V5: =ادخال1!$CE$5 -> الثالث الابتدائي | AE5: للصف | AK5: =ادخال1!$CE$5 -> الثالث الابتدائي | AT5: للصف | AZ5: =ادخال1!$CE$5 -> الثالث الابتدائي
A6: العام الدراسي | B6: =ادخال1!$CD$8 -> 1448هـ/1447 هـ | F6: هجرية | H6: الموافق | J6: =ادخال1!$CE$8 -> 2025م /2026م | N6: ميلادية | P6: العام الدراسي | Q6: =ادخال1!$CD$8 -> 1448هـ/1447 هـ | U6: هجرية | W6: الموافق | Y6: =ادخال1!$CE$8 -> 2025م /2026م | AC6: ميلادية | AE6: العام الدراسي | AF6: =ادخال1!$CD$8 -> 1448هـ/1447 هـ | AJ6: هجرية | AL6: الموافق | AN6: =ادخال1!$CE$8 -> 2025م /2026م | AR6: ميلادية | AT6: العام الدراسي | AU6: =ادخال1!$CD$8 -> 1448هـ/1447 هـ | AY6: هجرية | BA6: الموافق | BC6: =ادخال1!$CE$8 -> 2025م /2026م | BG6: ميلادية
A7: شؤون التعليم بمنطقة | B7: =ادخال1!$CE$4 -> تاجوراء | P7: شؤون التعليم بمنطقة | Q7: =ادخال1!$CE$4 -> تاجوراء | AE7: شؤون التعليم بمنطقة | AF7: =ادخال1!$CE$4 -> تاجوراء | AT7: شؤون التعليم بمنطقة | AU7: =ادخال1!$CE$4 -> تاجوراء
A8: مدرســــــــــــــــــــــة | B8: =ادخال1!$CC$6 -> سهول العلم للتعليم الخاص | J8: الكــــائنة بـ : | M8: =ادخال1!$CC$8 -> تاجوراء | P8: مدرســــــــــــــــــــــة | Q8: =ادخال1!$CC$6 -> سهول العلم للتعليم الخاص | Y8: الكــــائنة بـ : | AB8: =ادخال1!$CC$8 -> تاجوراء | AE8: مدرســــــــــــــــــــــة | AF8: =ادخال1!$CC$6 -> سهول العلم للتعليم الخاص | AN8: الكــــائنة بـ : | AQ8: =ادخال1!$CC$8 -> تاجوراء | AT8: مدرســــــــــــــــــــــة | AU8: =ادخال1!$CC$6 -> سهول العلم للتعليم الخاص | BC8: الكــــائنة بـ : | BF8: =ادخال1!$CC$8 -> تاجوراء
A9: اسم التلميذ بالكـــامل | B9: =IFERROR(VLOOKUP(A1,مسلسل,2,0),0) -> على عبد السلام شعبان بي | C9: =IFERROR(VLOOKUP(B9,مسلسل,2,0),0) -> 0 | D9: =IFERROR(VLOOKUP(C9,مسلسل,2,0),0) -> 0 | E9: =IFERROR(VLOOKUP(D9,مسلسل,2,0),0) -> 0 | F9: =IFERROR(VLOOKUP(E9,مسلسل,2,0),0) -> 0 | G9: =IFERROR(VLOOKUP(F9,مسلسل,2,0),0) -> 0 | H9: =IFERROR(VLOOKUP(G9,مسلسل,2,0),0) -> 0 | I9: =IFERROR(VLOOKUP(H9,مسلسل,2,0),0) -> 0 | J9: اللقــــــــب | M9: =IFERROR(VLOOKUP(B9,اسماء,66,0),"") -> بي | P9: اسم التلميذ بالكـــامل | Q9: =IFERROR(VLOOKUP(P1,مسلسل,2,0),0) -> الحارث مبروك محمد الزوي | R9: =IFERROR(VLOOKUP(Q9,مسلسل,2,0),0) -> 0 | S9: =IFERROR(VLOOKUP(R9,مسلسل,2,0),0) -> 0 | T9: =IFERROR(VLOOKUP(S9,مسلسل,2,0),0) -> 0 | U9: =IFERROR(VLOOKUP(T9,مسلسل,2,0),0) -> 0 | V9: =IFERROR(VLOOKUP(U9,مسلسل,2,0),0) -> 0 | W9: =IFERROR(VLOOKUP(V9,مسلسل,2,0),0) -> 0 | X9: =IFERROR(VLOOKUP(W9,مسلسل,2,0),0) -> 0 | Y9: اللقــــــــب | AB9: =IFERROR(VLOOKUP(Q9,اسماء,66,0),"") -> الزوى | AE9: اسم التلميذ بالكـــامل | AF9: =IFERROR(VLOOKUP(AE1,مسلسل,2,0),0) -> 0 | AG9: =IFERROR(VLOOKUP(AF9,مسلسل,2,0),0) -> 0 | AH9: =IFERROR(VLOOKUP(AG9,مسلسل,2,0),0) -> 0 | AI9: =IFERROR(VLOOKUP(AH9,مسلسل,2,0),0) -> 0 | AJ9: =IFERROR(VLOOKUP(AI9,مسلسل,2,0),0) -> 0 | AK9: =IFERROR(VLOOKUP(AJ9,مسلسل,2,0),0) -> 0 | AL9: =IFERROR(VLOOKUP(AK9,مسلسل,2,0),0) -> 0 | AM9: =IFERROR(VLOOKUP(AL9,مسلسل,2,0),0) -> 0 | AN9: اللقــــــــب | AQ9: =IFERROR(VLOOKUP(AF9,اسماء,66,0),"") | AT9: اسم التلميذ بالكـــامل | AU9: =IFERROR(VLOOKUP(AT1,مسلسل,2,0),0) -> 0 | AV9: =IFERROR(VLOOKUP(AU9,مسلسل,2,0),0) -> 0 | AW9: =IFERROR(VLOOKUP(AV9,مسلسل,2,0),0) -> 0 | AX9: =IFERROR(VLOOKUP(AW9,مسلسل,2,0),0) -> 0 | AY9: =IFERROR(VLOOKUP(AX9,مسلسل,2,0),0) -> 0 | AZ9: =IFERROR(VLOOKUP(AY9,مسلسل,2,0),0) -> 0 | BA9: =IFERROR(VLOOKUP(AZ9,مسلسل,2,0),0) -> 0 | BB9: =IFERROR(VLOOKUP(BA9,مسلسل,2,0),0) -> 0 | BC9: اللقــــــــب | BF9: =IFERROR(VLOOKUP(AU9,اسماء,66,0),"")
A10: مكان وتاريخ الميلاد | B10: =IFERROR(VLOOKUP(B9,اسماء,79,0),"") -> طرابلس | E10: =IFERROR(VLOOKUP(B9,اسماء,2,0),"") -> 42772 | I10: اسم الوالدة بالكامل | M10: =IFERROR(VLOOKUP(B9,اسماء,3,0),"") -> هدى فرحات الجعفري | P10: مكان وتاريخ الميلاد | Q10: =IFERROR(VLOOKUP(Q9,اسماء,79,0),"") -> 0 | T10: =IFERROR(VLOOKUP(Q9,اسماء,2,0),"") -> 43014 | X10: اسم الوالدة بالكامل | AB10: =IFERROR(VLOOKUP(Q9,اسماء,3,0),"") -> سيسبان عبدالحكيم الطاهر | AE10: مكان وتاريخ الميلاد | AF10: =IFERROR(VLOOKUP(AF9,اسماء,79,0),"") | AI10: =IFERROR(VLOOKUP(AF9,اسماء,2,0),"") | AM10: اسم الوالدة بالكامل | AQ10: =IFERROR(VLOOKUP(AF9,اسماء,3,0),"") | AT10: مكان وتاريخ الميلاد | AU10: =IFERROR(VLOOKUP(AU9,اسماء,79,0),"") | AX10: =IFERROR(VLOOKUP(AU9,اسماء,2,0),"") | BB10: اسم الوالدة بالكامل | BF10: =IFERROR(VLOOKUP(AU9,اسماء,3,0),"")
A11: الرقم الوطنــــــــــي | B11: =IFERROR(VLOOKUP(B9,اسماء,67,0),"") -> 8 | C11: =IFERROR(VLOOKUP(B9,اسماء,68,0),"") -> 0 | D11: =IFERROR(VLOOKUP(B9,اسماء,69,0),"") -> 4 | E11: =IFERROR(VLOOKUP(B9,اسماء,70,0),"") -> 5 | F11: =IFERROR(VLOOKUP(B9,اسماء,71,0),"") -> 8 | G11: =IFERROR(VLOOKUP(B9,اسماء,72,0),"") -> 0 | H11: =IFERROR(VLOOKUP(B9,اسماء,73,0),"") -> 0 | I11: =IFERROR(VLOOKUP(B9,اسماء,74,0),"") -> 7 | J11: =IFERROR(VLOOKUP(B9,اسماء,75,0),"") -> 1 | K11: =IFERROR(VLOOKUP(B9,اسماء,76,0),"") -> 0 | L11: =IFERROR(VLOOKUP(B9,اسماء,77,0),"") -> 2 | M11: =IFERROR(VLOOKUP(B9,اسماء,78,0),"") -> 1 | P11: الرقم الوطنــــــــــي | Q11: =IFERROR(VLOOKUP(Q9,اسماء,67,0),"") -> 7 | R11: =IFERROR(VLOOKUP(Q9,اسماء,68,0),"") -> 2 | S11: =IFERROR(VLOOKUP(Q9,اسماء,69,0),"") -> 2 | T11: =IFERROR(VLOOKUP(Q9,اسماء,70,0),"") -> 9 | U11: =IFERROR(VLOOKUP(Q9,اسماء,71,0),"") -> 2 | V11: =IFERROR(VLOOKUP(Q9,اسماء,72,0),"") -> 7 | W11: =IFERROR(VLOOKUP(Q9,اسماء,73,0),"") -> 0 | X11: =IFERROR(VLOOKUP(Q9,اسماء,74,0),"") -> 7 | Y11: =IFERROR(VLOOKUP(Q9,اسماء,75,0),"") -> 1 | Z11: =IFERROR(VLOOKUP(Q9,اسماء,76,0),"") -> 0 | AA11: =IFERROR(VLOOKUP(Q9,اسماء,77,0),"") -> 2 | AB11: =IFERROR(VLOOKUP(Q9,اسماء,78,0),"") -> 1 | AE11: الرقم الوطنــــــــــي | AF11: =IFERROR(VLOOKUP(AF9,اسماء,67,0),"") | AG11: =IFERROR(VLOOKUP(AF9,اسماء,68,0),"") | AH11: =IFERROR(VLOOKUP(AF9,اسماء,69,0),"") | AI11: =IFERROR(VLOOKUP(AF9,اسماء,70,0),"") | AJ11: =IFERROR(VLOOKUP(AF9,اسماء,71,0),"") | AK11: =IFERROR(VLOOKUP(AF9,اسماء,72,0),"") | AL11: =IFERROR(VLOOKUP(AF9,اسماء,73,0),"") | AM11: =IFERROR(VLOOKUP(AF9,اسماء,74,0),"") | AN11: =IFERROR(VLOOKUP(AF9,اسماء,75,0),"") | AO11: =IFERROR(VLOOKUP(AF9,اسماء,76,0),"") | AP11: =IFERROR(VLOOKUP(AF9,اسماء,77,0),"") | AQ11: =IFERROR(VLOOKUP(AF9,اسماء,78,0),"") | AT11: الرقم الوطنــــــــــي | AU11: =IFERROR(VLOOKUP(AU9,اسماء,67,0),"") | AV11: =IFERROR(VLOOKUP(AU9,اسماء,68,0),"") | AW11: =IFERROR(VLOOKUP(AU9,اسماء,69,0),"") | AX11: =IFERROR(VLOOKUP(AU9,اسماء,70,0),"") | AY11: =IFERROR(VLOOKUP(AU9,اسماء,71,0),"") | AZ11: =IFERROR(VLOOKUP(AU9,اسماء,72,0),"") | BA11: =IFERROR(VLOOKUP(AU9,اسماء,73,0),"") | BB11: =IFERROR(VLOOKUP(AU9,اسماء,74,0),"") | BC11: =IFERROR(VLOOKUP(AU9,اسماء,75,0),"") | BD11: =IFERROR(VLOOKUP(AU9,اسماء,76,0),"") | BE11: =IFERROR(VLOOKUP(AU9,اسماء,77,0),"") | BF11: =IFERROR(VLOOKUP(AU9,اسماء,78,0),"")
A12: جنسيـــــة التلمــــيذ | B12: =IFERROR(VLOOKUP(B9,اسماء,80,0),"") -> ليبي | G12: مستجد/ | I12: معيد | K12: =IFERROR(VLOOKUP(B9,اسماء,81,0),"") -> مستجد | P12: جنسيـــــة التلمــــيذ | Q12: =IFERROR(VLOOKUP(Q9,اسماء,80,0),"") -> ليبي | V12: مستجد/ | X12: معيد | Z12: =IFERROR(VLOOKUP(Q9,اسماء,81,0),"") -> مستجد | AE12: جنسيـــــة التلمــــيذ | AF12: =IFERROR(VLOOKUP(AF9,اسماء,80,0),"") | AK12: مستجد/ | AM12: معيد | AO12: =IFERROR(VLOOKUP(AF9,اسماء,81,0),"") | AT12: جنسيـــــة التلمــــيذ | AU12: =IFERROR(VLOOKUP(AU9,اسماء,80,0),"") | AZ12: مستجد/ | BB12: معيد | BD12: =IFERROR(VLOOKUP(AU9,اسماء,81,0),"")
A13: رائــــــد الصــــــف | B13: =IFERROR(VLOOKUP(B9,اسماء,83,0),"") -> ريمة صالح المختار | G13: صفة القيد | K13: =IFERROR(VLOOKUP(B9,اسماء,82,0),"") -> نظامي | P13: رائــــــد الصــــــف | Q13: =IFERROR(VLOOKUP(Q9,اسماء,83,0),"") -> ريمة صالح المختار | V13: صفة القيد | Z13: =IFERROR(VLOOKUP(Q9,اسماء,82,0),"") -> نظامي | AE13: رائــــــد الصــــــف | AF13: =IFERROR(VLOOKUP(AF9,اسماء,83,0),"") | AK13: صفة القيد | AO13: =IFERROR(VLOOKUP(AF9,اسماء,82,0),"") | AT13: رائــــــد الصــــــف | AU13: =IFERROR(VLOOKUP(AU9,اسماء,83,0),"") | AZ13: صفة القيد | BD13: =IFERROR(VLOOKUP(AU9,اسماء,82,0),"")
A14: (يكتب اسم التلميذ مطابقاً لشهادة الميلاد) | P14: (يكتب اسم التلميذ مطابقاً لشهادة الميلاد) | AE14: (يكتب اسم التلميذ مطابقاً لشهادة الميلاد) | AT14: (يكتب اسم التلميذ مطابقاً لشهادة الميلاد)
A15: الانتقـــــــــال | P15: الانتقـــــــــال | AE15: الانتقـــــــــال | AT15: الانتقـــــــــال
A16: بناء على طلب ولي أمر التلميذ فإن إدارة هذه المدرسة توافق على انتقاله إلــــــى | P16: بناء على طلب ولي أمر التلميذ فإن إدارة هذه المدرسة توافق على انتقاله إلــــــى | AE16: بناء على طلب ولي أمر التلميذ فإن إدارة هذه المدرسة توافق على انتقاله إلــــــى | AT16: بناء على طلب ولي أمر التلميذ فإن إدارة هذه المدرسة توافق على انتقاله إلــــــى
A17: مدرســــــة | P17: مدرســــــة | AE17: مدرســــــة | AT17: مدرســــــة
A18: يعتمد مديرالمدرسة | N18: يعتمد مكتب الامتحانات | P18: يعتمد مديرالمدرسة | AC18: يعتمد مكتب الامتحانات | AE18: يعتمد مديرالمدرسة | AR18: يعتمد مكتب الامتحانات | AT18: يعتمد مديرالمدرسة | BG18: يعتمد مكتب الامتحانات
A23: =A1-1 -> 7 | B23: دولة ليبيا | P23: =A23-5 -> 2 | Q23: دولة ليبيا | AE23: =P23-5 -> -3 | AF23: دولة ليبيا | AT23: =AE23-5 -> -8 | AU23: دولة ليبيا
A24: وزارة التعليم | P24: وزارة التعليم | AE24: وزارة التعليم | AT24: وزارة التعليم
A25: المركز الوطني للامتحانات | P25: المركز الوطني للامتحانات | AE25: المركز الوطني للامتحانات | AT25: المركز الوطني للامتحانات
A26: بطاقة تقدير الدرجات لمرحلة التعليم | K26: =ادخال1!$CG$7 -> الاساسي | P26: بطاقة تقدير الدرجات لمرحلة التعليم | Z26: =ادخال1!$CG$7 -> الاساسي | AE26: بطاقة تقدير الدرجات لمرحلة التعليم | AO26: =ادخال1!$CG$7 -> الاساسي | AT26: بطاقة تقدير الدرجات لمرحلة التعليم | BD26: =ادخال1!$CG$7 -> الاساسي
A27: للصف | G27: =ادخال1!$CE$5 -> الثالث الابتدائي | P27: للصف | V27: =ادخال1!$CE$5 -> الثالث الابتدائي | AE27: للصف | AK27: =ادخال1!$CE$5 -> الثالث الابتدائي | AT27: للصف | AZ27: =ادخال1!$CE$5 -> الثالث الابتدائي
A28: العام الدراسي | B28: =ادخال1!$CD$8 -> 1448هـ/1447 هـ | F28: هجرية | H28: الموافق | J28: =ادخال1!$CE$8 -> 2025م /2026م | N28: ميلادية | P28: العام الدراسي | Q28: =ادخال1!$CD$8 -> 1448هـ/1447 هـ | U28: هجرية | W28: الموافق | Y28: =ادخال1!$CE$8 -> 2025م /2026م | AC28: ميلادية | AE28: العام الدراسي | AF28: =ادخال1!$CD$8 -> 1448هـ/1447 هـ | AJ28: هجرية | AL28: الموافق | AN28: =ادخال1!$CE$8 -> 2025م /2026م | AR28: ميلادية | AT28: العام الدراسي | AU28: =ادخال1!$CD$8 -> 1448هـ/1447 هـ | AY28: هجرية | BA28: الموافق | BC28: =ادخال1!$CE$8 -> 2025م /2026م | BG28: ميلادية
A29: شؤون التعليم بمنطقة | B29: =ادخال1!$CE$4 -> تاجوراء | P29: شؤون التعليم بمنطقة | Q29: =ادخال1!$CE$4 -> تاجوراء | AE29: شؤون التعليم بمنطقة | AF29: =ادخال1!$CE$4 -> تاجوراء | AT29: شؤون التعليم بمنطقة | AU29: =ادخال1!$CE$4 -> تاجوراء
A30: مدرســــــــــــــــــــــة | B30: =ادخال1!$CC$6 -> سهول العلم للتعليم الخاص | J30: الكــــائنة بـ : | M30: =ادخال1!$CC$8 -> تاجوراء | P30: مدرســــــــــــــــــــــة | Q30: =ادخال1!$CC$6 -> سهول العلم للتعليم الخاص | Y30: الكــــائنة بـ : | AB30: =ادخال1!$CC$8 -> تاجوراء | AE30: مدرســــــــــــــــــــــة | AF30: =ادخال1!$CC$6 -> سهول العلم للتعليم الخاص | AN30: الكــــائنة بـ : | AQ30: =ادخال1!$CC$8 -> تاجوراء | AT30: مدرســــــــــــــــــــــة | AU30: =ادخال1!$CC$6 -> سهول العلم للتعليم الخاص | BC30: الكــــائنة بـ : | BF30: =ادخال1!$CC$8 -> تاجوراء
A31: اسم التلميذ بالكـــامل | B31: =IFERROR(VLOOKUP(A23,مسلسل,2,0),0) -> عبدالقدوس عزالدين سالم ادريدر | C31: =IFERROR(VLOOKUP(B31,مسلسل,2,0),0) -> 0 | D31: =IFERROR(VLOOKUP(C31,مسلسل,2,0),0) -> 0 | E31: =IFERROR(VLOOKUP(D31,مسلسل,2,0),0) -> 0 | F31: =IFERROR(VLOOKUP(E31,مسلسل,2,0),0) -> 0 | G31: =IFERROR(VLOOKUP(F31,مسلسل,2,0),0) -> 0 | H31: =IFERROR(VLOOKUP(G31,مسلسل,2,0),0) -> 0 | I31: =IFERROR(VLOOKUP(H31,مسلسل,2,0),0) -> 0 | J31: اللقــــــــب | M31: =IFERROR(VLOOKUP(B31,اسماء,66,0),"") -> ادريدر | P31: اسم التلميذ بالكـــامل | Q31: =IFERROR(VLOOKUP(P23,مسلسل,2,0),0) -> إيلاف نورالدين عياد حسين | R31: =IFERROR(VLOOKUP(Q31,مسلسل,2,0),0) -> 0 | S31: =IFERROR(VLOOKUP(R31,مسلسل,2,0),0) -> 0 | T31: =IFERROR(VLOOKUP(S31,مسلسل,2,0),0) -> 0 | U31: =IFERROR(VLOOKUP(T31,مسلسل,2,0),0) -> 0 | V31: =IFERROR(VLOOKUP(U31,مسلسل,2,0),0) -> 0 | W31: =IFERROR(VLOOKUP(V31,مسلسل,2,0),0) -> 0 | X31: =IFERROR(VLOOKUP(W31,مسلسل,2,0),0) -> 0 | Y31: اللقــــــــب | AB31: =IFERROR(VLOOKUP(Q31,اسماء,66,0),"") -> حسين | AE31: اسم التلميذ بالكـــامل | AF31: =IFERROR(VLOOKUP(AE23,مسلسل,2,0),0) -> 0 | AG31: =IFERROR(VLOOKUP(AF31,مسلسل,2,0),0) -> 0 | AH31: =IFERROR(VLOOKUP(AG31,مسلسل,2,0),0) -> 0 | AI31: =IFERROR(VLOOKUP(AH31,مسلسل,2,0),0) -> 0 | AJ31: =IFERROR(VLOOKUP(AI31,مسلسل,2,0),0) -> 0 | AK31: =IFERROR(VLOOKUP(AJ31,مسلسل,2,0),0) -> 0 | AL31: =IFERROR(VLOOKUP(AK31,مسلسل,2,0),0) -> 0 | AM31: =IFERROR(VLOOKUP(AL31,مسلسل,2,0),0) -> 0 | AN31: اللقــــــــب | AQ31: =IFERROR(VLOOKUP(AF31,اسماء,66,0),"") | AT31: اسم التلميذ بالكـــامل | AU31: =IFERROR(VLOOKUP(AT23,مسلسل,2,0),0) -> 0 | AV31: =IFERROR(VLOOKUP(AU31,مسلسل,2,0),0) -> 0 | AW31: =IFERROR(VLOOKUP(AV31,مسلسل,2,0),0) -> 0 | AX31: =IFERROR(VLOOKUP(AW31,مسلسل,2,0),0) -> 0 | AY31: =IFERROR(VLOOKUP(AX31,مسلسل,2,0),0) -> 0 | AZ31: =IFERROR(VLOOKUP(AY31,مسلسل,2,0),0) -> 0 | BA31: =IFERROR(VLOOKUP(AZ31,مسلسل,2,0),0) -> 0 | BB31: =IFERROR(VLOOKUP(BA31,مسلسل,2,0),0) -> 0 | BC31: اللقــــــــب | BF31: =IFERROR(VLOOKUP(AU31,اسماء,66,0),"")
A32: مكان وتاريخ الميلاد | B32: =IFERROR(VLOOKUP(B31,اسماء,79,0),"") -> تاجوراء | E32: =IFERROR(VLOOKUP(B31,اسماء,2,0),"") -> 43022 | I32: اسم الوالدة بالكامل | M32: =IFERROR(VLOOKUP(B31,اسماء,3,0),"") -> إيمان الطاهر على بن جابر | P32: مكان وتاريخ الميلاد | Q32: =IFERROR(VLOOKUP(Q31,اسماء,79,0),"") -> طرابلس | T32: =IFERROR(VLOOKUP(Q31,اسماء,2,0),"") -> 42906 | X32: اسم الوالدة بالكامل | AB32: =IFERROR(VLOOKUP(Q31,اسماء,3,0),"") -> هند الصادق عبدالقادر رمضان | AE32: مكان وتاريخ الميلاد | AF32: =IFERROR(VLOOKUP(AF31,اسماء,79,0),"") | AI32: =IFERROR(VLOOKUP(AF31,اسماء,2,0),"") | AM32: اسم الوالدة بالكامل | AQ32: =IFERROR(VLOOKUP(AF31,اسماء,3,0),"") | AT32: مكان وتاريخ الميلاد | AU32: =IFERROR(VLOOKUP(AU31,اسماء,79,0),"") | AX32: =IFERROR(VLOOKUP(AU31,اسماء,2,0),"") | BB32: اسم الوالدة بالكامل | BF32: =IFERROR(VLOOKUP(AU31,اسماء,3,0),"")
A33: الرقم الوطنــــــــــي | B33: =IFERROR(VLOOKUP(B31,اسماء,67,0),"") -> 6 | C33: =IFERROR(VLOOKUP(B31,اسماء,68,0),"") -> 5 | D33: =IFERROR(VLOOKUP(B31,اسماء,69,0),"") -> 0 | E33: =IFERROR(VLOOKUP(B31,اسماء,70,0),"") -> 9 | F33: =IFERROR(VLOOKUP(B31,اسماء,71,0),"") -> 7 | G33: =IFERROR(VLOOKUP(B31,اسماء,72,0),"") -> 6 | H33: =IFERROR(VLOOKUP(B31,اسماء,73,0),"") -> 0 | I33: =IFERROR(VLOOKUP(B31,اسماء,74,0),"") -> 7 | J33: =IFERROR(VLOOKUP(B31,اسماء,75,0),"") -> 1 | K33: =IFERROR(VLOOKUP(B31,اسماء,76,0),"") -> 0 | L33: =IFERROR(VLOOKUP(B31,اسماء,77,0),"") -> 2 | M33: =IFERROR(VLOOKUP(B31,اسماء,78,0),"") -> 1 | P33: الرقم الوطنــــــــــي | Q33: =IFERROR(VLOOKUP(Q31,اسماء,67,0),"") -> 4 | R33: =IFERROR(VLOOKUP(Q31,اسماء,68,0),"") -> 7 | S33: =IFERROR(VLOOKUP(Q31,اسماء,69,0),"") -> 7 | T33: =IFERROR(VLOOKUP(Q31,اسماء,70,0),"") -> 5 | U33: =IFERROR(VLOOKUP(Q31,اسماء,71,0),"") -> 6 | V33: =IFERROR(VLOOKUP(Q31,اسماء,72,0),"") -> 5 | W33: =IFERROR(VLOOKUP(Q31,اسماء,73,0),"") -> 0 | X33: =IFERROR(VLOOKUP(Q31,اسماء,74,0),"") -> 7 | Y33: =IFERROR(VLOOKUP(Q31,اسماء,75,0),"") -> 1 | Z33: =IFERROR(VLOOKUP(Q31,اسماء,76,0),"") -> 0 | AA33: =IFERROR(VLOOKUP(Q31,اسماء,77,0),"") -> 2 | AB33: =IFERROR(VLOOKUP(Q31,اسماء,78,0),"") -> 2 | AE33: الرقم الوطنــــــــــي | AF33: =IFERROR(VLOOKUP(AF31,اسماء,67,0),"") | AG33: =IFERROR(VLOOKUP(AF31,اسماء,68,0),"") | AH33: =IFERROR(VLOOKUP(AF31,اسماء,69,0),"") | AI33: =IFERROR(VLOOKUP(AF31,اسماء,70,0),"") | AJ33: =IFERROR(VLOOKUP(AF31,اسماء,71,0),"") | AK33: =IFERROR(VLOOKUP(AF31,اسماء,72,0),"") | AL33: =IFERROR(VLOOKUP(AF31,اسماء,73,0),"") | AM33: =IFERROR(VLOOKUP(AF31,اسماء,74,0),"") | AN33: =IFERROR(VLOOKUP(AF31,اسماء,75,0),"") | AO33: =IFERROR(VLOOKUP(AF31,اسماء,76,0),"") | AP33: =IFERROR(VLOOKUP(AF31,اسماء,77,0),"") | AQ33: =IFERROR(VLOOKUP(AF31,اسماء,78,0),"") | AT33: الرقم الوطنــــــــــي | AU33: =IFERROR(VLOOKUP(AU31,اسماء,67,0),"") | AV33: =IFERROR(VLOOKUP(AU31,اسماء,68,0),"") | AW33: =IFERROR(VLOOKUP(AU31,اسماء,69,0),"") | AX33: =IFERROR(VLOOKUP(AU31,اسماء,70,0),"") | AY33: =IFERROR(VLOOKUP(AU31,اسماء,71,0),"") | AZ33: =IFERROR(VLOOKUP(AU31,اسماء,72,0),"") | BA33: =IFERROR(VLOOKUP(AU31,اسماء,73,0),"") | BB33: =IFERROR(VLOOKUP(AU31,اسماء,74,0),"") | BC33: =IFERROR(VLOOKUP(AU31,اسماء,75,0),"") | BD33: =IFERROR(VLOOKUP(AU31,اسماء,76,0),"") | BE33: =IFERROR(VLOOKUP(AU31,اسماء,77,0),"") | BF33: =IFERROR(VLOOKUP(AU31,اسماء,78,0),"")
A34: جنسيـــــة التلمــــيذ | B34: =IFERROR(VLOOKUP(B31,اسماء,80,0),"") -> ليبي | G34: مستجد/ | I34: معيد | K34: =IFERROR(VLOOKUP(B31,اسماء,81,0),"") -> مستجد | P34: جنسيـــــة التلمــــيذ | Q34: =IFERROR(VLOOKUP(Q31,اسماء,80,0),"") -> ليبية | V34: مستجد/ | X34: معيد | Z34: =IFERROR(VLOOKUP(Q31,اسماء,81,0),"") -> مستجد | AE34: جنسيـــــة التلمــــيذ | AF34: =IFERROR(VLOOKUP(AF31,اسماء,80,0),"") | AK34: مستجد/ | AM34: معيد | AO34: =IFERROR(VLOOKUP(AF31,اسماء,81,0),"") | AT34: جنسيـــــة التلمــــيذ | AU34: =IFERROR(VLOOKUP(AU31,اسماء,80,0),"") | AZ34: مستجد/ | BB34: معيد | BD34: =IFERROR(VLOOKUP(AU31,اسماء,81,0),"")
A35: رائــــــد الصــــــف | B35: =IFERROR(VLOOKUP(B31,اسماء,83,0),"") -> ريمة صالح المختار | G35: صفة القيد | K35: =IFERROR(VLOOKUP(B31,اسماء,82,0),"") -> نظامي | P35: رائــــــد الصــــــف | Q35: =IFERROR(VLOOKUP(Q31,اسماء,83,0),"") -> ريمة صالح المختار | V35: صفة القيد | Z35: =IFERROR(VLOOKUP(Q31,اسماء,82,0),"") -> نظامي | AE35: رائــــــد الصــــــف | AF35: =IFERROR(VLOOKUP(AF31,اسماء,83,0),"") | AK35: صفة القيد | AO35: =IFERROR(VLOOKUP(AF31,اسماء,82,0),"") | AT35: رائــــــد الصــــــف | AU35: =IFERROR(VLOOKUP(AU31,اسماء,83,0),"") | AZ35: صفة القيد | BD35: =IFERROR(VLOOKUP(AU31,اسماء,82,0),"")
A36: (يكتب اسم التلميذ مطابقاً لشهادة الميلاد) | P36: (يكتب اسم التلميذ مطابقاً لشهادة الميلاد) | AE36: (يكتب اسم التلميذ مطابقاً لشهادة الميلاد) | AT36: (يكتب اسم التلميذ مطابقاً لشهادة الميلاد)
A37: الانتقـــــــــال | P37: الانتقـــــــــال | AE37: الانتقـــــــــال | AT37: الانتقـــــــــال
A38: بناء على طلب ولي أمر التلميذ فإن إدارة هذه المدرسة توافق على انتقاله إلــــــى | P38: بناء على طلب ولي أمر التلميذ فإن إدارة هذه المدرسة توافق على انتقاله إلــــــى | AE38: بناء على طلب ولي أمر التلميذ فإن إدارة هذه المدرسة توافق على انتقاله إلــــــى | AT38: بناء على طلب ولي أمر التلميذ فإن إدارة هذه المدرسة توافق على انتقاله إلــــــى
A39: مدرســــــة | P39: مدرســــــة | AE39: مدرســــــة | AT39: مدرســــــة
A40: يعتمد مديرالمدرسة | N40: يعتمد مكتب الامتحانات | P40: يعتمد مديرالمدرسة | AC40: يعتمد مكتب الامتحانات | AE40: يعتمد مديرالمدرسة | AR40: يعتمد مكتب الامتحانات | AT40: يعتمد مديرالمدرسة | BG40: يعتمد مكتب الامتحانات
A45: =A23-1 -> 6 | B45: دولة ليبيا | P45: =A45-5 -> 1 | Q45: دولة ليبيا | AE45: =P45-5 -> -4 | AF45: دولة ليبيا | AT45: =AE45-5 -> -9 | AU45: دولة ليبيا
A46: وزارة التعليم | P46: وزارة التعليم | AE46: وزارة التعليم | AT46: وزارة التعليم
A47: المركز الوطني للامتحانات | P47: المركز الوطني للامتحانات | AE47: المركز الوطني للامتحانات | AT47: المركز الوطني للامتحانات
A48: بطاقة تقدير الدرجات لمرحلة التعليم | K48: =ادخال1!$CG$7 -> الاساسي | P48: بطاقة تقدير الدرجات لمرحلة التعليم | Z48: =ادخال1!$CG$7 -> الاساسي | AE48: بطاقة تقدير الدرجات لمرحلة التعليم | AO48: =ادخال1!$CG$7 -> الاساسي | AT48: بطاقة تقدير الدرجات لمرحلة التعليم | BD48: =ادخال1!$CG$7 -> الاساسي
...

Sheet الرئيسية

Sheet صحيفة الفترات
A1: بطاقة تقدير الدرجات للصــــف | D1: =ادخال1!$L$4 -> الثالث | F1: من التعليم الأساسي | J1: 4 | L1: بطاقة تقدير الدرجات للصــــف | O1: =ادخال1!$L$4 -> الثالث | Q1: من التعليم الأساسي | U1: =J1+5 -> 9 | W1: بطاقة تقدير الدرجات للصــــف | Z1: =ادخال1!$L$4 -> الثالث | AB1: من التعليم الأساسي | AF1: =U1+5 -> 14 | AH1: بطاقة تقدير الدرجات للصــــف | AK1: =ادخال1!$L$4 -> الثالث | AM1: من التعليم الأساسي | AQ1: =AF1+5 -> 19
A2: المدرسة/ | B2: =ادخال1!$B$5 -> سهول العلم للتعليم الخاص | F2: الاسم | G2: =H15 -> دانية حسن مفتاح المقوب | M2: =ادخال1!$B$5 -> سهول العلم للتعليم الخاص | Q2: الاسم | R2: =S15 -> فاطمة سالم سالم الورفلى | W2: المدرسة/ | X2: =ادخال1!$B$5 -> سهول العلم للتعليم الخاص | AB2: الاسم | AC2: =AD15 -> ايلياء محمد عوض الحداد | AH2: المدرسة/ | AI2: =ادخال1!$B$5 -> سهول العلم للتعليم الخاص | AM2: الاسم | AN2: =AO15 -> 0
A3: الفترات | B3: عدد الحصص | C3: الفترة الأولي 30 % | E3: الفترة الثانية 30 % | H3: ملاحظــات عن نتيجة التلميذ خلال كل فترة : | L3: الفترات | M3: عدد الحصص | N3: الفترة الأولي 30 % | P3: الفترة الثانية 30 % | S3: ملاحظــات عن نتيجة التلميذ خلال كل فترة : | W3: الفترات | X3: عدد الحصص | Y3: الفترة الأولي 30 % | AA3: الفترة الثانية 30 % | AD3: ملاحظــات عن نتيجة التلميذ خلال كل فترة : | AH3: الفترات | AI3: عدد الحصص | AJ3: الفترة الأولي 30 % | AL3: الفترة الثانية 30 % | AO3: ملاحظــات عن نتيجة التلميذ خلال كل فترة :
A4: المواد الدراسية | C4: الدرجة الكبرى | D4: درجة التلميذ | E4: الدرجة الكبرى | F4: درجة التلميذ | H4: الأولي : | I4: =IF(D11=0,"",IF(AND(D5>=C5*0.4,D6>=C6*0.4,D7>=C7*0.4,D9>=C9*0.4,D10>=C10*0.4),LOOKUP(D11,'النتيجة النهائية'!$AC$6:$AD$10),"ضعيف ويحتاج الى اهتمام في المواد")) -> ممتاز | L4: المواد الدراسية | N4: الدرجة الكبرى | O4: درجة التلميذ | P4: الدرجة الكبرى | Q4: درجة التلميذ | S4: الأولي : | T4: =IF(O11=0,"",IF(AND(O5>=N5*0.4,O6>=N6*0.4,O7>=N7*0.4,O9>=N9*0.4,O10>=N10*0.4),LOOKUP(O11,'النتيجة النهائية'!$AC$6:$AD$10),"ضعيف ويحتاج الى اهتمام في المواد")) -> ممتاز | W4: المواد الدراسية | Y4: الدرجة الكبرى | Z4: درجة التلميذ | AA4: الدرجة الكبرى | AB4: درجة التلميذ | AD4: الأولي : | AE4: =IF(Z11=0,"",IF(AND(Z5>=Y5*0.4,Z6>=Y6*0.4,Z7>=Y7*0.4,Z9>=Y9*0.4,Z10>=Y10*0.4),LOOKUP(Z11,'النتيجة النهائية'!$AC$6:$AD$10),"ضعيف ويحتاج الى اهتمام في المواد")) -> ممتاز | AH4: المواد الدراسية | AJ4: الدرجة الكبرى | AK4: درجة التلميذ | AL4: الدرجة الكبرى | AM4: درجة التلميذ | AO4: الأولي : | AP4: =IF(AK11=0,"",IF(AND(AK5>=AJ5*0.4,AK6>=AJ6*0.4,AK7>=AJ7*0.4,AK9>=AJ9*0.4,AK10>=AJ10*0.4),LOOKUP(AK11,'النتيجة النهائية'!$AC$6:$AD$10),"ضعيف ويحتاج الى اهتمام في المواد"))
A5: =ادخال1!$F$9 -> التربية الإسلامية | B5: =ادخال1!$F$7 -> 3 | C5: =40*B5*0.3 -> 36 | D5: =IFERROR(VLOOKUP(H15,اسماء,5,0),"") -> 31 | E5: =40*B5*0.3 -> 36 | F5: =IFERROR(VLOOKUP(H15,اسماء,16,0),"") -> 0 | H5: =IF(D5=0,"",IF(D5<C5*0.4,A5,"")) | I5: =IF(D6=0,"",IF(D6<C6*0.4,A6,"")) | J5: =IF(D7=0,"",IF(D7<C7*0.4,A7,"")) | L5: =ادخال1!$F$9 -> التربية الإسلامية | M5: =ادخال1!$F$7 -> 3 | N5: =40*M5*0.3 -> 36 | O5: =IFERROR(VLOOKUP(S15,اسماء,5,0),"") -> 36 | P5: =40*M5*0.3 -> 36 | Q5: =IFERROR(VLOOKUP(S15,اسماء,16,0),"") -> 0 | S5: =IF(O5=0,"",IF(O5<N5*0.4,L5,"")) | T5: =IF(O6=0,"",IF(O6<N6*0.4,L6,"")) | U5: =IF(O7=0,"",IF(O7<N7*0.4,L7,"")) | W5: =ادخال1!$F$9 -> التربية الإسلامية | X5: =ادخال1!$F$7 -> 3 | Y5: =40*X5*0.3 -> 36 | Z5: =IFERROR(VLOOKUP(AD15,اسماء,5,0),"") -> 36 | AA5: =40*X5*0.3 -> 36 | AB5: =IFERROR(VLOOKUP(AD15,اسماء,16,0),"") -> 0 | AD5: =IF(Z5=0,"",IF(Z5<Y5*0.4,W5,"")) | AE5: =IF(Z6=0,"",IF(Z6<Y6*0.4,W6,"")) | AF5: =IF(Z7=0,"",IF(Z7<Y7*0.4,W7,"")) | AH5: =ادخال1!$F$9 -> التربية الإسلامية | AI5: =ادخال1!$F$7 -> 3 | AJ5: =40*AI5*0.3 -> 36 | AK5: =IFERROR(VLOOKUP(AO15,اسماء,5,0),"") | AL5: =40*AI5*0.3 -> 36 | AM5: =IFERROR(VLOOKUP(AO15,اسماء,16,0),"") | AO5: =IF(AK5=0,"",IF(AK5<AJ5*0.4,AH5,"")) | AP5: =IF(AK6=0,"",IF(AK6<AJ6*0.4,AH6,"")) | AQ5: =IF(AK7=0,"",IF(AK7<AJ7*0.4,AH7,""))
A6: =ادخال1!$G$9 -> اللغة العربية | B6: =ادخال1!$G$7 -> 6 | C6: =40*B6*0.3 -> 72 | D6: =IFERROR(VLOOKUP(H15,اسماء,6,0),"") -> 64 | E6: =40*B6*0.3 -> 72 | F6: =IFERROR(VLOOKUP(H15,اسماء,17,0),"") -> 0 | H6: =IF(D9=0,"",IF(D9<C9*0.4,A9,"")) | I6: =IF(D10=0,"",IF(D10<C10*0.4,A10,"")) | J6: =IF(D8=0,"",IF(D8<C8*0.4,A8,"")) | L6: =ادخال1!$G$9 -> اللغة العربية | M6: =ادخال1!$G$7 -> 6 | N6: =40*M6*0.3 -> 72 | O6: =IFERROR(VLOOKUP(S15,اسماء,6,0),"") -> 71 | P6: =40*M6*0.3 -> 72 | Q6: =IFERROR(VLOOKUP(S15,اسماء,17,0),"") -> 0 | S6: =IF(O9=0,"",IF(O9<N9*0.4,L9,"")) | T6: =IF(O10=0,"",IF(O10<N10*0.4,L10,"")) | U6: =IF(O8=0,"",IF(O8<N8*0.4,L8,"")) | W6: =ادخال1!$G$9 -> اللغة العربية | X6: =ادخال1!$G$7 -> 6 | Y6: =40*X6*0.3 -> 72 | Z6: =IFERROR(VLOOKUP(AD15,اسماء,6,0),"") -> 71 | AA6: =40*X6*0.3 -> 72 | AB6: =IFERROR(VLOOKUP(AD15,اسماء,17,0),"") -> 0 | AD6: =IF(Z9=0,"",IF(Z9<Y9*0.4,W9,"")) | AE6: =IF(Z10=0,"",IF(Z10<Y10*0.4,W10,"")) | AF6: =IF(Z8=0,"",IF(Z8<Y8*0.4,W8,"")) | AH6: =ادخال1!$G$9 -> اللغة العربية | AI6: =ادخال1!$G$7 -> 6 | AJ6: =40*AI6*0.3 -> 72 | AK6: =IFERROR(VLOOKUP(AO15,اسماء,6,0),"") | AL6: =40*AI6*0.3 -> 72 | AM6: =IFERROR(VLOOKUP(AO15,اسماء,17,0),"") | AO6: =IF(AK9=0,"",IF(AK9<AJ9*0.4,AH9,"")) | AP6: =IF(AK10=0,"",IF(AK10<AJ10*0.4,AH10,"")) | AQ6: =IF(AK8=0,"",IF(AK8<AJ8*0.4,AH8,""))
A7: =ادخال1!$H$9 -> اللغة الإنجليزية | B7: =ادخال1!$H$7 -> 3 | C7: =40*B7*0.3 -> 36 | D7: =IFERROR(VLOOKUP(H15,اسماء,7,0),"") -> 33 | E7: =40*B7*0.3 -> 36 | F7: =IFERROR(VLOOKUP(H15,اسماء,18,0),"") -> 0 | H7: الثانية :- | I7: =IF(F11=0,"",IF(AND(F5>=E5*0.4,F6>=E6*0.4,F7>=E7*0.4,F9>=E9*0.4,F10>=E10*0.4),LOOKUP(F11,'النتيجة النهائية'!$AC$6:$AD$10),"ضعيف ويحتاج الى اهتمام في المواد")) | L7: =ادخال1!$H$9 -> اللغة الإنجليزية | M7: =ادخال1!$H$7 -> 3 | N7: =40*M7*0.3 -> 36 | O7: =IFERROR(VLOOKUP(S15,اسماء,7,0),"") -> 33 | P7: =40*M7*0.3 -> 36 | Q7: =IFERROR(VLOOKUP(S15,اسماء,18,0),"") -> 0 | S7: الثانية :- | T7: =IF(Q11=0,"",IF(AND(Q5>=P5*0.4,Q6>=P6*0.4,Q7>=P7*0.4,Q9>=P9*0.4,Q10>=P10*0.4),LOOKUP(Q11,'النتيجة النهائية'!$AC$6:$AD$10),"ضعيف ويحتاج الى اهتمام في المواد")) | W7: =ادخال1!$H$9 -> اللغة الإنجليزية | X7: =ادخال1!$H$7 -> 3 | Y7: =40*X7*0.3 -> 36 | Z7: =IFERROR(VLOOKUP(AD15,اسماء,7,0),"") -> 34 | AA7: =40*X7*0.3 -> 36 | AB7: =IFERROR(VLOOKUP(AD15,اسماء,18,0),"") -> 0 | AD7: الثانية :- | AE7: =IF(AB11=0,"",IF(AND(AB5>=AA5*0.4,AB6>=AA6*0.4,AB7>=AA7*0.4,AB9>=AA9*0.4,AB10>=AA10*0.4),LOOKUP(AB11,'النتيجة النهائية'!$AC$6:$AD$10),"ضعيف ويحتاج الى اهتمام في المواد")) | AH7: =ادخال1!$H$9 -> اللغة الإنجليزية | AI7: =ادخال1!$H$7 -> 3 | AJ7: =40*AI7*0.3 -> 36 | AK7: =IFERROR(VLOOKUP(AO15,اسماء,7,0),"") | AL7: =40*AI7*0.3 -> 36 | AM7: =IFERROR(VLOOKUP(AO15,اسماء,18,0),"") | AO7: الثانية :- | AP7: =IF(AM11=0,"",IF(AND(AM5>=AL5*0.4,AM6>=AL6*0.4,AM7>=AL7*0.4,AM9>=AL9*0.4,AM10>=AL10*0.4),LOOKUP(AM11,'النتيجة النهائية'!$AC$6:$AD$10),"ضعيف ويحتاج الى اهتمام في المواد"))
A8: =ادخال1!$I$9 -> الحاسوب | B8: =ادخال1!$I$7 -> 1 | C8: =40*B8*0.3 -> 12 | D8: =IFERROR(VLOOKUP(H15,اسماء,8,0),"") -> 11 | E8: =40*B8*0.3 -> 12 | F8: =IFERROR(VLOOKUP(H15,اسماء,19,0),"") -> 0 | L8: =ادخال1!$I$9 -> الحاسوب | M8: =ادخال1!$I$7 -> 1 | N8: =40*M8*0.3 -> 12 | O8: =IFERROR(VLOOKUP(S15,اسماء,8,0),"") -> 12 | P8: =40*M8*0.3 -> 12 | Q8: =IFERROR(VLOOKUP(S15,اسماء,19,0),"") -> 0 | W8: =ادخال1!$I$9 -> الحاسوب | X8: =ادخال1!$I$7 -> 1 | Y8: =40*X8*0.3 -> 12 | Z8: =IFERROR(VLOOKUP(AD15,اسماء,8,0),"") -> 12 | AA8: =40*X8*0.3 -> 12 | AB8: =IFERROR(VLOOKUP(AD15,اسماء,19,0),"") -> 0 | AH8: =ادخال1!$I$9 -> الحاسوب | AI8: =ادخال1!$I$7 -> 1 | AJ8: =40*AI8*0.3 -> 12 | AK8: =IFERROR(VLOOKUP(AO15,اسماء,8,0),"") | AL8: =40*AI8*0.3 -> 12 | AM8: =IFERROR(VLOOKUP(AO15,اسماء,19,0),"")
A9: =ادخال1!$J$9 -> الرياضيات | B9: =ادخال1!$J$7 -> 5 | C9: =40*B9*0.3 -> 60 | D9: =IFERROR(VLOOKUP(H15,اسماء,9,0),"") -> 49 | E9: =40*B9*0.3 -> 60 | F9: =IFERROR(VLOOKUP(H15,اسماء,20,0),"") -> 0 | H9: =IF(F5=0,"",IF(F5<E5*0.4,A5,"")) | I9: =IF(F6=0,"",IF(F6<E6*0.4,A6,"")) | J9: =IF(F7=0,"",IF(F7<E7*0.4,A7,"")) | L9: =ادخال1!$J$9 -> الرياضيات | M9: =ادخال1!$J$7 -> 5 | N9: =40*M9*0.3 -> 60 | O9: =IFERROR(VLOOKUP(S15,اسماء,9,0),"") -> 55 | P9: =40*M9*0.3 -> 60 | Q9: =IFERROR(VLOOKUP(S15,اسماء,20,0),"") -> 0 | S9: =IF(Q5=0,"",IF(Q5<P5*0.4,L5,"")) | T9: =IF(Q6=0,"",IF(Q6<P6*0.4,L6,"")) | U9: =IF(Q7=0,"",IF(Q7<P7*0.4,L7,"")) | W9: =ادخال1!$J$9 -> الرياضيات | X9: =ادخال1!$J$7 -> 5 | Y9: =40*X9*0.3 -> 60 | Z9: =IFERROR(VLOOKUP(AD15,اسماء,9,0),"") -> 56 | AA9: =40*X9*0.3 -> 60 | AB9: =IFERROR(VLOOKUP(AD15,اسماء,20,0),"") -> 0 | AD9: =IF(AB5=0,"",IF(AB5<AA5*0.4,W5,"")) | AE9: =IF(AB6=0,"",IF(AB6<AA6*0.4,W6,"")) | AF9: =IF(AB7=0,"",IF(AB7<AA7*0.4,W7,"")) | AH9: =ادخال1!$J$9 -> الرياضيات | AI9: =ادخال1!$J$7 -> 5 | AJ9: =40*AI9*0.3 -> 60 | AK9: =IFERROR(VLOOKUP(AO15,اسماء,9,0),"") | AL9: =40*AI9*0.3 -> 60 | AM9: =IFERROR(VLOOKUP(AO15,اسماء,20,0),"") | AO9: =IF(AM5=0,"",IF(AM5<AL5*0.4,AH5,"")) | AP9: =IF(AM6=0,"",IF(AM6<AL6*0.4,AH6,"")) | AQ9: =IF(AM7=0,"",IF(AM7<AL7*0.4,AH7,""))
A10: =ادخال1!$K$9 -> العلوم | B10: =ادخال1!$K$7 -> 3 | C10: =40*B10*0.3 -> 36 | D10: =IFERROR(VLOOKUP(H15,اسماء,10,0),"") -> 36 | E10: =40*B10*0.3 -> 36 | F10: =IFERROR(VLOOKUP(H15,اسماء,21,0),"") -> 0 | H10: =IF(F9=0,"",IF(F9<E9*0.4,A9,"")) | I10: =IF(F10=0,"",IF(F10<E10*0.4,A10,"")) | J10: =IF(F8=0,"",IF(F8<E8*0.4,A8,"")) | L10: =ادخال1!$K$9 -> العلوم | M10: =ادخال1!$K$7 -> 3 | N10: =40*M10*0.3 -> 36 | O10: =IFERROR(VLOOKUP(S15,اسماء,10,0),"") -> 35 | P10: =40*M10*0.3 -> 36 | Q10: =IFERROR(VLOOKUP(S15,اسماء,21,0),"") -> 0 | S10: =IF(Q9=0,"",IF(Q9<P9*0.4,L9,"")) | T10: =IF(Q10=0,"",IF(Q10<P10*0.4,L10,"")) | U10: =IF(Q8=0,"",IF(Q8<P8*0.4,L8,"")) | W10: =ادخال1!$K$9 -> العلوم | X10: =ادخال1!$K$7 -> 3 | Y10: =40*X10*0.3 -> 36 | Z10: =IFERROR(VLOOKUP(AD15,اسماء,10,0),"") -> 35 | AA10: =40*X10*0.3 -> 36 | AB10: =IFERROR(VLOOKUP(AD15,اسماء,21,0),"") -> 0 | AD10: =IF(AB9=0,"",IF(AB9<AA9*0.4,W9,"")) | AE10: =IF(AB10=0,"",IF(AB10<AA10*0.4,W10,"")) | AF10: =IF(AB8=0,"",IF(AB8<AA8*0.4,W8,"")) | AH10: =ادخال1!$K$9 -> العلوم | AI10: =ادخال1!$K$7 -> 3 | AJ10: =40*AI10*0.3 -> 36 | AK10: =IFERROR(VLOOKUP(AO15,اسماء,10,0),"") | AL10: =40*AI10*0.3 -> 36 | AM10: =IFERROR(VLOOKUP(AO15,اسماء,21,0),"") | AO10: =IF(AM9=0,"",IF(AM9<AL9*0.4,AH9,"")) | AP10: =IF(AM10=0,"",IF(AM10<AL10*0.4,AH10,"")) | AQ10: =IF(AM8=0,"",IF(AM8<AL8*0.4,AH8,""))
A11: المجموع العـام | C11: =SUM(C5:C10) -> 252 | D11: =SUM(D5:D10) -> 224 | E11: =SUM(E5:E10) -> 252 | F11: =SUM(F5:F10) -> 0 | H11: مدير المدرسة/ | I11: =ادخال1!$BJ$5 -> د. عبدالرحمن خليفة العريبي | L11: المجموع العـام | N11: =SUM(N5:N10) -> 252 | O11: =SUM(O5:O10) -> 242 | P11: =SUM(P5:P10) -> 252 | Q11: =SUM(Q5:Q10) -> 0 | S11: مدير المدرسة/ | T11: =ادخال1!$BJ$5 -> د. عبدالرحمن خليفة العريبي | W11: المجموع العـام | Y11: =SUM(Y5:Y10) -> 252 | Z11: =SUM(Z5:Z10) -> 244 | AA11: =SUM(AA5:AA10) -> 252 | AB11: =SUM(AB5:AB10) -> 0 | AD11: مدير المدرسة/ | AE11: =ادخال1!$BJ$5 -> د. عبدالرحمن خليفة العريبي | AH11: المجموع العـام | AJ11: =SUM(AJ5:AJ10) -> 252 | AK11: =SUM(AK5:AK10) -> 0 | AL11: =SUM(AL5:AL10) -> 252 | AM11: =SUM(AM5:AM10) -> 0 | AO11: مدير المدرسة/ | AP11: =ادخال1!$BJ$5 -> د. عبدالرحمن خليفة العريبي
A12: =ادخال1!$M$8 -> التربية الفنية | B12: =ادخال1!$M$7 -> 1 | C12: =IFERROR(VLOOKUP(H15,اسماء,12,0),"") -> جيد جداً | E12: =IFERROR(VLOOKUP(H15,اسماء,23,0),"") -> 0 | H12: التاريخ | I12: =TODAY() -> 46009 | L12: =ادخال1!$M$8 -> التربية الفنية | M12: =ادخال1!$M$7 -> 1 | N12: =IFERROR(VLOOKUP(S15,اسماء,12,0),"") -> جيد جداً | P12: =IFERROR(VLOOKUP(S15,اسماء,23,0),"") -> 0 | S12: التاريخ | T12: =TODAY() -> 46009 | W12: =ادخال1!$M$8 -> التربية الفنية | X12: =ادخال1!$M$7 -> 1 | Y12: =IFERROR(VLOOKUP(AD15,اسماء,12,0),"") -> جيد جداً | AA12: =IFERROR(VLOOKUP(AD15,اسماء,23,0),"") -> 0 | AD12: التاريخ | AE12: =TODAY() -> 46009 | AH12: =ادخال1!$M$8 -> التربية الفنية | AI12: =ادخال1!$M$7 -> 1 | AJ12: =IFERROR(VLOOKUP(AO15,اسماء,12,0),"") | AL12: =IFERROR(VLOOKUP(AO15,اسماء,23,0),"") | AO12: التاريخ | AP12: =TODAY() -> 46009
A13: =ادخال1!$N$8 -> التربية البدنية | B13: =ادخال1!$N$7 -> 2 | C13: =IFERROR(VLOOKUP(H15,اسماء,13,0),"") -> جيد جداً | E13: =IFERROR(VLOOKUP(H15,اسماء,24,0),"") -> 0 | L13: =ادخال1!$N$8 -> التربية البدنية | M13: =ادخال1!$N$7 -> 2 | N13: =IFERROR(VLOOKUP(S15,اسماء,13,0),"") -> جيد جداً | P13: =IFERROR(VLOOKUP(S15,اسماء,24,0),"") -> 0 | W13: =ادخال1!$N$8 -> التربية البدنية | X13: =ادخال1!$N$7 -> 2 | Y13: =IFERROR(VLOOKUP(AD15,اسماء,13,0),"") -> جيد جداً | AA13: =IFERROR(VLOOKUP(AD15,اسماء,24,0),"") -> 0 | AH13: =ادخال1!$N$8 -> التربية البدنية | AI13: =ادخال1!$N$7 -> 2 | AJ13: =IFERROR(VLOOKUP(AO15,اسماء,13,0),"") | AL13: =IFERROR(VLOOKUP(AO15,اسماء,24,0),"")
A14: =ادخال1!$O$8 -> مكتبة | B14: =ادخال1!$O$7 -> 1 | L14: =ادخال1!$O$8 -> مكتبة | M14: =ادخال1!$O$7 -> 1 | W14: =ادخال1!$O$8 -> مكتبة | X14: =ادخال1!$O$7 -> 1 | AH14: =ادخال1!$O$8 -> مكتبة | AI14: =ادخال1!$O$7 -> 1
A15: الرقم الوطني | B15: =IFERROR(VLOOKUP(H15,اسماء,65,0),"") -> 220170664398 | C15: =IFERROR(VLOOKUP(G20,اسماء,8,0),"") | D15: =IFERROR(VLOOKUP(H20,اسماء,8,0),"") | E15: =IFERROR(VLOOKUP(I20,اسماء,8,0),"") | H15: =INDEX(عمود2,MATCH(J1,عمود1)) -> دانية حسن مفتاح المقوب | L15: الرقم الوطني | M15: =IFERROR(VLOOKUP(S15,اسماء,65,0),"") -> 220170951696 | N15: =IFERROR(VLOOKUP(R20,اسماء,8,0),"") | O15: =IFERROR(VLOOKUP(S20,اسماء,8,0),"") | P15: =IFERROR(VLOOKUP(T20,اسماء,8,0),"") | S15: =INDEX(عمود2,MATCH(U1,عمود1)) -> فاطمة سالم سالم الورفلى | W15: الرقم الوطني | X15: =IFERROR(VLOOKUP(AD15,اسماء,65,0),"") -> 220170240914 | Y15: =IFERROR(VLOOKUP(AC20,اسماء,8,0),"") | Z15: =IFERROR(VLOOKUP(AD20,اسماء,8,0),"") | AA15: =IFERROR(VLOOKUP(AE20,اسماء,8,0),"") | AD15: =INDEX(عمود2,MATCH(AF1,عمود1)) -> ايلياء محمد عوض الحداد | AH15: الرقم الوطني | AI15: =IFERROR(VLOOKUP(AO15,اسماء,65,0),"") | AJ15: =IFERROR(VLOOKUP(AN20,اسماء,8,0),"") | AK15: =IFERROR(VLOOKUP(AO20,اسماء,8,0),"") | AL15: =IFERROR(VLOOKUP(AP20,اسماء,8,0),"") | AO15: =INDEX(عمود2,MATCH(AQ1,عمود1)) -> 0
A16: الســــــلوك | C16: =IFERROR(VLOOKUP(H15,اسماء,37,0),"") -> 0 | E16: =IFERROR(VLOOKUP(H15,اسماء,38,0),"") -> 0 | H16: كل كشط أو تغيير في هذه البطاقة يلغيها. | L16: الســــــلوك | N16: =IFERROR(VLOOKUP(S15,اسماء,37,0),"") -> 0 | P16: =IFERROR(VLOOKUP(S15,اسماء,38,0),"") -> 0 | S16: كل كشط أو تغيير في هذه البطاقة يلغيها. | W16: الســــــلوك | Y16: =IFERROR(VLOOKUP(AD15,اسماء,37,0),"") -> 0 | AA16: =IFERROR(VLOOKUP(AD15,اسماء,38,0),"") -> 0 | AD16: كل كشط أو تغيير في هذه البطاقة يلغيها. | AH16: الســــــلوك | AJ16: =IFERROR(VLOOKUP(AO15,اسماء,37,0),"") | AL16: =IFERROR(VLOOKUP(AO15,اسماء,38,0),"") | AO16: كل كشط أو تغيير في هذه البطاقة يلغيها.
A17: غياب مشروع | C17: =IFERROR(VLOOKUP(H15,اسماء,40,0),"") -> 0 | E17: =IFERROR(VLOOKUP(H15,اسماء,42,0),"") -> 0 | L17: غياب مشروع | N17: =IFERROR(VLOOKUP(S15,اسماء,40,0),"") -> 0 | P17: =IFERROR(VLOOKUP(S15,اسماء,42,0),"") -> 0 | W17: غياب مشروع | Y17: =IFERROR(VLOOKUP(AD15,اسماء,40,0),"") -> 0 | AA17: =IFERROR(VLOOKUP(AD15,اسماء,42,0),"") -> 0 | AH17: غياب مشروع | AJ17: =IFERROR(VLOOKUP(AO15,اسماء,40,0),"") | AL17: =IFERROR(VLOOKUP(AO15,اسماء,42,0),"")
A18: غياب غير مشروع | C18: =IFERROR(VLOOKUP(H15,اسماء,41,0),"") -> 0 | E18: =IFERROR(VLOOKUP(H15,اسماء,43,0),"") -> 0 | L18: غياب غير مشروع | N18: =IFERROR(VLOOKUP(S15,اسماء,41,0),"") -> 0 | P18: =IFERROR(VLOOKUP(S15,اسماء,43,0),"") -> 0 | W18: غياب غير مشروع | Y18: =IFERROR(VLOOKUP(AD15,اسماء,41,0),"") -> 0 | AA18: =IFERROR(VLOOKUP(AD15,اسماء,43,0),"") -> 0 | AH18: غياب غير مشروع | AJ18: =IFERROR(VLOOKUP(AO15,اسماء,41,0),"") | AL18: =IFERROR(VLOOKUP(AO15,اسماء,43,0),"")
A20: التوقيعــــات | B20: رائــد الصف | D20: مديـر المدرسة | H20: ولي الامر | L20: التوقيعــــات | M20: رائــد الصف | O20: مديـر المدرسة | S20: ولي الامر | W20: التوقيعــــات | X20: رائــد الصف | Z20: مديـر المدرسة | AD20: ولي الامر | AH20: التوقيعــــات | AI20: رائــد الصف | AK20: مديـر المدرسة | AO20: ولي الامر
A21: الفترة الاولى | L21: الفترة الاولى | W21: الفترة الاولى | AH21: الفترة الاولى
A22: الفترة الثانية | L22: الفترة الثانية | W22: الفترة الثانية | AH22: الفترة الثانية
A24: بطاقة تقدير الدرجات للصــــف | D24: =ادخال1!$L$4 -> الثالث | F24: من التعليم الأساسي | J24: =J1+1 -> 5 | L24: بطاقة تقدير الدرجات للصــــف | O24: =ادخال1!$L$4 -> الثالث | Q24: من التعليم الأساسي | U24: =U1+1 -> 10 | W24: بطاقة تقدير الدرجات للصــــف | Z24: =ادخال1!$L$4 -> الثالث | AB24: من التعليم الأساسي | AF24: =AF1+1 -> 15 | AH24: بطاقة تقدير الدرجات للصــــف | AK24: =ادخال1!$L$4 -> الثالث | AM24: من التعليم الأساسي | AQ24: =AQ1+1 -> 20
A25: المدرسة/ | B25: =ادخال1!$B$5 -> سهول العلم للتعليم الخاص | F25: الاسم | G25: =H36 -> 0 | L25: المدرسة/ | M25: =ادخال1!$B$5 -> سهول العلم للتعليم الخاص | Q25: الاسم | R25: =S36 -> 0 | W25: المدرسة/ | X25: =ادخال1!$B$5 -> سهول العلم للتعليم الخاص | AB25: الاسم | AC25: =AD36 -> 0 | AH25: المدرسة/ | AI25: =ادخال1!$B$5 -> سهول العلم للتعليم الخاص | AM25: الاسم | AN25: =AO36 -> 0
A26: الفترات | B26: عدد الحصص | C26: الفترة الأولي 30 % | E26: الفترة الثانية 30 % | H26: ملاحظــات عن نتيجة التلميذ خلال كل فترة : | L26: الفترات | M26: عدد الحصص | N26: الفترة الأولي 30 % | P26: الفترة الثانية 30 % | S26: ملاحظــات عن نتيجة التلميذ خلال كل فترة : | W26: الفترات | X26: عدد الحصص | Y26: الفترة الأولي 30 % | AA26: الفترة الثانية 30 % | AD26: ملاحظــات عن نتيجة التلميذ خلال كل فترة : | AH26: الفترات | AI26: عدد الحصص | AJ26: الفترة الأولي 30 % | AL26: الفترة الثانية 30 % | AO26: ملاحظــات عن نتيجة التلميذ خلال كل فترة :
A27: المواد الدراسية | C27: الدرجة الكبرى | D27: درجة التلميذ | E27: الدرجة الكبرى | F27: درجة التلميذ | H27: الأولي : | I27: =IF(D33=0,"",IF(AND(D28>=C28*0.4,D29>=C29*0.4,D30>=C30*0.4,D31>=C31*0.4,D32>=C32*0.4),LOOKUP(D33,'النتيجة النهائية'!$AC$6:$AD$10),"ضعيف ويحتاج الى اهتمام في المواد")) -> ضعيف | L27: المواد الدراسية | N27: الدرجة الكبرى | O27: درجة التلميذ | P27: الدرجة الكبرى | Q27: درجة التلميذ | S27: الأولي : | T27: =IF(O33=0,"",IF(AND(O28>=N28*0.4,O29>=N29*0.4,O30>=N30*0.4,O31>=N31*0.4,O32>=N32*0.4),LOOKUP(O33,'النتيجة النهائية'!$AC$6:$AD$10),"ضعيف ويحتاج الى اهتمام في المواد")) -> ضعيف | W27: المواد الدراسية | Y27: الدرجة الكبرى | Z27: درجة التلميذ | AA27: الدرجة الكبرى | AB27: درجة التلميذ | AD27: الأولي : | AE27: =IF(Z33=0,"",IF(AND(Z28>=Y28*0.4,Z29>=Y29*0.4,Z30>=Y30*0.4,Z31>=Y31*0.4,Z32>=Y32*0.4),LOOKUP(Z33,'النتيجة النهائية'!$AC$6:$AD$10),"ضعيف ويحتاج الى اهتمام في المواد")) -> ضعيف | AH27: المواد الدراسية | AJ27: الدرجة الكبرى | AK27: درجة التلميذ | AL27: الدرجة الكبرى | AM27: درجة التلميذ | AO27: الأولي : | AP27: =IF(AK33=0,"",IF(AND(AK28>=AJ28*0.4,AK29>=AJ29*0.4,AK30>=AJ30*0.4,AK31>=AJ31*0.4,AK32>=AJ32*0.4),LOOKUP(AK33,'النتيجة النهائية'!$AC$6:$AD$10),"ضعيف ويحتاج الى اهتمام في المواد")) -> #N/A
A28: =ادخال1!$F$9 -> التربية الإسلامية | B28: =ادخال1!$F$7 -> 3 | C28: =40*B28*0.3 -> 36 | D28: =IFERROR(VLOOKUP(H38,اسماء,5,0),"") -> 35 | E28: =40*B28*0.3 -> 36 | F28: =IFERROR(VLOOKUP(H38,اسماء,16,0),"") -> 0 | H28: =IF(D28=0,"",IF(D28<C28*0.4,A28,"")) | I28: =IF(D29=0,"",IF(D29<C29*0.4,A29,"")) | J28: =IF(D30=0,"",IF(D30<C30*0.4,A30,"")) | L28: =ادخال1!$F$9 -> التربية الإسلامية | M28: =ادخال1!$F$7 -> 3 | N28: =40*M28*0.3 -> 36 | O28: =IFERROR(VLOOKUP(S38,اسماء,5,0),"") -> 36 | P28: =40*M28*0.3 -> 36 | Q28: =IFERROR(VLOOKUP(S38,اسماء,16,0),"") -> 0 | S28: =IF(O28=0,"",IF(O28<N28*0.4,L28,"")) | T28: =IF(O29=0,"",IF(O29<N29*0.4,L29,"")) | U28: =IF(O30=0,"",IF(O30<N30*0.4,L30,"")) | W28: =ادخال1!$F$9 -> التربية الإسلامية | X28: =ادخال1!$F$7 -> 3 | Y28: =40*X28*0.3 -> 36 | Z28: =IFERROR(VLOOKUP(AD38,اسماء,5,0),"") -> 36 | AA28: =40*X28*0.3 -> 36 | AB28: =IFERROR(VLOOKUP(AD38,اسماء,16,0),"") -> 0 | AD28: =IF(Z28=0,"",IF(Z28<Y28*0.4,W28,"")) | AE28: =IF(Z29=0,"",IF(Z29<Y29*0.4,W29,"")) | AF28: =IF(Z30=0,"",IF(Z30<Y30*0.4,W30,"")) | AH28: =ادخال1!$F$9 -> التربية الإسلامية | AI28: =ادخال1!$F$7 -> 3 | AJ28: =40*AI28*0.3 -> 36 | AK28: =IFERROR(VLOOKUP(AO38,اسماء,5,0),"") | AL28: =40*AI28*0.3 -> 36 | AM28: =IFERROR(VLOOKUP(AO38,اسماء,16,0),"") | AO28: =IF(AK28=0,"",IF(AK28<AJ28*0.4,AH28,"")) | AP28: =IF(AK29=0,"",IF(AK29<AJ29*0.4,AH29,"")) | AQ28: =IF(AK30=0,"",IF(AK30<AJ30*0.4,AH30,""))
A29: =ادخال1!$G$9 -> اللغة العربية | B29: =ادخال1!$G$7 -> 6 | C29: =40*B29*0.3 -> 72 | D29: =IFERROR(VLOOKUP(H38,اسماء,6,0),"") -> 64 | E29: =40*B29*0.3 -> 72 | F29: =IFERROR(VLOOKUP(H38,اسماء,17,0),"") -> 0 | H29: =IF(D32=0,"",IF(D32<C32*0.4,A32,"")) | I29: =IF(D33=0,"",IF(D33<C33*0.4,A33,"")) | J29: =IF(D31=0,"",IF(D31<C31*0.4,A31,"")) | L29: =ادخال1!$G$9 -> اللغة العربية | M29: =ادخال1!$G$7 -> 6 | N29: =40*M29*0.3 -> 72 | O29: =IFERROR(VLOOKUP(S38,اسماء,6,0),"") -> 71 | P29: =40*M29*0.3 -> 72 | Q29: =IFERROR(VLOOKUP(S38,اسماء,17,0),"") -> 0 | S29: =IF(O32=0,"",IF(O32<N32*0.4,L32,"")) | T29: =IF(O33=0,"",IF(O33<N33*0.4,L33,"")) | U29: =IF(O31=0,"",IF(O31<N31*0.4,L31,"")) | W29: =ادخال1!$G$9 -> اللغة العربية | X29: =ادخال1!$G$7 -> 6 | Y29: =40*X29*0.3 -> 72 | Z29: =IFERROR(VLOOKUP(AD38,اسماء,6,0),"") -> 68 | AA29: =40*X29*0.3 -> 72 | AB29: =IFERROR(VLOOKUP(AD38,اسماء,17,0),"") -> 0 | AD29: =IF(Z32=0,"",IF(Z32<Y32*0.4,W32,"")) | AE29: =IF(Z33=0,"",IF(Z33<Y33*0.4,W33,"")) | AF29: =IF(Z31=0,"",IF(Z31<Y31*0.4,W31,"")) | AH29: =ادخال1!$G$9 -> اللغة العربية | AI29: =ادخال1!$G$7 -> 6 | AJ29: =40*AI29*0.3 -> 72 | AK29: =IFERROR(VLOOKUP(AO38,اسماء,6,0),"") | AL29: =40*AI29*0.3 -> 72 | AM29: =IFERROR(VLOOKUP(AO38,اسماء,17,0),"") | AO29: =IF(AK32=0,"",IF(AK32<AJ32*0.4,AH32,"")) | AP29: =IF(AK33=0,"",IF(AK33<AJ33*0.4,AH33,"")) | AQ29: =IF(AK31=0,"",IF(AK31<AJ31*0.4,AH31,""))
A30: =ادخال1!$H$9 -> اللغة الإنجليزية | B30: =ادخال1!$H$7 -> 3 | C30: =40*B30*0.3 -> 36 | D30: =IFERROR(VLOOKUP(H38,اسماء,7,0),"") -> 31 | E30: =40*B30*0.3 -> 36 | F30: =IFERROR(VLOOKUP(H38,اسماء,18,0),"") -> 0 | H30: الثانية :- | I30: =IF(F34=0,"",IF(AND(F28>=E28*0.4,F29>=E29*0.4,F30>=E30*0.4,F32>=E32*0.4,F33>=E33*0.4),LOOKUP(F34,'النتيجة النهائية'!$AC$6:$AD$10),"ضعيف ويحتاج الى اهتمام في المواد")) | L30: =ادخال1!$H$9 -> اللغة الإنجليزية | M30: =ادخال1!$H$7 -> 3 | N30: =40*M30*0.3 -> 36 | O30: =IFERROR(VLOOKUP(S38,اسماء,7,0),"") -> 36 | P30: =40*M30*0.3 -> 36 | Q30: =IFERROR(VLOOKUP(S38,اسماء,18,0),"") -> 0 | S30: الثانية :- | T30: =IF(Q34=0,"",IF(AND(Q28>=P28*0.4,Q29>=P29*0.4,Q30>=P30*0.4,Q32>=P32*0.4,Q33>=P33*0.4),LOOKUP(Q34,'النتيجة النهائية'!$AC$6:$AD$10),"ضعيف ويحتاج الى اهتمام في المواد")) | W30: =ادخال1!$H$9 -> اللغة الإنجليزية | X30: =ادخال1!$H$7 -> 3 | Y30: =40*X30*0.3 -> 36 | Z30: =IFERROR(VLOOKUP(AD38,اسماء,7,0),"") -> 31 | AA30: =40*X30*0.3 -> 36 | AB30: =IFERROR(VLOOKUP(AD38,اسماء,18,0),"") -> 0 | AD30: الثانية :- | AE30: =IF(AB34=0,"",IF(AND(AB28>=AA28*0.4,AB29>=AA29*0.4,AB30>=AA30*0.4,AB32>=AA32*0.4,AB33>=AA33*0.4),LOOKUP(AB34,'النتيجة النهائية'!$AC$6:$AD$10),"ضعيف ويحتاج الى اهتمام في المواد")) | AH30: =ادخال1!$H$9 -> اللغة الإنجليزية | AI30: =ادخال1!$H$7 -> 3 | AJ30: =40*AI30*0.3 -> 36 | AK30: =IFERROR(VLOOKUP(AO38,اسماء,7,0),"") | AL30: =40*AI30*0.3 -> 36 | AM30: =IFERROR(VLOOKUP(AO38,اسماء,18,0),"") | AO30: الثانية :- | AP30: =IF(AM34=0,"",IF(AND(AM28>=AL28*0.4,AM29>=AL29*0.4,AM30>=AL30*0.4,AM32>=AL32*0.4,AM33>=AL33*0.4),LOOKUP(AM34,'النتيجة النهائية'!$AC$6:$AD$10),"ضعيف ويحتاج الى اهتمام في المواد"))
A31: =ادخال1!$I$9 -> الحاسوب | B31: =ادخال1!$I$7 -> 1 | C31: =40*B31*0.3 -> 12 | D31: =IFERROR(VLOOKUP(H38,اسماء,8,0),"") -> 10 | E31: =40*B31*0.3 -> 12 | F31: =IFERROR(VLOOKUP(H38,اسماء,19,0),"") -> 0 | L31: =ادخال1!$I$9 -> الحاسوب | M31: =ادخال1!$I$7 -> 1 | N31: =40*M31*0.3 -> 12 | O31: =IFERROR(VLOOKUP(S38,اسماء,8,0),"") -> 12 | P31: =40*M31*0.3 -> 12 | Q31: =IFERROR(VLOOKUP(S38,اسماء,19,0),"") -> 0 | W31: =ادخال1!$I$9 -> الحاسوب | X31: =ادخال1!$I$7 -> 1 | Y31: =40*X31*0.3 -> 12 | Z31: =IFERROR(VLOOKUP(AD38,اسماء,8,0),"") -> 12 | AA31: =40*X31*0.3 -> 12 | AB31: =IFERROR(VLOOKUP(AD38,اسماء,19,0),"") -> 0 | AH31: =ادخال1!$I$9 -> الحاسوب | AI31: =ادخال1!$I$7 -> 1 | AJ31: =40*AI31*0.3 -> 12 | AK31: =IFERROR(VLOOKUP(AO38,اسماء,8,0),"") | AL31: =40*AI31*0.3 -> 12 | AM31: =IFERROR(VLOOKUP(AO38,اسماء,19,0),"")
A32: =ادخال1!$J$9 -> الرياضيات | B32: =ادخال1!$J$7 -> 5 | C32: =40*B32*0.3 -> 60 | D32: =IFERROR(VLOOKUP(H38,اسماء,9,0),"") -> 41 | E32: =40*B32*0.3 -> 60 | F32: =IFERROR(VLOOKUP(H38,اسماء,20,0),"") -> 0 | H32: =IF(F28=0,"",IF(F28<E28*0.4,A28,"")) | I32: =IF(F29=0,"",IF(F29<E29*0.4,A29,"")) | J32: =IF(F30=0,"",IF(F30<E30*0.4,A30,"")) | L32: =ادخال1!$J$9 -> الرياضيات | M32: =ادخال1!$J$7 -> 5 | N32: =40*M32*0.3 -> 60 | O32: =IFERROR(VLOOKUP(S38,اسماء,9,0),"") -> 60 | P32: =40*M32*0.3 -> 60 | Q32: =IFERROR(VLOOKUP(S38,اسماء,20,0),"") -> 0 | S32: =IF(Q28=0,"",IF(Q28<P28*0.4,L28,"")) | T32: =IF(Q29=0,"",IF(Q29<P29*0.4,L29,"")) | U32: =IF(Q30=0,"",IF(Q30<P30*0.4,L30,"")) | W32: =ادخال1!$J$9 -> الرياضيات | X32: =ادخال1!$J$7 -> 5 | Y32: =40*X32*0.3 -> 60 | Z32: =IFERROR(VLOOKUP(AD38,اسماء,9,0),"") -> 56 | AA32: =40*X32*0.3 -> 60 | AB32: =IFERROR(VLOOKUP(AD38,اسماء,20,0),"") -> 0 | AD32: =IF(AB28=0,"",IF(AB28<AA28*0.4,W28,"")) | AE32: =IF(AB29=0,"",IF(AB29<AA29*0.4,W29,"")) | AF32: =IF(AB30=0,"",IF(AB30<AA30*0.4,W30,"")) | AH32: =ادخال1!$J$9 -> الرياضيات | AI32: =ادخال1!$J$7 -> 5 | AJ32: =40*AI32*0.3 -> 60 | AK32: =IFERROR(VLOOKUP(AO38,اسماء,9,0),"") | AL32: =40*AI32*0.3 -> 60 | AM32: =IFERROR(VLOOKUP(AO38,اسماء,20,0),"") | AO32: =IF(AM28=0,"",IF(AM28<AL28*0.4,AH28,"")) | AP32: =IF(AM29=0,"",IF(AM29<AL29*0.4,AH29,"")) | AQ32: =IF(AM30=0,"",IF(AM30<AL30*0.4,AH30,""))
A33: =ادخال1!$K$9 -> العلوم | B33: =ادخال1!$K$7 -> 3 | C33: =40*B33*0.3 -> 36 | D33: =IFERROR(VLOOKUP(H38,اسماء,10,0),"") -> 30 | E33: =40*B33*0.3 -> 36 | F33: =IFERROR(VLOOKUP(H38,اسماء,21,0),"") -> 0 | H33: =IF(F32=0,"",IF(F32<E32*0.4,A32,"")) | I33: =IF(F33=0,"",IF(F33<E33*0.4,A33,"")) | J33: =IF(F31=0,"",IF(F31<E31*0.4,A31,"")) | L33: =ادخال1!$K$9 -> العلوم | M33: =ادخال1!$K$7 -> 3 | N33: =40*M33*0.3 -> 36 | O33: =IFERROR(VLOOKUP(S38,اسماء,10,0),"") -> 36 | P33: =40*M33*0.3 -> 36 | Q33: =IFERROR(VLOOKUP(S38,اسماء,21,0),"") -> 0 | S33: =IF(Q32=0,"",IF(Q32<P32*0.4,L32,"")) | T33: =IF(Q33=0,"",IF(Q33<P33*0.4,L33,"")) | U33: =IF(Q31=0,"",IF(Q31<P31*0.4,L31,"")) | W33: =ادخال1!$K$9 -> العلوم | X33: =ادخال1!$K$7 -> 3 | Y33: =40*X33*0.3 -> 36 | Z33: =IFERROR(VLOOKUP(AD38,اسماء,10,0),"") -> 36 | AA33: =40*X33*0.3 -> 36 | AB33: =IFERROR(VLOOKUP(AD38,اسماء,21,0),"") -> 0 | AD33: =IF(AB32=0,"",IF(AB32<AA32*0.4,W32,"")) | AE33: =IF(AB33=0,"",IF(AB33<AA33*0.4,W33,"")) | AF33: =IF(AB31=0,"",IF(AB31<AA31*0.4,W31,"")) | AH33: =ادخال1!$K$9 -> العلوم | AI33: =ادخال1!$K$7 -> 3 | AJ33: =40*AI33*0.3 -> 36 | AK33: =IFERROR(VLOOKUP(AO38,اسماء,10,0),"") | AL33: =40*AI33*0.3 -> 36 | AM33: =IFERROR(VLOOKUP(AO38,اسماء,21,0),"") | AO33: =IF(AM32=0,"",IF(AM32<AL32*0.4,AH32,"")) | AP33: =IF(AM33=0,"",IF(AM33<AL33*0.4,AH33,"")) | AQ33: =IF(AM31=0,"",IF(AM31<AL31*0.4,AH31,""))
A34: المجموع العـام | C34: =SUM(C28:C33) -> 252 | D34: =SUM(D28:D33) -> 211 | E34: =SUM(E28:E33) -> 252 | F34: =SUM(F28:F33) -> 0 | H34: مدير المدرسة/ | I34: =ادخال1!$BJ$5 -> د. عبدالرحمن خليفة العريبي | L34: المجموع العـام | N34: =SUM(N28:N33) -> 252 | O34: =SUM(O28:O33) -> 251 | P34: =SUM(P28:P33) -> 252 | Q34: =SUM(Q28:Q33) -> 0 | S34: مدير المدرسة/ | T34: =ادخال1!$BJ$5 -> د. عبدالرحمن خليفة العريبي | W34: المجموع العـام | Y34: =SUM(Y28:Y33) -> 252 | Z34: =SUM(Z28:Z33) -> 239 | AA34: =SUM(AA28:AA33) -> 252 | AB34: =SUM(AB28:AB33) -> 0 | AD34: مدير المدرسة/ | AE34: =ادخال1!$BJ$5 -> د. عبدالرحمن خليفة العريبي | AH34: المجموع العـام | AJ34: =SUM(AJ28:AJ33) -> 252 | AK34: =SUM(AK28:AK33) -> 0 | AL34: =SUM(AL28:AL33) -> 252 | AM34: =SUM(AM28:AM33) -> 0 | AO34: مدير المدرسة/ | AP34: =ادخال1!$BJ$5 -> د. عبدالرحمن خليفة العريبي
A35: =ادخال1!$M$8 -> التربية الفنية | B35: =ادخال1!$M$7 -> 1 | C35: =IFERROR(VLOOKUP(H38,اسماء,12,0),"") -> جيد جداً | E35: =IFERROR(VLOOKUP(H38,اسماء,23,0),"") -> 0 | H35: التاريخ | I35: =TODAY() -> 46009 | L35: =ادخال1!$M$8 -> التربية الفنية | M35: =ادخال1!$M$7 -> 1 | N35: =IFERROR(VLOOKUP(S38,اسماء,12,0),"") -> جيد جداً | P35: =IFERROR(VLOOKUP(S38,اسماء,23,0),"") -> 0 | S35: التاريخ | T35: =TODAY() -> 46009 | W35: =ادخال1!$M$8 -> التربية الفنية | X35: =ادخال1!$M$7 -> 1 | Y35: =IFERROR(VLOOKUP(AD38,اسماء,12,0),"") -> جيد جداً | AA35: =IFERROR(VLOOKUP(AD38,اسماء,23,0),"") -> 0 | AD35: التاريخ | AE35: =TODAY() -> 46009 | AH35: =ادخال1!$M$8 -> التربية الفنية | AI35: =ادخال1!$M$7 -> 1 | AJ35: =IFERROR(VLOOKUP(AO38,اسماء,12,0),"") | AL35: =IFERROR(VLOOKUP(AO38,اسماء,23,0),"") | AO35: التاريخ | AP35: =TODAY() -> 46009
A36: =ادخال1!$N$8 -> التربية البدنية | B36: =ادخال1!$N$7 -> 2 | C36: =IFERROR(VLOOKUP(H38,اسماء,13,0),"") -> جيد جداً | E36: =IFERROR(VLOOKUP(H38,اسماء,24,0),"") -> 0 | L36: =ادخال1!$N$8 -> التربية البدنية | M36: =ادخال1!$N$7 -> 2 | N36: =IFERROR(VLOOKUP(S38,اسماء,13,0),"") -> جيد جداً | P36: =IFERROR(VLOOKUP(S38,اسماء,24,0),"") -> 0 | W36: =ادخال1!$N$8 -> التربية البدنية | X36: =ادخال1!$N$7 -> 2 | Y36: =IFERROR(VLOOKUP(AD38,اسماء,13,0),"") -> جيد جداً | AA36: =IFERROR(VLOOKUP(AD38,اسماء,24,0),"") -> 0 | AH36: =ادخال1!$N$8 -> التربية البدنية | AI36: =ادخال1!$N$7 -> 2 | AJ36: =IFERROR(VLOOKUP(AO38,اسماء,13,0),"") | AL36: =IFERROR(VLOOKUP(AO38,اسماء,24,0),"")
A37: =ادخال1!$O$8 -> مكتبة | B37: =ادخال1!$O$7 -> 1 | L37: =ادخال1!$O$8 -> مكتبة | M37: =ادخال1!$O$7 -> 1 | W37: =ادخال1!$O$8 -> مكتبة | X37: =ادخال1!$O$7 -> 1 | AH37: =ادخال1!$O$8 -> مكتبة | AI37: =ادخال1!$O$7 -> 1
A38: الرقم الوطني | B38: =IFERROR(VLOOKUP(H38,اسماء,65,0),"") -> 220170079396 | C38: =IFERROR(VLOOKUP(G43,اسماء,8,0),"") | D38: =IFERROR(VLOOKUP(H43,اسماء,8,0),"") | E38: =IFERROR(VLOOKUP(I43,اسماء,8,0),"") | H38: =INDEX(عمود2,MATCH(J24,عمود1)) -> ساجدة عبد السلام شعبان بى | L38: الرقم الوطني | M38: =IFERROR(VLOOKUP(S38,اسماء,65,0),"") -> 120171103057 | N38: =IFERROR(VLOOKUP(R43,اسماء,8,0),"") | O38: =IFERROR(VLOOKUP(S43,اسماء,8,0),"") | P38: =IFERROR(VLOOKUP(T43,اسماء,8,0),"") | S38: =INDEX(عمود2,MATCH(U24,عمود1)) -> كنان سالم عبد الكريم النفاتى | W38: الرقم الوطني | X38: =IFERROR(VLOOKUP(AD38,اسماء,65,0),"") -> 120170096866 | Y38: =IFERROR(VLOOKUP(AC43,اسماء,8,0),"") | Z38: =IFERROR(VLOOKUP(AD43,اسماء,8,0),"") | AA38: =IFERROR(VLOOKUP(AE43,اسماء,8,0),"") | AD38: =INDEX(عمود2,MATCH(AF24,عمود1)) -> يوسف انويجى عثمان ابوزويدة | AH38: الرقم الوطني | AI38: =IFERROR(VLOOKUP(AO38,اسماء,65,0),"") | AJ38: =IFERROR(VLOOKUP(AN43,اسماء,8,0),"") | AK38: =IFERROR(VLOOKUP(AO43,اسماء,8,0),"") | AL38: =IFERROR(VLOOKUP(AP43,اسماء,8,0),"") | AO38: =INDEX(عمود2,MATCH(AQ24,عمود1)) -> 0
A39: الســــــلوك | C39: =IFERROR(VLOOKUP(H38,اسماء,37,0),"") -> 0 | E39: =IFERROR(VLOOKUP(H38,اسماء,38,0),"") -> 0 | H39: كل كشط أو تغيير في هذه البطاقة يلغيها. | L39: الســــــلوك | N39: =IFERROR(VLOOKUP(S38,اسماء,37,0),"") -> 0 | P39: =IFERROR(VLOOKUP(S38,اسماء,38,0),"") -> 0 | S39: كل كشط أو تغيير في هذه البطاقة يلغيها. | W39: الســــــلوك | Y39: =IFERROR(VLOOKUP(AD38,اسماء,37,0),"") -> 0 | AA39: =IFERROR(VLOOKUP(AD38,اسماء,38,0),"") -> 0 | AD39: كل كشط أو تغيير في هذه البطاقة يلغيها. | AH39: الســــــلوك | AJ39: =IFERROR(VLOOKUP(AO38,اسماء,37,0),"") | AL39: =IFERROR(VLOOKUP(AO38,اسماء,38,0),"") | AO39: كل كشط أو تغيير في هذه البطاقة يلغيها.
A40: غياب مشروع | C40: =IFERROR(VLOOKUP(H38,اسماء,40,0),"") -> 0 | E40: =IFERROR(VLOOKUP(H38,اسماء,42,0),"") -> 0 | L40: غياب مشروع | N40: =IFERROR(VLOOKUP(S38,اسماء,40,0),"") -> 0 | P40: =IFERROR(VLOOKUP(S38,اسماء,42,0),"") -> 0 | W40: غياب مشروع | Y40: =IFERROR(VLOOKUP(AD38,اسماء,40,0),"") -> 0 | AA40: =IFERROR(VLOOKUP(AD38,اسماء,42,0),"") -> 0 | AH40: غياب مشروع | AJ40: =IFERROR(VLOOKUP(AO38,اسماء,40,0),"") | AL40: =IFERROR(VLOOKUP(AO38,اسماء,42,0),"")
A41: غياب غير مشروع | C41: =IFERROR(VLOOKUP(H38,اسماء,41,0),"") -> 0 | E41: =IFERROR(VLOOKUP(H38,اسماء,43,0),"") -> 0 | L41: غياب غير مشروع | N41: =IFERROR(VLOOKUP(S38,اسماء,41,0),"") -> 0 | P41: =IFERROR(VLOOKUP(S38,اسماء,43,0),"") -> 0 | W41: غياب غير مشروع | Y41: =IFERROR(VLOOKUP(AD38,اسماء,41,0),"") -> 0 | AA41: =IFERROR(VLOOKUP(AD38,اسماء,43,0),"") -> 0 | AH41: غياب غير مشروع | AJ41: =IFERROR(VLOOKUP(AO38,اسماء,41,0),"") | AL41: =IFERROR(VLOOKUP(AO38,اسماء,43,0),"")
A42: الفترة الاولى | L42: الفترة الاولى | W42: الفترة الاولى | AH42: الفترة الاولى
...

Sheet الصحيفة النهائية
A1: بطاقة تقدير الدرجات للصــــف | D1: =ادخال1!$L$4 -> الثالث | F1: من التعليم الأساسي | O1: 1 | Q1: بطاقة تقدير الدرجات للصــــف | T1: =ادخال1!$L$4 -> الثالث | V1: من التعليم الأساسي | AE1: =O1+5 -> 6 | AG1: بطاقة تقدير الدرجات للصــــف | AJ1: =ادخال1!$L$4 -> الثالث | AL1: من التعليم الأساسي | AU1: =AE1+5 -> 11 | AW1: بطاقة تقدير الدرجات للصــــف | AZ1: =ادخال1!$L$4 -> الثالث | BB1: من التعليم الأساسي | BK1: =AU1+5 -> 16 | BN1: =SUM(I5:I10) -> 840
A2: المدرسة/ | B2: =ادخال1!$B$5 -> سهول العلم للتعليم الخاص | H2: الاسم | J2: =M16 -> امجد عمر عبداللطيف سلطان | Q2: المدرسة/ | R2: =ادخال1!$B$5 -> سهول العلم للتعليم الخاص | X2: الاسم | Z2: =AC16 -> عبد العاطى احمد محمود محمد | AG2: المدرسة/ | AH2: =ادخال1!$B$5 -> سهول العلم للتعليم الخاص | AN2: الاسم | AP2: =AS16 -> مريم سامى محمد النفاتى | AW2: المدرسة/ | AX2: =ادخال1!$B$5 -> سهول العلم للتعليم الخاص | BD2: الاسم | BF2: =BI16 -> ريم احمد ابوبكر النفاتى | BN2: =BN1*0.3 -> 252 | BO2: 0 | BP2: ضعيف
A3: الفترات | B3: عدد الحصص | C3: الفترة الأولي 30 % | E3: الفترة الثانية 30 % | G3: الفترة الثالثة 40% | I3: النتيجة النهائيــة 100% | M3: ملاحظــات عن نتيجة التلميذ خلال كل فترة : | Q3: الفترات | R3: عدد الحصص | S3: الفترة الأولي 30 % | U3: الفترة الثانية 30 % | W3: الفترة الثالثة 40% | Y3: النتيجة النهائيــة 100% | AC3: ملاحظــات عن نتيجة التلميذ خلال كل فترة : | AG3: الفترات | AH3: عدد الحصص | AI3: الفترة الأولي 30 % | AK3: الفترة الثانية 30 % | AM3: الفترة الثالثة 40% | AO3: النتيجة النهائيــة 100% | AS3: ملاحظــات عن نتيجة التلميذ خلال كل فترة : | AW3: الفترات | AX3: عدد الحصص | AY3: الفترة الأولي 30 % | BA3: الفترة الثانية 30 % | BC3: الفترة الثالثة 40% | BE3: النتيجة النهائيــة 100% | BI3: ملاحظــات عن نتيجة التلميذ خلال كل فترة : | BN3: =BN1*0.4 -> 336 | BO3: =BN3*0.5 -> 168 | BP3: مقبول
A4: المواد الدراسية | C4: الدرجة الكبرى | D4: درجة التلميذ | E4: الدرجة الكبرى | F4: درجة التلميذ | G4: الدرجة الكبرى | H4: درجة التلميذ | I4: النهاية الكبرى | J4: النهاية الصغري | K4: درجة التلميذ | M4: الأولي : | N4: =IF(D11=0,"",IF(AND(D5>=C5*0.4,D6>=C6*0.4,D7>=C7*0.4,D8>=C8*0.4,D9>=C9*0.4),LOOKUP(D11,$BO$15:$BP$19),"ضعيف ويحتاج الى اهتمام في المواد")) -> ممتاز | Q4: المواد الدراسية | S4: الدرجة الكبرى | T4: درجة التلميذ | U4: الدرجة الكبرى | V4: درجة التلميذ | W4: الدرجة الكبرى | X4: درجة التلميذ | Y4: النهاية الكبرى | Z4: النهاية الصغري | AA4: درجة التلميذ | AC4: الأولي : | AD4: =IF(T11=0,"",IF(AND(T5>=S5*0.4,T6>=S6*0.4,T7>=S7*0.4,T8>=S8*0.4,T9>=S9*0.4),LOOKUP(T11,$BO$15:$BP$19),"ضعيف ويحتاج الى اهتمام في المواد")) -> ممتاز | AG4: المواد الدراسية | AI4: الدرجة الكبرى | AJ4: درجة التلميذ | AK4: الدرجة الكبرى | AL4: درجة التلميذ | AM4: الدرجة الكبرى | AN4: درجة التلميذ | AO4: النهاية الكبرى | AP4: النهاية الصغري | AQ4: درجة التلميذ | AS4: الأولي : | AT4: =IF(AJ11=0,"",IF(AND(AJ5>=AI5*0.4,AJ6>=AI6*0.4,AJ7>=AI7*0.4,AJ8>=AI8*0.4,AJ9>=AI9*0.4),LOOKUP(AJ11,$BO$15:$BP$19),"ضعيف ويحتاج الى اهتمام في المواد")) -> ممتاز | AW4: المواد الدراسية | AY4: الدرجة الكبرى | AZ4: درجة التلميذ | BA4: الدرجة الكبرى | BB4: درجة التلميذ | BC4: الدرجة الكبرى | BD4: درجة التلميذ | BE4: النهاية الكبرى | BF4: النهاية الصغري | BG4: درجة التلميذ | BI4: الأولي : | BJ4: =IF(AZ11=0,"",IF(AND(AZ5>=AY5*0.4,AZ6>=AY6*0.4,AZ7>=AY7*0.4,AZ8>=AY8*0.4,AZ9>=AY9*0.4),LOOKUP(AZ11,$BO$15:$BP$19),"ضعيف ويحتاج الى اهتمام في المواد")) -> ممتاز | BO4: =$BN$1*0.65 -> 546 | BP4: جيد
A5: =ادخال1!$F$9 -> التربية الإسلامية | B5: =ادخال1!$F$7 -> 3 | C5: =40*B5*0.3 -> 36 | D5: =IFERROR(VLOOKUP(M16,اسماء,5,0),"") -> 36 | E5: =40*B5*0.3 -> 36 | F5: =IFERROR(VLOOKUP(M16,اسماء,16,0),"") -> 0 | G5: =40*B5*0.4 -> 48 | H5: =IFERROR(VLOOKUP(M16,اسماء,27,0),"") -> 0 | I5: =SUM(C5,E5,G5) -> 120 | J5: =0.4*I5 -> 48 | K5: =SUM(D5,F5,H5) -> 36 | M5: =IF(D5=0,"",IF(D5<C5*0.4,A5,"")) | N5: =IF(D6=0,"",IF(D6<C6*0.4,A6,"")) | O5: =IF(D7=0,"",IF(D7<C7*0.4,A7,"")) | Q5: =ادخال1!$F$9 -> التربية الإسلامية | R5: =ادخال1!$F$7 -> 3 | S5: =40*R5*0.3 -> 36 | T5: =IFERROR(VLOOKUP(AC16,اسماء,5,0),"") -> 36 | U5: =40*R5*0.3 -> 36 | V5: =IFERROR(VLOOKUP(AC16,اسماء,16,0),"") -> 0 | W5: =40*R5*0.4 -> 48 | X5: =IFERROR(VLOOKUP(AC16,اسماء,27,0),"") -> 0 | Y5: =SUM(S5,U5,W5) -> 120 | Z5: =0.4*Y5 -> 48 | AA5: =SUM(T5,V5,X5) -> 36 | AC5: =IF(T5=0,"",IF(T5<S5*0.4,Q5,"")) | AD5: =IF(T6=0,"",IF(T6<S6*0.4,Q6,"")) | AE5: =IF(T7=0,"",IF(T7<S7*0.4,Q7,"")) | AG5: =ادخال1!$F$9 -> التربية الإسلامية | AH5: =ادخال1!$F$7 -> 3 | AI5: =40*AH5*0.3 -> 36 | AJ5: =IFERROR(VLOOKUP(AS16,اسماء,5,0),"") -> 36 | AK5: =40*AH5*0.3 -> 36 | AL5: =IFERROR(VLOOKUP(AS16,اسماء,16,0),"") -> 0 | AM5: =40*AH5*0.4 -> 48 | AN5: =IFERROR(VLOOKUP(AS16,اسماء,27,0),"") -> 0 | AO5: =SUM(AI5,AK5,AM5) -> 120 | AP5: =0.4*AO5 -> 48 | AQ5: =SUM(AJ5,AL5,AN5) -> 36 | AS5: =IF(AJ5=0,"",IF(AJ5<AI5*0.4,AG5,"")) | AT5: =IF(AJ6=0,"",IF(AJ6<AI6*0.4,AG6,"")) | AU5: =IF(AJ7=0,"",IF(AJ7<AI7*0.4,AG7,"")) | AW5: =ادخال1!$F$9 -> التربية الإسلامية | AX5: =ادخال1!$F$7 -> 3 | AY5: =40*AX5*0.3 -> 36 | AZ5: =IFERROR(VLOOKUP(BI16,اسماء,5,0),"") -> 36 | BA5: =40*AX5*0.3 -> 36 | BB5: =IFERROR(VLOOKUP(BI16,اسماء,16,0),"") -> 0 | BC5: =40*AX5*0.4 -> 48 | BD5: =IFERROR(VLOOKUP(BI16,اسماء,27,0),"") -> 0 | BE5: =SUM(AY5,BA5,BC5) -> 120 | BF5: =0.4*BE5 -> 48 | BG5: =SUM(AZ5,BB5,BD5) -> 36 | BI5: =IF(AZ5=0,"",IF(AZ5<AY5*0.4,AW5,"")) | BJ5: =IF(AZ6=0,"",IF(AZ6<AY6*0.4,AW6,"")) | BK5: =IF(AZ7=0,"",IF(AZ7<AY7*0.4,AW7,"")) | BO5: =$BN$1*0.75 -> 630 | BP5: جيدجداً
A6: =ادخال1!$G$9 -> اللغة العربية | B6: =ادخال1!$G$7 -> 6 | C6: =40*B6*0.3 -> 72 | D6: =IFERROR(VLOOKUP(M16,اسماء,6,0),"") -> 70 | E6: =40*B6*0.3 -> 72 | F6: =IFERROR(VLOOKUP(M16,اسماء,17,0),"") -> 0 | G6: =40*B6*0.4 -> 96 | H6: =IFERROR(VLOOKUP(M16,اسماء,28,0),"") -> 0 | I6: =SUM(C6,E6,G6) -> 240 | J6: =0.4*I6 -> 96 | K6: =SUM(D6,F6,H6) -> 70 | M6: =IF(D8=0,"",IF(D8<C8*0.4,A8,"")) | N6: =IF(D9=0,"",IF(D9<C9*0.4,A9,"")) | O6: =IF(D10=0,"",IF(D10<C10*0.4,A10,"")) | Q6: =ادخال1!$G$9 -> اللغة العربية | R6: =ادخال1!$G$7 -> 6 | S6: =40*R6*0.3 -> 72 | T6: =IFERROR(VLOOKUP(AC16,اسماء,6,0),"") -> 68 | U6: =40*R6*0.3 -> 72 | V6: =IFERROR(VLOOKUP(AC16,اسماء,17,0),"") -> 0 | W6: =40*R6*0.4 -> 96 | X6: =IFERROR(VLOOKUP(AC16,اسماء,28,0),"") -> 0 | Y6: =SUM(S6,U6,W6) -> 240 | Z6: =0.4*Y6 -> 96 | AA6: =SUM(T6,V6,X6) -> 68 | AC6: =IF(T8=0,"",IF(T8<S8*0.4,Q8,"")) | AD6: =IF(T9=0,"",IF(T9<S9*0.4,Q9,"")) | AE6: =IF(T10=0,"",IF(T10<S10*0.4,Q10,"")) | AG6: =ادخال1!$G$9 -> اللغة العربية | AH6: =ادخال1!$G$7 -> 6 | AI6: =40*AH6*0.3 -> 72 | AJ6: =IFERROR(VLOOKUP(AS16,اسماء,6,0),"") -> 71 | AK6: =40*AH6*0.3 -> 72 | AL6: =IFERROR(VLOOKUP(AS16,اسماء,17,0),"") -> 0 | AM6: =40*AH6*0.4 -> 96 | AN6: =IFERROR(VLOOKUP(AS16,اسماء,28,0),"") -> 0 | AO6: =SUM(AI6,AK6,AM6) -> 240 | AP6: =0.4*AO6 -> 96 | AQ6: =SUM(AJ6,AL6,AN6) -> 71 | AS6: =IF(AJ8=0,"",IF(AJ8<AI8*0.4,AG8,"")) | AT6: =IF(AJ9=0,"",IF(AJ9<AI9*0.4,AG9,"")) | AU6: =IF(AJ10=0,"",IF(AJ10<AI10*0.4,AG10,"")) | AW6: =ادخال1!$G$9 -> اللغة العربية | AX6: =ادخال1!$G$7 -> 6 | AY6: =40*AX6*0.3 -> 72 | AZ6: =IFERROR(VLOOKUP(BI16,اسماء,6,0),"") -> 71 | BA6: =40*AX6*0.3 -> 72 | BB6: =IFERROR(VLOOKUP(BI16,اسماء,17,0),"") -> 0 | BC6: =40*AX6*0.4 -> 96 | BD6: =IFERROR(VLOOKUP(BI16,اسماء,28,0),"") -> 0 | BE6: =SUM(AY6,BA6,BC6) -> 240 | BF6: =0.4*BE6 -> 96 | BG6: =SUM(AZ6,BB6,BD6) -> 71 | BI6: =IF(AZ8=0,"",IF(AZ8<AY8*0.4,AW8,"")) | BJ6: =IF(AZ9=0,"",IF(AZ9<AY9*0.4,AW9,"")) | BK6: =IF(AZ10=0,"",IF(AZ10<AY10*0.4,AW10,"")) | BO6: =$BN$1*0.85 -> 714 | BP6: ممتاز
