Workbook
Name اسماء: ادخال1!$B$11:$EY$524
Name الترتيب1: ادخال1!$BA$11:$BB$410
Name الترتيب2: ادخال1!$BG$11:$BH$409
Name الترتيب3: ادخال1!$BL$11:$BM$411
Name عمود1: ادخال1!$A$11:$A$409
Name عمود2: ادخال1!$B$11:$B$409
Name مستجد: ادخال1!$CQ$3:$CQ$4
Name مسلسل: ادخال1!$A$11:$B$409

Sheet بيانات الصحيفة 
A1: 15 | B1: دولة ليبيا | P1: =A1-5 -> 10 | Q1: دولة ليبيا | AE1: =P1-5 -> 5 | AF1: دولة ليبيا | AT1: =AE1-5 -> 0 | AU1: دولة ليبيا
A2: وزارة التعليم | P2: وزارة التعليم | AE2: وزارة التعليم | AT2: وزارة التعليم
A3: المركز الوطني للامتحانات | P3: المركز الوطني للامتحانات | AE3: المركز الوطني للامتحانات | AT3: المركز الوطني للامتحانات
A4: بطاقة تقدير الدرجات لمرحلة التعليم | K4: =ادخال1!$CM$7 -> الاساسي | P4: بطاقة تقدير الدرجات لمرحلة التعليم | Z4: =ادخال1!$CM$7 -> الاساسي | AE4: بطاقة تقدير الدرجات لمرحلة التعليم | AO4: =ادخال1!$CM$7 -> الاساسي | AT4: بطاقة تقدير الدرجات لمرحلة التعليم | BD4: =ادخال1!$CM$7 -> الاساسي
A5: للصف | G5: =ادخال1!$CK$5 -> الرابع | P5: للصف | V5: =ادخال1!$CK$5 -> الرابع | AE5: للصف | AK5: =ادخال1!$CK$5 -> الرابع | AT5: للصف | AZ5: =ادخال1!$CK$5 -> الرابع
A6: العام الدراسي | B6: =ادخال1!$CJ$8 -> 1447ـ/1448 هـ | F6: هجرية | H6: الموافق | J6: =ادخال1!$CK$8 -> 2026 /2025 | N6: ميلادية | P6: العام الدراسي | Q6: =ادخال1!$CJ$8 -> 1447ـ/1448 هـ | U6: هجرية | W6: الموافق | Y6: =ادخال1!$CK$8 -> 2026 /2025 | AC6: ميلادية | AE6: العام الدراسي | AF6: =ادخال1!$CJ$8 -> 1447ـ/1448 هـ | AJ6: هجرية | AL6: الموافق | AN6: =ادخال1!$CK$8 -> 2026 /2025 | AR6: ميلادية | AT6: العام الدراسي | AU6: =ادخال1!$CJ$8 -> 1447ـ/1448 هـ | AY6: هجرية | BA6: الموافق | BC6: =ادخال1!$CK$8 -> 2026 /2025 | BG6: ميلادية
A7: شؤون التعليم بمنطقة | B7: =ادخال1!$CK$4 -> تاجوراء | P7: شؤون التعليم بمنطقة | Q7: =ادخال1!$CK$4 -> تاجوراء | AE7: شؤون التعليم بمنطقة | AF7: =ادخال1!$CK$4 -> تاجوراء | AT7: شؤون التعليم بمنطقة | AU7: =ادخال1!$CK$4 -> تاجوراء
A8: مدرســــــــــــــــــــــة | B8: =ادخال1!$B$5 -> سهول العلم للتعليم الخاص | J8: الكــــائنة بـ : | M8: =ادخال1!$CI$8 -> تاجوراء | P8: مدرســــــــــــــــــــــة | Q8: =ادخال1!$CI$6 -> سهول العلم للتعليم الخاص | Y8: الكــــائنة بـ : | AB8: =ادخال1!$CI$8 -> تاجوراء | AE8: مدرســــــــــــــــــــــة | AF8: =ادخال1!$CI$6 -> سهول العلم للتعليم الخاص | AN8: الكــــائنة بـ : | AQ8: =ادخال1!$CI$8 -> تاجوراء | AT8: مدرســــــــــــــــــــــة | AU8: =ادخال1!$CI$6 -> سهول العلم للتعليم الخاص | BC8: الكــــائنة بـ : | BF8: =ادخال1!$CI$8 -> تاجوراء
A9: اسم التلميذ بالكـــامل | B9: =IFERROR(VLOOKUP(A1,مسلسل,2,0),0) -> مصطفى طارق فتحي الختال | C9: =IFERROR(VLOOKUP(B9,مسلسل,2,0),0) -> 0 | D9: =IFERROR(VLOOKUP(C9,مسلسل,2,0),0) -> 0 | E9: =IFERROR(VLOOKUP(D9,مسلسل,2,0),0) -> 0 | F9: =IFERROR(VLOOKUP(E9,مسلسل,2,0),0) -> 0 | G9: =IFERROR(VLOOKUP(F9,مسلسل,2,0),0) -> 0 | H9: =IFERROR(VLOOKUP(G9,مسلسل,2,0),0) -> 0 | I9: =IFERROR(VLOOKUP(H9,مسلسل,2,0),0) -> 0 | J9: اللقــــــــب | M9: =IFERROR(VLOOKUP(B9,اسماء,72,0),"") -> الختال | P9: اسم التلميذ بالكـــامل | Q9: =IFERROR(VLOOKUP(P1,مسلسل,2,0),0) -> عبد السميع محمد الهادي موسى | R9: =IFERROR(VLOOKUP(Q9,مسلسل,2,0),0) -> 0 | S9: =IFERROR(VLOOKUP(R9,مسلسل,2,0),0) -> 0 | T9: =IFERROR(VLOOKUP(S9,مسلسل,2,0),0) -> 0 | U9: =IFERROR(VLOOKUP(T9,مسلسل,2,0),0) -> 0 | V9: =IFERROR(VLOOKUP(U9,مسلسل,2,0),0) -> 0 | W9: =IFERROR(VLOOKUP(V9,مسلسل,2,0),0) -> 0 | X9: =IFERROR(VLOOKUP(W9,مسلسل,2,0),0) -> 0 | Y9: اللقــــــــب | AB9: =IFERROR(VLOOKUP(Q9,اسماء,72,0),"") -> موسى | AE9: اسم التلميذ بالكـــامل | AF9: =IFERROR(VLOOKUP(AE1,مسلسل,2,0),0) -> حور حمدي عبدالهادي ديهوم | AG9: =IFERROR(VLOOKUP(AF9,مسلسل,2,0),0) -> 0 | AH9: =IFERROR(VLOOKUP(AG9,مسلسل,2,0),0) -> 0 | AI9: =IFERROR(VLOOKUP(AH9,مسلسل,2,0),0) -> 0 | AJ9: =IFERROR(VLOOKUP(AI9,مسلسل,2,0),0) -> 0 | AK9: =IFERROR(VLOOKUP(AJ9,مسلسل,2,0),0) -> 0 | AL9: =IFERROR(VLOOKUP(AK9,مسلسل,2,0),0) -> 0 | AM9: =IFERROR(VLOOKUP(AL9,مسلسل,2,0),0) -> 0 | AN9: اللقــــــــب | AQ9: =IFERROR(VLOOKUP(AF9,اسماء,72,0),"") -> ديهوم | AT9: اسم التلميذ بالكـــامل | AU9: =IFERROR(VLOOKUP(AT1,مسلسل,2,0),0) -> 0 | AV9: =IFERROR(VLOOKUP(AU9,مسلسل,2,0),0) -> 0 | AW9: =IFERROR(VLOOKUP(AV9,مسلسل,2,0),0) -> 0 | AX9: =IFERROR(VLOOKUP(AW9,مسلسل,2,0),0) -> 0 | AY9: =IFERROR(VLOOKUP(AX9,مسلسل,2,0),0) -> 0 | AZ9: =IFERROR(VLOOKUP(AY9,مسلسل,2,0),0) -> 0 | BA9: =IFERROR(VLOOKUP(AZ9,مسلسل,2,0),0) -> 0 | BB9: =IFERROR(VLOOKUP(BA9,مسلسل,2,0),0) -> 0 | BC9: اللقــــــــب | BF9: =IFERROR(VLOOKUP(AU9,اسماء,72,0),"")
A10: مكان وتاريخ الميلاد | B10: =IFERROR(VLOOKUP(B9,اسماء,85,0),"") -> ليبي | E10: =IFERROR(VLOOKUP(B9,اسماء,2,0),"") -> 42569 | I10: اسم الوالدة بالكامل | M10: =IFERROR(VLOOKUP(B9,اسماء,3,0),"") -> صبرية محمد الصادق | P10: مكان وتاريخ الميلاد | Q10: =IFERROR(VLOOKUP(Q9,اسماء,85,0),"") -> ليبي | T10: =IFERROR(VLOOKUP(Q9,اسماء,2,0),"") -> 42626 | X10: اسم الوالدة بالكامل | AB10: =IFERROR(VLOOKUP(Q9,اسماء,3,0),"") -> مريم علي حسين علي | AE10: مكان وتاريخ الميلاد | AF10: =IFERROR(VLOOKUP(AF9,اسماء,85,0),"") -> ليبية | AI10: =IFERROR(VLOOKUP(AF9,اسماء,2,0),"") -> 42569 | AM10: اسم الوالدة بالكامل | AQ10: =IFERROR(VLOOKUP(AF9,اسماء,3,0),"") -> هدى حسين مسعود | AT10: مكان وتاريخ الميلاد | AU10: =IFERROR(VLOOKUP(AU9,اسماء,85,0),"") | AX10: =IFERROR(VLOOKUP(AU9,اسماء,2,0),"") | BB10: اسم الوالدة بالكامل | BF10: =IFERROR(VLOOKUP(AU9,اسماء,3,0),"")
A11: الرقم الوطنــــــــــي | B11: =IFERROR(VLOOKUP(B9,اسماء,73,0),"") -> 5 | C11: =IFERROR(VLOOKUP(B9,اسماء,74,0),"") -> 6 | D11: =IFERROR(VLOOKUP(B9,اسماء,75,0),"") -> 4 | E11: =IFERROR(VLOOKUP(B9,اسماء,76,0),"") -> 4 | F11: =IFERROR(VLOOKUP(B9,اسماء,77,0),"") -> 5 | G11: =IFERROR(VLOOKUP(B9,اسماء,78,0),"") -> 4 | H11: 0 | I11: 6 | J11: 1 | K11: =IFERROR(VLOOKUP(B9,اسماء,82,0),"") -> 0 | L11: =IFERROR(VLOOKUP(B9,اسماء,83,0),"") -> 2 | M11: =IFERROR(VLOOKUP(B9,اسماء,84,0),"") -> 1 | P11: الرقم الوطنــــــــــي | Q11: =IFERROR(VLOOKUP(Q9,اسماء,73,0),"") -> 9 | R11: =IFERROR(VLOOKUP(Q9,اسماء,74,0),"") -> 5 | S11: =IFERROR(VLOOKUP(Q9,اسماء,75,0),"") -> 0 | T11: =IFERROR(VLOOKUP(Q9,اسماء,76,0),"") -> 2 | U11: =IFERROR(VLOOKUP(Q9,اسماء,77,0),"") -> 7 | V11: =IFERROR(VLOOKUP(Q9,اسماء,78,0),"") -> 5 | W11: =IFERROR(VLOOKUP(Q9,اسماء,78,0),"") -> 5 | X11: =IFERROR(VLOOKUP(Q9,اسماء,79,0),"") -> 0 | Y11: =IFERROR(VLOOKUP(Q9,اسماء,80,0),"") -> 6 | Z11: =IFERROR(VLOOKUP(Q9,اسماء,82,0),"") -> 0 | AA11: =IFERROR(VLOOKUP(Q9,اسماء,83,0),"") -> 2 | AB11: =IFERROR(VLOOKUP(Q9,اسماء,84,0),"") -> 1 | AE11: الرقم الوطنــــــــــي | AF11: =IFERROR(VLOOKUP(AF9,اسماء,73,0),"") -> 4 | AG11: =IFERROR(VLOOKUP(AF9,اسماء,74,0),"") -> 4 | AH11: =IFERROR(VLOOKUP(AF9,اسماء,75,0),"") -> 4 | AI11: =IFERROR(VLOOKUP(AF9,اسماء,76,0),"") -> 4 | AJ11: =IFERROR(VLOOKUP(AF9,اسماء,77,0),"") -> 7 | AK11: =IFERROR(VLOOKUP(AF9,اسماء,78,0),"") -> 4 | AL11: =IFERROR(VLOOKUP(AF9,اسماء,78,0),"") -> 4 | AM11: =IFERROR(VLOOKUP(AF9,اسماء,79,0),"") -> 0 | AN11: =IFERROR(VLOOKUP(AF9,اسماء,80,0),"") -> 6 | AO11: =IFERROR(VLOOKUP(AF9,اسماء,82,0),"") -> 0 | AP11: =IFERROR(VLOOKUP(AF9,اسماء,83,0),"") -> 2 | AQ11: =IFERROR(VLOOKUP(AF9,اسماء,84,0),"") -> 2 | AT11: الرقم الوطنــــــــــي | AU11: =IFERROR(VLOOKUP(AU9,اسماء,73,0),"") | AV11: =IFERROR(VLOOKUP(AU9,اسماء,74,0),"") | AW11: =IFERROR(VLOOKUP(AU9,اسماء,75,0),"") | AX11: =IFERROR(VLOOKUP(AU9,اسماء,76,0),"") | AY11: =IFERROR(VLOOKUP(AU9,اسماء,77,0),"") | AZ11: =IFERROR(VLOOKUP(AU9,اسماء,78,0),"") | BA11: =IFERROR(VLOOKUP(AU9,اسماء,78,0),"") | BB11: =IFERROR(VLOOKUP(AU9,اسماء,79,0),"") | BC11: =IFERROR(VLOOKUP(AU9,اسماء,80,0),"") | BD11: =IFERROR(VLOOKUP(AU9,اسماء,82,0),"") | BE11: =IFERROR(VLOOKUP(AU9,اسماء,83,0),"") | BF11: =IFERROR(VLOOKUP(AU9,اسماء,84,0),"")
A12: جنسيـــــة التلمــــيذ | B12: =IFERROR(VLOOKUP(B9,اسماء,86,0),"") -> ليبي | G12: مستجد/ | I12: معيد | K12: =IFERROR(VLOOKUP(B9,اسماء,87,0),"") -> مستجد | P12: جنسيـــــة التلمــــيذ | Q12: =IFERROR(VLOOKUP(Q9,اسماء,86,0),"") -> ليبي | V12: مستجد/ | X12: معيد | Z12: =IFERROR(VLOOKUP(Q9,اسماء,87,0),"") -> مستجد | AE12: جنسيـــــة التلمــــيذ | AF12: =IFERROR(VLOOKUP(AF9,اسماء,86,0),"") -> ليبية | AK12: مستجد/ | AM12: معيد | AO12: =IFERROR(VLOOKUP(AF9,اسماء,87,0),"") -> مستجد | AT12: جنسيـــــة التلمــــيذ | AU12: =IFERROR(VLOOKUP(AU9,اسماء,86,0),"") | AZ12: مستجد/ | BB12: معيد | BD12: =IFERROR(VLOOKUP(AU9,اسماء,87,0),"")
A13: رائــــــد الصــــــف | B13: =IFERROR(VLOOKUP(B9,اسماء,89,0),"") -> سلسبيل الكاسح | G13: صفة القيد | K13: =IFERROR(VLOOKUP(B9,اسماء,88,0),"") -> نظامي | P13: رائــــــد الصــــــف | Q13: =IFERROR(VLOOKUP(Q9,اسماء,89,0),"") -> سلسبيل الكاسح | V13: صفة القيد | Z13: =IFERROR(VLOOKUP(Q9,اسماء,88,0),"") -> نظامي | AE13: رائــــــد الصــــــف | AF13: =IFERROR(VLOOKUP(AF9,اسماء,89,0),"") -> سلسبيل الكاسح | AK13: صفة القيد | AO13: =IFERROR(VLOOKUP(AF9,اسماء,88,0),"") -> نظامي | AT13: رائــــــد الصــــــف | AU13: =IFERROR(VLOOKUP(AU9,اسماء,89,0),"") | AZ13: صفة القيد | BD13: =IFERROR(VLOOKUP(AU9,اسماء,88,0),"")
A14: (يكتب اسم التلميذ مطابقاً لشهادة الميلاد) | P14: (يكتب اسم التلميذ مطابقاً لشهادة الميلاد) | AE14: (يكتب اسم التلميذ مطابقاً لشهادة الميلاد) | AT14: (يكتب اسم التلميذ مطابقاً لشهادة الميلاد)
A15: الانتقـــــــــال | P15: الانتقـــــــــال | AE15: الانتقـــــــــال | AT15: الانتقـــــــــال
A16: بناء على طلب ولي أمر التلميذ فإن إدارة هذه المدرسة توافق على انتقاله إلــــــى | P16: بناء على طلب ولي أمر التلميذ فإن إدارة هذه المدرسة توافق على انتقاله إلــــــى | AE16: بناء على طلب ولي أمر التلميذ فإن إدارة هذه المدرسة توافق على انتقاله إلــــــى | AT16: بناء على طلب ولي أمر التلميذ فإن إدارة هذه المدرسة توافق على انتقاله إلــــــى
A17: مدرســــــة | P17: مدرســــــة | AE17: مدرســــــة | AT17: مدرســــــة
A18: يعتمد مديرالمدرسة | N18: يعتمد مكتب الامتحانات | P18: يعتمد مديرالمدرسة | AC18: يعتمد مكتب الامتحانات | AE18: يعتمد مديرالمدرسة | AR18: يعتمد مكتب الامتحانات | AT18: يعتمد مديرالمدرسة | BG18: يعتمد مكتب الامتحانات
A23: =A1-1 -> 14 | B23: دولة ليبيا | P23: =A23-5 -> 9 | Q23: دولة ليبيا | AE23: =P23-5 -> 4 | AF23: دولة ليبيا | AT23: =AE23-5 -> -1 | AU23: دولة ليبيا
A24: وزارة التعليم | P24: وزارة التعليم | AE24: وزارة التعليم | AT24: وزارة التعليم
A25: المركز الوطني للامتحانات | P25: المركز الوطني للامتحانات | AE25: المركز الوطني للامتحانات | AT25: المركز الوطني للامتحانات
A26: بطاقة تقدير الدرجات لمرحلة التعليم | K26: =ادخال1!$CM$7 -> الاساسي | P26: بطاقة تقدير الدرجات لمرحلة التعليم | Z26: =ادخال1!$CM$7 -> الاساسي | AE26: بطاقة تقدير الدرجات لمرحلة التعليم | AO26: =ادخال1!$CM$7 -> الاساسي | AT26: بطاقة تقدير الدرجات لمرحلة التعليم | BD26: =ادخال1!$CM$7 -> الاساسي
A27: للصف | G27: =ادخال1!$CK$5 -> الرابع | P27: للصف | V27: =ادخال1!$CK$5 -> الرابع | AE27: للصف | AK27: =ادخال1!$CK$5 -> الرابع | AT27: للصف | AZ27: =ادخال1!$CK$5 -> الرابع
A28: العام الدراسي | B28: =ادخال1!$CJ$8 -> 1447ـ/1448 هـ | F28: هجرية | H28: الموافق | J28: =ادخال1!$CK$8 -> 2026 /2025 | N28: ميلادية | P28: العام الدراسي | Q28: =ادخال1!$CJ$8 -> 1447ـ/1448 هـ | U28: هجرية | W28: الموافق | Y28: =ادخال1!$CK$8 -> 2026 /2025 | AC28: ميلادية | AE28: العام الدراسي | AF28: =ادخال1!$CJ$8 -> 1447ـ/1448 هـ | AJ28: هجرية | AL28: الموافق | AN28: =ادخال1!$CK$8 -> 2026 /2025 | AR28: ميلادية | AT28: العام الدراسي | AU28: =ادخال1!$CJ$8 -> 1447ـ/1448 هـ | AY28: هجرية | BA28: الموافق | BC28: =ادخال1!$CK$8 -> 2026 /2025 | BG28: ميلادية
A29: شؤون التعليم بمنطقة | B29: =ادخال1!$CK$4 -> تاجوراء | P29: شؤون التعليم بمنطقة | Q29: =ادخال1!$CK$4 -> تاجوراء | AE29: شؤون التعليم بمنطقة | AF29: =ادخال1!$CK$4 -> تاجوراء | AT29: شؤون التعليم بمنطقة | AU29: =ادخال1!$CK$4 -> تاجوراء
A30: مدرســــــــــــــــــــــة | B30: =ادخال1!$CI$6 -> سهول العلم للتعليم الخاص | J30: الكــــائنة بـ : | M30: =ادخال1!$CI$8 -> تاجوراء | P30: مدرســــــــــــــــــــــة | Q30: =ادخال1!$CI$6 -> سهول العلم للتعليم الخاص | Y30: الكــــائنة بـ : | AB30: =ادخال1!$CI$8 -> تاجوراء | AE30: مدرســــــــــــــــــــــة | AF30: =ادخال1!$CI$6 -> سهول العلم للتعليم الخاص | AN30: الكــــائنة بـ : | AQ30: =ادخال1!$CI$8 -> تاجوراء | AT30: مدرســــــــــــــــــــــة | AU30: =ادخال1!$CI$6 -> سهول العلم للتعليم الخاص | BC30: الكــــائنة بـ : | BF30: =ادخال1!$CI$8 -> تاجوراء
A31: اسم التلميذ بالكـــامل | B31: =IFERROR(VLOOKUP(A23,مسلسل,2,0),0) -> محمد مجدي عبدالله سليمان | C31: =IFERROR(VLOOKUP(B31,مسلسل,2,0),0) -> 0 | D31: =IFERROR(VLOOKUP(C31,مسلسل,2,0),0) -> 0 | E31: =IFERROR(VLOOKUP(D31,مسلسل,2,0),0) -> 0 | F31: =IFERROR(VLOOKUP(E31,مسلسل,2,0),0) -> 0 | G31: =IFERROR(VLOOKUP(F31,مسلسل,2,0),0) -> 0 | H31: =IFERROR(VLOOKUP(G31,مسلسل,2,0),0) -> 0 | I31: =IFERROR(VLOOKUP(H31,مسلسل,2,0),0) -> 0 | J31: اللقــــــــب | M31: =IFERROR(VLOOKUP(B31,اسماء,72,0),"") -> سليمان | P31: اسم التلميذ بالكـــامل | Q31: =IFERROR(VLOOKUP(P23,مسلسل,2,0),0) -> سوار وليد مصطفي الورشفاني | R31: =IFERROR(VLOOKUP(Q31,مسلسل,2,0),0) -> 0 | S31: =IFERROR(VLOOKUP(R31,مسلسل,2,0),0) -> 0 | T31: =IFERROR(VLOOKUP(S31,مسلسل,2,0),0) -> 0 | U31: =IFERROR(VLOOKUP(T31,مسلسل,2,0),0) -> 0 | V31: =IFERROR(VLOOKUP(U31,مسلسل,2,0),0) -> 0 | W31: =IFERROR(VLOOKUP(V31,مسلسل,2,0),0) -> 0 | X31: =IFERROR(VLOOKUP(W31,مسلسل,2,0),0) -> 0 | Y31: اللقــــــــب | AB31: =IFERROR(VLOOKUP(Q31,اسماء,72,0),"") -> الورشفاني | AE31: اسم التلميذ بالكـــامل | AF31: =IFERROR(VLOOKUP(AE23,مسلسل,2,0),0) -> جنان عبدالسلام محمد الجوادي | AG31: =IFERROR(VLOOKUP(AF31,مسلسل,2,0),0) -> 0 | AH31: =IFERROR(VLOOKUP(AG31,مسلسل,2,0),0) -> 0 | AI31: =IFERROR(VLOOKUP(AH31,مسلسل,2,0),0) -> 0 | AJ31: =IFERROR(VLOOKUP(AI31,مسلسل,2,0),0) -> 0 | AK31: =IFERROR(VLOOKUP(AJ31,مسلسل,2,0),0) -> 0 | AL31: =IFERROR(VLOOKUP(AK31,مسلسل,2,0),0) -> 0 | AM31: =IFERROR(VLOOKUP(AL31,مسلسل,2,0),0) -> 0 | AN31: اللقــــــــب | AQ31: =IFERROR(VLOOKUP(AF31,اسماء,72,0),"") -> الجوادي | AT31: اسم التلميذ بالكـــامل | AU31: =IFERROR(VLOOKUP(AT23,مسلسل,2,0),0) -> 0 | AV31: =IFERROR(VLOOKUP(AU31,مسلسل,2,0),0) -> 0 | AW31: =IFERROR(VLOOKUP(AV31,مسلسل,2,0),0) -> 0 | AX31: =IFERROR(VLOOKUP(AW31,مسلسل,2,0),0) -> 0 | AY31: =IFERROR(VLOOKUP(AX31,مسلسل,2,0),0) -> 0 | AZ31: =IFERROR(VLOOKUP(AY31,مسلسل,2,0),0) -> 0 | BA31: =IFERROR(VLOOKUP(AZ31,مسلسل,2,0),0) -> 0 | BB31: =IFERROR(VLOOKUP(BA31,مسلسل,2,0),0) -> 0 | BC31: اللقــــــــب | BF31: =IFERROR(VLOOKUP(AU31,اسماء,72,0),"")
A32: مكان وتاريخ الميلاد | B32: =IFERROR(VLOOKUP(B31,اسماء,85,0),"") -> ليبي | E32: =IFERROR(VLOOKUP(B31,اسماء,2,0),"") -> 42656 | I32: اسم الوالدة بالكامل | M32: =IFERROR(VLOOKUP(B31,اسماء,3,0),"") -> أميرة بشير سالم | P32: مكان وتاريخ الميلاد | Q32: =IFERROR(VLOOKUP(Q31,اسماء,85,0),"") -> ليبية | T32: =IFERROR(VLOOKUP(Q31,اسماء,2,0),"") -> 42527 | X32: اسم الوالدة بالكامل | AB32: =IFERROR(VLOOKUP(Q31,اسماء,3,0),"") -> إيمان علي سالم | AE32: مكان وتاريخ الميلاد | AF32: =IFERROR(VLOOKUP(AF31,اسماء,85,0),"") -> ليبية | AI32: =IFERROR(VLOOKUP(AF31,اسماء,2,0),"") -> 42705 | AM32: اسم الوالدة بالكامل | AQ32: =IFERROR(VLOOKUP(AF31,اسماء,3,0),"") -> هدى زيدام علي الجماعي | AT32: مكان وتاريخ الميلاد | AU32: =IFERROR(VLOOKUP(AU31,اسماء,85,0),"") | AX32: =IFERROR(VLOOKUP(AU31,اسماء,2,0),"") | BB32: اسم الوالدة بالكامل | BF32: =IFERROR(VLOOKUP(AU31,اسماء,3,0),"")
A33: الرقم الوطنــــــــــي | B33: =IFERROR(VLOOKUP(B31,اسماء,73,0),"") -> 8 | C33: =IFERROR(VLOOKUP(B31,اسماء,74,0),"") -> 8 | D33: =IFERROR(VLOOKUP(B31,اسماء,75,0),"") -> 7 | E33: =IFERROR(VLOOKUP(B31,اسماء,76,0),"") -> 4 | F33: =IFERROR(VLOOKUP(B31,اسماء,77,0),"") -> 7 | G33: =IFERROR(VLOOKUP(B31,اسماء,78,0),"") -> 6 | H33: =IFERROR(VLOOKUP(B31,اسماء,78,0),"") -> 6 | I33: =IFERROR(VLOOKUP(B31,اسماء,79,0),"") -> 0 | J33: =IFERROR(VLOOKUP(B31,اسماء,80,0),"") -> 6 | K33: =IFERROR(VLOOKUP(B31,اسماء,82,0),"") -> 0 | L33: =IFERROR(VLOOKUP(B31,اسماء,83,0),"") -> 2 | M33: =IFERROR(VLOOKUP(B31,اسماء,84,0),"") -> 1 | P33: الرقم الوطنــــــــــي | Q33: =IFERROR(VLOOKUP(Q31,اسماء,73,0),"") | R33: =IFERROR(VLOOKUP(Q31,اسماء,74,0),"") | S33: =IFERROR(VLOOKUP(Q31,اسماء,75,0),"") | T33: =IFERROR(VLOOKUP(Q31,اسماء,76,0),"") | U33: =IFERROR(VLOOKUP(Q31,اسماء,77,0),"") | V33: =IFERROR(VLOOKUP(Q31,اسماء,78,0),"") | W33: =IFERROR(VLOOKUP(Q31,اسماء,78,0),"") | X33: =IFERROR(VLOOKUP(Q31,اسماء,79,0),"") | Y33: =IFERROR(VLOOKUP(Q31,اسماء,80,0),"") | Z33: =IFERROR(VLOOKUP(Q31,اسماء,82,0),"") | AA33: =IFERROR(VLOOKUP(Q31,اسماء,83,0),"") | AB33: =IFERROR(VLOOKUP(Q31,اسماء,84,0),"") | AE33: الرقم الوطنــــــــــي | AF33: =IFERROR(VLOOKUP(AF31,اسماء,73,0),"") -> 5 | AG33: =IFERROR(VLOOKUP(AF31,اسماء,74,0),"") -> 0 | AH33: =IFERROR(VLOOKUP(AF31,اسماء,75,0),"") -> 1 | AI33: =IFERROR(VLOOKUP(AF31,اسماء,76,0),"") -> 8 | AJ33: =IFERROR(VLOOKUP(AF31,اسماء,77,0),"") -> 4 | AK33: =IFERROR(VLOOKUP(AF31,اسماء,78,0),"") -> 9 | AL33: =IFERROR(VLOOKUP(AF31,اسماء,78,0),"") -> 9 | AM33: =IFERROR(VLOOKUP(AF31,اسماء,79,0),"") -> 0 | AN33: =IFERROR(VLOOKUP(AF31,اسماء,80,0),"") -> 6 | AO33: =IFERROR(VLOOKUP(AF31,اسماء,82,0),"") -> 0 | AP33: =IFERROR(VLOOKUP(AF31,اسماء,83,0),"") -> 2 | AQ33: =IFERROR(VLOOKUP(AF31,اسماء,84,0),"") -> 2 | AT33: الرقم الوطنــــــــــي | AU33: =IFERROR(VLOOKUP(AU31,اسماء,73,0),"") | AV33: =IFERROR(VLOOKUP(AU31,اسماء,74,0),"") | AW33: =IFERROR(VLOOKUP(AU31,اسماء,75,0),"") | AX33: =IFERROR(VLOOKUP(AU31,اسماء,76,0),"") | AY33: =IFERROR(VLOOKUP(AU31,اسماء,77,0),"") | AZ33: =IFERROR(VLOOKUP(AU31,اسماء,78,0),"") | BA33: =IFERROR(VLOOKUP(AU31,اسماء,78,0),"") | BB33: =IFERROR(VLOOKUP(AU31,اسماء,79,0),"") | BC33: =IFERROR(VLOOKUP(AU31,اسماء,80,0),"") | BD33: =IFERROR(VLOOKUP(AU31,اسماء,82,0),"") | BE33: =IFERROR(VLOOKUP(AU31,اسماء,83,0),"") | BF33: =IFERROR(VLOOKUP(AU31,اسماء,84,0),"")
A34: جنسيـــــة التلمــــيذ | B34: =IFERROR(VLOOKUP(B31,اسماء,86,0),"") -> ليبي | G34: مستجد/ | I34: معيد | K34: =IFERROR(VLOOKUP(B31,اسماء,87,0),"") -> مستجد | P34: جنسيـــــة التلمــــيذ | Q34: =IFERROR(VLOOKUP(Q31,اسماء,86,0),"") -> ليبية | V34: مستجد/ | X34: معيد | Z34: =IFERROR(VLOOKUP(Q31,اسماء,87,0),"") -> مستجد | AE34: جنسيـــــة التلمــــيذ | AF34: =IFERROR(VLOOKUP(AF31,اسماء,86,0),"") -> ليبية | AK34: مستجد/ | AM34: معيد | AO34: =IFERROR(VLOOKUP(AF31,اسماء,87,0),"") -> مستجد | AT34: جنسيـــــة التلمــــيذ | AU34: =IFERROR(VLOOKUP(AU31,اسماء,86,0),"") | AZ34: مستجد/ | BB34: معيد | BD34: =IFERROR(VLOOKUP(AU31,اسماء,87,0),"")
A35: رائــــــد الصــــــف | B35: =IFERROR(VLOOKUP(B31,اسماء,89,0),"") -> سلسبيل الكاسح | G35: صفة القيد | K35: =IFERROR(VLOOKUP(B31,اسماء,88,0),"") -> نظامي | P35: رائــــــد الصــــــف | Q35: =IFERROR(VLOOKUP(Q31,اسماء,89,0),"") -> سلسبيل الكاسح | V35: صفة القيد | Z35: =IFERROR(VLOOKUP(Q31,اسماء,88,0),"") -> نظامي | AE35: رائــــــد الصــــــف | AF35: =IFERROR(VLOOKUP(AF31,اسماء,89,0),"") -> سلسبيل الكاسح | AK35: صفة القيد | AO35: =IFERROR(VLOOKUP(AF31,اسماء,88,0),"") -> نظامي | AT35: رائــــــد الصــــــف | AU35: =IFERROR(VLOOKUP(AU31,اسماء,89,0),"") | AZ35: صفة القيد | BD35: =IFERROR(VLOOKUP(AU31,اسماء,88,0),"")
A36: (يكتب اسم التلميذ مطابقاً لشهادة الميلاد) | P36: (يكتب اسم التلميذ مطابقاً لشهادة الميلاد) | AE36: (يكتب اسم التلميذ مطابقاً لشهادة الميلاد) | AT36: (يكتب اسم التلميذ مطابقاً لشهادة الميلاد)
A37: الانتقـــــــــال | P37: الانتقـــــــــال | AE37: الانتقـــــــــال | AT37: الانتقـــــــــال
A38: بناء على طلب ولي أمر التلميذ فإن إدارة هذه المدرسة توافق على انتقاله إلــــــى | P38: بناء على طلب ولي أمر التلميذ فإن إدارة هذه المدرسة توافق على انتقاله إلــــــى | AE38: بناء على طلب ولي أمر التلميذ فإن إدارة هذه المدرسة توافق على انتقاله إلــــــى | AT38: بناء على طلب ولي أمر التلميذ فإن إدارة هذه المدرسة توافق على انتقاله إلــــــى
A39: مدرســــــة | P39: مدرســــــة | AE39: مدرســــــة | AT39: مدرســــــة
A40: يعتمد مديرالمدرسة | N40: يعتمد مكتب الامتحانات | P40: يعتمد مديرالمدرسة | AC40: يعتمد مكتب الامتحانات | AE40: يعتمد مديرالمدرسة | AR40: يعتمد مكتب الامتحانات | AT40: يعتمد مديرالمدرسة | BG40: يعتمد مكتب الامتحانات
A45: =A23-1 -> 13 | B45: دولة ليبيا | P45: =A45-5 -> 8 | Q45: دولة ليبيا | AE45: =P45-5 -> 3 | AF45: دولة ليبيا | AT45: =AE45-5 -> -2 | AU45: دولة ليبيا
A46: وزارة التعليم | P46: وزارة التعليم | AE46: وزارة التعليم | AT46: وزارة التعليم
A47: المركز الوطني للامتحانات | P47: المركز الوطني للامتحانات | AE47: المركز الوطني للامتحانات | AT47: المركز الوطني للامتحانات
A48: بطاقة تقدير الدرجات لمرحلة التعليم | K48: =ادخال1!$CM$7 -> الاساسي | P48: بطاقة تقدير الدرجات لمرحلة التعليم | Z48: =ادخال1!$CM$7 -> الاساسي | AE48: بطاقة تقدير الدرجات لمرحلة التعليم | AO48: =ادخال1!$CM$7 -> الاساسي | AT48: بطاقة تقدير الدرجات لمرحلة التعليم | BD48: =ادخال1!$CM$7 -> الاساسي
...

Sheet الرئيسية

Sheet صحيفة الفترات
A1: بطاقة تقدير الدرجات للصــــف | D1: =ادخال1!$N$4 -> الرابع | F1: من التعليم الأساسي | J1: 15 | L1: بطاقة تقدير الدرجات للصــــف | O1: =ادخال1!$N$4 -> الرابع | Q1: من التعليم الأساسي | U1: 15 | W1: بطاقة تقدير الدرجات للصــــف | Z1: =ادخال1!$N$4 -> الرابع | AB1: من التعليم الأساسي | AF1: =U1+5 -> 20 | AH1: بطاقة تقدير الدرجات للصــــف | AK1: =ادخال1!$N$4 -> الرابع | AM1: من التعليم الأساسي | AQ1: =AF1+5 -> 25
A2: المدرسة/ | B2: =ادخال1!$B$5 -> سهول العلم للتعليم الخاص | F2: الاسم | G2: =H17 -> مصطفى طارق فتحي الختال | M2: =ادخال1!$B$5 -> سهول العلم للتعليم الخاص | Q2: الاسم | R2: =S17 -> مصطفى طارق فتحي الختال | W2: المدرسة/ | X2: =ادخال1!$B$5 -> سهول العلم للتعليم الخاص | AB2: الاسم | AC2: =AD17 -> 0 | AH2: المدرسة/ | AI2: =ادخال1!$B$5 -> سهول العلم للتعليم الخاص | AM2: الاسم | AN2: =AO17 -> 0
A3: الفترات | B3: عدد الحصص | C3: الفترة الأولي 30 % | E3: الفترة الثانية 30 % | H3: ملاحظــات عن نتيجة التلميذ خلال كل فترة : | L3: الفترات | M3: عدد الحصص | N3: الفترة الأولي 30 % | P3: الفترة الثانية 30 % | S3: ملاحظــات عن نتيجة التلميذ خلال كل فترة : | W3: الفترات | X3: عدد الحصص | Y3: الفترة الأولي 30 % | AA3: الفترة الثانية 30 % | AD3: ملاحظــات عن نتيجة التلميذ خلال كل فترة : | AH3: الفترات | AI3: عدد الحصص | AJ3: الفترة الأولي 30 % | AL3: الفترة الثانية 30 % | AO3: ملاحظــات عن نتيجة التلميذ خلال كل فترة :
A4: المواد الدراسية | C4: الدرجة الكبرى | D4: درجة التلميذ | E4: الدرجة الكبرى | F4: درجة التلميذ | H4: الأولي : | I4: =IF(D13=0,"",IF(AND(D5>=C5*0.4,D6>=C6*0.4,D10>=C10*0.4,D11>=C11*0.4,D12>=C12*0.4,D7>=C7*0.4,D8>=C8*0.4,D9>=C9*0.4),LOOKUP(D13,'النتيجة النهائية'!$AF$6:$AG$10),"ضعيف ويحتاج الى اهتمام في المواد")) -> مقبول | L4: المواد الدراسية | N4: الدرجة الكبرى | O4: درجة التلميذ | P4: الدرجة الكبرى | Q4: درجة التلميذ | S4: الأولي : | T4: =IF(O13=0,"",IF(AND(O5>=N5*0.4,O6>=N6*0.4,O10>=N10*0.4,O11>=N11*0.4,O12>=N12*0.4,O7>=N7*0.4,O8>=N8*0.4,O9>=N9*0.4),LOOKUP(O13,'النتيجة النهائية'!$AF$6:$AG$10),"ضعيف ويحتاج الى اهتمام في المواد")) -> مقبول | W4: المواد الدراسية | Y4: الدرجة الكبرى | Z4: درجة التلميذ | AA4: الدرجة الكبرى | AB4: درجة التلميذ | AD4: الأولي : | AE4: =IF(Z13=0,"",IF(AND(Z5>=Y5*0.4,Z6>=Y6*0.4,Z10>=Y10*0.4,Z11>=Y11*0.4,Z12>=Y12*0.4,Z7>=Y7*0.4,Z8>=Y8*0.4,Z9>=Y9*0.4),LOOKUP(Z13,'النتيجة النهائية'!$AF$6:$AG$10),"ضعيف ويحتاج الى اهتمام في المواد")) | AH4: المواد الدراسية | AJ4: الدرجة الكبرى | AK4: درجة التلميذ | AL4: الدرجة الكبرى | AM4: درجة التلميذ | AO4: الأولي : | AP4: =IF(AK13=0,"",IF(AND(AK5>=AJ5*0.4,AK6>=AJ6*0.4,AK10>=AJ10*0.4,AK11>=AJ11*0.4,AK12>=AJ12*0.4,AK7>=AJ7*0.4,AK8>=AJ8*0.4,AK9>=AJ9*0.4),LOOKUP(AK13,'النتيجة النهائية'!$AF$6:$AG$10),"ضعيف ويحتاج الى اهتمام في المواد"))
A5: =ادخال1!$F$9 -> التربية الإسلامية | B5: =ادخال1!$F$7 -> 3 | C5: =40*B5*0.3 -> 36 | D5: =IFERROR(VLOOKUP(H17,اسماء,5,0),"") -> 24 | E5: =40*B5*0.3 -> 36 | F5: =IFERROR(VLOOKUP(H17,اسماء,18,0),"") -> 0 | H5: =IF(D5=0,"",IF(D5<C5*0.4,A5,"")) | I5: =IF(D6=0,"",IF(D6<C6*0.4,A6,"")) | J5: =IF(D7=0,"",IF(D7<C7*0.4,A7,"")) | L5: =ادخال1!$F$9 -> التربية الإسلامية | M5: =ادخال1!$F$7 -> 3 | N5: =40*M5*0.3 -> 36 | O5: =IFERROR(VLOOKUP(S17,اسماء,5,0),"") -> 24 | P5: =40*M5*0.3 -> 36 | Q5: =IFERROR(VLOOKUP(S17,اسماء,18,0),"") -> 0 | S5: =IF(O5=0,"",IF(O5<N5*0.4,L5,"")) | T5: =IF(O6=0,"",IF(O6<N6*0.4,L6,"")) | U5: =IF(O7=0,"",IF(O7<N7*0.4,L7,"")) | W5: =ادخال1!$F$9 -> التربية الإسلامية | X5: =ادخال1!$F$7 -> 3 | Y5: =40*X5*0.3 -> 36 | Z5: =IFERROR(VLOOKUP(AD17,اسماء,5,0),"") | AA5: =40*X5*0.3 -> 36 | AB5: =IFERROR(VLOOKUP(AD17,اسماء,18,0),"") | AD5: =IF(Z5=0,"",IF(Z5<Y5*0.4,W5,"")) | AE5: =IF(Z6=0,"",IF(Z6<Y6*0.4,W6,"")) | AF5: =IF(Z7=0,"",IF(Z7<Y7*0.4,W7,"")) | AH5: =ادخال1!$F$9 -> التربية الإسلامية | AI5: =ادخال1!$F$7 -> 3 | AJ5: =40*AI5*0.3 -> 36 | AK5: =IFERROR(VLOOKUP(AO17,اسماء,5,0),"") | AL5: =40*AI5*0.3 -> 36 | AM5: =IFERROR(VLOOKUP(AO17,اسماء,18,0),"") | AO5: =IF(AK5=0,"",IF(AK5<AJ5*0.4,AH5,"")) | AP5: =IF(AK6=0,"",IF(AK6<AJ6*0.4,AH6,"")) | AQ5: =IF(AK7=0,"",IF(AK7<AJ7*0.4,AH7,""))
A6: =ادخال1!$G$9 -> اللغة العربية | B6: =ادخال1!$G$7 -> 4 | C6: =40*B6*0.3 -> 48 | D6: =IFERROR(VLOOKUP(H17,اسماء,6,0),"") -> 24 | E6: =40*B6*0.3 -> 48 | F6: =IFERROR(VLOOKUP(H17,اسماء,19,0),"") -> 0 | H6: =IF(D8=0,"",IF(D10<C10*0.4,A8,"")) | I6: =IF(D12=0,"",IF(D12<C12*0.4,A9,"")) | J6: =IF(D9=0,"",IF(D9<C9*0.4,A10,"")) | L6: =ادخال1!$G$9 -> اللغة العربية | M6: =ادخال1!$G$7 -> 4 | N6: =40*M6*0.3 -> 48 | O6: =IFERROR(VLOOKUP(S17,اسماء,6,0),"") -> 24 | P6: =40*M6*0.3 -> 48 | Q6: =IFERROR(VLOOKUP(S17,اسماء,19,0),"") -> 0 | S6: =IF(O10=0,"",IF(O10<N10*0.4,L8,"")) | T6: =IF(O12=0,"",IF(O12<N12*0.4,L9,"")) | U6: =IF(O9=0,"",IF(O9<N9*0.4,L10,"")) | W6: =ادخال1!$G$9 -> اللغة العربية | X6: =ادخال1!$G$7 -> 4 | Y6: =40*X6*0.3 -> 48 | Z6: =IFERROR(VLOOKUP(AD17,اسماء,6,0),"") | AA6: =40*X6*0.3 -> 48 | AB6: =IFERROR(VLOOKUP(AD17,اسماء,19,0),"") | AD6: =IF(Z10=0,"",IF(Z10<Y10*0.4,W8,"")) | AE6: =IF(Z12=0,"",IF(Z12<Y12*0.4,W9,"")) | AF6: =IF(Z9=0,"",IF(Z9<Y9*0.4,W10,"")) | AH6: =ادخال1!$G$9 -> اللغة العربية | AI6: =ادخال1!$G$7 -> 4 | AJ6: =40*AI6*0.3 -> 48 | AK6: =IFERROR(VLOOKUP(AO17,اسماء,6,0),"") | AL6: =40*AI6*0.3 -> 48 | AM6: =IFERROR(VLOOKUP(AO17,اسماء,19,0),"") | AO6: =IF(AK10=0,"",IF(AK10<AJ10*0.4,AH8,"")) | AP6: =IF(AK12=0,"",IF(AK12<AJ12*0.4,AH9,"")) | AQ6: =IF(AK9=0,"",IF(AK9<AJ9*0.4,AH10,""))
A7: =ادخال1!$H$9 -> الكتابة | B7: =ادخال1!$H$7 -> 2 | C7: =40*B7*0.3 -> 24 | D7: =IFERROR(VLOOKUP(H17,اسماء,7,0),"") -> 15 | E7: =40*B7*0.3 -> 24 | F7: =IFERROR(VLOOKUP(H17,اسماء,20,0),"") -> 0 | H7: =IF(D11=0,"",IF(D11<C11*0.4,A11,"")) | I7: =IF(D12=0,"",IF(D12<C12*0.4,A12,"")) | L7: =ادخال1!$H$9 -> الكتابة | M7: =ادخال1!$H$7 -> 2 | N7: =40*M7*0.3 -> 24 | O7: =IFERROR(VLOOKUP(S17,اسماء,7,0),"") -> 15 | P7: =40*M7*0.3 -> 24 | Q7: =IFERROR(VLOOKUP(S17,اسماء,20,0),"") -> 0 | S7: =IF(O11=0,"",IF(O11<N11*0.4,L11,"")) | T7: =IF(O12=0,"",IF(O12<N12*0.4,L12,"")) | W7: =ادخال1!$H$9 -> الكتابة | X7: =ادخال1!$H$7 -> 2 | Y7: =40*X7*0.3 -> 24 | Z7: =IFERROR(VLOOKUP(AD17,اسماء,7,0),"") | AA7: =40*X7*0.3 -> 24 | AB7: =IFERROR(VLOOKUP(AD17,اسماء,20,0),"") | AD7: =IF(Z11=0,"",IF(Z11<Y11*0.4,W11,"")) | AE7: =IF(Z12=0,"",IF(Z12<Y12*0.4,W12,"")) | AH7: =ادخال1!$H$9 -> الكتابة | AI7: =ادخال1!$H$7 -> 2 | AJ7: =40*AI7*0.3 -> 24 | AK7: =IFERROR(VLOOKUP(AO17,اسماء,7,0),"") | AL7: =40*AI7*0.3 -> 24 | AM7: =IFERROR(VLOOKUP(AO17,اسماء,20,0),"") | AO7: =IF(AK11=0,"",IF(AK11<AJ11*0.4,AH11,"")) | AP7: =IF(AK12=0,"",IF(AK12<AJ12*0.4,AH12,""))
A8: =ادخال1!$I$9 -> اللغة الإنجليزية | B8: =ادخال1!$I$7 -> 3 | C8: =40*B8*0.3 -> 36 | D8: =IFERROR(VLOOKUP(H17,اسماء,8,0),"") -> 28 | E8: =40*B8*0.3 -> 36 | F8: =IFERROR(VLOOKUP(H17,اسماء,21,0),"") -> 0 | H8: الثانية :- | I8: =IF(F13=0,"",IF(AND(F5>=E5*0.4,F6>=E6*0.4,F10>=E10*0.4,F11>=E11*0.4,F12>=E12*0.4,F7>=E7*0.4,F8>=E8*0.4,F9>=E9*0.4),LOOKUP(F13,'النتيجة النهائية'!$AF$6:$AG$10),"ضعيف ويحتاج الى اهتمام في المواد")) | L8: =ادخال1!$I$9 -> اللغة الإنجليزية | M8: =ادخال1!$I$7 -> 3 | N8: =40*M8*0.3 -> 36 | O8: =IFERROR(VLOOKUP(S17,اسماء,8,0),"") -> 28 | P8: =40*M8*0.3 -> 36 | Q8: =IFERROR(VLOOKUP(S17,اسماء,21,0),"") -> 0 | S8: الثانية :- | T8: =IF(Q13=0,"",IF(AND(Q5>=P5*0.4,Q6>=P6*0.4,Q10>=P10*0.4,Q11>=P11*0.4,Q12>=P12*0.4,Q7>=P7*0.4,Q8>=P8*0.4,Q9>=P9*0.4),LOOKUP(Q13,'النتيجة النهائية'!$AF$6:$AG$10),"ضعيف ويحتاج الى اهتمام في المواد")) | W8: =ادخال1!$I$9 -> اللغة الإنجليزية | X8: =ادخال1!$I$7 -> 3 | Y8: =40*X8*0.3 -> 36 | Z8: =IFERROR(VLOOKUP(AD17,اسماء,8,0),"") | AA8: =40*X8*0.3 -> 36 | AB8: =IFERROR(VLOOKUP(AD17,اسماء,21,0),"") | AD8: الثانية :- | AE8: =IF(AB13=0,"",IF(AND(AB5>=AA5*0.4,AB6>=AA6*0.4,AB10>=AA10*0.4,AB11>=AA11*0.4,AB12>=AA12*0.4,AB7>=AA7*0.4,AB8>=AA8*0.4,AB9>=AA9*0.4),LOOKUP(AB13,'النتيجة النهائية'!$AF$6:$AG$10),"ضعيف ويحتاج الى اهتمام في المواد")) | AH8: =ادخال1!$I$9 -> اللغة الإنجليزية | AI8: =ادخال1!$I$7 -> 3 | AJ8: =40*AI8*0.3 -> 36 | AK8: =IFERROR(VLOOKUP(AO17,اسماء,8,0),"") | AL8: =40*AI8*0.3 -> 36 | AM8: =IFERROR(VLOOKUP(AO17,اسماء,21,0),"") | AO8: الثانية :- | AP8: =IF(AM13=0,"",IF(AND(AM5>=AL5*0.4,AM6>=AL6*0.4,AM10>=AL10*0.4,AM11>=AL11*0.4,AM12>=AL12*0.4,AM7>=AL7*0.4,AM8>=AL8*0.4,AM9>=AL9*0.4),LOOKUP(AM13,'النتيجة النهائية'!$AF$6:$AG$10),"ضعيف ويحتاج الى اهتمام في المواد"))
A9: =ادخال1!$J$9 -> الحاسوب | B9: =ادخال1!$J$7 -> 1 | C9: =40*B9*0.3 -> 12 | D9: =IFERROR(VLOOKUP(H17,اسماء,9,0),"") -> 9 | E9: =40*B9*0.3 -> 12 | F9: =IFERROR(VLOOKUP(H17,اسماء,22,0),"") -> 0 | L9: =ادخال1!$J$9 -> الحاسوب | M9: =ادخال1!$J$7 -> 1 | N9: =40*M9*0.3 -> 12 | O9: =IFERROR(VLOOKUP(S17,اسماء,9,0),"") -> 9 | P9: =40*M9*0.3 -> 12 | Q9: =IFERROR(VLOOKUP(S17,اسماء,22,0),"") -> 0 | W9: =ادخال1!$J$9 -> الحاسوب | X9: =ادخال1!$J$7 -> 1 | Y9: =40*X9*0.3 -> 12 | Z9: =IFERROR(VLOOKUP(AD17,اسماء,9,0),"") | AA9: =40*X9*0.3 -> 12 | AB9: =IFERROR(VLOOKUP(AD17,اسماء,22,0),"") | AH9: =ادخال1!$J$9 -> الحاسوب | AI9: =ادخال1!$J$7 -> 1 | AJ9: =40*AI9*0.3 -> 12 | AK9: =IFERROR(VLOOKUP(AO17,اسماء,9,0),"") | AL9: =40*AI9*0.3 -> 12 | AM9: =IFERROR(VLOOKUP(AO17,اسماء,22,0),"")
A10: =ادخال1!$K$9 -> الرياضيات | B10: =ادخال1!$K$7 -> 5 | C10: =40*B10*0.3 -> 60 | D10: =IFERROR(VLOOKUP(H17,اسماء,10,0),"") -> 30 | E10: =40*B10*0.3 -> 60 | F10: =IFERROR(VLOOKUP(H17,اسماء,23,0),"") -> 0 | H10: =IF(F5=0,"",IF(F5<E5*0.4,A5,"")) | I10: =IF(F6=0,"",IF(F6<E6*0.4,A6,"")) | J10: =IF(F7=0,"",IF(F7<E7*0.4,A7,"")) | L10: =ادخال1!$K$9 -> الرياضيات | M10: =ادخال1!$K$7 -> 5 | N10: =40*M10*0.3 -> 60 | O10: =IFERROR(VLOOKUP(S17,اسماء,10,0),"") -> 30 | P10: =40*M10*0.3 -> 60 | Q10: =IFERROR(VLOOKUP(S17,اسماء,23,0),"") -> 0 | S10: =IF(Q5=0,"",IF(Q5<P5*0.4,L5,"")) | T10: =IF(Q6=0,"",IF(Q6<P6*0.4,L6,"")) | U10: =IF(Q7=0,"",IF(Q7<P7*0.4,L7,"")) | W10: =ادخال1!$K$9 -> الرياضيات | X10: =ادخال1!$K$7 -> 5 | Y10: =40*X10*0.3 -> 60 | Z10: =IFERROR(VLOOKUP(AD17,اسماء,10,0),"") | AA10: =40*X10*0.3 -> 60 | AB10: =IFERROR(VLOOKUP(AD17,اسماء,23,0),"") | AD10: =IF(AB5=0,"",IF(AB5<AA5*0.4,W5,"")) | AE10: =IF(AB6=0,"",IF(AB6<AA6*0.4,W6,"")) | AF10: =IF(AB7=0,"",IF(AB7<AA7*0.4,W7,"")) | AH10: =ادخال1!$K$9 -> الرياضيات | AI10: =ادخال1!$K$7 -> 5 | AJ10: =40*AI10*0.3 -> 60 | AK10: =IFERROR(VLOOKUP(AO17,اسماء,10,0),"") | AL10: =40*AI10*0.3 -> 60 | AM10: =IFERROR(VLOOKUP(AO17,اسماء,23,0),"") | AO10: =IF(AM5=0,"",IF(AM5<AL5*0.4,AH5,"")) | AP10: =IF(AM6=0,"",IF(AM6<AL6*0.4,AH6,"")) | AQ10: =IF(AM7=0,"",IF(AM7<AL7*0.4,AH7,""))
A11: =ادخال1!$L$9 -> العلوم | B11: =ادخال1!$L$7 -> 3 | C11: =40*B11*0.3 -> 36 | D11: =IFERROR(VLOOKUP(H17,اسماء,11,0),"") -> 35 | E11: =40*B11*0.3 -> 36 | F11: =IFERROR(VLOOKUP(H17,اسماء,24,0),"") -> 0 | H11: =IF(F8=0,"",IF(F8<E8*0.4,A8,"")) | I11: =IF(F9=0,"",IF(F9<E9*0.4,A9,"")) | J11: =IF(F10=0,"",IF(F10<E10*0.4,A10,"")) | L11: =ادخال1!$L$9 -> العلوم | M11: =ادخال1!$L$7 -> 3 | N11: =40*M11*0.3 -> 36 | O11: =IFERROR(VLOOKUP(S17,اسماء,11,0),"") -> 35 | P11: =40*M11*0.3 -> 36 | Q11: =IFERROR(VLOOKUP(S17,اسماء,24,0),"") -> 0 | S11: =IF(Q8=0,"",IF(Q8<P8*0.4,L8,"")) | T11: =IF(Q9=0,"",IF(Q9<P9*0.4,L9,"")) | U11: =IF(Q10=0,"",IF(Q10<P10*0.4,L10,"")) | W11: =ادخال1!$L$9 -> العلوم | X11: =ادخال1!$L$7 -> 3 | Y11: =40*X11*0.3 -> 36 | Z11: =IFERROR(VLOOKUP(AD17,اسماء,11,0),"") | AA11: =40*X11*0.3 -> 36 | AB11: =IFERROR(VLOOKUP(AD17,اسماء,24,0),"") | AD11: =IF(AB8=0,"",IF(AB8<AA8*0.4,W8,"")) | AE11: =IF(AB9=0,"",IF(AB9<AA9*0.4,W9,"")) | AF11: =IF(AB10=0,"",IF(AB10<AA10*0.4,W10,"")) | AH11: =ادخال1!$L$9 -> العلوم | AI11: =ادخال1!$L$7 -> 3 | AJ11: =40*AI11*0.3 -> 36 | AK11: =IFERROR(VLOOKUP(AO17,اسماء,11,0),"") | AL11: =40*AI11*0.3 -> 36 | AM11: =IFERROR(VLOOKUP(AO17,اسماء,24,0),"") | AO11: =IF(AM8=0,"",IF(AM8<AL8*0.4,AH8,"")) | AP11: =IF(AM9=0,"",IF(AM9<AL9*0.4,AH9,"")) | AQ11: =IF(AM10=0,"",IF(AM10<AL10*0.4,AH10,""))
A12: =ادخال1!$M$9 -> الاجتماعيات | B12: =ادخال1!$M$7 -> 2 | C12: =40*B12*0.3 -> 24 | D12: =IFERROR(VLOOKUP(H17,اسماء,12,0),"") -> 14 | E12: =40*B12*0.3 -> 24 | F12: =IFERROR(VLOOKUP(H17,اسماء,25,0),"") -> 0 | H12: =IF(F11=0,"",IF(F11<E11*0.4,A11,"")) | I12: =IF(F12=0,"",IF(F12<E12*0.4,A12,"")) | L12: =ادخال1!$M$9 -> الاجتماعيات | M12: =ادخال1!$M$7 -> 2 | N12: =40*M12*0.3 -> 24 | O12: =IFERROR(VLOOKUP(S17,اسماء,12,0),"") -> 14 | P12: =40*M12*0.3 -> 24 | Q12: =IFERROR(VLOOKUP(S17,اسماء,25,0),"") -> 0 | S12: =IF(Q11=0,"",IF(Q11<P11*0.4,L11,"")) | T12: =IF(Q12=0,"",IF(Q12<P12*0.4,L12,"")) | W12: =ادخال1!$M$9 -> الاجتماعيات | X12: =ادخال1!$M$7 -> 2 | Y12: =40*X12*0.3 -> 24 | Z12: =IFERROR(VLOOKUP(AD17,اسماء,12,0),"") | AA12: =40*X12*0.3 -> 24 | AB12: =IFERROR(VLOOKUP(AD17,اسماء,25,0),"") | AD12: =IF(AB11=0,"",IF(AB11<AA11*0.4,W11,"")) | AE12: =IF(AB12=0,"",IF(AB12<AA12*0.4,W12,"")) | AH12: =ادخال1!$M$9 -> الاجتماعيات | AI12: =ادخال1!$M$7 -> 2 | AJ12: =40*AI12*0.3 -> 24 | AK12: =IFERROR(VLOOKUP(AO17,اسماء,12,0),"") | AL12: =40*AI12*0.3 -> 24 | AM12: =IFERROR(VLOOKUP(AO17,اسماء,25,0),"") | AO12: =IF(AM11=0,"",IF(AM11<AL11*0.4,AH11,"")) | AP12: =IF(AM12=0,"",IF(AM12<AL12*0.4,AH12,""))
A13: المجموع العـام | C13: =SUM(C5:C12) -> 276 | D13: =SUM(D5:D12) -> 179 | E13: =SUM(E5:E12) -> 276 | F13: =SUM(F5:F12) -> 0 | H13: مدير المدرسة/ | I13: =ادخال1!$BP$5 -> د.عبدالرحمن خليفة العريبي | L13: المجموع العـام | N13: =SUM(N5:N12) -> 276 | O13: =SUM(O5:O12) -> 179 | P13: =SUM(P5:P12) -> 276 | Q13: =SUM(Q5:Q12) -> 0 | S13: مدير المدرسة/ | T13: =ادخال1!$BP$5 -> د.عبدالرحمن خليفة العريبي | W13: المجموع العـام | Y13: =SUM(Y5:Y12) -> 276 | Z13: =SUM(Z5:Z12) -> 0 | AA13: =SUM(AA5:AA12) -> 276 | AB13: =SUM(AB5:AB12) -> 0 | AD13: مدير المدرسة/ | AE13: =ادخال1!$BP$5 -> د.عبدالرحمن خليفة العريبي | AH13: المجموع العـام | AJ13: =SUM(AJ5:AJ12) -> 276 | AK13: =SUM(AK5:AK12) -> 0 | AL13: =SUM(AL5:AL12) -> 276 | AM13: =SUM(AM5:AM12) -> 0 | AO13: مدير المدرسة/ | AP13: =ادخال1!$BP$5 -> د.عبدالرحمن خليفة العريبي
A14: =ادخال1!$O$8 -> التربية الفنية | B14: =ادخال1!$O$7 -> 1 | C14: =IFERROR(VLOOKUP(H17,اسماء,14,0),"") -> جيد جداً | E14: =IFERROR(VLOOKUP(H17,اسماء,27,0),"") -> 0 | H14: التاريخ | I14: =TODAY() -> 46035 | L14: =ادخال1!$O$8 -> التربية الفنية | M14: =ادخال1!$O$7 -> 1 | N14: =IFERROR(VLOOKUP(S17,اسماء,14,0),"") -> جيد جداً | P14: =IFERROR(VLOOKUP(S17,اسماء,27,0),"") -> 0 | S14: التاريخ | T14: =TODAY() -> 46035 | W14: =ادخال1!$O$8 -> التربية الفنية | X14: =ادخال1!$O$7 -> 1 | Y14: =IFERROR(VLOOKUP(AD17,اسماء,14,0),"") | AA14: =IFERROR(VLOOKUP(AD17,اسماء,27,0),"") | AD14: التاريخ | AE14: =TODAY() -> 46035 | AH14: =ادخال1!$O$8 -> التربية الفنية | AI14: =ادخال1!$O$7 -> 1 | AJ14: =IFERROR(VLOOKUP(AO17,اسماء,14,0),"") | AL14: =IFERROR(VLOOKUP(AO17,اسماء,27,0),"") | AO14: التاريخ | AP14: =TODAY() -> 46035
A15: =ادخال1!$P$8 -> التربية البدنية | B15: =ادخال1!$P$7 -> 2 | C15: =IFERROR(VLOOKUP(H17,اسماء,15,0),"") -> جيد جداً | E15: =IFERROR(VLOOKUP(H17,اسماء,28,0),"") -> 0 | L15: =ادخال1!$P$8 -> التربية البدنية | M15: =ادخال1!$P$7 -> 2 | N15: =IFERROR(VLOOKUP(S17,اسماء,15,0),"") -> جيد جداً | P15: =IFERROR(VLOOKUP(S17,اسماء,28,0),"") -> 0 | W15: =ادخال1!$P$8 -> التربية البدنية | X15: =ادخال1!$P$7 -> 2 | Y15: =IFERROR(VLOOKUP(AD17,اسماء,15,0),"") | AA15: =IFERROR(VLOOKUP(AD17,اسماء,28,0),"") | AH15: =ادخال1!$P$8 -> التربية البدنية | AI15: =ادخال1!$P$7 -> 2 | AJ15: =IFERROR(VLOOKUP(AO17,اسماء,15,0),"") | AL15: =IFERROR(VLOOKUP(AO17,اسماء,28,0),"")
A16: =ادخال1!$Q$8 -> التربية الموسيقية | B16: =ادخال1!$Q$7 -> 1 | C16: =IFERROR(VLOOKUP(H18,اسماء,16,0),"") | E16: =IFERROR(VLOOKUP(H18,اسماء,29,0),"") | L16: =ادخال1!$Q$8 -> التربية الموسيقية | M16: =ادخال1!$Q$7 -> 1 | N16: =IFERROR(VLOOKUP(S18,اسماء,16,0),"") | P16: =IFERROR(VLOOKUP(S18,اسماء,29,0),"") | W16: =ادخال1!$Q$8 -> التربية الموسيقية | X16: =ادخال1!$Q$7 -> 1 | Y16: =IFERROR(VLOOKUP(AD18,اسماء,16,0),"") | AA16: =IFERROR(VLOOKUP(AD18,اسماء,29,0),"") | AH16: =ادخال1!$Q$8 -> التربية الموسيقية | AI16: =ادخال1!$Q$7 -> 1 | AJ16: =IFERROR(VLOOKUP(AO18,اسماء,16,0),"") | AL16: =IFERROR(VLOOKUP(AO18,اسماء,29,0),"")
A17: الرقم الوطني | B17: =IFERROR(VLOOKUP(H17,اسماء,71,0),"") -> 120160454465 | C17: =IFERROR(VLOOKUP(G22,اسماء,8,0),"") | D17: =IFERROR(VLOOKUP(H22,اسماء,8,0),"") | E17: =IFERROR(VLOOKUP(I22,اسماء,8,0),"") | H17: =INDEX(عمود2,MATCH(J1,عمود1)) -> مصطفى طارق فتحي الختال | L17: الرقم الوطني | M17: =IFERROR(VLOOKUP(S17,اسماء,71,0),"") -> 120160454465 | N17: =IFERROR(VLOOKUP(R22,اسماء,8,0),"") | O17: =IFERROR(VLOOKUP(S22,اسماء,8,0),"") | P17: =IFERROR(VLOOKUP(T22,اسماء,8,0),"") | S17: =INDEX(عمود2,MATCH(U1,عمود1)) -> مصطفى طارق فتحي الختال | W17: الرقم الوطني | X17: =IFERROR(VLOOKUP(AD17,اسماء,71,0),"") | Y17: =IFERROR(VLOOKUP(AC22,اسماء,8,0),"") | Z17: =IFERROR(VLOOKUP(AD22,اسماء,8,0),"") | AA17: =IFERROR(VLOOKUP(AE22,اسماء,8,0),"") | AD17: =INDEX(عمود2,MATCH(AF1,عمود1)) -> 0 | AH17: الرقم الوطني | AI17: =IFERROR(VLOOKUP(AO17,اسماء,71,0),"") | AJ17: =IFERROR(VLOOKUP(AN22,اسماء,8,0),"") | AK17: =IFERROR(VLOOKUP(AO22,اسماء,8,0),"") | AL17: =IFERROR(VLOOKUP(AP22,اسماء,8,0),"") | AO17: =INDEX(عمود2,MATCH(AQ1,عمود1)) -> 0
A18: الســــــلوك | C18: =IFERROR(VLOOKUP(H17,اسماء,31,0),"") -> 0 | E18: =IFERROR(VLOOKUP(H17,اسماء,32,0),"") -> 0 | H18: كل كشط أو تغيير في هذه البطاقة يلغيها. | L18: الســــــلوك | N18: =IFERROR(VLOOKUP(S17,اسماء,31,0),"") -> 0 | P18: =IFERROR(VLOOKUP(S17,اسماء,32,0),"") -> 0 | S18: كل كشط أو تغيير في هذه البطاقة يلغيها. | W18: الســــــلوك | Y18: =IFERROR(VLOOKUP(AD17,اسماء,31,0),"") | AA18: =IFERROR(VLOOKUP(AD17,اسماء,32,0),"") | AD18: كل كشط أو تغيير في هذه البطاقة يلغيها. | AH18: الســــــلوك | AJ18: =IFERROR(VLOOKUP(AO17,اسماء,31,0),"") | AL18: =IFERROR(VLOOKUP(AO17,اسماء,32,0),"") | AO18: كل كشط أو تغيير في هذه البطاقة يلغيها.
A19: غياب مشروع | C19: =IFERROR(VLOOKUP(H17,اسماء,34,0),"") -> 0 | E19: =IFERROR(VLOOKUP(H17,اسماء,36,0),"") -> 0 | L19: غياب مشروع | N19: =IFERROR(VLOOKUP(S17,اسماء,34,0),"") -> 0 | P19: =IFERROR(VLOOKUP(S17,اسماء,36,0),"") -> 0 | W19: غياب مشروع | Y19: =IFERROR(VLOOKUP(AD17,اسماء,34,0),"") | AA19: =IFERROR(VLOOKUP(AD17,اسماء,36,0),"") | AH19: غياب مشروع | AJ19: =IFERROR(VLOOKUP(AO17,اسماء,34,0),"") | AL19: =IFERROR(VLOOKUP(AO17,اسماء,36,0),"")
A20: غياب غير مشروع | C20: =IFERROR(VLOOKUP(H17,اسماء,35,0),"") -> 0 | E20: =IFERROR(VLOOKUP(H17,اسماء,37,0),"") -> 0 | L20: غياب غير مشروع | N20: =IFERROR(VLOOKUP(S17,اسماء,35,0),"") -> 0 | P20: =IFERROR(VLOOKUP(S17,اسماء,37,0),"") -> 0 | W20: غياب غير مشروع | Y20: =IFERROR(VLOOKUP(AD17,اسماء,35,0),"") | AA20: =IFERROR(VLOOKUP(AD17,اسماء,37,0),"") | AH20: غياب غير مشروع | AJ20: =IFERROR(VLOOKUP(AO17,اسماء,35,0),"") | AL20: =IFERROR(VLOOKUP(AO17,اسماء,37,0),"")
A22: التوقيعــــات | B22: رائــد الصف | D22: مديـر المدرسة | H22: ولي الامر | L22: التوقيعــــات | M22: رائــد الصف | O22: مديـر المدرسة | S22: ولي الامر | W22: التوقيعــــات | X22: رائــد الصف | Z22: مديـر المدرسة | AD22: ولي الامر | AH22: التوقيعــــات | AI22: رائــد الصف | AK22: مديـر المدرسة | AO22: ولي الامر
A23: الفترة الاولى | L23: الفترة الاولى | W23: الفترة الاولى | AH23: الفترة الاولى
A24: الفترة الثانية | L24: الفترة الثانية | W24: الفترة الثانية | AH24: الفترة الثانية
A26: بطاقة تقدير الدرجات للصــــف | D26: =ادخال1!$N$4 -> الرابع | F26: من التعليم الأساسي | J26: =J1+1 -> 16 | L26: بطاقة تقدير الدرجات للصــــف | O26: =ادخال1!$N$4 -> الرابع | Q26: من التعليم الأساسي | U26: =J26+5 -> 21 | W26: بطاقة تقدير الدرجات للصــــف | Z26: =ادخال1!$N$4 -> الرابع | AB26: من التعليم الأساسي | AF26: =U26+5 -> 26 | AH26: بطاقة تقدير الدرجات للصــــف | AK26: =ادخال1!$N$4 -> الرابع | AM26: من التعليم الأساسي | AQ26: =AF26+5 -> 31
A27: المدرسة/ | B27: =ادخال1!$B$5 -> سهول العلم للتعليم الخاص | F27: الاسم | G27: =H42 -> معاوية عز الدين محمد أحفيظان | L27: المدرسة/ | M27: =ادخال1!$B$5 -> سهول العلم للتعليم الخاص | Q27: الاسم | R27: =S42 -> 0 | W27: المدرسة/ | X27: =ادخال1!$B$5 -> سهول العلم للتعليم الخاص | AB27: الاسم | AC27: =AD42 -> 0 | AH27: المدرسة/ | AI27: =ادخال1!$B$5 -> سهول العلم للتعليم الخاص | AM27: الاسم | AN27: =AO42 -> 0
A28: الفترات | B28: عدد الحصص | C28: الفترة الأولي 30 % | E28: الفترة الثانية 30 % | H28: ملاحظــات عن نتيجة التلميذ خلال كل فترة : | L28: الفترات | M28: عدد الحصص | N28: الفترة الأولي 30 % | P28: الفترة الثانية 30 % | S28: ملاحظــات عن نتيجة التلميذ خلال كل فترة : | W28: الفترات | X28: عدد الحصص | Y28: الفترة الأولي 30 % | AA28: الفترة الثانية 30 % | AD28: ملاحظــات عن نتيجة التلميذ خلال كل فترة : | AH28: الفترات | AI28: عدد الحصص | AJ28: الفترة الأولي 30 % | AL28: الفترة الثانية 30 % | AO28: ملاحظــات عن نتيجة التلميذ خلال كل فترة :
A29: المواد الدراسية | C29: الدرجة الكبرى | D29: درجة التلميذ | E29: الدرجة الكبرى | F29: درجة التلميذ | H29: الأولي : | I29: =IF(D38=0,"",IF(AND(D30>=C30*0.4,D31>=C31*0.4,D35>=C35*0.4,D36>=C36*0.4,D37>=C37*0.4,D32>=C32*0.4,D33>=C33*0.4,D34>=C34*0.4),LOOKUP(D38,'النتيجة النهائية'!$AF$6:$AG$10),"ضعيف ويحتاج الى اهتمام في المواد")) -> ممتاز | L29: المواد الدراسية | N29: الدرجة الكبرى | O29: درجة التلميذ | P29: الدرجة الكبرى | Q29: درجة التلميذ | S29: الأولي : | T29: =IF(O38=0,"",IF(AND(O30>=N30*0.4,O31>=N31*0.4,O35>=N35*0.4,O36>=N36*0.4,O37>=N37*0.4,O32>=N32*0.4,O33>=N33*0.4,O34>=N34*0.4),LOOKUP(O38,'النتيجة النهائية'!$AF$6:$AG$10),"ضعيف ويحتاج الى اهتمام في المواد")) | W29: المواد الدراسية | Y29: الدرجة الكبرى | Z29: درجة التلميذ | AA29: الدرجة الكبرى | AB29: درجة التلميذ | AD29: الأولي : | AE29: =IF(Z38=0,"",IF(AND(Z30>=Y30*0.4,Z31>=Y31*0.4,Z35>=Y35*0.4,Z36>=Y36*0.4,Z37>=Y37*0.4,Z32>=Y32*0.4,Z33>=Y33*0.4,Z34>=Y34*0.4),LOOKUP(Z38,'النتيجة النهائية'!$AF$6:$AG$10),"ضعيف ويحتاج الى اهتمام في المواد")) | AH29: المواد الدراسية | AJ29: الدرجة الكبرى | AK29: درجة التلميذ | AL29: الدرجة الكبرى | AM29: درجة التلميذ | AO29: الأولي : | AP29: =IF(AK38=0,"",IF(AND(AK30>=AJ30*0.4,AK31>=AJ31*0.4,AK35>=AJ35*0.4,AK36>=AJ36*0.4,AK37>=AJ37*0.4,AK32>=AJ32*0.4,AK33>=AJ33*0.4,AK34>=AJ34*0.4),LOOKUP(AK38,'النتيجة النهائية'!$AF$6:$AG$10),"ضعيف ويحتاج الى اهتمام في المواد"))
A30: =ادخال1!$F$9 -> التربية الإسلامية | B30: =ادخال1!$F$7 -> 3 | C30: =40*B30*0.3 -> 36 | D30: =IFERROR(VLOOKUP(H42,اسماء,5,0),"") -> 36 | E30: =40*B30*0.3 -> 36 | F30: =IFERROR(VLOOKUP(H42,اسماء,18,0),"") -> 0 | H30: =IF(D30=0,"",IF(D30<C30*0.4,A30,"")) | I30: =IF(D31=0,"",IF(D31<C31*0.4,A31,"")) | J30: =IF(D32=0,"",IF(D32<C32*0.4,A32,"")) | L30: =ادخال1!$F$9 -> التربية الإسلامية | M30: =ادخال1!$F$7 -> 3 | N30: =40*M30*0.3 -> 36 | O30: =IFERROR(VLOOKUP(S42,اسماء,5,0),"") | P30: =40*M30*0.3 -> 36 | Q30: =IFERROR(VLOOKUP(S42,اسماء,18,0),"") | S30: =IF(O30=0,"",IF(O30<N30*0.4,L30,"")) | T30: =IF(O31=0,"",IF(O31<N31*0.4,L31,"")) | U30: =IF(O32=0,"",IF(O32<N32*0.4,L32,"")) | W30: =ادخال1!$F$9 -> التربية الإسلامية | X30: =ادخال1!$F$7 -> 3 | Y30: =40*X30*0.3 -> 36 | Z30: =IFERROR(VLOOKUP(AD42,اسماء,5,0),"") | AA30: =40*X30*0.3 -> 36 | AB30: =IFERROR(VLOOKUP(AD42,اسماء,18,0),"") | AD30: =IF(Z30=0,"",IF(Z30<Y30*0.4,W30,"")) | AE30: =IF(Z31=0,"",IF(Z31<Y31*0.4,W31,"")) | AF30: =IF(Z32=0,"",IF(Z32<Y32*0.4,W32,"")) | AH30: =ادخال1!$F$9 -> التربية الإسلامية | AI30: =ادخال1!$F$7 -> 3 | AJ30: =40*AI30*0.3 -> 36 | AK30: =IFERROR(VLOOKUP(AO42,اسماء,5,0),"") | AL30: =40*AI30*0.3 -> 36 | AM30: =IFERROR(VLOOKUP(AO42,اسماء,18,0),"") | AO30: =IF(AK30=0,"",IF(AK30<AJ30*0.4,AH30,"")) | AP30: =IF(AK31=0,"",IF(AK31<AJ31*0.4,AH31,"")) | AQ30: =IF(AK32=0,"",IF(AK32<AJ32*0.4,AH32,""))
A31: =ادخال1!$G$9 -> اللغة العربية | B31: =ادخال1!$G$7 -> 4 | C31: =40*B31*0.3 -> 48 | D31: =IFERROR(VLOOKUP(H42,اسماء,6,0),"") -> 48 | E31: =40*B31*0.3 -> 48 | F31: =IFERROR(VLOOKUP(H42,اسماء,19,0),"") -> 0 | H31: =IF(D35=0,"",IF(D35<C35*0.4,A33,"")) | I31: =IF(D37=0,"",IF(D37<C37*0.4,A34,"")) | J31: =IF(D34=0,"",IF(D34<C34*0.4,A35,"")) | L31: =ادخال1!$G$9 -> اللغة العربية | M31: =ادخال1!$G$7 -> 4 | N31: =40*M31*0.3 -> 48 | O31: =IFERROR(VLOOKUP(S42,اسماء,6,0),"") | P31: =40*M31*0.3 -> 48 | Q31: =IFERROR(VLOOKUP(S42,اسماء,19,0),"") | S31: =IF(O35=0,"",IF(O35<N35*0.4,L33,"")) | T31: =IF(O37=0,"",IF(O37<N37*0.4,L34,"")) | U31: =IF(O34=0,"",IF(O34<N34*0.4,L35,"")) | W31: =ادخال1!$G$9 -> اللغة العربية | X31: =ادخال1!$G$7 -> 4 | Y31: =40*X31*0.3 -> 48 | Z31: =IFERROR(VLOOKUP(AD42,اسماء,6,0),"") | AA31: =40*X31*0.3 -> 48 | AB31: =IFERROR(VLOOKUP(AD42,اسماء,19,0),"") | AD31: =IF(Z35=0,"",IF(Z35<Y35*0.4,W33,"")) | AE31: =IF(Z37=0,"",IF(Z37<Y37*0.4,W34,"")) | AF31: =IF(Z34=0,"",IF(Z34<Y34*0.4,W35,"")) | AH31: =ادخال1!$G$9 -> اللغة العربية | AI31: =ادخال1!$G$7 -> 4 | AJ31: =40*AI31*0.3 -> 48 | AK31: =IFERROR(VLOOKUP(AO42,اسماء,6,0),"") | AL31: =40*AI31*0.3 -> 48 | AM31: =IFERROR(VLOOKUP(AO42,اسماء,19,0),"") | AO31: =IF(AK35=0,"",IF(AK35<AJ35*0.4,AH33,"")) | AP31: =IF(AK37=0,"",IF(AK37<AJ37*0.4,AH34,"")) | AQ31: =IF(AK34=0,"",IF(AK34<AJ34*0.4,AH35,""))
A32: =ادخال1!$H$9 -> الكتابة | B32: =ادخال1!$H$7 -> 2 | C32: =40*B32*0.3 -> 24 | D32: =IFERROR(VLOOKUP(H42,اسماء,7,0),"") -> 23 | E32: =40*B32*0.3 -> 24 | F32: =IFERROR(VLOOKUP(H42,اسماء,20,0),"") -> 0 | H32: =IF(D36=0,"",IF(D36<C36*0.4,A36,"")) | I32: =IF(D37=0,"",IF(D37<C37*0.4,A37,"")) | L32: =ادخال1!$H$9 -> الكتابة | M32: =ادخال1!$H$7 -> 2 | N32: =40*M32*0.3 -> 24 | O32: =IFERROR(VLOOKUP(S42,اسماء,7,0),"") | P32: =40*M32*0.3 -> 24 | Q32: =IFERROR(VLOOKUP(S42,اسماء,20,0),"") | S32: =IF(O36=0,"",IF(O36<N36*0.4,L36,"")) | T32: =IF(O37=0,"",IF(O37<N37*0.4,L37,"")) | W32: =ادخال1!$H$9 -> الكتابة | X32: =ادخال1!$H$7 -> 2 | Y32: =40*X32*0.3 -> 24 | Z32: =IFERROR(VLOOKUP(AD42,اسماء,7,0),"") | AA32: =40*X32*0.3 -> 24 | AB32: =IFERROR(VLOOKUP(AD42,اسماء,20,0),"") | AD32: =IF(Z36=0,"",IF(Z36<Y36*0.4,W36,"")) | AE32: =IF(Z37=0,"",IF(Z37<Y37*0.4,W37,"")) | AH32: =ادخال1!$H$9 -> الكتابة | AI32: =ادخال1!$H$7 -> 2 | AJ32: =40*AI32*0.3 -> 24 | AK32: =IFERROR(VLOOKUP(AO42,اسماء,7,0),"") | AL32: =40*AI32*0.3 -> 24 | AM32: =IFERROR(VLOOKUP(AO42,اسماء,20,0),"") | AO32: =IF(AK36=0,"",IF(AK36<AJ36*0.4,AH36,"")) | AP32: =IF(AK37=0,"",IF(AK37<AJ37*0.4,AH37,""))
A33: =ادخال1!$I$9 -> اللغة الإنجليزية | B33: =ادخال1!$I$7 -> 3 | C33: =40*B33*0.3 -> 36 | D33: =IFERROR(VLOOKUP(H42,اسماء,8,0),"") -> 32 | E33: =40*B33*0.3 -> 36 | F33: =IFERROR(VLOOKUP(H42,اسماء,21,0),"") -> 0 | H33: الثانية :- | I33: =IF(F38=0,"",IF(AND(F30>=E30*0.4,F31>=E31*0.4,F35>=E35*0.4,F36>=E36*0.4,F37>=E37*0.4,F32>=E32*0.4,F33>=E33*0.4,F34>=E34*0.4),LOOKUP(F38,'النتيجة النهائية'!$AF$6:$AG$10),"ضعيف ويحتاج الى اهتمام في المواد")) | L33: =ادخال1!$I$9 -> اللغة الإنجليزية | M33: =ادخال1!$I$7 -> 3 | N33: =40*M33*0.3 -> 36 | O33: =IFERROR(VLOOKUP(S42,اسماء,8,0),"") | P33: =40*M33*0.3 -> 36 | Q33: =IFERROR(VLOOKUP(S42,اسماء,21,0),"") | S33: الثانية :- | T33: =IF(Q38=0,"",IF(AND(Q30>=P30*0.4,Q31>=P31*0.4,Q35>=P35*0.4,Q36>=P36*0.4,Q37>=P37*0.4,Q32>=P32*0.4,Q33>=P33*0.4,Q34>=P34*0.4),LOOKUP(Q38,'النتيجة النهائية'!$AF$6:$AG$10),"ضعيف ويحتاج الى اهتمام في المواد")) | W33: =ادخال1!$I$9 -> اللغة الإنجليزية | X33: =ادخال1!$I$7 -> 3 | Y33: =40*X33*0.3 -> 36 | Z33: =IFERROR(VLOOKUP(AD42,اسماء,8,0),"") | AA33: =40*X33*0.3 -> 36 | AB33: =IFERROR(VLOOKUP(AD42,اسماء,21,0),"") | AD33: الثانية :- | AE33: =IF(AB38=0,"",IF(AND(AB30>=AA30*0.4,AB31>=AA31*0.4,AB35>=AA35*0.4,AB36>=AA36*0.4,AB37>=AA37*0.4,AB32>=AA32*0.4,AB33>=AA33*0.4,AB34>=AA34*0.4),LOOKUP(AB38,'النتيجة النهائية'!$AF$6:$AG$10),"ضعيف ويحتاج الى اهتمام في المواد")) | AH33: =ادخال1!$I$9 -> اللغة الإنجليزية | AI33: =ادخال1!$I$7 -> 3 | AJ33: =40*AI33*0.3 -> 36 | AK33: =IFERROR(VLOOKUP(AO42,اسماء,8,0),"") | AL33: =40*AI33*0.3 -> 36 | AM33: =IFERROR(VLOOKUP(AO42,اسماء,21,0),"") | AO33: الثانية :- | AP33: =IF(AM38=0,"",IF(AND(AM30>=AL30*0.4,AM31>=AL31*0.4,AM35>=AL35*0.4,AM36>=AL36*0.4,AM37>=AL37*0.4,AM32>=AL32*0.4,AM33>=AL33*0.4,AM34>=AL34*0.4),LOOKUP(AM38,'النتيجة النهائية'!$AF$6:$AG$10),"ضعيف ويحتاج الى اهتمام في المواد"))
A34: =ادخال1!$J$9 -> الحاسوب | B34: =ادخال1!$J$7 -> 1 | C34: =40*B34*0.3 -> 12 | D34: =IFERROR(VLOOKUP(H42,اسماء,9,0),"") -> 12 | E34: =40*B34*0.3 -> 12 | F34: =IFERROR(VLOOKUP(H42,اسماء,22,0),"") -> 0 | L34: =ادخال1!$J$9 -> الحاسوب | M34: =ادخال1!$J$7 -> 1 | N34: =40*M34*0.3 -> 12 | O34: =IFERROR(VLOOKUP(S42,اسماء,9,0),"") | P34: =40*M34*0.3 -> 12 | Q34: =IFERROR(VLOOKUP(S42,اسماء,22,0),"") | W34: =ادخال1!$J$9 -> الحاسوب | X34: =ادخال1!$J$7 -> 1 | Y34: =40*X34*0.3 -> 12 | Z34: =IFERROR(VLOOKUP(AD42,اسماء,9,0),"") | AA34: =40*X34*0.3 -> 12 | AB34: =IFERROR(VLOOKUP(AD42,اسماء,22,0),"") | AH34: =ادخال1!$J$9 -> الحاسوب | AI34: =ادخال1!$J$7 -> 1 | AJ34: =40*AI34*0.3 -> 12 | AK34: =IFERROR(VLOOKUP(AO42,اسماء,9,0),"") | AL34: =40*AI34*0.3 -> 12 | AM34: =IFERROR(VLOOKUP(AO42,اسماء,22,0),"")
A35: =ادخال1!$K$9 -> الرياضيات | B35: =ادخال1!$K$7 -> 5 | C35: =40*B35*0.3 -> 60 | D35: =IFERROR(VLOOKUP(H42,اسماء,10,0),"") -> 52 | E35: =40*B35*0.3 -> 60 | F35: =IFERROR(VLOOKUP(H42,اسماء,23,0),"") -> 0 | H35: =IF(F30=0,"",IF(F30<E30*0.4,A30,"")) | I35: =IF(F31=0,"",IF(F31<E31*0.4,A31,"")) | J35: =IF(F32=0,"",IF(F32<E32*0.4,A32,"")) | L35: =ادخال1!$K$9 -> الرياضيات | M35: =ادخال1!$K$7 -> 5 | N35: =40*M35*0.3 -> 60 | O35: =IFERROR(VLOOKUP(S42,اسماء,10,0),"") | P35: =40*M35*0.3 -> 60 | Q35: =IFERROR(VLOOKUP(S42,اسماء,23,0),"") | S35: =IF(Q30=0,"",IF(Q30<P30*0.4,L30,"")) | T35: =IF(Q31=0,"",IF(Q31<P31*0.4,L31,"")) | U35: =IF(Q32=0,"",IF(Q32<P32*0.4,L32,"")) | W35: =ادخال1!$K$9 -> الرياضيات | X35: =ادخال1!$K$7 -> 5 | Y35: =40*X35*0.3 -> 60 | Z35: =IFERROR(VLOOKUP(AD42,اسماء,10,0),"") | AA35: =40*X35*0.3 -> 60 | AB35: =IFERROR(VLOOKUP(AD42,اسماء,23,0),"") | AD35: =IF(AB30=0,"",IF(AB30<AA30*0.4,W30,"")) | AE35: =IF(AB31=0,"",IF(AB31<AA31*0.4,W31,"")) | AF35: =IF(AB32=0,"",IF(AB32<AA32*0.4,W32,"")) | AH35: =ادخال1!$K$9 -> الرياضيات | AI35: =ادخال1!$K$7 -> 5 | AJ35: =40*AI35*0.3 -> 60 | AK35: =IFERROR(VLOOKUP(AO42,اسماء,10,0),"") | AL35: =40*AI35*0.3 -> 60 | AM35: =IFERROR(VLOOKUP(AO42,اسماء,23,0),"") | AO35: =IF(AM30=0,"",IF(AM30<AL30*0.4,AH30,"")) | AP35: =IF(AM31=0,"",IF(AM31<AL31*0.4,AH31,"")) | AQ35: =IF(AM32=0,"",IF(AM32<AL32*0.4,AH32,""))
A36: =ادخال1!$L$9 -> العلوم | B36: =ادخال1!$L$7 -> 3 | C36: =40*B36*0.3 -> 36 | D36: =IFERROR(VLOOKUP(H42,اسماء,11,0),"") -> 36 | E36: =40*B36*0.3 -> 36 | F36: =IFERROR(VLOOKUP(H42,اسماء,24,0),"") -> 0 | H36: =IF(F33=0,"",IF(F33<E33*0.4,A33,"")) | I36: =IF(F34=0,"",IF(F34<E34*0.4,A34,"")) | J36: =IF(F35=0,"",IF(F35<E35*0.4,A35,"")) | L36: =ادخال1!$L$9 -> العلوم | M36: =ادخال1!$L$7 -> 3 | N36: =40*M36*0.3 -> 36 | O36: =IFERROR(VLOOKUP(S42,اسماء,11,0),"") | P36: =40*M36*0.3 -> 36 | Q36: =IFERROR(VLOOKUP(S42,اسماء,24,0),"") | S36: =IF(Q33=0,"",IF(Q33<P33*0.4,L33,"")) | T36: =IF(Q34=0,"",IF(Q34<P34*0.4,L34,"")) | U36: =IF(Q35=0,"",IF(Q35<P35*0.4,L35,"")) | W36: =ادخال1!$L$9 -> العلوم | X36: =ادخال1!$L$7 -> 3 | Y36: =40*X36*0.3 -> 36 | Z36: =IFERROR(VLOOKUP(AD42,اسماء,11,0),"") | AA36: =40*X36*0.3 -> 36 | AB36: =IFERROR(VLOOKUP(AD42,اسماء,24,0),"") | AD36: =IF(AB33=0,"",IF(AB33<AA33*0.4,W33,"")) | AE36: =IF(AB34=0,"",IF(AB34<AA34*0.4,W34,"")) | AF36: =IF(AB35=0,"",IF(AB35<AA35*0.4,W35,"")) | AH36: =ادخال1!$L$9 -> العلوم | AI36: =ادخال1!$L$7 -> 3 | AJ36: =40*AI36*0.3 -> 36 | AK36: =IFERROR(VLOOKUP(AO42,اسماء,11,0),"") | AL36: =40*AI36*0.3 -> 36 | AM36: =IFERROR(VLOOKUP(AO42,اسماء,24,0),"") | AO36: =IF(AM33=0,"",IF(AM33<AL33*0.4,AH33,"")) | AP36: =IF(AM34=0,"",IF(AM34<AL34*0.4,AH34,"")) | AQ36: =IF(AM35=0,"",IF(AM35<AL35*0.4,AH35,""))
A37: =ادخال1!$M$9 -> الاجتماعيات | B37: =ادخال1!$M$7 -> 2 | C37: =40*B37*0.3 -> 24 | D37: =IFERROR(VLOOKUP(H42,اسماء,12,0),"") -> 24 | E37: =40*B37*0.3 -> 24 | F37: =IFERROR(VLOOKUP(H42,اسماء,25,0),"") -> 0 | H37: =IF(F36=0,"",IF(F36<E36*0.4,A36,"")) | I37: =IF(F37=0,"",IF(F37<E37*0.4,A37,"")) | L37: =ادخال1!$M$9 -> الاجتماعيات | M37: =ادخال1!$M$7 -> 2 | N37: =40*M37*0.3 -> 24 | O37: =IFERROR(VLOOKUP(S42,اسماء,12,0),"") | P37: =40*M37*0.3 -> 24 | Q37: =IFERROR(VLOOKUP(S42,اسماء,25,0),"") | S37: =IF(Q36=0,"",IF(Q36<P36*0.4,L36,"")) | T37: =IF(Q37=0,"",IF(Q37<P37*0.4,L37,"")) | W37: =ادخال1!$M$9 -> الاجتماعيات | X37: =ادخال1!$M$7 -> 2 | Y37: =40*X37*0.3 -> 24 | Z37: =IFERROR(VLOOKUP(AD42,اسماء,12,0),"") | AA37: =40*X37*0.3 -> 24 | AB37: =IFERROR(VLOOKUP(AD42,اسماء,25,0),"") | AD37: =IF(AB36=0,"",IF(AB36<AA36*0.4,W36,"")) | AE37: =IF(AB37=0,"",IF(AB37<AA37*0.4,W37,"")) | AH37: =ادخال1!$M$9 -> الاجتماعيات | AI37: =ادخال1!$M$7 -> 2 | AJ37: =40*AI37*0.3 -> 24 | AK37: =IFERROR(VLOOKUP(AO42,اسماء,12,0),"") | AL37: =40*AI37*0.3 -> 24 | AM37: =IFERROR(VLOOKUP(AO42,اسماء,25,0),"") | AO37: =IF(AM36=0,"",IF(AM36<AL36*0.4,AH36,"")) | AP37: =IF(AM37=0,"",IF(AM37<AL37*0.4,AH37,""))
A38: المجموع العـام | C38: =SUM(C30:C37) -> 276 | D38: =SUM(D30:D37) -> 263 | E38: =SUM(E30:E37) -> 276 | F38: =SUM(F30:F37) -> 0 | H38: مدير المدرسة/ | I38: =ادخال1!$BP$5 -> د.عبدالرحمن خليفة العريبي | L38: المجموع العـام | N38: =SUM(N30:N37) -> 276 | O38: =SUM(O30:O37) -> 0 | P38: =SUM(P30:P37) -> 276 | Q38: =SUM(Q30:Q37) -> 0 | S38: مدير المدرسة/ | T38: =ادخال1!$BP$5 -> د.عبدالرحمن خليفة العريبي | W38: المجموع العـام | Y38: =SUM(Y30:Y37) -> 276 | Z38: =SUM(Z30:Z37) -> 0 | AA38: =SUM(AA30:AA37) -> 276 | AB38: =SUM(AB30:AB37) -> 0 | AD38: مدير المدرسة/ | AE38: =ادخال1!$BP$5 -> د.عبدالرحمن خليفة العريبي | AH38: المجموع العـام | AJ38: =SUM(AJ30:AJ37) -> 276 | AK38: =SUM(AK30:AK37) -> 0 | AL38: =SUM(AL30:AL37) -> 276 | AM38: =SUM(AM30:AM37) -> 0 | AO38: مدير المدرسة/ | AP38: =ادخال1!$BP$5 -> د.عبدالرحمن خليفة العريبي
A39: =ادخال1!$O$8 -> التربية الفنية | B39: =ادخال1!$O$7 -> 1 | C39: =IFERROR(VLOOKUP(H42,اسماء,14,0),"") -> جيد جداً | E39: =IFERROR(VLOOKUP(H42,اسماء,27,0),"") -> 0 | H39: التاريخ | I39: =TODAY() -> 46035 | L39: =ادخال1!$O$8 -> التربية الفنية | M39: =ادخال1!$O$7 -> 1 | N39: =IFERROR(VLOOKUP(S42,اسماء,14,0),"") | P39: =IFERROR(VLOOKUP(S42,اسماء,27,0),"") | S39: التاريخ | T39: =TODAY() -> 46035 | W39: =ادخال1!$O$8 -> التربية الفنية | X39: =ادخال1!$O$7 -> 1 | Y39: =IFERROR(VLOOKUP(AD42,اسماء,14,0),"") | AA39: =IFERROR(VLOOKUP(AD42,اسماء,27,0),"") | AD39: التاريخ | AE39: =TODAY() -> 46035 | AH39: =ادخال1!$O$8 -> التربية الفنية | AI39: =ادخال1!$O$7 -> 1 | AJ39: =IFERROR(VLOOKUP(AO42,اسماء,14,0),"") | AL39: =IFERROR(VLOOKUP(AO42,اسماء,27,0),"") | AO39: التاريخ | AP39: =TODAY() -> 46035
A40: =ادخال1!$P$8 -> التربية البدنية | B40: =ادخال1!$P$7 -> 2 | C40: =IFERROR(VLOOKUP(H42,اسماء,15,0),"") -> جيد جداً | E40: =IFERROR(VLOOKUP(H42,اسماء,28,0),"") -> 0 | L40: =ادخال1!$P$8 -> التربية البدنية | M40: =ادخال1!$P$7 -> 2 | N40: =IFERROR(VLOOKUP(S42,اسماء,15,0),"") | P40: =IFERROR(VLOOKUP(S42,اسماء,28,0),"") | W40: =ادخال1!$P$8 -> التربية البدنية | X40: =ادخال1!$P$7 -> 2 | Y40: =IFERROR(VLOOKUP(AD42,اسماء,15,0),"") | AA40: =IFERROR(VLOOKUP(AD42,اسماء,28,0),"") | AH40: =ادخال1!$P$8 -> التربية البدنية | AI40: =ادخال1!$P$7 -> 2 | AJ40: =IFERROR(VLOOKUP(AO42,اسماء,15,0),"") | AL40: =IFERROR(VLOOKUP(AO42,اسماء,28,0),"")
A41: =ادخال1!$Q$8 -> التربية الموسيقية | B41: =ادخال1!$Q$7 -> 1 | C41: =IFERROR(VLOOKUP(H43,اسماء,16,0),"") | E41: =IFERROR(VLOOKUP(H43,اسماء,29,0),"") | L41: =ادخال1!$Q$8 -> التربية الموسيقية | M41: =ادخال1!$Q$7 -> 1 | N41: =IFERROR(VLOOKUP(S43,اسماء,16,0),"") | P41: =IFERROR(VLOOKUP(S43,اسماء,29,0),"") | W41: =ادخال1!$Q$8 -> التربية الموسيقية | X41: =ادخال1!$Q$7 -> 1 | Y41: =IFERROR(VLOOKUP(AD43,اسماء,16,0),"") | AA41: =IFERROR(VLOOKUP(AD43,اسماء,29,0),"") | AH41: =ادخال1!$Q$8 -> التربية الموسيقية | AI41: =ادخال1!$Q$7 -> 1 | AJ41: =IFERROR(VLOOKUP(AO43,اسماء,16,0),"") | AL41: =IFERROR(VLOOKUP(AO43,اسماء,29,0),"")
A42: الرقم الوطني | B42: =IFERROR(VLOOKUP(H42,اسماء,71,0),"") -> 120160386388 | C42: =IFERROR(VLOOKUP(G47,اسماء,8,0),"") | D42: =IFERROR(VLOOKUP(H47,اسماء,8,0),"") | E42: =IFERROR(VLOOKUP(I47,اسماء,8,0),"") | H42: =INDEX(عمود2,MATCH(J26,عمود1)) -> معاوية عز الدين محمد أحفيظان | L42: الرقم الوطني | M42: =IFERROR(VLOOKUP(S42,اسماء,71,0),"") | N42: =IFERROR(VLOOKUP(R47,اسماء,8,0),"") | O42: =IFERROR(VLOOKUP(S47,اسماء,8,0),"") | P42: =IFERROR(VLOOKUP(T47,اسماء,8,0),"") | S42: =INDEX(عمود2,MATCH(U26,عمود1)) -> 0 | W42: الرقم الوطني | X42: =IFERROR(VLOOKUP(AD42,اسماء,71,0),"") | Y42: =IFERROR(VLOOKUP(AC47,اسماء,8,0),"") | Z42: =IFERROR(VLOOKUP(AD47,اسماء,8,0),"") | AA42: =IFERROR(VLOOKUP(AE47,اسماء,8,0),"") | AD42: =INDEX(عمود2,MATCH(AF26,عمود1)) -> 0 | AH42: الرقم الوطني | AI42: =IFERROR(VLOOKUP(AO42,اسماء,71,0),"") | AJ42: =IFERROR(VLOOKUP(AN47,اسماء,8,0),"") | AK42: =IFERROR(VLOOKUP(AO47,اسماء,8,0),"") | AL42: =IFERROR(VLOOKUP(AP47,اسماء,8,0),"") | AO42: =INDEX(عمود2,MATCH(AQ26,عمود1)) -> 0
...

Sheet الصحيفة النهائية
A1: بطاقة تقدير الدرجات للصــــف | D1: =ادخال1!$N$4 -> الرابع | F1: من التعليم الأساسي | O1: 1 | Q1: بطاقة تقدير الدرجات للصــــف | T1: =ادخال1!$N$4 -> الرابع | V1: من التعليم الأساسي | AE1: =O1+5 -> 6 | AG1: بطاقة تقدير الدرجات للصــــف | AJ1: =ادخال1!$N$4 -> الرابع | AL1: من التعليم الأساسي | AU1: =AE1+5 -> 11 | AW1: بطاقة تقدير الدرجات للصــــف | AZ1: =ادخال1!$N$4 -> الرابع | BB1: من التعليم الأساسي | BK1: =AU1+5 -> 16 | BN1: =SUM(I5:I11) -> 840
A2: المدرسة/ | B2: =ادخال1!$B$5 -> سهول العلم للتعليم الخاص | H2: الاسم | J2: =M19 -> أحمد نورالدين أحمد الذيب | Q2: المدرسة/ | R2: =ادخال1!$B$5 -> سهول العلم للتعليم الخاص | X2: الاسم | Z2: =AC19 -> خديجة خليل محمد علي | AG2: المدرسة/ | AH2: =ادخال1!$B$5 -> سهول العلم للتعليم الخاص | AN2: الاسم | AP2: =AS19 -> عبد العزيز عبدالله محمد المغربي | AW2: المدرسة/ | AX2: =ادخال1!$B$5 -> سهول العلم للتعليم الخاص | BD2: الاسم | BF2: =BI19 -> معاوية عز الدين محمد أحفيظان | BN2: =BN1*0.3 -> 252 | BO2: 0 | BP2: ضعيف
A3: الفترات | B3: عدد الحصص | C3: الفترة الأولي 30 % | E3: الفترة الثانية 30 % | G3: الفترة الثالثة 40% | I3: النتيجة النهائيــة 100% | M3: ملاحظــات عن نتيجة التلميذ خلال كل فترة : | Q3: الفترات | R3: عدد الحصص | S3: الفترة الأولي 30 % | U3: الفترة الثانية 30 % | W3: الفترة الثالثة 40% | Y3: النتيجة النهائيــة 100% | AC3: ملاحظــات عن نتيجة التلميذ خلال كل فترة : | AG3: الفترات | AH3: عدد الحصص | AI3: الفترة الأولي 30 % | AK3: الفترة الثانية 30 % | AM3: الفترة الثالثة 40% | AO3: النتيجة النهائيــة 100% | AS3: ملاحظــات عن نتيجة التلميذ خلال كل فترة : | AW3: الفترات | AX3: عدد الحصص | AY3: الفترة الأولي 30 % | BA3: الفترة الثانية 30 % | BC3: الفترة الثالثة 40% | BE3: النتيجة النهائيــة 100% | BI3: ملاحظــات عن نتيجة التلميذ خلال كل فترة : | BN3: =BN1*0.4 -> 336 | BO3: =BN3*0.5 -> 168 | BP3: مقبول
A4: المواد الدراسية | C4: الدرجة الكبرى | D4: درجة التلميذ | E4: الدرجة الكبرى | F4: درجة التلميذ | G4: الدرجة الكبرى | H4: درجة التلميذ | I4: النهاية الكبرى | J4: النهاية الصغري | K4: درجة التلميذ | M4: الأولي : | N4: =IF(D13=0,"",IF(AND(D5>=C5*0.4,D6>=C6*0.4,D8>=C8*0.4,D10>=C10*0.4,D11>=C11*0.4),LOOKUP(D13,$BO$18:$BP$22),"ضعيف ويحتاج الى اهتمام في المواد")) -> ممتاز | Q4: المواد الدراسية | S4: الدرجة الكبرى | T4: درجة التلميذ | U4: الدرجة الكبرى | V4: درجة التلميذ | W4: الدرجة الكبرى | X4: درجة التلميذ | Y4: النهاية الكبرى | Z4: النهاية الصغري | AA4: درجة التلميذ | AC4: الأولي : | AD4: =IF(T13=0,"",IF(AND(T5>=S5*0.4,T6>=S6*0.4,T8>=S8*0.4,T10>=S10*0.4,T11>=S11*0.4),LOOKUP(T13,$BO$18:$BP$22),"ضعيف ويحتاج الى اهتمام في المواد")) -> ممتاز | AG4: المواد الدراسية | AI4: الدرجة الكبرى | AJ4: درجة التلميذ | AK4: الدرجة الكبرى | AL4: درجة التلميذ | AM4: الدرجة الكبرى | AN4: درجة التلميذ | AO4: النهاية الكبرى | AP4: النهاية الصغري | AQ4: درجة التلميذ | AS4: الأولي : | AT4: =IF(AJ13=0,"",IF(AND(AJ5>=AI5*0.4,AJ6>=AI6*0.4,AJ8>=AI8*0.4,AJ10>=AI10*0.4,AJ11>=AI11*0.4),LOOKUP(AJ13,$BO$18:$BP$22),"ضعيف ويحتاج الى اهتمام في المواد")) -> ممتاز | AW4: المواد الدراسية | AY4: الدرجة الكبرى | AZ4: درجة التلميذ | BA4: الدرجة الكبرى | BB4: درجة التلميذ | BC4: الدرجة الكبرى | BD4: درجة التلميذ | BE4: النهاية الكبرى | BF4: النهاية الصغري | BG4: درجة التلميذ | BI4: الأولي : | BJ4: =IF(AZ13=0,"",IF(AND(AZ5>=AY5*0.4,AZ6>=AY6*0.4,AZ8>=AY8*0.4,AZ10>=AY10*0.4,AZ11>=AY11*0.4),LOOKUP(AZ13,$BO$18:$BP$22),"ضعيف ويحتاج الى اهتمام في المواد")) -> ممتاز | BO4: =$BN$1*0.65 -> 546 | BP4: جيد
