Workbook
Name اسماء: ادخال1!$B$11:$EP$510
Name الترتيب1: ادخال1!$AR$11:$AS$396
Name الترتيب2: ادخال1!$AX$11:$AY$395
Name الترتيب3: ادخال1!$BC$11:$BD$397
Name عمود1: ادخال1!$A$11:$A$395
Name عمود2: ادخال1!$B$11:$B$395
Name مستجد: ادخال1!$CH$3:$CH$4
Name مسلسل: ادخال1!$A$11:$B$395

Sheet بيانات الصحيفة 
A1: 1 | B1: دولة ليبيا | P1: =A1-5 -> -4 | Q1: دولة ليبيا | AE1: =P1-5 -> -9 | AF1: دولة ليبيا | AT1: =AE1-5 -> -14 | AU1: دولة ليبيا
A2: وزارة التعليم | P2: وزارة التعليم | AE2: وزارة التعليم | AT2: وزارة التعليم
A3: المركز الوطني للامتحانات | P3: المركز الوطني للامتحانات | AE3: المركز الوطني للامتحانات | AT3: المركز الوطني للامتحانات
A4: بطاقة تقدير الدرجات لمرحلة التعليم | K4: =ادخال1!$CD$7 -> الاساسي | P4: بطاقة تقدير الدرجات لمرحلة التعليم | Z4: =ادخال1!$CD$7 -> الاساسي | AE4: بطاقة تقدير الدرجات لمرحلة التعليم | AO4: =ادخال1!$CD$7 -> الاساسي | AT4: بطاقة تقدير الدرجات لمرحلة التعليم | BD4: =ادخال1!$CD$7 -> الاساسي
A5: للصف | G5: =ادخال1!$CB$5 -> الثاني الابتدائي | P5: للصف | V5: =ادخال1!$CB$5 -> الثاني الابتدائي | AE5: للصف | AK5: =ادخال1!$CB$5 -> الثاني الابتدائي | AT5: للصف | AZ5: =ادخال1!$CB$5 -> الثاني الابتدائي
A6: العام الدراسي | B6: =ادخال1!$CA$8 -> 1446هـ/1447 هـ | F6: هجرية | H6: الموافق | J6: =ادخال1!$CB$8 -> 2026 /2025م | N6: ميلادية | P6: العام الدراسي | Q6: =ادخال1!$CA$8 -> 1446هـ/1447 هـ | U6: هجرية | W6: الموافق | Y6: =ادخال1!$CB$8 -> 2026 /2025م | AC6: ميلادية | AE6: العام الدراسي | AF6: =ادخال1!$CA$8 -> 1446هـ/1447 هـ | AJ6: هجرية | AL6: الموافق | AN6: =ادخال1!$CB$8 -> 2026 /2025م | AR6: ميلادية | AT6: العام الدراسي | AU6: =ادخال1!$CA$8 -> 1446هـ/1447 هـ | AY6: هجرية | BA6: الموافق | BC6: =ادخال1!$CB$8 -> 2026 /2025م | BG6: ميلادية
A7: شؤون التعليم بمنطقة | B7: =ادخال1!$CB$4 -> تاجوراء | P7: شؤون التعليم بمنطقة | Q7: =ادخال1!$CB$4 -> تاجوراء | AE7: شؤون التعليم بمنطقة | AF7: =ادخال1!$CB$4 -> تاجوراء | AT7: شؤون التعليم بمنطقة | AU7: =ادخال1!$CB$4 -> تاجوراء
A8: مدرســــــــــــــــــــــة | B8: =ادخال1!$BZ$6 -> مدرسة سهول العلم للتعيم الخاص | J8: الكــــائنة بـ : | M8: =ادخال1!$BZ$8 -> تاجوراء الجنوبي | P8: مدرســــــــــــــــــــــة | Q8: =ادخال1!$BZ$6 -> مدرسة سهول العلم للتعيم الخاص | Y8: الكــــائنة بـ : | AB8: =ادخال1!$BZ$8 -> تاجوراء الجنوبي | AE8: مدرســــــــــــــــــــــة | AF8: =ادخال1!$BZ$6 -> مدرسة سهول العلم للتعيم الخاص | AN8: الكــــائنة بـ : | AQ8: =ادخال1!$BZ$8 -> تاجوراء الجنوبي | AT8: مدرســــــــــــــــــــــة | AU8: =ادخال1!$BZ$6 -> مدرسة سهول العلم للتعيم الخاص | BC8: الكــــائنة بـ : | BF8: =ادخال1!$BZ$8 -> تاجوراء الجنوبي
A9: اسم التلميذ بالكـــامل | B9: =IFERROR(VLOOKUP(A1,مسلسل,2,0),0) -> الجبير خليل الدوكالي اليونسي | C9: =IFERROR(VLOOKUP(B9,مسلسل,2,0),0) -> 0 | D9: =IFERROR(VLOOKUP(C9,مسلسل,2,0),0) -> 0 | E9: =IFERROR(VLOOKUP(D9,مسلسل,2,0),0) -> 0 | F9: =IFERROR(VLOOKUP(E9,مسلسل,2,0),0) -> 0 | G9: =IFERROR(VLOOKUP(F9,مسلسل,2,0),0) -> 0 | H9: =IFERROR(VLOOKUP(G9,مسلسل,2,0),0) -> 0 | I9: =IFERROR(VLOOKUP(H9,مسلسل,2,0),0) -> 0 | J9: اللقــــــــب | M9: =IFERROR(VLOOKUP(B9,اسماء,63,0),"") -> اليونسي | P9: اسم التلميذ بالكـــامل | Q9: =IFERROR(VLOOKUP(P1,مسلسل,2,0),0) -> 0 | R9: =IFERROR(VLOOKUP(Q9,مسلسل,2,0),0) -> 0 | S9: =IFERROR(VLOOKUP(R9,مسلسل,2,0),0) -> 0 | T9: =IFERROR(VLOOKUP(S9,مسلسل,2,0),0) -> 0 | U9: =IFERROR(VLOOKUP(T9,مسلسل,2,0),0) -> 0 | V9: =IFERROR(VLOOKUP(U9,مسلسل,2,0),0) -> 0 | W9: =IFERROR(VLOOKUP(V9,مسلسل,2,0),0) -> 0 | X9: =IFERROR(VLOOKUP(W9,مسلسل,2,0),0) -> 0 | Y9: اللقــــــــب | AB9: =IFERROR(VLOOKUP(Q9,اسماء,63,0),"") | AE9: اسم التلميذ بالكـــامل | AF9: =IFERROR(VLOOKUP(AE1,مسلسل,2,0),0) -> 0 | AG9: =IFERROR(VLOOKUP(AF9,مسلسل,2,0),0) -> 0 | AH9: =IFERROR(VLOOKUP(AG9,مسلسل,2,0),0) -> 0 | AI9: =IFERROR(VLOOKUP(AH9,مسلسل,2,0),0) -> 0 | AJ9: =IFERROR(VLOOKUP(AI9,مسلسل,2,0),0) -> 0 | AK9: =IFERROR(VLOOKUP(AJ9,مسلسل,2,0),0) -> 0 | AL9: =IFERROR(VLOOKUP(AK9,مسلسل,2,0),0) -> 0 | AM9: =IFERROR(VLOOKUP(AL9,مسلسل,2,0),0) -> 0 | AN9: اللقــــــــب | AQ9: =IFERROR(VLOOKUP(AF9,اسماء,63,0),"") | AT9: اسم التلميذ بالكـــامل | AU9: =IFERROR(VLOOKUP(AT1,مسلسل,2,0),0) -> 0 | AV9: =IFERROR(VLOOKUP(AU9,مسلسل,2,0),0) -> 0 | AW9: =IFERROR(VLOOKUP(AV9,مسلسل,2,0),0) -> 0 | AX9: =IFERROR(VLOOKUP(AW9,مسلسل,2,0),0) -> 0 | AY9: =IFERROR(VLOOKUP(AX9,مسلسل,2,0),0) -> 0 | AZ9: =IFERROR(VLOOKUP(AY9,مسلسل,2,0),0) -> 0 | BA9: =IFERROR(VLOOKUP(AZ9,مسلسل,2,0),0) -> 0 | BB9: =IFERROR(VLOOKUP(BA9,مسلسل,2,0),0) -> 0 | BC9: اللقــــــــب | BF9: =IFERROR(VLOOKUP(AU9,اسماء,63,0),"")
A10: مكان وتاريخ الميلاد | B10: =IFERROR(VLOOKUP(B9,اسماء,76,0),"") -> تاجوراء | E10: =IFERROR(VLOOKUP(B9,اسماء,2,0),"") -> 43087 | I10: اسم الوالدة بالكامل | M10: =IFERROR(VLOOKUP(B9,اسماء,3,0),"") -> مفيدة اليونسي | P10: مكان وتاريخ الميلاد | Q10: =IFERROR(VLOOKUP(Q9,اسماء,76,0),"") | T10: =IFERROR(VLOOKUP(Q9,اسماء,2,0),"") | X10: اسم الوالدة بالكامل | AB10: =IFERROR(VLOOKUP(Q9,اسماء,3,0),"") | AE10: مكان وتاريخ الميلاد | AF10: =IFERROR(VLOOKUP(AF9,اسماء,76,0),"") | AI10: =IFERROR(VLOOKUP(AF9,اسماء,2,0),"") | AM10: اسم الوالدة بالكامل | AQ10: =IFERROR(VLOOKUP(AF9,اسماء,3,0),"") | AT10: مكان وتاريخ الميلاد | AU10: =IFERROR(VLOOKUP(AU9,اسماء,76,0),"") | AX10: =IFERROR(VLOOKUP(AU9,اسماء,2,0),"") | BB10: اسم الوالدة بالكامل | BF10: =IFERROR(VLOOKUP(AU9,اسماء,3,0),"")
A11: الرقم الوطنــــــــــي | B11: =IFERROR(VLOOKUP(B9,اسماء,64,0),"") -> 5 | C11: =IFERROR(VLOOKUP(B9,اسماء,65,0),"") -> 2 | D11: =IFERROR(VLOOKUP(B9,اسماء,66,0),"") -> 7 | E11: =IFERROR(VLOOKUP(B9,اسماء,67,0),"") -> 4 | F11: =IFERROR(VLOOKUP(B9,اسماء,68,0),"") -> 6 | G11: =IFERROR(VLOOKUP(B9,اسماء,69,0),"") -> 0 | H11: =IFERROR(VLOOKUP(B9,اسماء,70,0),"") -> 1 | I11: =IFERROR(VLOOKUP(B9,اسماء,71,0),"") -> 7 | J11: =IFERROR(VLOOKUP(B9,اسماء,72,0),"") -> 1 | K11: =IFERROR(VLOOKUP(B9,اسماء,73,0),"") -> 0 | L11: =IFERROR(VLOOKUP(B9,اسماء,74,0),"") -> 2 | M11: =IFERROR(VLOOKUP(B9,اسماء,75,0),"") -> 1 | P11: الرقم الوطنــــــــــي | Q11: =IFERROR(VLOOKUP(Q9,اسماء,64,0),"") | R11: =IFERROR(VLOOKUP(Q9,اسماء,65,0),"") | S11: =IFERROR(VLOOKUP(Q9,اسماء,66,0),"") | T11: =IFERROR(VLOOKUP(Q9,اسماء,67,0),"") | U11: =IFERROR(VLOOKUP(Q9,اسماء,68,0),"") | V11: =IFERROR(VLOOKUP(Q9,اسماء,69,0),"") | W11: =IFERROR(VLOOKUP(Q9,اسماء,70,0),"") | X11: =IFERROR(VLOOKUP(Q9,اسماء,71,0),"") | Y11: =IFERROR(VLOOKUP(Q9,اسماء,72,0),"") | Z11: =IFERROR(VLOOKUP(Q9,اسماء,73,0),"") | AA11: =IFERROR(VLOOKUP(Q9,اسماء,74,0),"") | AB11: =IFERROR(VLOOKUP(Q9,اسماء,75,0),"") | AE11: الرقم الوطنــــــــــي | AF11: =IFERROR(VLOOKUP(AF9,اسماء,64,0),"") | AG11: =IFERROR(VLOOKUP(AF9,اسماء,65,0),"") | AH11: =IFERROR(VLOOKUP(AF9,اسماء,66,0),"") | AI11: =IFERROR(VLOOKUP(AF9,اسماء,67,0),"") | AJ11: =IFERROR(VLOOKUP(AF9,اسماء,68,0),"") | AK11: =IFERROR(VLOOKUP(AF9,اسماء,69,0),"") | AL11: =IFERROR(VLOOKUP(AF9,اسماء,70,0),"") | AM11: =IFERROR(VLOOKUP(AF9,اسماء,71,0),"") | AN11: =IFERROR(VLOOKUP(AF9,اسماء,72,0),"") | AO11: =IFERROR(VLOOKUP(AF9,اسماء,73,0),"") | AP11: =IFERROR(VLOOKUP(AF9,اسماء,74,0),"") | AQ11: =IFERROR(VLOOKUP(AF9,اسماء,75,0),"") | AT11: الرقم الوطنــــــــــي | AU11: =IFERROR(VLOOKUP(AU9,اسماء,64,0),"") | AV11: =IFERROR(VLOOKUP(AU9,اسماء,65,0),"") | AW11: =IFERROR(VLOOKUP(AU9,اسماء,66,0),"") | AX11: =IFERROR(VLOOKUP(AU9,اسماء,67,0),"") | AY11: =IFERROR(VLOOKUP(AU9,اسماء,68,0),"") | AZ11: =IFERROR(VLOOKUP(AU9,اسماء,69,0),"") | BA11: =IFERROR(VLOOKUP(AU9,اسماء,70,0),"") | BB11: =IFERROR(VLOOKUP(AU9,اسماء,71,0),"") | BC11: =IFERROR(VLOOKUP(AU9,اسماء,72,0),"") | BD11: =IFERROR(VLOOKUP(AU9,اسماء,73,0),"") | BE11: =IFERROR(VLOOKUP(AU9,اسماء,74,0),"") | BF11: =IFERROR(VLOOKUP(AU9,اسماء,75,0),"")
A12: جنسيـــــة التلمــــيذ | B12: =IFERROR(VLOOKUP(B9,اسماء,77,0),"") -> ليبي | G12: مستجد/ | I12: معيد | K12: =IFERROR(VLOOKUP(B9,اسماء,78,0),"") -> مستجد | P12: جنسيـــــة التلمــــيذ | Q12: =IFERROR(VLOOKUP(Q9,اسماء,77,0),"") | V12: مستجد/ | X12: معيد | Z12: =IFERROR(VLOOKUP(Q9,اسماء,78,0),"") | AE12: جنسيـــــة التلمــــيذ | AF12: =IFERROR(VLOOKUP(AF9,اسماء,77,0),"") | AK12: مستجد/ | AM12: معيد | AO12: =IFERROR(VLOOKUP(AF9,اسماء,78,0),"") | AT12: جنسيـــــة التلمــــيذ | AU12: =IFERROR(VLOOKUP(AU9,اسماء,77,0),"") | AZ12: مستجد/ | BB12: معيد | BD12: =IFERROR(VLOOKUP(AU9,اسماء,78,0),"")
A13: رائــــــد الصــــــف | B13: =IFERROR(VLOOKUP(B9,اسماء,80,0),"") -> أحلام الشيباني | G13: صفة القيد | K13: =IFERROR(VLOOKUP(B9,اسماء,79,0),"") -> نظامي | P13: رائــــــد الصــــــف | Q13: =IFERROR(VLOOKUP(Q9,اسماء,80,0),"") | V13: صفة القيد | Z13: =IFERROR(VLOOKUP(Q9,اسماء,79,0),"") | AE13: رائــــــد الصــــــف | AF13: =IFERROR(VLOOKUP(AF9,اسماء,80,0),"") | AK13: صفة القيد | AO13: =IFERROR(VLOOKUP(AF9,اسماء,79,0),"") | AT13: رائــــــد الصــــــف | AU13: =IFERROR(VLOOKUP(AU9,اسماء,77,0),"") | AZ13: صفة القيد | BD13: =IFERROR(VLOOKUP(AU9,اسماء,76,0),"")
A14: (يكتب اسم التلميذ مطابقاً لشهادة الميلاد) | P14: (يكتب اسم التلميذ مطابقاً لشهادة الميلاد) | AE14: (يكتب اسم التلميذ مطابقاً لشهادة الميلاد) | AT14: (يكتب اسم التلميذ مطابقاً لشهادة الميلاد)
A15: الانتقـــــــــال | P15: الانتقـــــــــال | AE15: الانتقـــــــــال | AT15: الانتقـــــــــال
A16: بناء على طلب ولي أمر التلميذ فإن إدارة هذه المدرسة توافق على انتقاله إلــــــى | P16: بناء على طلب ولي أمر التلميذ فإن إدارة هذه المدرسة توافق على انتقاله إلــــــى | AE16: بناء على طلب ولي أمر التلميذ فإن إدارة هذه المدرسة توافق على انتقاله إلــــــى | AT16: بناء على طلب ولي أمر التلميذ فإن إدارة هذه المدرسة توافق على انتقاله إلــــــى
A17: مدرســــــة | P17: مدرســــــة | AE17: مدرســــــة | AT17: مدرســــــة
A18: يعتمد مديرالمدرسة | N18: يعتمد مكتب الامتحانات | P18: يعتمد مديرالمدرسة | AC18: يعتمد مكتب الامتحانات | AE18: يعتمد مديرالمدرسة | AR18: يعتمد مكتب الامتحانات | AT18: يعتمد مديرالمدرسة | BG18: يعتمد مكتب الامتحانات
A23: =A1-1 -> 0 | B23: دولة ليبيا | P23: =P1-1 -> -5 | Q23: دولة ليبيا | AE23: =AE1-1 -> -10 | AF23: دولة ليبيا | AT23: =AT1-1 -> -15 | AU23: دولة ليبيا
A24: وزارة التعليم | P24: وزارة التعليم | AE24: وزارة التعليم | AT24: وزارة التعليم
A25: المركز الوطني للامتحانات | P25: المركز الوطني للامتحانات | AE25: المركز الوطني للامتحانات | AT25: المركز الوطني للامتحانات
A26: بطاقة تقدير الدرجات لمرحلة التعليم | K26: =ادخال1!$CD$7 -> الاساسي | P26: بطاقة تقدير الدرجات لمرحلة التعليم | Z26: =ادخال1!$CD$7 -> الاساسي | AE26: بطاقة تقدير الدرجات لمرحلة التعليم | AO26: =ادخال1!$CD$7 -> الاساسي | AT26: بطاقة تقدير الدرجات لمرحلة التعليم | BD26: =ادخال1!$CD$7 -> الاساسي
A27: للصف | G27: =ادخال1!$CB$5 -> الثاني الابتدائي | P27: للصف | V27: =ادخال1!$CB$5 -> الثاني الابتدائي | AE27: للصف | AK27: =ادخال1!$CB$5 -> الثاني الابتدائي | AT27: للصف | AZ27: =ادخال1!$CB$5 -> الثاني الابتدائي
A28: العام الدراسي | B28: =ادخال1!$CA$8 -> 1446هـ/1447 هـ | F28: هجرية | H28: الموافق | J28: =ادخال1!$CB$8 -> 2026 /2025م | N28: ميلادية | P28: العام الدراسي | Q28: =ادخال1!$CA$8 -> 1446هـ/1447 هـ | U28: هجرية | W28: الموافق | Y28: =ادخال1!$CB$8 -> 2026 /2025م | AC28: ميلادية | AE28: العام الدراسي | AF28: =ادخال1!$CA$8 -> 1446هـ/1447 هـ | AJ28: هجرية | AL28: الموافق | AN28: =ادخال1!$CB$8 -> 2026 /2025م | AR28: ميلادية | AT28: العام الدراسي | AU28: =ادخال1!$CA$8 -> 1446هـ/1447 هـ | AY28: هجرية | BA28: الموافق | BC28: =ادخال1!$CB$8 -> 2026 /2025م | BG28: ميلادية
A29: شؤون التعليم بمنطقة | B29: =ادخال1!$CB$4 -> تاجوراء | P29: شؤون التعليم بمنطقة | Q29: =ادخال1!$CB$4 -> تاجوراء | AE29: شؤون التعليم بمنطقة | AF29: =ادخال1!$CB$4 -> تاجوراء | AT29: شؤون التعليم بمنطقة | AU29: =ادخال1!$CB$4 -> تاجوراء
A30: مدرســــــــــــــــــــــة | B30: =ادخال1!$BZ$6 -> مدرسة سهول العلم للتعيم الخاص | J30: الكــــائنة بـ : | M30: =ادخال1!$BZ$8 -> تاجوراء الجنوبي | P30: مدرســــــــــــــــــــــة | Q30: =ادخال1!$BZ$6 -> مدرسة سهول العلم للتعيم الخاص | Y30: الكــــائنة بـ : | AB30: =ادخال1!$BZ$8 -> تاجوراء الجنوبي | AE30: مدرســــــــــــــــــــــة | AF30: =ادخال1!$BZ$6 -> مدرسة سهول العلم للتعيم الخاص | AN30: الكــــائنة بـ : | AQ30: =ادخال1!$BZ$8 -> تاجوراء الجنوبي | AT30: مدرســــــــــــــــــــــة | AU30: =ادخال1!$BZ$6 -> مدرسة سهول العلم للتعيم الخاص | BC30: الكــــائنة بـ : | BF30: =ادخال1!$BZ$8 -> تاجوراء الجنوبي
A31: اسم التلميذ بالكـــامل | B31: =IFERROR(VLOOKUP(A23,مسلسل,2,0),0) -> 0 | C31: =IFERROR(VLOOKUP(B31,مسلسل,2,0),0) -> 0 | D31: =IFERROR(VLOOKUP(C31,مسلسل,2,0),0) -> 0 | E31: =IFERROR(VLOOKUP(D31,مسلسل,2,0),0) -> 0 | F31: =IFERROR(VLOOKUP(E31,مسلسل,2,0),0) -> 0 | G31: =IFERROR(VLOOKUP(F31,مسلسل,2,0),0) -> 0 | H31: =IFERROR(VLOOKUP(G31,مسلسل,2,0),0) -> 0 | I31: =IFERROR(VLOOKUP(H31,مسلسل,2,0),0) -> 0 | J31: اللقــــــــب | M31: =IFERROR(VLOOKUP(B31,اسماء,63,0),"") | P31: اسم التلميذ بالكـــامل | Q31: =IFERROR(VLOOKUP(P23,مسلسل,2,0),0) -> 0 | R31: =IFERROR(VLOOKUP(Q31,مسلسل,2,0),0) -> 0 | S31: =IFERROR(VLOOKUP(R31,مسلسل,2,0),0) -> 0 | T31: =IFERROR(VLOOKUP(S31,مسلسل,2,0),0) -> 0 | U31: =IFERROR(VLOOKUP(T31,مسلسل,2,0),0) -> 0 | V31: =IFERROR(VLOOKUP(U31,مسلسل,2,0),0) -> 0 | W31: =IFERROR(VLOOKUP(V31,مسلسل,2,0),0) -> 0 | X31: =IFERROR(VLOOKUP(W31,مسلسل,2,0),0) -> 0 | Y31: اللقــــــــب | AB31: =IFERROR(VLOOKUP(Q31,اسماء,63,0),"") | AE31: اسم التلميذ بالكـــامل | AF31: =IFERROR(VLOOKUP(AE23,مسلسل,2,0),0) -> 0 | AG31: =IFERROR(VLOOKUP(AF31,مسلسل,2,0),0) -> 0 | AH31: =IFERROR(VLOOKUP(AG31,مسلسل,2,0),0) -> 0 | AI31: =IFERROR(VLOOKUP(AH31,مسلسل,2,0),0) -> 0 | AJ31: =IFERROR(VLOOKUP(AI31,مسلسل,2,0),0) -> 0 | AK31: =IFERROR(VLOOKUP(AJ31,مسلسل,2,0),0) -> 0 | AL31: =IFERROR(VLOOKUP(AK31,مسلسل,2,0),0) -> 0 | AM31: =IFERROR(VLOOKUP(AL31,مسلسل,2,0),0) -> 0 | AN31: اللقــــــــب | AQ31: =IFERROR(VLOOKUP(AF31,اسماء,63,0),"") | AT31: اسم التلميذ بالكـــامل | AU31: =IFERROR(VLOOKUP(AT23,مسلسل,2,0),0) -> 0 | AV31: =IFERROR(VLOOKUP(AU31,مسلسل,2,0),0) -> 0 | AW31: =IFERROR(VLOOKUP(AV31,مسلسل,2,0),0) -> 0 | AX31: =IFERROR(VLOOKUP(AW31,مسلسل,2,0),0) -> 0 | AY31: =IFERROR(VLOOKUP(AX31,مسلسل,2,0),0) -> 0 | AZ31: =IFERROR(VLOOKUP(AY31,مسلسل,2,0),0) -> 0 | BA31: =IFERROR(VLOOKUP(AZ31,مسلسل,2,0),0) -> 0 | BB31: =IFERROR(VLOOKUP(BA31,مسلسل,2,0),0) -> 0 | BC31: اللقــــــــب | BF31: =IFERROR(VLOOKUP(AU31,اسماء,63,0),"")
A32: مكان وتاريخ الميلاد | B32: =IFERROR(VLOOKUP(B31,اسماء,76,0),"") | E32: =IFERROR(VLOOKUP(B31,اسماء,2,0),"") | I32: اسم الوالدة بالكامل | M32: =IFERROR(VLOOKUP(B31,اسماء,3,0),"") | P32: مكان وتاريخ الميلاد | Q32: =IFERROR(VLOOKUP(Q31,اسماء,76,0),"") | T32: =IFERROR(VLOOKUP(Q31,اسماء,2,0),"") | X32: اسم الوالدة بالكامل | AB32: =IFERROR(VLOOKUP(Q31,اسماء,3,0),"") | AE32: مكان وتاريخ الميلاد | AF32: =IFERROR(VLOOKUP(AF31,اسماء,76,0),"") | AI32: =IFERROR(VLOOKUP(AF31,اسماء,2,0),"") | AM32: اسم الوالدة بالكامل | AQ32: =IFERROR(VLOOKUP(AF31,اسماء,3,0),"") | AT32: مكان وتاريخ الميلاد | AU32: =IFERROR(VLOOKUP(AU31,اسماء,76,0),"") | AX32: =IFERROR(VLOOKUP(AU31,اسماء,2,0),"") | BB32: اسم الوالدة بالكامل | BF32: =IFERROR(VLOOKUP(AU31,اسماء,3,0),"")
A33: الرقم الوطنــــــــــي | B33: =IFERROR(VLOOKUP(B31,اسماء,64,0),"") | C33: =IFERROR(VLOOKUP(B31,اسماء,65,0),"") | D33: =IFERROR(VLOOKUP(B31,اسماء,66,0),"") | E33: =IFERROR(VLOOKUP(B31,اسماء,67,0),"") | F33: =IFERROR(VLOOKUP(B31,اسماء,68,0),"") | G33: =IFERROR(VLOOKUP(B31,اسماء,69,0),"") | H33: =IFERROR(VLOOKUP(B31,اسماء,70,0),"") | I33: =IFERROR(VLOOKUP(B31,اسماء,71,0),"") | J33: =IFERROR(VLOOKUP(B31,اسماء,72,0),"") | K33: =IFERROR(VLOOKUP(B31,اسماء,73,0),"") | L33: =IFERROR(VLOOKUP(B31,اسماء,74,0),"") | M33: =IFERROR(VLOOKUP(B31,اسماء,75,0),"") | P33: الرقم الوطنــــــــــي | Q33: =IFERROR(VLOOKUP(Q31,اسماء,64,0),"") | R33: =IFERROR(VLOOKUP(Q31,اسماء,65,0),"") | S33: =IFERROR(VLOOKUP(Q31,اسماء,66,0),"") | T33: =IFERROR(VLOOKUP(Q31,اسماء,67,0),"") | U33: =IFERROR(VLOOKUP(Q31,اسماء,68,0),"") | V33: =IFERROR(VLOOKUP(Q31,اسماء,69,0),"") | W33: =IFERROR(VLOOKUP(Q31,اسماء,70,0),"") | X33: =IFERROR(VLOOKUP(Q31,اسماء,71,0),"") | Y33: =IFERROR(VLOOKUP(Q31,اسماء,72,0),"") | Z33: =IFERROR(VLOOKUP(Q31,اسماء,73,0),"") | AA33: =IFERROR(VLOOKUP(Q31,اسماء,74,0),"") | AB33: =IFERROR(VLOOKUP(Q31,اسماء,75,0),"") | AE33: الرقم الوطنــــــــــي | AF33: =IFERROR(VLOOKUP(AF31,اسماء,64,0),"") | AG33: =IFERROR(VLOOKUP(AF31,اسماء,65,0),"") | AH33: =IFERROR(VLOOKUP(AF31,اسماء,66,0),"") | AI33: =IFERROR(VLOOKUP(AF31,اسماء,67,0),"") | AJ33: =IFERROR(VLOOKUP(AF31,اسماء,68,0),"") | AK33: =IFERROR(VLOOKUP(AF31,اسماء,69,0),"") | AL33: =IFERROR(VLOOKUP(AF31,اسماء,70,0),"") | AM33: =IFERROR(VLOOKUP(AF31,اسماء,71,0),"") | AN33: =IFERROR(VLOOKUP(AF31,اسماء,72,0),"") | AO33: =IFERROR(VLOOKUP(AF31,اسماء,73,0),"") | AP33: =IFERROR(VLOOKUP(AF31,اسماء,74,0),"") | AQ33: =IFERROR(VLOOKUP(AF31,اسماء,75,0),"") | AT33: الرقم الوطنــــــــــي | AU33: =IFERROR(VLOOKUP(AU31,اسماء,64,0),"") | AV33: =IFERROR(VLOOKUP(AU31,اسماء,65,0),"") | AW33: =IFERROR(VLOOKUP(AU31,اسماء,66,0),"") | AX33: =IFERROR(VLOOKUP(AU31,اسماء,67,0),"") | AY33: =IFERROR(VLOOKUP(AU31,اسماء,68,0),"") | AZ33: =IFERROR(VLOOKUP(AU31,اسماء,69,0),"") | BA33: =IFERROR(VLOOKUP(AU31,اسماء,70,0),"") | BB33: =IFERROR(VLOOKUP(AU31,اسماء,71,0),"") | BC33: =IFERROR(VLOOKUP(AU31,اسماء,72,0),"") | BD33: =IFERROR(VLOOKUP(AU31,اسماء,73,0),"") | BE33: =IFERROR(VLOOKUP(AU31,اسماء,74,0),"") | BF33: =IFERROR(VLOOKUP(AU31,اسماء,75,0),"")
A34: جنسيـــــة التلمــــيذ | B34: =IFERROR(VLOOKUP(B31,اسماء,77,0),"") | G34: مستجد/ | I34: معيد | K34: =IFERROR(VLOOKUP(B31,اسماء,78,0),"") | P34: جنسيـــــة التلمــــيذ | Q34: =IFERROR(VLOOKUP(Q31,اسماء,77,0),"") | V34: مستجد/ | X34: معيد | Z34: =IFERROR(VLOOKUP(Q31,اسماء,78,0),"") | AE34: جنسيـــــة التلمــــيذ | AF34: =IFERROR(VLOOKUP(AF31,اسماء,77,0),"") | AK34: مستجد/ | AM34: معيد | AO34: =IFERROR(VLOOKUP(AF31,اسماء,78,0),"") | AT34: جنسيـــــة التلمــــيذ | AU34: =IFERROR(VLOOKUP(AU31,اسماء,77,0),"") | AZ34: مستجد/ | BB34: معيد | BD34: =IFERROR(VLOOKUP(AU31,اسماء,78,0),"")
A35: رائــــــد الصــــــف | B35: =IFERROR(VLOOKUP(B31,اسماء,80,0),"") | G35: صفة القيد | K35: =IFERROR(VLOOKUP(B31,اسماء,79,0),"") | P35: رائــــــد الصــــــف | Q35: =IFERROR(VLOOKUP(Q31,اسماء,80,0),"") | V35: صفة القيد | Z35: =IFERROR(VLOOKUP(Q31,اسماء,79,0),"") | AE35: رائــــــد الصــــــف | AF35: =IFERROR(VLOOKUP(AF31,اسماء,80,0),"") | AK35: صفة القيد | AO35: =IFERROR(VLOOKUP(AF31,اسماء,79,0),"") | AT35: رائــــــد الصــــــف | AU35: =IFERROR(VLOOKUP(AU31,اسماء,77,0),"") | AZ35: صفة القيد | BD35: =IFERROR(VLOOKUP(AU31,اسماء,76,0),"")
A36: (يكتب اسم التلميذ مطابقاً لشهادة الميلاد) | P36: (يكتب اسم التلميذ مطابقاً لشهادة الميلاد) | AE36: (يكتب اسم التلميذ مطابقاً لشهادة الميلاد) | AT36: (يكتب اسم التلميذ مطابقاً لشهادة الميلاد)
A37: الانتقـــــــــال | P37: الانتقـــــــــال | AE37: الانتقـــــــــال | AT37: الانتقـــــــــال
A38: بناء على طلب ولي أمر التلميذ فإن إدارة هذه المدرسة توافق على انتقاله إلــــــى | P38: بناء على طلب ولي أمر التلميذ فإن إدارة هذه المدرسة توافق على انتقاله إلــــــى | AE38: بناء على طلب ولي أمر التلميذ فإن إدارة هذه المدرسة توافق على انتقاله إلــــــى | AT38: بناء على طلب ولي أمر التلميذ فإن إدارة هذه المدرسة توافق على انتقاله إلــــــى
A39: مدرســــــة | P39: مدرســــــة | AE39: مدرســــــة | AT39: مدرســــــة
A40: يعتمد مديرالمدرسة | N40: يعتمد مكتب الامتحانات | P40: يعتمد مديرالمدرسة | AC40: يعتمد مكتب الامتحانات | AE40: يعتمد مديرالمدرسة | AR40: يعتمد مكتب الامتحانات | AT40: يعتمد مديرالمدرسة | BG40: يعتمد مكتب الامتحانات
A45: =A23-1 -> -1 | B45: دولة ليبيا | P45: =P23-1 -> -6 | Q45: دولة ليبيا | AE45: =AE23-1 -> -11 | AF45: دولة ليبيا | AT45: =AT23-1 -> -16 | AU45: دولة ليبيا
A46: وزارة التعليم | P46: وزارة التعليم | AE46: وزارة التعليم | AT46: وزارة التعليم
A47: المركز الوطني للامتحانات | P47: المركز الوطني للامتحانات | AE47: المركز الوطني للامتحانات | AT47: المركز الوطني للامتحانات
A48: بطاقة تقدير الدرجات لمرحلة التعليم | K48: =ادخال1!$CD$7 -> الاساسي | P48: بطاقة تقدير الدرجات لمرحلة التعليم | Z48: =ادخال1!$CD$7 -> الاساسي | AE48: بطاقة تقدير الدرجات لمرحلة التعليم | AO48: =ادخال1!$CD$7 -> الاساسي | AT48: بطاقة تقدير الدرجات لمرحلة التعليم | BD48: =ادخال1!$CD$7 -> الاساسي
...

Sheet الرئيسية

Sheet صحيفة الفترات
A1: بطاقة تقدير الدرجات للصــــف | D1: =ادخال1!$K$4 -> الثاني | F1: من التعليم الأساسي | J1: 1 | L1: بطاقة تقدير الدرجات للصــــف | O1: =ادخال1!$K$4 -> الثاني | Q1: من التعليم الأساسي | U1: =J1+5 -> 6 | W1: بطاقة تقدير الدرجات للصــــف | Z1: =ادخال1!$K$4 -> الثاني | AB1: من التعليم الأساسي | AF1: =U1+5 -> 11 | AH1: بطاقة تقدير الدرجات للصــــف | AK1: =ادخال1!$K$4 -> الثاني | AM1: من التعليم الأساسي | AQ1: =AF1+5 -> 16
A2: المدرسة/ | B2: =ادخال1!$B$5 -> سهول العلم للتعليم الخاص | F2: الاسم | G2: =H14 -> الجبير خليل الدوكالي اليونسي | M2: =ادخال1!$B$5 -> سهول العلم للتعليم الخاص | Q2: الاسم | R2: =S14 -> سوزان عبدالباسط اللافى محمد | W2: المدرسة/ | X2: =ادخال1!$B$5 -> سهول العلم للتعليم الخاص | AB2: الاسم | AC2: =AD14 -> ميرال صالح محمد ديماس | AH2: المدرسة/ | AI2: =ادخال1!$B$5 -> سهول العلم للتعليم الخاص | AM2: الاسم | AN2: =AO14 -> 0
A3: الفترات | B3: عدد الحصص | C3: الفترة الأولي 30 % | E3: الفترة الثانية 30 % | H3: ملاحظــات عن نتيجة التلميذ خلال كل فترة : | L3: الفترات | M3: عدد الحصص | N3: الفترة الأولي 30 % | P3: الفترة الثانية 30 % | S3: ملاحظــات عن نتيجة التلميذ خلال كل فترة : | W3: الفترات | X3: عدد الحصص | Y3: الفترة الأولي 30 % | AA3: الفترة الثانية 30 % | AD3: ملاحظــات عن نتيجة التلميذ خلال كل فترة : | AH3: الفترات | AI3: عدد الحصص | AJ3: الفترة الأولي 30 % | AL3: الفترة الثانية 30 % | AO3: ملاحظــات عن نتيجة التلميذ خلال كل فترة :
A4: المواد الدراسية | C4: الدرجة الكبرى | D4: درجة التلميذ | E4: الدرجة الكبرى | F4: درجة التلميذ | H4: الأولي : | I4: =IF(D10=0,"",IF(AND(D5>=C5*0.4,D6>=C6*0.4,D7>=C7*0.4,D8>=C8*0.4,D9>=C9*0.4),LOOKUP(D10,'النتيجة النهائية'!$AA$6:$AB$10),"ضعيف ويحتاج الى اهتمام في المواد")) -> مقبول | L4: المواد الدراسية | N4: الدرجة الكبرى | O4: درجة التلميذ | P4: الدرجة الكبرى | Q4: درجة التلميذ | S4: الأولي : | T4: =IF(O10=0,"",IF(AND(O5>=N5*0.4,O6>=N6*0.4,O7>=N7*0.4,O8>=N8*0.4,O9>=N9*0.4),LOOKUP(O10,'النتيجة النهائية'!$AA$6:$AB$10),"ضعيف ويحتاج الى اهتمام في المواد")) -> ممتاز | W4: المواد الدراسية | Y4: الدرجة الكبرى | Z4: درجة التلميذ | AA4: الدرجة الكبرى | AB4: درجة التلميذ | AD4: الأولي : | AE4: =IF(Z10=0,"",IF(AND(Z5>=Y5*0.4,Z6>=Y6*0.4,Z7>=Y7*0.4,Z8>=Y8*0.4,Z9>=Y9*0.4),LOOKUP(Z10,'النتيجة النهائية'!$AA$6:$AB$10),"ضعيف ويحتاج الى اهتمام في المواد")) -> ممتاز | AH4: المواد الدراسية | AJ4: الدرجة الكبرى | AK4: درجة التلميذ | AL4: الدرجة الكبرى | AM4: درجة التلميذ | AO4: الأولي : | AP4: =IF(AK10=0,"",IF(AND(AK5>=AJ5*0.4,AK6>=AJ6*0.4,AK7>=AJ7*0.4,AK8>=AJ8*0.4,AK9>=AJ9*0.4),LOOKUP(AK10,'النتيجة النهائية'!$AA$6:$AB$10),"ضعيف ويحتاج الى اهتمام في المواد"))
A5: =ادخال1!$F$9 -> التربية الإسلامية | B5: =ادخال1!$F$7 -> 3 | C5: =40*B5*0.3 -> 36 | D5: =IFERROR(VLOOKUP(H14,اسماء,5,0),"") -> 25 | E5: =40*B5*0.3 -> 36 | F5: =IFERROR(VLOOKUP(H14,اسماء,15,0),"") -> 0 | H5: =IF(D5=0,"",IF(D5<C5*0.4,A5,"")) | I5: =IF(D6=0,"",IF(D6<C6*0.4,A6,"")) | J5: =IF(D7=0,"",IF(D7<C7*0.4,A7,"")) | L5: =ادخال1!$F$9 -> التربية الإسلامية | M5: =ادخال1!$F$7 -> 3 | N5: =40*M5*0.3 -> 36 | O5: =IFERROR(VLOOKUP(S14,اسماء,5,0),"") -> 36 | P5: =40*M5*0.3 -> 36 | Q5: =IFERROR(VLOOKUP(S14,اسماء,15,0),"") -> 0 | S5: =IF(O5=0,"",IF(O5<N5*0.4,L5,"")) | T5: =IF(O6=0,"",IF(O6<N6*0.4,L6,"")) | U5: =IF(O7=0,"",IF(O7<N7*0.4,L7,"")) | W5: =ادخال1!$F$9 -> التربية الإسلامية | X5: =ادخال1!$F$7 -> 3 | Y5: =40*X5*0.3 -> 36 | Z5: =IFERROR(VLOOKUP(AD14,اسماء,5,0),"") -> 36 | AA5: =40*X5*0.3 -> 36 | AB5: =IFERROR(VLOOKUP(AD14,اسماء,15,0),"") -> 0 | AD5: =IF(Z5=0,"",IF(Z5<Y5*0.4,W5,"")) | AE5: =IF(Z6=0,"",IF(Z6<Y6*0.4,W6,"")) | AF5: =IF(Z7=0,"",IF(Z7<Y7*0.4,W7,"")) | AH5: =ادخال1!$F$9 -> التربية الإسلامية | AI5: =ادخال1!$F$7 -> 3 | AJ5: =40*AI5*0.3 -> 36 | AK5: =IFERROR(VLOOKUP(AO14,اسماء,5,0),"") | AL5: =40*AI5*0.3 -> 36 | AM5: =IFERROR(VLOOKUP(AO14,اسماء,15,0),"") | AO5: =IF(AK5=0,"",IF(AK5<AJ5*0.4,AH5,"")) | AP5: =IF(AK6=0,"",IF(AK6<AJ6*0.4,AH6,"")) | AQ5: =IF(AK7=0,"",IF(AK7<AJ7*0.4,AH7,""))
A6: =ادخال1!$G$9 -> اللغة العربية | B6: =ادخال1!$G$7 -> 6 | C6: =40*B6*0.3 -> 72 | D6: =IFERROR(VLOOKUP(H14,اسماء,6,0),"") -> 54 | E6: =40*B6*0.3 -> 72 | F6: =IFERROR(VLOOKUP(H14,اسماء,16,0),"") -> 0 | H6: =IF(D8=0,"",IF(D8<C8*0.4,A8,"")) | I6: =IF(D9=0,"",IF(D9<C9*0.4,A9,"")) | L6: =ادخال1!$G$9 -> اللغة العربية | M6: =ادخال1!$G$7 -> 6 | N6: =40*M6*0.3 -> 72 | O6: =IFERROR(VLOOKUP(S14,اسماء,6,0),"") -> 70 | P6: =40*M6*0.3 -> 72 | Q6: =IFERROR(VLOOKUP(S14,اسماء,16,0),"") -> 0 | S6: =IF(O8=0,"",IF(O8<N8*0.4,L8,"")) | T6: =IF(O9=0,"",IF(O9<N9*0.4,L9,"")) | W6: =ادخال1!$G$9 -> اللغة العربية | X6: =ادخال1!$G$7 -> 6 | Y6: =40*X6*0.3 -> 72 | Z6: =IFERROR(VLOOKUP(AD14,اسماء,6,0),"") -> 66 | AA6: =40*X6*0.3 -> 72 | AB6: =IFERROR(VLOOKUP(AD14,اسماء,16,0),"") -> 0 | AD6: =IF(Z8=0,"",IF(Z8<Y8*0.4,W8,"")) | AE6: =IF(Z9=0,"",IF(Z9<Y9*0.4,W9,"")) | AH6: =ادخال1!$G$9 -> اللغة العربية | AI6: =ادخال1!$G$7 -> 6 | AJ6: =40*AI6*0.3 -> 72 | AK6: =IFERROR(VLOOKUP(AO14,اسماء,6,0),"") | AL6: =40*AI6*0.3 -> 72 | AM6: =IFERROR(VLOOKUP(AO14,اسماء,16,0),"") | AO6: =IF(AK8=0,"",IF(AK8<AJ8*0.4,AH8,"")) | AP6: =IF(AK9=0,"",IF(AK9<AJ9*0.4,AH9,""))
A7: =ادخال1!$H$9 -> اللغة الإنجليزية | B7: =ادخال1!$H$7 -> 3 | C7: =40*B7*0.3 -> 36 | D7: =IFERROR(VLOOKUP(H14,اسماء,7,0),"") -> 25 | E7: =40*B7*0.3 -> 36 | F7: =IFERROR(VLOOKUP(H14,اسماء,17,0),"") -> 0 | H7: الثانية :- | I7: =IF(F10=0,"",IF(AND(F5>=E5*0.4,F6>=E6*0.4,F7>=E7*0.4,F8>=E8*0.4,F9>=E9*0.4),LOOKUP(F10,'النتيجة النهائية'!$AA$6:$AB$10),"ضعيف ويحتاج الى اهتمام في المواد")) | L7: =ادخال1!$H$9 -> اللغة الإنجليزية | M7: =ادخال1!$H$7 -> 3 | N7: =40*M7*0.3 -> 36 | O7: =IFERROR(VLOOKUP(S14,اسماء,7,0),"") -> 36 | P7: =40*M7*0.3 -> 36 | Q7: =IFERROR(VLOOKUP(S14,اسماء,17,0),"") -> 0 | S7: الثانية :- | T7: =IF(Q10=0,"",IF(AND(Q5>=P5*0.4,Q6>=P6*0.4,Q7>=P7*0.4,Q8>=P8*0.4,Q9>=P9*0.4),LOOKUP(Q10,'النتيجة النهائية'!$AA$6:$AB$10),"ضعيف ويحتاج الى اهتمام في المواد")) | W7: =ادخال1!$H$9 -> اللغة الإنجليزية | X7: =ادخال1!$H$7 -> 3 | Y7: =40*X7*0.3 -> 36 | Z7: =IFERROR(VLOOKUP(AD14,اسماء,7,0),"") -> 36 | AA7: =40*X7*0.3 -> 36 | AB7: =IFERROR(VLOOKUP(AD14,اسماء,17,0),"") -> 0 | AD7: الثانية :- | AE7: =IF(AB10=0,"",IF(AND(AB5>=AA5*0.4,AB6>=AA6*0.4,AB7>=AA7*0.4,AB8>=AA8*0.4,AB9>=AA9*0.4),LOOKUP(AB10,'النتيجة النهائية'!$AA$6:$AB$10),"ضعيف ويحتاج الى اهتمام في المواد")) | AH7: =ادخال1!$H$9 -> اللغة الإنجليزية | AI7: =ادخال1!$H$7 -> 3 | AJ7: =40*AI7*0.3 -> 36 | AK7: =IFERROR(VLOOKUP(AO14,اسماء,7,0),"") | AL7: =40*AI7*0.3 -> 36 | AM7: =IFERROR(VLOOKUP(AO14,اسماء,17,0),"") | AO7: الثانية :- | AP7: =IF(AM10=0,"",IF(AND(AM5>=AL5*0.4,AM6>=AL6*0.4,AM7>=AL7*0.4,AM8>=AL8*0.4,AM9>=AL9*0.4),LOOKUP(AM10,'النتيجة النهائية'!$AA$6:$AB$10),"ضعيف ويحتاج الى اهتمام في المواد"))
A8: =ادخال1!$I$9 -> الحاسوب | B8: =ادخال1!$I$7 -> 1 | C8: =40*B8*0.3 -> 12 | D8: =IFERROR(VLOOKUP(H14,اسماء,8,0),"") -> 10 | E8: =40*B8*0.3 -> 12 | F8: =IFERROR(VLOOKUP(H14,اسماء,18,0),"") -> 0 | H8: =IF(F5=0,"",IF(F5<E5*0.4,A5,"")) | I8: =IF(F6=0,"",IF(F6<E6*0.4,A6,"")) | J8: =IF(F7=0,"",IF(F7<E7*0.4,A7,"")) | L8: =ادخال1!$I$9 -> الحاسوب | M8: =ادخال1!$I$7 -> 1 | N8: =40*M8*0.3 -> 12 | O8: =IFERROR(VLOOKUP(S14,اسماء,8,0),"") -> 12 | P8: =40*M8*0.3 -> 12 | Q8: =IFERROR(VLOOKUP(S14,اسماء,18,0),"") -> 0 | S8: =IF(Q5=0,"",IF(Q5<P5*0.4,L5,"")) | T8: =IF(Q6=0,"",IF(Q6<P6*0.4,L6,"")) | U8: =IF(Q7=0,"",IF(Q7<P7*0.4,L7,"")) | W8: =ادخال1!$I$9 -> الحاسوب | X8: =ادخال1!$I$7 -> 1 | Y8: =40*X8*0.3 -> 12 | Z8: =IFERROR(VLOOKUP(AD14,اسماء,8,0),"") -> 12 | AA8: =40*X8*0.3 -> 12 | AB8: =IFERROR(VLOOKUP(AD14,اسماء,18,0),"") -> 0 | AD8: =IF(AB5=0,"",IF(AB5<AA5*0.4,W5,"")) | AE8: =IF(AB6=0,"",IF(AB6<AA6*0.4,W6,"")) | AF8: =IF(AB7=0,"",IF(AB7<AA7*0.4,W7,"")) | AH8: =ادخال1!$I$9 -> الحاسوب | AI8: =ادخال1!$I$7 -> 1 | AJ8: =40*AI8*0.3 -> 12 | AK8: =IFERROR(VLOOKUP(AO14,اسماء,8,0),"") | AL8: =40*AI8*0.3 -> 12 | AM8: =IFERROR(VLOOKUP(AO14,اسماء,18,0),"") | AO8: =IF(AM5=0,"",IF(AM5<AL5*0.4,AH5,"")) | AP8: =IF(AM6=0,"",IF(AM6<AL6*0.4,AH6,"")) | AQ8: =IF(AM7=0,"",IF(AM7<AL7*0.4,AH7,""))
A9: =ادخال1!$J$9 -> الرياضيات | B9: =ادخال1!$J$7 -> 5 | C9: =40*B9*0.3 -> 60 | D9: =IFERROR(VLOOKUP(H14,اسماء,9,0),"") -> 24 | E9: =40*B9*0.3 -> 60 | F9: =IFERROR(VLOOKUP(H14,اسماء,19,0),"") -> 0 | H9: =IF(F8=0,"",IF(F8<E8*0.4,A8,"")) | I9: =IF(F9=0,"",IF(F9<E9*0.4,A9,"")) | L9: =ادخال1!$J$9 -> الرياضيات | M9: =ادخال1!$J$7 -> 5 | N9: =40*M9*0.3 -> 60 | O9: =IFERROR(VLOOKUP(S14,اسماء,9,0),"") -> 60 | P9: =40*M9*0.3 -> 60 | Q9: =IFERROR(VLOOKUP(S14,اسماء,19,0),"") -> 0 | S9: =IF(Q8=0,"",IF(Q8<P8*0.4,L8,"")) | T9: =IF(Q9=0,"",IF(Q9<P9*0.4,L9,"")) | W9: =ادخال1!$J$9 -> الرياضيات | X9: =ادخال1!$J$7 -> 5 | Y9: =40*X9*0.3 -> 60 | Z9: =IFERROR(VLOOKUP(AD14,اسماء,9,0),"") -> 60 | AA9: =40*X9*0.3 -> 60 | AB9: =IFERROR(VLOOKUP(AD14,اسماء,19,0),"") -> 0 | AD9: =IF(AB8=0,"",IF(AB8<AA8*0.4,W8,"")) | AE9: =IF(AB9=0,"",IF(AB9<AA9*0.4,W9,"")) | AH9: =ادخال1!$J$9 -> الرياضيات | AI9: =ادخال1!$J$7 -> 5 | AJ9: =40*AI9*0.3 -> 60 | AK9: =IFERROR(VLOOKUP(AO14,اسماء,9,0),"") | AL9: =40*AI9*0.3 -> 60 | AM9: =IFERROR(VLOOKUP(AO14,اسماء,19,0),"") | AO9: =IF(AM8=0,"",IF(AM8<AL8*0.4,AH8,"")) | AP9: =IF(AM9=0,"",IF(AM9<AL9*0.4,AH9,""))
A10: المجموع العـام | C10: =SUM(C5:C9) -> 216 | D10: =SUM(D5:D9) -> 138 | E10: =SUM(E5:E9) -> 216 | F10: =SUM(F5:F9) -> 0 | H10: مدير المدرسة/ | I10: =ادخال1!$BG$5 -> د. عبدالرحمن خليفة العريبي | L10: المجموع العـام | N10: =SUM(N5:N9) -> 216 | O10: =SUM(O5:O9) -> 214 | P10: =SUM(P5:P9) -> 216 | Q10: =SUM(Q5:Q9) -> 0 | S10: مدير المدرسة/ | T10: =ادخال1!$BG$5 -> د. عبدالرحمن خليفة العريبي | W10: المجموع العـام | Y10: =SUM(Y5:Y9) -> 216 | Z10: =SUM(Z5:Z9) -> 210 | AA10: =SUM(AA5:AA9) -> 216 | AB10: =SUM(AB5:AB9) -> 0 | AD10: مدير المدرسة/ | AE10: =ادخال1!$BG$5 -> د. عبدالرحمن خليفة العريبي | AH10: المجموع العـام | AJ10: =SUM(AJ5:AJ9) -> 216 | AK10: =SUM(AK5:AK9) -> 0 | AL10: =SUM(AL5:AL9) -> 216 | AM10: =SUM(AM5:AM9) -> 0 | AO10: مدير المدرسة/ | AP10: =ادخال1!$BG$5 -> د. عبدالرحمن خليفة العريبي
A11: =ادخال1!$L$8 -> التربية الفنية | B11: =ادخال1!$L$7 -> 1 | C11: =IFERROR(VLOOKUP(H14,اسماء,11,0),"") -> جيد جداَ | E11: =IFERROR(VLOOKUP(H14,اسماء,21,0),"") -> 0 | H11: التاريخ | I11: =TODAY() -> 46005 | L11: =ادخال1!$L$8 -> التربية الفنية | M11: =ادخال1!$L$7 -> 1 | N11: =IFERROR(VLOOKUP(S14,اسماء,11,0),"") -> جيد جداَ | P11: =IFERROR(VLOOKUP(S14,اسماء,21,0),"") -> 0 | S11: التاريخ | T11: =TODAY() -> 46005 | W11: =ادخال1!$L$8 -> التربية الفنية | X11: =ادخال1!$L$7 -> 1 | Y11: =IFERROR(VLOOKUP(AD14,اسماء,11,0),"") -> جيد جداَ | AA11: =IFERROR(VLOOKUP(AD14,اسماء,21,0),"") -> 0 | AD11: التاريخ | AE11: =TODAY() -> 46005 | AH11: =ادخال1!$L$8 -> التربية الفنية | AI11: =ادخال1!$L$7 -> 1 | AJ11: =IFERROR(VLOOKUP(AO14,اسماء,11,0),"") | AL11: =IFERROR(VLOOKUP(AO14,اسماء,21,0),"") | AO11: التاريخ | AP11: =TODAY() -> 46005
A12: =ادخال1!$M$8 -> التربية البدنية | B12: =ادخال1!$M$7 -> 2 | C12: =IFERROR(VLOOKUP(H14,اسماء,12,0),"") -> جيد جداَ | E12: =IFERROR(VLOOKUP(H14,اسماء,22,0),"") -> 0 | L12: =ادخال1!$M$8 -> التربية البدنية | M12: =ادخال1!$M$7 -> 2 | N12: =IFERROR(VLOOKUP(S14,اسماء,12,0),"") -> جيد جداَ | P12: =IFERROR(VLOOKUP(S14,اسماء,22,0),"") -> 0 | W12: =ادخال1!$M$8 -> التربية البدنية | X12: =ادخال1!$M$7 -> 2 | Y12: =IFERROR(VLOOKUP(AD14,اسماء,12,0),"") -> جيد جداَ | AA12: =IFERROR(VLOOKUP(AD14,اسماء,22,0),"") -> 0 | AH12: =ادخال1!$M$8 -> التربية البدنية | AI12: =ادخال1!$M$7 -> 2 | AJ12: =IFERROR(VLOOKUP(AO14,اسماء,12,0),"") | AL12: =IFERROR(VLOOKUP(AO14,اسماء,22,0),"")
A13: =ادخال1!$N$8 -> مكتبة | B13: =ادخال1!$N$7 -> 1 | C13: =IFERROR(VLOOKUP(H14,اسماء,13,0),"") -> 0 | E13: =IFERROR(VLOOKUP(H14,اسماء,23,0),"") -> 0 | L13: =ادخال1!$N$8 -> مكتبة | M13: =ادخال1!$N$7 -> 1 | N13: =IFERROR(VLOOKUP(S14,اسماء,13,0),"") -> 0 | P13: =IFERROR(VLOOKUP(S14,اسماء,23,0),"") -> 0 | W13: =ادخال1!$N$8 -> مكتبة | X13: =ادخال1!$N$7 -> 1 | Y13: =IFERROR(VLOOKUP(AD14,اسماء,13,0),"") -> 0 | AA13: =IFERROR(VLOOKUP(AD14,اسماء,23,0),"") -> 0 | AH13: =ادخال1!$N$8 -> مكتبة | AI13: =ادخال1!$N$7 -> 1 | AJ13: =IFERROR(VLOOKUP(AO14,اسماء,13,0),"") | AL13: =IFERROR(VLOOKUP(AO14,اسماء,23,0),"")
A14: الرقم الوطني | B14: =IFERROR(VLOOKUP(H14,اسماء,62,0),"") -> 120171064725 | C14: =IFERROR(VLOOKUP(G19,اسماء,8,0),"") | D14: =IFERROR(VLOOKUP(H19,اسماء,8,0),"") | E14: =IFERROR(VLOOKUP(I19,اسماء,8,0),"") | H14: =INDEX(عمود2,MATCH(J1,عمود1)) -> الجبير خليل الدوكالي اليونسي | L14: الرقم الوطني | M14: =IFERROR(VLOOKUP(S14,اسماء,62,0),"") -> 220180204533 | N14: =IFERROR(VLOOKUP(R19,اسماء,8,0),"") | O14: =IFERROR(VLOOKUP(S19,اسماء,8,0),"") | P14: =IFERROR(VLOOKUP(T19,اسماء,8,0),"") | S14: =INDEX(عمود2,MATCH(U1,عمود1)) -> سوزان عبدالباسط اللافى محمد | W14: الرقم الوطني | X14: =IFERROR(VLOOKUP(AD14,اسماء,62,0),"") -> 0 | Y14: =IFERROR(VLOOKUP(AC19,اسماء,8,0),"") | Z14: =IFERROR(VLOOKUP(AD19,اسماء,8,0),"") | AA14: =IFERROR(VLOOKUP(AE19,اسماء,8,0),"") | AD14: =INDEX(عمود2,MATCH(AF1,عمود1)) -> ميرال صالح محمد ديماس | AH14: الرقم الوطني | AI14: =IFERROR(VLOOKUP(AO14,اسماء,62,0),"") | AJ14: =IFERROR(VLOOKUP(AN19,اسماء,8,0),"") | AK14: =IFERROR(VLOOKUP(AO19,اسماء,8,0),"") | AL14: =IFERROR(VLOOKUP(AP19,اسماء,8,0),"") | AO14: =INDEX(عمود2,MATCH(AQ1,عمود1)) -> 0
A15: الســــــلوك | C15: =IFERROR(VLOOKUP(H14,اسماء,34,0),"") -> 0 | E15: =IFERROR(VLOOKUP(H14,اسماء,35,0),"") -> 0 | H15: كل كشط أو تغيير في هذه البطاقة يلغيها. | L15: الســــــلوك | N15: =IFERROR(VLOOKUP(S14,اسماء,34,0),"") -> 0 | P15: =IFERROR(VLOOKUP(S14,اسماء,35,0),"") -> 0 | S15: كل كشط أو تغيير في هذه البطاقة يلغيها. | W15: الســــــلوك | Y15: =IFERROR(VLOOKUP(AD14,اسماء,34,0),"") -> 0 | AA15: =IFERROR(VLOOKUP(AD14,اسماء,35,0),"") -> 0 | AD15: كل كشط أو تغيير في هذه البطاقة يلغيها. | AH15: الســــــلوك | AJ15: =IFERROR(VLOOKUP(AO14,اسماء,34,0),"") | AL15: =IFERROR(VLOOKUP(AO14,اسماء,35,0),"") | AO15: كل كشط أو تغيير في هذه البطاقة يلغيها.
A16: غياب مشروع | C16: =IFERROR(VLOOKUP(H14,اسماء,37,0),"") -> 0 | E16: =IFERROR(VLOOKUP(H14,اسماء,39,0),"") -> 0 | L16: غياب مشروع | N16: =IFERROR(VLOOKUP(S14,اسماء,37,0),"") -> 0 | P16: =IFERROR(VLOOKUP(S14,اسماء,39,0),"") -> 0 | W16: غياب مشروع | Y16: =IFERROR(VLOOKUP(AD14,اسماء,37,0),"") -> 0 | AA16: =IFERROR(VLOOKUP(AD14,اسماء,39,0),"") -> 0 | AH16: غياب مشروع | AJ16: =IFERROR(VLOOKUP(AO14,اسماء,37,0),"") | AL16: =IFERROR(VLOOKUP(AO14,اسماء,39,0),"")
A17: غياب غير مشروع | C17: =IFERROR(VLOOKUP(H14,اسماء,38,0),"") -> 0 | E17: =IFERROR(VLOOKUP(H14,اسماء,40,0),"") -> 0 | L17: غياب غير مشروع | N17: =IFERROR(VLOOKUP(S14,اسماء,38,0),"") -> 0 | P17: =IFERROR(VLOOKUP(S14,اسماء,40,0),"") -> 0 | W17: غياب غير مشروع | Y17: =IFERROR(VLOOKUP(AD14,اسماء,38,0),"") -> 0 | AA17: =IFERROR(VLOOKUP(AD14,اسماء,40,0),"") -> 0 | AH17: غياب غير مشروع | AJ17: =IFERROR(VLOOKUP(AO14,اسماء,38,0),"") | AL17: =IFERROR(VLOOKUP(AO14,اسماء,40,0),"")
A19: التوقيعــــات | B19: رائــد الصف | D19: مديـر المدرسة | H19: ولي الامر | L19: التوقيعــــات | M19: رائــد الصف | O19: مديـر المدرسة | S19: ولي الامر | W19: التوقيعــــات | X19: رائــد الصف | Z19: مديـر المدرسة | AD19: ولي الامر | AH19: التوقيعــــات | AI19: رائــد الصف | AK19: مديـر المدرسة | AO19: ولي الامر
A20: الفترة الاولى | L20: الفترة الاولى | W20: الفترة الاولى | AH20: الفترة الاولى
A21: الفترة الثانية | L21: الفترة الثانية | W21: الفترة الثانية | AH21: الفترة الثانية
A23: بطاقة تقدير الدرجات للصــــف | D23: =ادخال1!$K$4 -> الثاني | F23: من التعليم الأساسي | J23: =J1+1 -> 2 | L23: بطاقة تقدير الدرجات للصــــف | O23: =ادخال1!$K$4 -> الثاني | Q23: من التعليم الأساسي | U23: =U1+1 -> 7 | W23: بطاقة تقدير الدرجات للصــــف | Z23: =ادخال1!$K$4 -> الثاني | AB23: من التعليم الأساسي | AF23: =AF1+1 -> 12 | AH23: بطاقة تقدير الدرجات للصــــف | AK23: =ادخال1!$K$4 -> الثاني | AM23: من التعليم الأساسي | AQ23: =AQ1+1 -> 17
A24: المدرسة/ | B24: =ادخال1!$B$5 -> سهول العلم للتعليم الخاص | F24: الاسم | G24: =H36 -> ديالا علي حمد القبائلي | L24: المدرسة/ | M24: =ادخال1!$B$5 -> سهول العلم للتعليم الخاص | Q24: الاسم | R24: =S36 -> عبدالرحمن فرج محمد المغربي | W24: المدرسة/ | X24: =ادخال1!$B$5 -> سهول العلم للتعليم الخاص | AB24: الاسم | AC24: =AD36 -> ندى علاء محمد سلطان | AH24: المدرسة/ | AI24: =ادخال1!$B$5 -> سهول العلم للتعليم الخاص | AM24: الاسم | AN24: =AO36 -> 0
A25: الفترات | B25: عدد الحصص | C25: الفترة الأولي 30 % | E25: الفترة الثانية 30 % | H25: ملاحظــات عن نتيجة التلميذ خلال كل فترة : | L25: الفترات | M25: عدد الحصص | N25: الفترة الأولي 30 % | P25: الفترة الثانية 30 % | S25: ملاحظــات عن نتيجة التلميذ خلال كل فترة : | W25: الفترات | X25: عدد الحصص | Y25: الفترة الأولي 30 % | AA25: الفترة الثانية 30 % | AD25: ملاحظــات عن نتيجة التلميذ خلال كل فترة : | AH25: الفترات | AI25: عدد الحصص | AJ25: الفترة الأولي 30 % | AL25: الفترة الثانية 30 % | AO25: ملاحظــات عن نتيجة التلميذ خلال كل فترة :
A26: المواد الدراسية | C26: الدرجة الكبرى | D26: درجة التلميذ | E26: الدرجة الكبرى | F26: درجة التلميذ | H26: الأولي : | I26: =IF(D32=0,"",IF(AND(D27>=C27*0.4,D28>=C28*0.4,D29>=C29*0.4,D30>=C30*0.4,D31>=C31*0.4),LOOKUP(D32,'النتيجة النهائية'!$AA$6:$AB$10),"ضعيف ويحتاج الى اهتمام في المواد")) -> ممتاز | L26: المواد الدراسية | N26: الدرجة الكبرى | O26: درجة التلميذ | P26: الدرجة الكبرى | Q26: درجة التلميذ | S26: الأولي : | T26: =IF(O32=0,"",IF(AND(O27>=N27*0.4,O28>=N28*0.4,O29>=N29*0.4,O30>=N30*0.4,O31>=N31*0.4),LOOKUP(O32,'النتيجة النهائية'!$AA$6:$AB$10),"ضعيف ويحتاج الى اهتمام في المواد")) -> ممتاز | W26: المواد الدراسية | Y26: الدرجة الكبرى | Z26: درجة التلميذ | AA26: الدرجة الكبرى | AB26: درجة التلميذ | AD26: الأولي : | AE26: =IF(Z32=0,"",IF(AND(Z27>=Y27*0.4,Z28>=Y28*0.4,Z29>=Y29*0.4,Z30>=Y30*0.4,Z31>=Y31*0.4),LOOKUP(Z32,'النتيجة النهائية'!$AA$6:$AB$10),"ضعيف ويحتاج الى اهتمام في المواد")) -> ممتاز | AH26: المواد الدراسية | AJ26: الدرجة الكبرى | AK26: درجة التلميذ | AL26: الدرجة الكبرى | AM26: درجة التلميذ | AO26: الأولي : | AP26: =IF(AK32=0,"",IF(AND(AK27>=AJ27*0.4,AK28>=AJ28*0.4,AK29>=AJ29*0.4,AK30>=AJ30*0.4,AK31>=AJ31*0.4),LOOKUP(AK32,'النتيجة النهائية'!$AA$6:$AB$10),"ضعيف ويحتاج الى اهتمام في المواد"))
A27: =ادخال1!$F$9 -> التربية الإسلامية | B27: =ادخال1!$F$7 -> 3 | C27: =40*B27*0.3 -> 36 | D27: =IFERROR(VLOOKUP(H36,اسماء,5,0),"") -> 34 | E27: =40*B27*0.3 -> 36 | F27: =IFERROR(VLOOKUP(H36,اسماء,15,0),"") -> 0 | H27: =IF(D27=0,"",IF(D27<C27*0.4,A27,"")) | I27: =IF(D28=0,"",IF(D28<C28*0.4,A28,"")) | J27: =IF(D29=0,"",IF(D29<C29*0.4,A29,"")) | L27: =ادخال1!$F$9 -> التربية الإسلامية | M27: =ادخال1!$F$7 -> 3 | N27: =40*M27*0.3 -> 36 | O27: =IFERROR(VLOOKUP(S36,اسماء,5,0),"") -> 32 | P27: =40*M27*0.3 -> 36 | Q27: =IFERROR(VLOOKUP(S36,اسماء,15,0),"") -> 0 | S27: =IF(O27=0,"",IF(O27<N27*0.4,L27,"")) | T27: =IF(O28=0,"",IF(O28<N28*0.4,L28,"")) | U27: =IF(O29=0,"",IF(O29<N29*0.4,L29,"")) | W27: =ادخال1!$F$9 -> التربية الإسلامية | X27: =ادخال1!$F$7 -> 3 | Y27: =40*X27*0.3 -> 36 | Z27: =IFERROR(VLOOKUP(AD36,اسماء,5,0),"") -> 35 | AA27: =40*X27*0.3 -> 36 | AB27: =IFERROR(VLOOKUP(AD36,اسماء,15,0),"") -> 0 | AD27: =IF(Z27=0,"",IF(Z27<Y27*0.4,W27,"")) | AE27: =IF(Z28=0,"",IF(Z28<Y28*0.4,W28,"")) | AF27: =IF(Z29=0,"",IF(Z29<Y29*0.4,W29,"")) | AH27: =ادخال1!$F$9 -> التربية الإسلامية | AI27: =ادخال1!$F$7 -> 3 | AJ27: =40*AI27*0.3 -> 36 | AK27: =IFERROR(VLOOKUP(AO36,اسماء,5,0),"") | AL27: =40*AI27*0.3 -> 36 | AM27: =IFERROR(VLOOKUP(AO36,اسماء,15,0),"") | AO27: =IF(AK27=0,"",IF(AK27<AJ27*0.4,AH27,"")) | AP27: =IF(AK28=0,"",IF(AK28<AJ28*0.4,AH28,"")) | AQ27: =IF(AK29=0,"",IF(AK29<AJ29*0.4,AH29,""))
A28: =ادخال1!$G$9 -> اللغة العربية | B28: =ادخال1!$G$7 -> 6 | C28: =40*B28*0.3 -> 72 | D28: =IFERROR(VLOOKUP(H36,اسماء,6,0),"") -> 70 | E28: =40*B28*0.3 -> 72 | F28: =IFERROR(VLOOKUP(H36,اسماء,16,0),"") -> 0 | H28: =IF(D30=0,"",IF(D30<C30*0.4,A30,"")) | I28: =IF(D31=0,"",IF(D31<C31*0.4,A31,"")) | L28: =ادخال1!$G$9 -> اللغة العربية | M28: =ادخال1!$G$7 -> 6 | N28: =40*M28*0.3 -> 72 | O28: =IFERROR(VLOOKUP(S36,اسماء,6,0),"") -> 70 | P28: =40*M28*0.3 -> 72 | Q28: =IFERROR(VLOOKUP(S36,اسماء,16,0),"") -> 0 | S28: =IF(O30=0,"",IF(O30<N30*0.4,L30,"")) | T28: =IF(O31=0,"",IF(O31<N31*0.4,L31,"")) | W28: =ادخال1!$G$9 -> اللغة العربية | X28: =ادخال1!$G$7 -> 6 | Y28: =40*X28*0.3 -> 72 | Z28: =IFERROR(VLOOKUP(AD36,اسماء,6,0),"") -> 69 | AA28: =40*X28*0.3 -> 72 | AB28: =IFERROR(VLOOKUP(AD36,اسماء,16,0),"") -> 0 | AD28: =IF(Z30=0,"",IF(Z30<Y30*0.4,W30,"")) | AE28: =IF(Z31=0,"",IF(Z31<Y31*0.4,W31,"")) | AH28: =ادخال1!$G$9 -> اللغة العربية | AI28: =ادخال1!$G$7 -> 6 | AJ28: =40*AI28*0.3 -> 72 | AK28: =IFERROR(VLOOKUP(AO36,اسماء,6,0),"") | AL28: =40*AI28*0.3 -> 72 | AM28: =IFERROR(VLOOKUP(AO36,اسماء,16,0),"") | AO28: =IF(AK30=0,"",IF(AK30<AJ30*0.4,AH30,"")) | AP28: =IF(AK31=0,"",IF(AK31<AJ31*0.4,AH31,""))
A29: =ادخال1!$H$9 -> اللغة الإنجليزية | B29: =ادخال1!$H$7 -> 3 | C29: =40*B29*0.3 -> 36 | D29: =IFERROR(VLOOKUP(H36,اسماء,7,0),"") -> 36 | E29: =40*B29*0.3 -> 36 | F29: =IFERROR(VLOOKUP(H36,اسماء,17,0),"") -> 0 | H29: الثانية :- | I29: =IF(F32=0,"",IF(AND(F27>=E27*0.4,F28>=E28*0.4,F29>=E29*0.4,F30>=E30*0.4,F31>=E31*0.4),LOOKUP(F32,'النتيجة النهائية'!$AA$6:$AB$10),"ضعيف ويحتاج الى اهتمام في المواد")) | L29: =ادخال1!$H$9 -> اللغة الإنجليزية | M29: =ادخال1!$H$7 -> 3 | N29: =40*M29*0.3 -> 36 | O29: =IFERROR(VLOOKUP(S36,اسماء,7,0),"") -> 36 | P29: =40*M29*0.3 -> 36 | Q29: =IFERROR(VLOOKUP(S36,اسماء,17,0),"") -> 0 | S29: الثانية :- | T29: =IF(Q32=0,"",IF(AND(Q27>=P27*0.4,Q28>=P28*0.4,Q29>=P29*0.4,Q30>=P30*0.4,Q31>=P31*0.4),LOOKUP(Q32,'النتيجة النهائية'!$AA$6:$AB$10),"ضعيف ويحتاج الى اهتمام في المواد")) | W29: =ادخال1!$H$9 -> اللغة الإنجليزية | X29: =ادخال1!$H$7 -> 3 | Y29: =40*X29*0.3 -> 36 | Z29: =IFERROR(VLOOKUP(AD36,اسماء,7,0),"") -> 36 | AA29: =40*X29*0.3 -> 36 | AB29: =IFERROR(VLOOKUP(AD36,اسماء,17,0),"") -> 0 | AD29: الثانية :- | AE29: =IF(AB32=0,"",IF(AND(AB27>=AA27*0.4,AB28>=AA28*0.4,AB29>=AA29*0.4,AB30>=AA30*0.4,AB31>=AA31*0.4),LOOKUP(AB32,'النتيجة النهائية'!$AA$6:$AB$10),"ضعيف ويحتاج الى اهتمام في المواد")) | AH29: =ادخال1!$H$9 -> اللغة الإنجليزية | AI29: =ادخال1!$H$7 -> 3 | AJ29: =40*AI29*0.3 -> 36 | AK29: =IFERROR(VLOOKUP(AO36,اسماء,7,0),"") | AL29: =40*AI29*0.3 -> 36 | AM29: =IFERROR(VLOOKUP(AO36,اسماء,17,0),"") | AO29: الثانية :- | AP29: =IF(AM32=0,"",IF(AND(AM27>=AL27*0.4,AM28>=AL28*0.4,AM29>=AL29*0.4,AM30>=AL30*0.4,AM31>=AL31*0.4),LOOKUP(AM32,'النتيجة النهائية'!$AA$6:$AB$10),"ضعيف ويحتاج الى اهتمام في المواد"))
A30: =ادخال1!$I$9 -> الحاسوب | B30: =ادخال1!$I$7 -> 1 | C30: =40*B30*0.3 -> 12 | D30: =IFERROR(VLOOKUP(H36,اسماء,8,0),"") -> 12 | E30: =40*B30*0.3 -> 12 | F30: =IFERROR(VLOOKUP(H36,اسماء,18,0),"") -> 0 | H30: =IF(F27=0,"",IF(F27<E27*0.4,A27,"")) | I30: =IF(F28=0,"",IF(F28<E28*0.4,A28,"")) | J30: =IF(F29=0,"",IF(F29<E29*0.4,A29,"")) | L30: =ادخال1!$I$9 -> الحاسوب | M30: =ادخال1!$I$7 -> 1 | N30: =40*M30*0.3 -> 12 | O30: =IFERROR(VLOOKUP(S36,اسماء,8,0),"") -> 12 | P30: =40*M30*0.3 -> 12 | Q30: =IFERROR(VLOOKUP(S36,اسماء,18,0),"") -> 0 | S30: =IF(Q27=0,"",IF(Q27<P27*0.4,L27,"")) | T30: =IF(Q28=0,"",IF(Q28<P28*0.4,L28,"")) | U30: =IF(Q29=0,"",IF(Q29<P29*0.4,L29,"")) | W30: =ادخال1!$I$9 -> الحاسوب | X30: =ادخال1!$I$7 -> 1 | Y30: =40*X30*0.3 -> 12 | Z30: =IFERROR(VLOOKUP(AD36,اسماء,8,0),"") -> 12 | AA30: =40*X30*0.3 -> 12 | AB30: =IFERROR(VLOOKUP(AD36,اسماء,18,0),"") -> 0 | AD30: =IF(AB27=0,"",IF(AB27<AA27*0.4,W27,"")) | AE30: =IF(AB28=0,"",IF(AB28<AA28*0.4,W28,"")) | AF30: =IF(AB29=0,"",IF(AB29<AA29*0.4,W29,"")) | AH30: =ادخال1!$I$9 -> الحاسوب | AI30: =ادخال1!$I$7 -> 1 | AJ30: =40*AI30*0.3 -> 12 | AK30: =IFERROR(VLOOKUP(AO36,اسماء,8,0),"") | AL30: =40*AI30*0.3 -> 12 | AM30: =IFERROR(VLOOKUP(AO36,اسماء,18,0),"") | AO30: =IF(AM27=0,"",IF(AM27<AL27*0.4,AH27,"")) | AP30: =IF(AM28=0,"",IF(AM28<AL28*0.4,AH28,"")) | AQ30: =IF(AM29=0,"",IF(AM29<AL29*0.4,AH29,""))
A31: =ادخال1!$J$9 -> الرياضيات | B31: =ادخال1!$J$7 -> 5 | C31: =40*B31*0.3 -> 60 | D31: =IFERROR(VLOOKUP(H36,اسماء,9,0),"") -> 60 | E31: =40*B31*0.3 -> 60 | F31: =IFERROR(VLOOKUP(H36,اسماء,19,0),"") -> 0 | H31: =IF(F30=0,"",IF(F30<E30*0.4,A30,"")) | I31: =IF(F31=0,"",IF(F31<E31*0.4,A31,"")) | L31: =ادخال1!$J$9 -> الرياضيات | M31: =ادخال1!$J$7 -> 5 | N31: =40*M31*0.3 -> 60 | O31: =IFERROR(VLOOKUP(S36,اسماء,9,0),"") -> 58 | P31: =40*M31*0.3 -> 60 | Q31: =IFERROR(VLOOKUP(S36,اسماء,19,0),"") -> 0 | S31: =IF(Q30=0,"",IF(Q30<P30*0.4,L30,"")) | T31: =IF(Q31=0,"",IF(Q31<P31*0.4,L31,"")) | W31: =ادخال1!$J$9 -> الرياضيات | X31: =ادخال1!$J$7 -> 5 | Y31: =40*X31*0.3 -> 60 | Z31: =IFERROR(VLOOKUP(AD36,اسماء,9,0),"") -> 59 | AA31: =40*X31*0.3 -> 60 | AB31: =IFERROR(VLOOKUP(AD36,اسماء,19,0),"") -> 0 | AD31: =IF(AB30=0,"",IF(AB30<AA30*0.4,W30,"")) | AE31: =IF(AB31=0,"",IF(AB31<AA31*0.4,W31,"")) | AH31: =ادخال1!$J$9 -> الرياضيات | AI31: =ادخال1!$J$7 -> 5 | AJ31: =40*AI31*0.3 -> 60 | AK31: =IFERROR(VLOOKUP(AO36,اسماء,9,0),"") | AL31: =40*AI31*0.3 -> 60 | AM31: =IFERROR(VLOOKUP(AO36,اسماء,19,0),"") | AO31: =IF(AM30=0,"",IF(AM30<AL30*0.4,AH30,"")) | AP31: =IF(AM31=0,"",IF(AM31<AL31*0.4,AH31,""))
A32: المجموع العـام | C32: =SUM(C27:C31) -> 216 | D32: =SUM(D27:D31) -> 212 | E32: =SUM(E27:E31) -> 216 | F32: =SUM(F27:F31) -> 0 | H32: مدير المدرسة/ | I32: =ادخال1!$BG$5 -> د. عبدالرحمن خليفة العريبي | L32: المجموع العـام | N32: =SUM(N27:N31) -> 216 | O32: =SUM(O27:O31) -> 208 | P32: =SUM(P27:P31) -> 216 | Q32: =SUM(Q27:Q31) -> 0 | S32: مدير المدرسة/ | T32: =ادخال1!$BG$5 -> د. عبدالرحمن خليفة العريبي | W32: المجموع العـام | Y32: =SUM(Y27:Y31) -> 216 | Z32: =SUM(Z27:Z31) -> 211 | AA32: =SUM(AA27:AA31) -> 216 | AB32: =SUM(AB27:AB31) -> 0 | AD32: مدير المدرسة/ | AE32: =ادخال1!$BG$5 -> د. عبدالرحمن خليفة العريبي | AH32: المجموع العـام | AJ32: =SUM(AJ27:AJ31) -> 216 | AK32: =SUM(AK27:AK31) -> 0 | AL32: =SUM(AL27:AL31) -> 216 | AM32: =SUM(AM27:AM31) -> 0 | AO32: مدير المدرسة/ | AP32: =ادخال1!$BG$5 -> د. عبدالرحمن خليفة العريبي
A33: =ادخال1!$L$8 -> التربية الفنية | B33: =ادخال1!$L$7 -> 1 | C33: =IFERROR(VLOOKUP(H36,اسماء,11,0),"") -> جيد جداَ | E33: =IFERROR(VLOOKUP(H36,اسماء,21,0),"") -> 0 | H33: التاريخ | I33: =TODAY() -> 46005 | L33: =ادخال1!$L$8 -> التربية الفنية | M33: =ادخال1!$L$7 -> 1 | N33: =IFERROR(VLOOKUP(S36,اسماء,11,0),"") -> جيد جداَ | P33: =IFERROR(VLOOKUP(S36,اسماء,21,0),"") -> 0 | S33: التاريخ | T33: =TODAY() -> 46005 | W33: =ادخال1!$L$8 -> التربية الفنية | X33: =ادخال1!$L$7 -> 1 | Y33: =IFERROR(VLOOKUP(AD36,اسماء,11,0),"") -> جيد جداَ | AA33: =IFERROR(VLOOKUP(AD36,اسماء,21,0),"") -> 0 | AD33: التاريخ | AE33: =TODAY() -> 46005 | AH33: =ادخال1!$L$8 -> التربية الفنية | AI33: =ادخال1!$L$7 -> 1 | AJ33: =IFERROR(VLOOKUP(AO36,اسماء,11,0),"") | AL33: =IFERROR(VLOOKUP(AO36,اسماء,21,0),"") | AO33: التاريخ | AP33: =TODAY() -> 46005
A34: =ادخال1!$M$8 -> التربية البدنية | B34: =ادخال1!$M$7 -> 2 | C34: =IFERROR(VLOOKUP(H36,اسماء,12,0),"") -> جيد جداَ | E34: =IFERROR(VLOOKUP(H36,اسماء,22,0),"") -> 0 | L34: =ادخال1!$M$8 -> التربية البدنية | M34: =ادخال1!$M$7 -> 2 | N34: =IFERROR(VLOOKUP(S36,اسماء,12,0),"") -> جيد جداَ | P34: =IFERROR(VLOOKUP(S36,اسماء,22,0),"") -> 0 | W34: =ادخال1!$M$8 -> التربية البدنية | X34: =ادخال1!$M$7 -> 2 | Y34: =IFERROR(VLOOKUP(AD36,اسماء,12,0),"") -> جيد جداَ | AA34: =IFERROR(VLOOKUP(AD36,اسماء,22,0),"") -> 0 | AH34: =ادخال1!$M$8 -> التربية البدنية | AI34: =ادخال1!$M$7 -> 2 | AJ34: =IFERROR(VLOOKUP(AO36,اسماء,12,0),"") | AL34: =IFERROR(VLOOKUP(AO36,اسماء,22,0),"")
A35: =ادخال1!$N$8 -> مكتبة | B35: =ادخال1!$N$7 -> 1 | C35: =IFERROR(VLOOKUP(H36,اسماء,13,0),"") -> 0 | E35: =IFERROR(VLOOKUP(H36,اسماء,23,0),"") -> 0 | L35: =ادخال1!$N$8 -> مكتبة | M35: =ادخال1!$N$7 -> 1 | N35: =IFERROR(VLOOKUP(S36,اسماء,13,0),"") -> 0 | P35: =IFERROR(VLOOKUP(S36,اسماء,23,0),"") -> 0 | W35: =ادخال1!$N$8 -> مكتبة | X35: =ادخال1!$N$7 -> 1 | Y35: =IFERROR(VLOOKUP(AD36,اسماء,13,0),"") -> 0 | AA35: =IFERROR(VLOOKUP(AD36,اسماء,23,0),"") -> 0 | AH35: =ادخال1!$N$8 -> مكتبة | AI35: =ادخال1!$N$7 -> 1 | AJ35: =IFERROR(VLOOKUP(AO36,اسماء,13,0),"") | AL35: =IFERROR(VLOOKUP(AO36,اسماء,23,0),"")
A36: الرقم الوطني | B36: =IFERROR(VLOOKUP(H36,اسماء,62,0),"") -> 220180172537 | C36: =IFERROR(VLOOKUP(G41,اسماء,8,0),"") | D36: =IFERROR(VLOOKUP(H41,اسماء,8,0),"") | E36: =IFERROR(VLOOKUP(I41,اسماء,8,0),"") | H36: =INDEX(عمود2,MATCH(J23,عمود1)) -> ديالا علي حمد القبائلي | L36: الرقم الوطني | M36: =IFERROR(VLOOKUP(S36,اسماء,62,0),"") -> 120180241465 | N36: =IFERROR(VLOOKUP(R41,اسماء,8,0),"") | O36: =IFERROR(VLOOKUP(S41,اسماء,8,0),"") | P36: =IFERROR(VLOOKUP(T41,اسماء,8,0),"") | S36: =INDEX(عمود2,MATCH(U23,عمود1)) -> عبدالرحمن فرج محمد المغربي | W36: الرقم الوطني | X36: =IFERROR(VLOOKUP(AD36,اسماء,62,0),"") -> 0 | Y36: =IFERROR(VLOOKUP(AC41,اسماء,8,0),"") | Z36: =IFERROR(VLOOKUP(AD41,اسماء,8,0),"") | AA36: =IFERROR(VLOOKUP(AE41,اسماء,8,0),"") | AD36: =INDEX(عمود2,MATCH(AF23,عمود1)) -> ندى علاء محمد سلطان | AH36: الرقم الوطني | AI36: =IFERROR(VLOOKUP(AO36,اسماء,62,0),"") | AJ36: =IFERROR(VLOOKUP(AN41,اسماء,8,0),"") | AK36: =IFERROR(VLOOKUP(AO41,اسماء,8,0),"") | AL36: =IFERROR(VLOOKUP(AP41,اسماء,8,0),"") | AO36: =INDEX(عمود2,MATCH(AQ23,عمود1)) -> 0
A37: الســــــلوك | C37: =IFERROR(VLOOKUP(H36,اسماء,34,0),"") -> 0 | E37: =IFERROR(VLOOKUP(H36,اسماء,35,0),"") -> 0 | H37: كل كشط أو تغيير في هذه البطاقة يلغيها. | L37: الســــــلوك | N37: =IFERROR(VLOOKUP(S36,اسماء,34,0),"") -> 0 | P37: =IFERROR(VLOOKUP(S36,اسماء,35,0),"") -> 0 | S37: كل كشط أو تغيير في هذه البطاقة يلغيها. | W37: الســــــلوك | Y37: =IFERROR(VLOOKUP(AD36,اسماء,34,0),"") -> 0 | AA37: =IFERROR(VLOOKUP(AD36,اسماء,35,0),"") -> 0 | AD37: كل كشط أو تغيير في هذه البطاقة يلغيها. | AH37: الســــــلوك | AJ37: =IFERROR(VLOOKUP(AO36,اسماء,34,0),"") | AL37: =IFERROR(VLOOKUP(AO36,اسماء,35,0),"") | AO37: كل كشط أو تغيير في هذه البطاقة يلغيها.
A38: غياب مشروع | C38: =IFERROR(VLOOKUP(H36,اسماء,37,0),"") -> 0 | E38: =IFERROR(VLOOKUP(H36,اسماء,39,0),"") -> 0 | L38: غياب مشروع | N38: =IFERROR(VLOOKUP(S36,اسماء,37,0),"") -> 0 | P38: =IFERROR(VLOOKUP(S36,اسماء,39,0),"") -> 0 | W38: غياب مشروع | Y38: =IFERROR(VLOOKUP(AD36,اسماء,37,0),"") -> 0 | AA38: =IFERROR(VLOOKUP(AD36,اسماء,39,0),"") -> 0 | AH38: غياب مشروع | AJ38: =IFERROR(VLOOKUP(AO36,اسماء,37,0),"") | AL38: =IFERROR(VLOOKUP(AO36,اسماء,39,0),"")
A39: غياب غير مشروع | C39: =IFERROR(VLOOKUP(H36,اسماء,38,0),"") -> 0 | E39: =IFERROR(VLOOKUP(H36,اسماء,40,0),"") -> 0 | L39: غياب غير مشروع | N39: =IFERROR(VLOOKUP(S36,اسماء,38,0),"") -> 0 | P39: =IFERROR(VLOOKUP(S36,اسماء,40,0),"") -> 0 | W39: غياب غير مشروع | Y39: =IFERROR(VLOOKUP(AD36,اسماء,38,0),"") -> 0 | AA39: =IFERROR(VLOOKUP(AD36,اسماء,40,0),"") -> 0 | AH39: غياب غير مشروع | AJ39: =IFERROR(VLOOKUP(AO36,اسماء,38,0),"") | AL39: =IFERROR(VLOOKUP(AO36,اسماء,40,0),"")
A40: التوقيعــــات | B40: رائــد الصف | D40: مديـر المدرسة | H40: ولي الامر | L40: التوقيعــــات | M40: رائــد الصف | O40: مديـر المدرسة | S40: ولي الامر | W40: التوقيعــــات | X40: رائــد الصف | Z40: مديـر المدرسة | AD40: ولي الامر | AH40: التوقيعــــات | AI40: رائــد الصف | AK40: مديـر المدرسة | AO40: ولي الامر
A41: الفترة الاولى | L41: الفترة الاولى | W41: الفترة الاولى | AH41: الفترة الاولى
A42: الفترة الثانية | L42: الفترة الثانية | W42: الفترة الثانية | AH42: الفترة الثانية
...

Sheet ادخال1
B1: 1 | C1: 2 | D1: 3 | E1: 4 | F1: 5 | G1: 6 | H1: 7 | I1: 8 | J1: 9 | K1: 10 | L1: 11 | M1: 12 | N1: 13 | O1: 14 | P1: 15 | Q1: 16 | R1: 17 | S1: 18 | T1: 19 | U1: 20 | V1: 21 | W1: 22 | X1: 23 | Y1: 24 | Z1: 25 | AA1: 26 | AB1: 27 | AC1: 28 | AD1: 29 | AE1: 30 | AF1: 31 | AG1: 32 | AH1: 33 | AI1: 34 | AJ1: 35 | AK1: 36 | AL1: 37 | AM1: 38 | AN1: 39 | AO1: 40 | AP1: 41 | AQ1: 42 | AR1: 43 | AS1: 44 | AT1: 45 | AU1: 46 | AV1: 47 | AW1: 48 | AX1: 49 | AY1: 50 | AZ1: 51 | BA1: 52 | BB1: 53 | BC1: 54 | BD1: 55 | BE1: 56 | BF1: 57 | BG1: 58 | BH1: 59 | BI1: 60 | BJ1: 61 | BK1: 62 | BL1: 63 | BM1: 64 | BN1: 65 | BO1: 66 | BP1: 67 | BQ1: 68 | BR1: 69 | BS1: 70 | BT1: 71 | BU1: 72 | BV1: 73 | BW1: 74 | BX1: 75 | BY1: 76 | BZ1: 77 | CA1: 78 | CB1: 79 | CC1: 80 | CD1: 81 | CE1: 82 | CF1: 83 | CG1: 84 | CH1: 85 | CI1: 86 | CJ1: 87 | CK1: 85 | CL1: 86 | CM1: 87
A2: دولة ليبيا | D2: كشف رصد النتائج النهائية للصف الثاني من مرحلة التعليم الاساسي | O2: 4 | P2: 5 | Q2: 6 | R2: 7 | S2: 8 | T2: 9 | U2: 12 | V2: 13 | W2: 14 | Y2: 4 | Z2: 5 | AA2: 6 | AB2: 7 | AC2: 8 | AD2: 9 | AE2: 12 | AF2: 13 | AG2: 14 | BF2: أسماء المراجعين
A3: وزارة التعليم | L3: مكتب الامتحانات بمنطقة / تاجوراء | BF3: كتبه | CH3: مستجد
A4: المركز الوطني للامتحانات | D4: المرحلة/ | E4: التعليم الاساسي | K4: الثاني | O4: =ادخال1!O3 -> 0 | P4: =ادخال1!P3 -> 0 | Q4: =ادخال1!Q3 -> 0 | R4: =ادخال1!R3 -> 0 | S4: =ادخال1!S3 -> 0 | T4: =ادخال1!T3 -> 0 | U4: =ادخال1!U3 -> 0 | Y4: =ادخال1!Y3 -> 0 | Z4: =ادخال1!Z3 -> 0 | AA4: =ادخال1!AA3 -> 0 | AB4: =ادخال1!AB3 -> 0 | AC4: =ادخال1!AC3 -> 0 | AD4: =ادخال1!AD3 -> 0 | AE4: =ادخال1!AE3 -> 0 | BF4: املاه | CA4: شئون التعليم بمنطقة | CB4: تاجوراء | CH4: معيد
A5: المدرسة/ | B5: سهول العلم للتعليم الخاص | E5: العام الدراسي 1446 - 1447 هجرية/ الموافق : 2025 -2026 ميلادية مكتب الامتحانات بمنطقة / تاجوراء | AI5: خاص بالصحيفة | BF5: مدير المدرسة | BG5: د. عبدالرحمن خليفة العريبي | CA5: الصف | CB5: الثاني الابتدائي
A6: رقم مسلسل | B6: الاسم بالكامل | C6: تاريخ الميلاد | D6: اسم الام | E6: الفترة الأولى 30% من النهاية العظمى لكل مادة | O6: الفترة الثانية 30% من النهاية العظمى لكل مادة | Y6: الفترة الثالثة 40% من النهاية العظمى لكل مادة | AI6: السلوك | AL6: الغياب | BF6: مدير مكتب الامتحانات | BY6: المدرسة | BZ6: مدرسة سهول العلم للتعيم الخاص
F7: 3 | G7: 6 | H7: 3 | I7: 1 | J7: 5 | K7: المجموع | L7: 1 | M7: 2 | N7: 1 | P7: =F7 -> 3 | Q7: =G7 -> 6 | R7: =H7 -> 3 | S7: =I7 -> 1 | T7: =J7 -> 5 | U7: المجموع | V7: =L7 -> 1 | W7: =M7 -> 2 | X7: =N7 -> 1 | Z7: =F7 -> 3 | AA7: =G7 -> 6 | AB7: =H7 -> 3 | AC7: =I7 -> 1 | AD7: =J7 -> 5 | AE7: المجموع | AF7: =L7 -> 1 | AG7: =M7 -> 2 | AH7: =N7 -> 1 | CA7: العام الدراسي | CC7: المرحلة | CD7: الاساسي
F8: =F7*40*0.3 -> 36 | G8: =G7*40*0.3 -> 72 | H8: =H7*40*0.3 -> 36 | I8: =I7*40*0.3 -> 12 | J8: =J7*40*0.3 -> 60 | L8: التربية الفنية | M8: التربية البدنية | N8: مكتبة | P8: =F8 -> 36 | Q8: =G8 -> 72 | R8: =H8 -> 36 | S8: =I8 -> 12 | T8: =J8 -> 60 | V8: =L8 -> التربية الفنية | W8: =M8 -> التربية البدنية | X8: =N8 -> مكتبة | Z8: =Z7*40*0.4 -> 48 | AA8: =AA7*40*0.4 -> 96 | AB8: =AB7*40*0.4 -> 48 | AC8: =AC7*40*0.4 -> 16 | AD8: =AD7*40*0.4 -> 80 | AF8: =L8 -> التربية الفنية | AG8: =M8 -> التربية البدنية | AH8: =N8 -> مكتبة | BY8: المدرسة كائنة بمنطقة | BZ8: تاجوراء الجنوبي | CA8: 1446هـ/1447 هـ | CB8: 2026 /2025م
F9: التربية الإسلامية | G9: اللغة العربية | H9: اللغة الإنجليزية | I9: الحاسوب | J9: الرياضيات | P9: =F9 -> التربية الإسلامية | Q9: =G9 -> اللغة العربية | R9: =H9 -> اللغة الإنجليزية | S9: =I9 -> الحاسوب | T9: =J9 -> الرياضيات | Z9: =F9 -> التربية الإسلامية | AA9: =G9 -> اللغة العربية | AB9: =H9 -> اللغة الإنجليزية | AC9: =I9 -> الحاسوب | AD9: =J9 -> الرياضيات | AL9: الفترة الأولى | AN9: الفترة الثانية | AP9: الفترة الثالثة
K10: =SUM(F8:J8) -> 216 | L10: تقديرات | M10: تقديرات | N10: تقديرات | U10: =SUM(P8:T8) -> 216 | V10: =L10 -> تقديرات | W10: =M10 -> تقديرات | AE10: =SUM(Z8:AD8) -> 288 | AF10: =L10 -> تقديرات | AG10: =M10 -> تقديرات | AH10: =N10 -> تقديرات | AI10: الفترة الأولى | AJ10: الفترة الثانية | AK10: الفترة الثالثة | AL10: مشروع | AM10: غير مشروع | AN10: مشروع | AO10: غير مشروع | AP10: مشروع | AQ10: غير مشروع | AT10: غياب الانقطاع | AU10: تراتيب الفترة الأولى | AZ10: تراتيب الفترة الثانية | BE10: تراتيب الفترة الثالثة | BK10: اكتب الرقم الوطني هنا | BL10: اللقب | BM10: الرقم الوطني | BY10: مكان الميلاد | BZ10: جنسية الطالب | CA10: مستجد/ معيد | CB10: صفة القيد | CC10: رائد الفصل
A11: 1 | B11: الجبير خليل الدوكالي اليونسي | C11: 43087 | D11: مفيدة اليونسي | E11: الفترة الاول | F11: 25 | G11: 54 | H11: 25 | I11: 10 | J11: 24 | K11: =SUM(F11:J11) -> 138 | L11: جيد جداَ | M11: جيد جداَ | O11: الفترة الثانية | Y11: الفترة الثالثة | AR11: =K11+ROW()*0.0000001 -> 138 | AS11: =B11 -> الجبير خليل الدوكالي اليونسي | AU11: 1 | AV11: =IFERROR(LARGE($AR$11:$AR$396,AU11),"") -> 214 | AW11: =IFERROR(VLOOKUP(AV11,الترتيب1,2,0),"") -> سوزان عبدالباسط اللافى محمد | AX11: =U11+ROW()*0.0000001 -> 1.1e-06 | AY11: =AS11 -> الجبير خليل الدوكالي اليونسي | AZ11: 1 | BA11: =IFERROR(LARGE($AX$11:$AX$396,AZ11),"") -> 3.96e-05 | BB11: =IFERROR(VLOOKUP(BA11,الترتيب2,2,0),"") | BC11: =AE11+ROW()*0.0000001 -> 1.1e-06 | BD11: =AY11 -> الجبير خليل الدوكالي اليونسي | BE11: 1 | BF11: =IFERROR(LARGE($BC$11:$BC$396,BE11),"") -> 3.96e-05 | BG11: =IFERROR(VLOOKUP(BF11,الترتيب3,2,0),"") -> 0 | BK11: 120171064725 | BL11: اليونسي | BM11: =MID($BK11,12,1) -> 5 | BN11: =MID($BK11,11,1) -> 2 | BO11: =MID($BK11,10,1) -> 7 | BP11: =MID($BK11,9,1) -> 4 | BQ11: =MID($BK11,8,1) -> 6 | BR11: =MID($BK11,7,1) -> 0 | BS11: =MID($BK11,6,1) -> 1 | BT11: =MID($BK11,5,1) -> 7 | BU11: =MID($BK11,4,1) -> 1 | BV11: =MID($BK11,3,1) -> 0 | BW11: =MID($BK11,2,1) -> 2 | BX11: =MID($BK11,1,1) -> 1 | BY11: تاجوراء | BZ11: ليبي | CA11: مستجد | CB11: نظامي | CC11: أحلام الشيباني
A12: 2 | B12: ديالا علي حمد القبائلي | C12: 43147 | D12: أمل حسين أبوبكر | E12: الفترة الاول | F12: 34 | G12: 70 | H12: 36 | I12: 12 | J12: 60 | K12: =SUM(F12:J12) -> 212 | L12: جيد جداَ | M12: جيد جداَ | O12: الفترة الثانية | U12: =SUM(P12:T12) -> 0 | Y12: الفترة الثالثة | AE12: =SUM(Z12:AD12) -> 0 | AR12: =K12+ROW()*0.0000001 -> 212 | AS12: =B12 -> ديالا علي حمد القبائلي | AU12: 7 | AV12: =IFERROR(LARGE($AR$11:$AR$396,AU12),"") -> 210 | AW12: =IFERROR(VLOOKUP(AV12,الترتيب1,2,0),"") -> ميرال صالح محمد ديماس | AX12: =U12+ROW()*0.0000001 -> 1.2e-06 | AY12: =AS12 -> ديالا علي حمد القبائلي | AZ12: 7 | BA12: =IFERROR(LARGE($AX$11:$AX$396,AZ12),"") -> 3.9e-05 | BB12: =IFERROR(VLOOKUP(BA12,الترتيب2,2,0),"") -> 0 | BC12: =AE12+ROW()*0.0000001 -> 1.2e-06 | BD12: =AY12 -> ديالا علي حمد القبائلي | BE12: 7 | BF12: =IFERROR(LARGE($BC$11:$BC$396,BE12),"") -> 3.9e-05 | BG12: =IFERROR(VLOOKUP(BF12,الترتيب3,2,0),"") -> 0 | BK12: 220180172537 | BL12: القبائلي | BM12: =MID($BK12,12,1) -> 7 | BN12: =MID($BK12,11,1) -> 3 | BO12: =MID($BK12,10,1) -> 5 | BP12: =MID($BK12,9,1) -> 2 | BQ12: =MID($BK12,8,1) -> 7 | BR12: =MID($BK12,7,1) -> 1 | BS12: =MID($BK12,6,1) -> 0 | BT12: =MID($BK12,5,1) -> 8 | BU12: =MID($BK12,4,1) -> 1 | BV12: =MID($BK12,3,1) -> 0 | BW12: =MID($BK12,2,1) -> 2 | BX12: =MID($BK12,1,1) -> 2 | BY12: مصراته | BZ12: ليبية | CA12: مستجد | CB12: نظامي | CC12: أحلام الشيباني
A13: 3 | B13: رؤى عبدالحميد سيد ابوبكر عبداللطيف | C13: 43288 | D13: دنيا عرابي | E13: الفترة الاول | F13: 30 | G13: 48 | H13: 29 | I13: 12 | J13: 24 | K13: =SUM(F13:J13) -> 143 | L13: جيد جداَ | M13: جيد جداَ | O13: الفترة الثانية | U13: =SUM(P13:T13) -> 0 | Y13: الفترة الثالثة | AE13: =SUM(Z13:AD13) -> 0 | AR13: =K13+ROW()*0.0000001 -> 143 | AS13: =B13 -> رؤى عبدالحميد سيد ابوبكر عبداللطيف | AU13: 14 | AV13: =IFERROR(LARGE($AR$11:$AR$396,AU13),"") -> 128 | AW13: =IFERROR(VLOOKUP(AV13,الترتيب1,2,0),"") -> عبدالمجيد محمد عبدالمجيد عرابى | AX13: =U13+ROW()*0.0000001 -> 1.3e-06 | AY13: =AS13 -> رؤى عبدالحميد سيد ابوبكر عبداللطيف | AZ13: 14 | BA13: =IFERROR(LARGE($AX$11:$AX$396,AZ13),"") -> 3.83e-05 | BB13: =IFERROR(VLOOKUP(BA13,الترتيب2,2,0),"") -> 0 | BC13: =AE13+ROW()*0.0000001 -> 1.3e-06 | BD13: =AY13 -> رؤى عبدالحميد سيد ابوبكر عبداللطيف | BE13: 14 | BF13: =IFERROR(LARGE($BC$11:$BC$396,BE13),"") -> 3.83e-05 | BG13: =IFERROR(VLOOKUP(BF13,الترتيب3,2,0),"") -> 0 | BL13: عبداللطيف | BM13: =MID($BK13,12,1) | BN13: =MID($BK13,11,1) | BO13: =MID($BK13,10,1) | BP13: =MID($BK13,9,1) | BQ13: =MID($BK13,8,1) | BR13: =MID($BK13,7,1) | BS13: =MID($BK13,6,1) | BT13: =MID($BK13,5,1) | BU13: =MID($BK13,4,1) | BV13: =MID($BK13,3,1) | BW13: =MID($BK13,2,1) | BX13: =MID($BK13,1,1) | BY13: ليبيا | BZ13: مصرية | CA13: مستجد | CB13: نظامي | CC13: أحلام الشيباني
